Workbook

Sheet Matriz de Prioridade
B6: Projeto | I6: Complexidade | J6: =C27 | K6: =D27 -> 0
B7: ID Tprocess | I7: Criticidade | J7: =C36 | K7: =D36 -> 0
B8: Data de Abertura | I8: =B39 -> Criticidade x Complexidade | J8: =C39 | K8: =D39 -> 0
B9: Líder TI Alocado
B10: Quantidade de PAs
B11: =Dados!B7 -> Tipo de demanda
B12: =Dados!C7 -> Quantidade de PAs
B13: =Dados!D7 -> Áreas de TI envolvidas/Expertise
B14: =Dados!E7 -> Infra Plataforma (servidores, etc)
B15: =Dados!F7 -> Insumos Telecom (Links, etc)
B16: =Dados!G7 -> Licenças Gravação / Discador / Etc
B17: =Dados!H7 -> Fornecedores
B18: =Dados!I7 -> Outras áreas de apoio
B22: MATRIZ COMPLEXIDADE
B23: Lista | C23: Critérios | D23: Pontos
B24: =IF($C11<>"",$B11,"") | C24: =IF($C11<>"",$C11,"") | D24: =IF($C24<>"",VLOOKUP(CONCATENATE($B24,".",$C24),Dados!$D$38:$G$87,4,FALSE),"")
B25: =IF($C12<>"",$B12,"") | C25: =IF($C12<>"",$C12,"") | D25: =IF($C25<>"",VLOOKUP(CONCATENATE($B25,".",$C25),Dados!$D$38:$G$87,4,FALSE),"")
B26: =IF($C13<>"",$B13,"") | C26: =IF($C13<>"",$C13,"") | D26: =IF($C26<>"",VLOOKUP(CONCATENATE($B26,".",$C26),Dados!$D$38:$G$87,4,FALSE),"")
B27: Complexidade | C27: =IF(AND(D27>=Dados!B93,D27<=Dados!C93),Dados!D93,IF(AND(D27>=Dados!B92,D27<=Dados!C92),Dados!D92,IF(AND(D27>=Dados!B91,D27<=Dados!C91),Dados!D91,""))) | D27: =IFERROR(SUM(D24:D26),"") -> 0
B29: MATRIZ CRITICIDADE
B30: Lista | C30: Critérios | D30: Pontos
B31: =IF($C14<>"",$B14,"") | C31: =IF($C14<>"",$C14,"") | D31: =IF($C31<>"",VLOOKUP(CONCATENATE($B31,".",$C31),Dados!$D$38:$G$88,4,FALSE),"")
B32: =IF($C15<>"",$B15,"") | C32: =IF($C15<>"",$C15,"") | D32: =IF($C32<>"",VLOOKUP(CONCATENATE($B32,".",$C32),Dados!$D$38:$G$88,4,FALSE),"")
B33: =IF($C16<>"",$B16,"") | C33: =IF($C16<>"",$C16,"") | D33: =IF($C33<>"",VLOOKUP(CONCATENATE($B33,".",$C33),Dados!$D$38:$G$88,4,FALSE),"")
B34: =IF($C17<>"",$B17,"") | C34: =IF($C17<>"",$C17,"") | D34: =IF($C34<>"",VLOOKUP(CONCATENATE($B34,".",$C34),Dados!$D$38:$G$88,4,FALSE),"")
B35: =IF($C18<>"",$B18,"") | C35: =IF($C18<>"",$C18,"") | D35: =IF($C35<>"",VLOOKUP(CONCATENATE($B35,".",$C35),Dados!$D$38:$G$88,4,FALSE),"")
B36: Criticidade | C36: =IF(AND(D36>=Dados!B99,D36<=Dados!C99),Dados!D99,IF(AND(D36>=Dados!B98,D36<=Dados!C98),Dados!D98,IF(AND(D36>=Dados!B97,D36<=Dados!C97),Dados!D97,""))) | D36: =IFERROR(SUM(D31:D34),"") -> 0
B39: Criticidade x Complexidade | C39: =IF(AND((D27*D36)<=Dados!C103,(D27*D36)>=Dados!B103),Dados!D103,IF(AND(('Matriz de Prioridade'!D27*'Matriz de Prioridade'!D36)>=Dados!B104,('Matriz de Prioridade'!D27*'Matriz de Prioridade'!D36)<=Dados!C104),Dados!D104,IF(AND(('Matriz de Prioridade'!D27*'Matriz de Prioridade'!D36)>=Dados!B105,('Matriz de Prioridade'!D27*'Matriz de Prioridade'!D36)<=Dados!C105),Dados!D105,""))) | D39: =D27*D36 -> 0

Sheet Dados
B6: Lista
B7: Tipo de demanda | C7: Quantidade de PAs | D7: Áreas de TI envolvidas/Expertise | E7: Infra Plataforma (servidores, etc) | F7: Insumos Telecom (Links, etc) | G7: Licenças Gravação / Discador / Etc | H7: Fornecedores | I7: Outras áreas de apoio
B8: Implantação | C8: Até 10 PAs | D8: 1 | E8: 100% Saving | F8: 100% Saving | G8: 100% Saving | H8: Não há custo | I8: 1
B9: Infraestrutura | C9: de 10 a 50 PAs | D9: 2 | E9: 100% Compras | F9: 100% Compras | G9: 100% Compras | H9: Até R$ 5.000,00 | I9: 2
B10: Desenvolvimento | C10: De 51 a 100 PAs | D10: 3 | E10: 50% Saving e 50% Compras | F10: 50% Saving e 50% Compras | G10: 50% Saving e 50% Compras | H10: De R$ 5.000,00 a Até R$ 10.000,00 | I10: 3
B11: RTI | C11: Mais de 100 PAs | D11: Mais que 4 | E11: 75% Saving e 25% Compras | F11: 75% Saving e 25% Compras | G11: 75% Saving e 25% Compras | H11: De R$ 10.000,00 a Até R$ 30.000,00 | I11: Mais de 3
B12: Upgrade | E12: 75% Compras e 25% Saving | F12: 75% Compras e 25% Saving | G12: 75% Compras e 25% Saving | H12: Mais de R$ 30.000,00
B13: URA
B29: Nível de Urgência
B30: Pontuação | C30: Urgência
B31: 5 | C31: Necessidade de ação imediata
B32: 4 | C32: Muito Urgente
B33: 3 | C33: Urgente
B34: 2 | C34: Pouco urgente
B35: 1 | C35: Pode esperar
B37: Pontuação dos critérios
B38: Lista | C38: Critério | D38: Código | E38: Urgência | F38: Peso | G38: Pontuação
B39: =$B$7 -> Tipo de demanda | C39: =B8 -> Implantação | D39: =CONCATENATE(B39,".",C39) -> Tipo de demanda.Implantação | E39: 3 | F39: 1 | G39: =E39*F39 -> 3
B40: =$B$7 -> Tipo de demanda | C40: =B9 -> Infraestrutura | D40: =CONCATENATE(B40,".",C40) -> Tipo de demanda.Infraestrutura | E40: 2 | F40: 1 | G40: =E40*F40 -> 2
B41: =$B$7 -> Tipo de demanda | C41: =B10 -> Desenvolvimento | D41: =CONCATENATE(B41,".",C41) -> Tipo de demanda.Desenvolvimento | E41: 5 | F41: 1 | G41: =E41*F41 -> 5
B42: =$B$7 -> Tipo de demanda | C42: =B11 -> RTI | D42: =CONCATENATE(B42,".",C42) -> Tipo de demanda.RTI | E42: 4 | F42: 1 | G42: =E42*F42 -> 4
B43: =$B$7 -> Tipo de demanda | C43: =B12 -> Upgrade | D43: =CONCATENATE(B43,".",C43) -> Tipo de demanda.Upgrade | E43: 1 | F43: 1 | G43: =E43*F43 -> 1
B44: =$B$7 -> Tipo de demanda | C44: =B13 -> URA | D44: =CONCATENATE(B44,".",C44) -> Tipo de demanda.URA | E44: 2 | F44: 1 | G44: =E44*F44 -> 2
B45: =$C$7 -> Quantidade de PAs | C45: =C8 -> Até 10 PAs | D45: =CONCATENATE(B45,".",C45) -> Quantidade de PAs.Até 10 PAs | E45: 1 | F45: 1 | G45: =E45*F45 -> 1
B46: =$C$7 -> Quantidade de PAs | C46: =C9 -> de 10 a 50 PAs | D46: =CONCATENATE(B46,".",C46) -> Quantidade de PAs.de 10 a 50 PAs | E46: 2 | F46: 1 | G46: =E46*F46 -> 2
B47: =$C$7 -> Quantidade de PAs | C47: =C10 -> De 51 a 100 PAs | D47: =CONCATENATE(B47,".",C47) -> Quantidade de PAs.De 51 a 100 PAs | E47: 3 | F47: 1 | G47: =E47*F47 -> 3
B48: =$C$7 -> Quantidade de PAs | C48: =C11 -> Mais de 100 PAs | D48: =CONCATENATE(B48,".",C48) -> Quantidade de PAs.Mais de 100 PAs | E48: 4 | F48: 1 | G48: =E48*F48 -> 4
B49: =$D$7 -> Áreas de TI envolvidas/Expertise | C49: =D8 -> 1 | D49: =CONCATENATE(B49,".",C49) -> Áreas de TI envolvidas/Expertise.1 | E49: 2 | F49: 1 | G49: =E49*F49 -> 2
B50: =$D$7 -> Áreas de TI envolvidas/Expertise | C50: =D9 -> 2 | D50: =CONCATENATE(B50,".",C50) -> Áreas de TI envolvidas/Expertise.2 | E50: 3 | F50: 1 | G50: =E50*F50 -> 3
B51: =$D$7 -> Áreas de TI envolvidas/Expertise | C51: =D10 -> 3 | D51: =CONCATENATE(B51,".",C51) -> Áreas de TI envolvidas/Expertise.3 | E51: 4 | F51: 1 | G51: =E51*F51 -> 4
B52: =$D$7 -> Áreas de TI envolvidas/Expertise | C52: =D11 -> Mais que 4 | D52: =CONCATENATE(B52,".",C52) -> Áreas de TI envolvidas/Expertise.Mais que 4 | E52: 5 | F52: 1 | G52: =E52*F52 -> 5
B53: =$E$7 -> Infra Plataforma (servidores, etc) | C53: =E8 -> 100% Saving | D53: =CONCATENATE(B53,".",C53) -> Infra Plataforma (servidores, etc).100% Saving | E53: 1 | F53: 1 | G53: =E53*F53 -> 1
B54: =$E$7 -> Infra Plataforma (servidores, etc) | C54: =E9 -> 100% Compras | D54: =CONCATENATE(B54,".",C54) -> Infra Plataforma (servidores, etc).100% Compras | E54: 5 | F54: 1 | G54: =E54*F54 -> 5
B55: =$E$7 -> Infra Plataforma (servidores, etc) | C55: =E10 -> 50% Saving e 50% Compras | D55: =CONCATENATE(B55,".",C55) -> Infra Plataforma (servidores, etc).50% Saving e 50% Compras | E55: 3 | F55: 1 | G55: =E55*F55 -> 3
B56: =$E$7 -> Infra Plataforma (servidores, etc) | C56: =E11 -> 75% Saving e 25% Compras | D56: =CONCATENATE(B56,".",C56) -> Infra Plataforma (servidores, etc).75% Saving e 25% Compras | E56: 2 | F56: 1 | G56: =E56*F56 -> 2
B57: =$E$7 -> Infra Plataforma (servidores, etc) | C57: =E12 -> 75% Compras e 25% Saving | D57: =CONCATENATE(B57,".",C57) -> Infra Plataforma (servidores, etc).75% Compras e 25% Saving | E57: 4 | F57: 1 | G57: =E57*F57 -> 4
B58: =$F$7 -> Insumos Telecom (Links, etc) | C58: =F8 -> 100% Saving | D58: =CONCATENATE(B58,".",C58) -> Insumos Telecom (Links, etc).100% Saving | E58: 1 | F58: 1 | G58: =E58*F58 -> 1
B59: =$F$7 -> Insumos Telecom (Links, etc) | C59: =F9 -> 100% Compras | D59: =CONCATENATE(B59,".",C59) -> Insumos Telecom (Links, etc).100% Compras | E59: 5 | F59: 1 | G59: =E59*F59 -> 5
B60: =$F$7 -> Insumos Telecom (Links, etc) | C60: =F10 -> 50% Saving e 50% Compras | D60: =CONCATENATE(B60,".",C60) -> Insumos Telecom (Links, etc).50% Saving e 50% Compras | E60: 3 | F60: 1 | G60: =E60*F60 -> 3
B61: =$F$7 -> Insumos Telecom (Links, etc) | C61: =F11 -> 75% Saving e 25% Compras | D61: =CONCATENATE(B61,".",C61) -> Insumos Telecom (Links, etc).75% Saving e 25% Compras | E61: 2 | F61: 1 | G61: =E61*F61 -> 2
...

Sheet Plan1
B3: Complexidade
B4: Pontuar de 1 até 5 para Grau de Complexidade
B5: Tipo de demanda (1 a 5)
B6: Quantidade de PAs (1 a 4)
B7: Áreas de TI envolvidas/Exerpetise (2 a 5)
E9: De | F9: Até | G9: Grau
E10: 4 | F10: 6 | G10: Baixa
E11: 7 | F11: 10 | G11: Média
E12: 11 | F12: 14 | G12: Alta
B15: Criticidade
B16: Pontuar de 1 até 5 para Grau de Criticidade
B17: Infra Plataforma (servidores, etc) (1 a 5)
B18: Insumos Telecom (Links, etc) (1 a 5)
B19: Licenças Gravação / Discador / Etc (1 a 5)
B20: Fornecedores (1 a 5)
B21: Outras áreas de apoio (2 a 4)
E23: De | F23: Até | G23: Grau
E24: 6 | F24: 12 | G24: Baixa
E25: 13 | F25: 18 | G25: Média
E26: 19 | F26: 25 | G26: Alta
H28: MATRIZ EIXO X
H29: 24 < 133 | I29: P
H30: 134 < 243 | I30: M
H31: 244 < 350 | I31: G
