Workbook

Sheet Base
A1: Tipo de hora | B1: Cliente | C1: Campanha | D1: Funcionário | E1: Produto | F1: Jan/2019 | G1: Fev/2019 | H1: Mar/2019 | I1: Abr/2019 | J1: Mai/2019 | K1: Jun/2019 | L1: Jul/2019 | M1: Ago/2019 | N1: Set/2019 | O1: Out/2019 | P1: Nov/2019 | Q1: Dez/2019 | R1: Total 2019 | S1: Total | T1: Q1 | U1: Q2 | V1: Q3 | W1: Q4
A2: CLIENTE | B2: BOTICÁRIO | C2: Análise de Comunicação | D2: FLAVIA CASSIAS PEREIRA | E2: INSTITUCIONAL | F2: 0 | G2: 0 | H2: 0 | I2: 406.4514 | J2: 0 | K2: 0 | L2: 139.70673 | M2: 967.15613 | N2: 0 | O2: 0 | P2: 0 | Q2: 0 | R2: 0 | S2: 1513.3143 | T2: =SUM(BaseHoras[[#This Row],[Jan/2019]:[Mar/2019]]) -> 0 | U2: =SUM(BaseHoras[[#This Row],[Abr/2019]:[Jun/2019]]) -> 406.4514 | V2: =SUM(BaseHoras[[#This Row],[Jul/2019]:[Set/2019]]) -> 1106.8629 | W2: =SUM(BaseHoras[[#This Row],[Out/2019]:[Dez/2019]]) -> 0
A3: CLIENTE | B3: BOTICÁRIO | C3: Análise de Comunicação | D3: RAFAEL DE ANDRADE | E3: INSTITUCIONAL | F3: 0 | G3: 0 | H3: 0 | I3: 0 | J3: 0 | K3: 0 | L3: 36.166442 | M3: 0 | N3: 0 | O3: 0 | P3: 0 | Q3: 0 | R3: 0 | S3: 36.166442 | T3: =SUM(BaseHoras[[#This Row],[Jan/2019]:[Mar/2019]]) -> 0 | U3: =SUM(BaseHoras[[#This Row],[Abr/2019]:[Jun/2019]]) -> 0 | V3: =SUM(BaseHoras[[#This Row],[Jul/2019]:[Set/2019]]) -> 36.166442 | W3: =SUM(BaseHoras[[#This Row],[Out/2019]:[Dez/2019]]) -> 0
A4: CLIENTE | B4: BOTICÁRIO | C4: Arbo 2019 | D4: DANIELA MONTEIRO TEIXEIRA | E4: INSTITUCIONAL | F4: 0 | G4: 459.97973 | H4: 0 | I4: 0 | J4: 0 | K4: 0 | L4: 0 | M4: 0 | N4: 0 | O4: 0 | P4: 0 | Q4: 0 | R4: 0 | S4: 459.97973 | T4: =SUM(BaseHoras[[#This Row],[Jan/2019]:[Mar/2019]]) -> 459.97973 | U4: =SUM(BaseHoras[[#This Row],[Abr/2019]:[Jun/2019]]) -> 0 | V4: =SUM(BaseHoras[[#This Row],[Jul/2019]:[Set/2019]]) -> 0 | W4: =SUM(BaseHoras[[#This Row],[Out/2019]:[Dez/2019]]) -> 0
A5: CLIENTE | B5: BOTICÁRIO | C5: Arbo 2019 | D5: DANUBIA MIDORI BERTO FUJITA | E5: INSTITUCIONAL | F5: 829.62236 | G5: 0 | H5: 0 | I5: 0 | J5: 0 | K5: 0 | L5: 0 | M5: 0 | N5: 0 | O5: 0 | P5: 0 | Q5: 0 | R5: 0 | S5: 829.62236 | T5: =SUM(BaseHoras[[#This Row],[Jan/2019]:[Mar/2019]]) -> 829.62236 | U5: =SUM(BaseHoras[[#This Row],[Abr/2019]:[Jun/2019]]) -> 0 | V5: =SUM(BaseHoras[[#This Row],[Jul/2019]:[Set/2019]]) -> 0 | W5: =SUM(BaseHoras[[#This Row],[Out/2019]:[Dez/2019]]) -> 0
A6: CLIENTE | B6: BOTICÁRIO | C6: Arbo 2019 | D6: FLAVIA CASSIAS PEREIRA | E6: INSTITUCIONAL | F6: 0 | G6: 0 | H6: 0 | I6: 0 | J6: 0 | K6: 0 | L6: 0 | M6: 0 | N6: 0 | O6: 0 | P6: 224.24195 | Q6: 0 | R6: 0 | S6: 224.24195 | T6: =SUM(BaseHoras[[#This Row],[Jan/2019]:[Mar/2019]]) -> 0 | U6: =SUM(BaseHoras[[#This Row],[Abr/2019]:[Jun/2019]]) -> 0 | V6: =SUM(BaseHoras[[#This Row],[Jul/2019]:[Set/2019]]) -> 0 | W6: =SUM(BaseHoras[[#This Row],[Out/2019]:[Dez/2019]]) -> 224.24195
A7: CLIENTE | B7: BOTICÁRIO | C7: Arbo 2019 | D7: KATIA FONTANA | E7: INSTITUCIONAL | F7: 0 | G7: 0 | H7: 0 | I7: 0 | J7: 0 | K7: 0 | L7: 0 | M7: 0 | N7: 0 | O7: 89.179959 | P7: 0 | Q7: 0 | R7: 0 | S7: 89.179959 | T7: =SUM(BaseHoras[[#This Row],[Jan/2019]:[Mar/2019]]) -> 0 | U7: =SUM(BaseHoras[[#This Row],[Abr/2019]:[Jun/2019]]) -> 0 | V7: =SUM(BaseHoras[[#This Row],[Jul/2019]:[Set/2019]]) -> 0 | W7: =SUM(BaseHoras[[#This Row],[Out/2019]:[Dez/2019]]) -> 89.179959
A8: CLIENTE | B8: BOTICÁRIO | C8: Arbo 2019 | D8: LUCAS CABRINI | E8: INSTITUCIONAL | F8: 5.1362728 | G8: 0 | H8: 0 | I8: 0 | J8: 0 | K8: 0 | L8: 0 | M8: 0 | N8: 0 | O8: 0 | P8: 0 | Q8: 0 | R8: 0 | S8: 5.1362728 | T8: =SUM(BaseHoras[[#This Row],[Jan/2019]:[Mar/2019]]) -> 5.1362728 | U8: =SUM(BaseHoras[[#This Row],[Abr/2019]:[Jun/2019]]) -> 0 | V8: =SUM(BaseHoras[[#This Row],[Jul/2019]:[Set/2019]]) -> 0 | W8: =SUM(BaseHoras[[#This Row],[Out/2019]:[Dez/2019]]) -> 0
A9: CLIENTE | B9: BOTICÁRIO | C9: Arbo 2019 | D9: MARCOS PAULO SANTOS FALCAO | E9: INSTITUCIONAL | F9: 96.940704 | G9: 8.1240933 | H9: 0 | I9: 0 | J9: 0 | K9: 0 | L9: 0 | M9: 0 | N9: 0 | O9: 0 | P9: 0 | Q9: 0 | R9: 0 | S9: 105.0648 | T9: =SUM(BaseHoras[[#This Row],[Jan/2019]:[Mar/2019]]) -> 105.0648 | U9: =SUM(BaseHoras[[#This Row],[Abr/2019]:[Jun/2019]]) -> 0 | V9: =SUM(BaseHoras[[#This Row],[Jul/2019]:[Set/2019]]) -> 0 | W9: =SUM(BaseHoras[[#This Row],[Out/2019]:[Dez/2019]]) -> 0
A10: CLIENTE | B10: BOTICÁRIO | C10: Arbo 2019 | D10: RAFAEL DE ANDRADE | E10: INSTITUCIONAL | F10: 0 | G10: 0 | H10: 0 | I10: 0 | J10: 0 | K10: 0 | L10: 0 | M10: 0 | N10: 0 | O10: 1703.7299 | P10: 15.148307 | Q10: 0 | R10: 0 | S10: 1718.8782 | T10: =SUM(BaseHoras[[#This Row],[Jan/2019]:[Mar/2019]]) -> 0 | U10: =SUM(BaseHoras[[#This Row],[Abr/2019]:[Jun/2019]]) -> 0 | V10: =SUM(BaseHoras[[#This Row],[Jul/2019]:[Set/2019]]) -> 0 | W10: =SUM(BaseHoras[[#This Row],[Out/2019]:[Dez/2019]]) -> 1718.8782
A11: CLIENTE | B11: BOTICÁRIO | C11: Arbo 2019 | D11: RODRIGO DE MEDEIROS FALCAO | E11: INSTITUCIONAL | F11: 100.65043 | G11: 6.8154527 | H11: 0 | I11: 0 | J11: 0 | K11: 0 | L11: 0 | M11: 0 | N11: 0 | O11: 0 | P11: 0 | Q11: 0 | R11: 0 | S11: 107.46588 | T11: =SUM(BaseHoras[[#This Row],[Jan/2019]:[Mar/2019]]) -> 107.46588 | U11: =SUM(BaseHoras[[#This Row],[Abr/2019]:[Jun/2019]]) -> 0 | V11: =SUM(BaseHoras[[#This Row],[Jul/2019]:[Set/2019]]) -> 0 | W11: =SUM(BaseHoras[[#This Row],[Out/2019]:[Dez/2019]]) -> 0
A12: CLIENTE | B12: BOTICÁRIO | C12: Arbo 2020 | D12: CAROLINE DIAS CRAVEIRO FADEL | E12: ARBO | F12: 0 | G12: 0 | H12: 0 | I12: 0 | J12: 0 | K12: 0 | L12: 0 | M12: 0 | N12: 0 | O12: 0 | P12: 30.39964 | Q12: 0 | R12: 0 | S12: 30.39964 | T12: =SUM(BaseHoras[[#This Row],[Jan/2019]:[Mar/2019]]) -> 0 | U12: =SUM(BaseHoras[[#This Row],[Abr/2019]:[Jun/2019]]) -> 0 | V12: =SUM(BaseHoras[[#This Row],[Jul/2019]:[Set/2019]]) -> 0 | W12: =SUM(BaseHoras[[#This Row],[Out/2019]:[Dez/2019]]) -> 30.39964
A13: CLIENTE | B13: BOTICÁRIO | C13: Arbo 2020 | D13: DANIELA MONTEIRO TEIXEIRA | E13: ARBO | F13: 0 | G13: 0 | H13: 0 | I13: 0 | J13: 0 | K13: 0 | L13: 0 | M13: 0 | N13: 0 | O13: 0 | P13: 0 | Q13: 38.341262 | R13: 0 | S13: 38.341262 | T13: =SUM(BaseHoras[[#This Row],[Jan/2019]:[Mar/2019]]) -> 0 | U13: =SUM(BaseHoras[[#This Row],[Abr/2019]:[Jun/2019]]) -> 0 | V13: =SUM(BaseHoras[[#This Row],[Jul/2019]:[Set/2019]]) -> 0 | W13: =SUM(BaseHoras[[#This Row],[Out/2019]:[Dez/2019]]) -> 38.341262
... A35: CLIENTE | B35: BOTICÁRIO | C35: BOTICA 214 2019 | D35: CARLOS YANKE | E35: ANFORAS COLECIONAVEIS | F35: 51.847692 | G35: 233.59802 | H35: 0 | I35: 0 | J35: 0 | K35: 0 | L35: 0 | M35: 0 | N35: 0 | O35: 0 | P35: 0 | Q35: 0 | R35: 0 | S35: 285.44571 | T35: =SUM(BaseHoras[[#This Row],[Jan/2019]:[Mar/2019]]) -> 285.44571 | U35: =SUM(BaseHoras[[#This Row],[Abr/2019]:[Jun/2019]]) -> 0 | V35: =SUM(BaseHoras[[#This Row],[Jul/2019]:[Set/2019]]) -> 0 | W35: =SUM(BaseHoras[[#This Row],[Out/2019]:[Dez/2019]]) -> 0
A36: CLIENTE | B36: BOTICÁRIO | C36: BOTICA 214 2019 | D36: ELIANA APARECIDA PAVAN | E36: ANFORAS COLECIONAVEIS | F36: 0 | G36: 0 | H36: 0 | I36: 0 | J36: 0 | K36: 0 | L36: 0 | M36: 0 | N36: 0 | O36: 0 | P36: .5 | Q36: 0 | R36: 0 | S36: 0 | T36: =SUM(BaseHoras[[#This Row],[Jan/2019]:[Mar/2019]]) -> 0 | U36: =SUM(BaseHoras[[#This Row],[Abr/2019]:[Jun/2019]]) -> 0 | V36: =SUM(BaseHoras[[#This Row],[Jul/2019]:[Set/2019]]) -> 0 | W36: =SUM(BaseHoras[[#This Row],[Out/2019]:[Dez/2019]]) -> 0
A37: CLIENTE | B37: BOTICÁRIO | C37: BOTICA 214 2019 | D37: HUGO LUQUETTI PONTES | E37: ANFORAS COLECIONAVEIS | F37: 37.577399 | G37: 47.028295 | H37: 0 | I37: 0 | J37: 0 | K37: 0 | L37: 0 | M37: 0 | N37: 0 | O37: 0 | P37: 0 | Q37: 0 | R37: 0 | S37: 84.605694 | T37: =SUM(BaseHoras[[#This Row],[Jan/2019]:[Mar/2019]]) -> 84.605694 | U37: =SUM(BaseHoras[[#This Row],[Abr/2019]:[Jun/2019]]) -> 0 | V37: =SUM(BaseHoras[[#This Row],[Jul/2019]:[Set/2019]]) -> 0 | W37: =SUM(BaseHoras[[#This Row],[Out/2019]:[Dez/2019]]) -> 0
A38: CLIENTE | B38: BOTICÁRIO | C38: BOTICA 214 2019 | D38: LUCIO CLETO DE FREITAS | E38: ANFORAS COLECIONAVEIS | F38: 13.847966 | G38: 0 | H38: 0 | I38: 0 | J38: 0 | K38: 0 | L38: 0 | M38: 0 | N38: 0 | O38: 0 | P38: 0 | Q38: 0 | R38: 0 | S38: 13.847966 | T38: =SUM(BaseHoras[[#This Row],[Jan/2019]:[Mar/2019]]) -> 13.847966 | U38: =SUM(BaseHoras[[#This Row],[Abr/2019]:[Jun/2019]]) -> 0 | V38: =SUM(BaseHoras[[#This Row],[Jul/2019]:[Set/2019]]) -> 0 | W38: =SUM(BaseHoras[[#This Row],[Out/2019]:[Dez/2019]]) -> 0
A39: CLIENTE | B39: BOTICÁRIO | C39: BOTICA 214 2019 | D39: MARCELO LOPES NOGUEIRA | E39: ANFORAS COLECIONAVEIS | F39: 0 | G39: 36.183388 | H39: 0 | I39: 0 | J39: 0 | K39: 0 | L39: 0 | M39: 0 | N39: 0 | O39: 0 | P39: 0 | Q39: 0 | R39: 0 | S39: 36.183388 | T39: =SUM(BaseHoras[[#This Row],[Jan/2019]:[Mar/2019]]) -> 36.183388 | U39: =SUM(BaseHoras[[#This Row],[Abr/2019]:[Jun/2019]]) -> 0 | V39: =SUM(BaseHoras[[#This Row],[Jul/2019]:[Set/2019]]) -> 0 | W39: =SUM(BaseHoras[[#This Row],[Out/2019]:[Dez/2019]]) -> 0
A40: CLIENTE | B40: BOTICÁRIO | C40: BOTICA 214 2019 | D40: MARCO LUIZ BORTOLAZZO | E40: ANFORAS COLECIONAVEIS | F40: 51.169219 | G40: 0 | H40: 0 | I40: 0 | J40: 0 | K40: 0 | L40: 0 | M40: 0 | N40: 0 | O40: 0 | P40: 0 | Q40: 0 | R40: 0 | S40: 51.169219 | T40: =SUM(BaseHoras[[#This Row],[Jan/2019]:[Mar/2019]]) -> 51.169219 | U40: =SUM(BaseHoras[[#This Row],[Abr/2019]:[Jun/2019]]) -> 0 | V40: =SUM(BaseHoras[[#This Row],[Jul/2019]:[Set/2019]]) -> 0 | W40: =SUM(BaseHoras[[#This Row],[Out/2019]:[Dez/2019]]) -> 0
A41: CLIENTE | B41: BOTICÁRIO | C41: BOTICA 214 2019 | D41: MARIA FERNANDA SANTIAGO VELLUTINI | E41: ANFORAS COLECIONAVEIS | F41: 317.84829 | G41: 0 | H41: 0 | I41: 0 | J41: 0 | K41: 0 | L41: 0 | M41: 0 | N41: 0 | O41: 0 | P41: 0 | Q41: 0 | R41: 0 | S41: 317.84829 | T41: =SUM(BaseHoras[[#This Row],[Jan/2019]:[Mar/2019]]) -> 317.84829 | U41: =SUM(BaseHoras[[#This Row],[Abr/2019]:[Jun/2019]]) -> 0 | V41: =SUM(BaseHoras[[#This Row],[Jul/2019]:[Set/2019]]) -> 0 | W41: =SUM(BaseHoras[[#This Row],[Out/2019]:[Dez/2019]]) -> 0
A42: CLIENTE | B42: BOTICÁRIO | C42: BOTICA 214 2019 | D42: MARIA GABRIELA WEY SALMON | E42: ANFORAS COLECIONAVEIS | F42: 7.5007883 | G42: 0 | H42: 0 | I42: 0 | J42: 0 | K42: 0 | L42: 0 | M42: 0 | N42: 0 | O42: 0 | P42: 0 | Q42: 0 | R42: 0 | S42: 7.5007883 | T42: =SUM(BaseHoras[[#This Row],[Jan/2019]:[Mar/2019]]) -> 7.5007883 | U42: =SUM(BaseHoras[[#This Row],[Abr/2019]:[Jun/2019]]) -> 0 | V42: =SUM(BaseHoras[[#This Row],[Jul/2019]:[Set/2019]]) -> 0 | W42: =SUM(BaseHoras[[#This Row],[Out/2019]:[Dez/2019]]) -> 0
A43: CLIENTE | B43: BOTICÁRIO | C43: BOTICA 214 2019 | D43: MARIA TEREZA SETTI DE ARRUDA MORAN | E43: ANFORAS COLECIONAVEIS | F43: 0 | G43: 0 | H43: 0 | I43: 18.393016 | J43: 0 | K43: 0 | L43: 0 | M43: 0 | N43: 0 | O43: 0 | P43: 0 | Q43: 0 | R43: 0 | S43: 18.393016 | T43: =SUM(BaseHoras[[#This Row],[Jan/2019]:[Mar/2019]]) -> 0 | U43: =SUM(BaseHoras[[#This Row],[Abr/2019]:[Jun/2019]]) -> 18.393016 | V43: =SUM(BaseHoras[[#This Row],[Jul/2019]:[Set/2019]]) -> 0 | W43: =SUM(BaseHoras[[#This Row],[Out/2019]:[Dez/2019]]) -> 0
A44: CLIENTE | B44: BOTICÁRIO | C44: BOTICA 214 2019 | D44: MAURO MIYASHIRO MAEDO JUNIOR | E44: ANFORAS COLECIONAVEIS | F44: 1067.4783 | G44: 370.55561 | H44: 0 | I44: 0 | J44: 0 | K44: 0 | L44: 0 | M44: 0 | N44: 0 | O44: 0 | P44: 0 | Q44: 0 | R44: 0 | S44: 1438.0339 | T44: =SUM(BaseHoras[[#This Row],[Jan/2019]:[Mar/2019]]) -> 1438.0339 | U44: =SUM(BaseHoras[[#This Row],[Abr/2019]:[Jun/2019]]) -> 0 | V44: =SUM(BaseHoras[[#This Row],[Jul/2019]:[Set/2019]]) -> 0 | W44: =SUM(BaseHoras[[#This Row],[Out/2019]:[Dez/2019]]) -> 0
A45: CLIENTE | B45: BOTICÁRIO | C45: BOTICA 214 2019 | D45: NELSON PRADO DOS SANTOS | E45: ANFORAS COLECIONAVEIS | F45: 0 | G45: 20.743222 | H45: 0 | I45: 0 | J45: 0 | K45: 0 | L45: 0 | M45: 0 | N45: 0 | O45: 0 | P45: 0 | Q45: 0 | R45: 0 | S45: 20.743222 | T45: =SUM(BaseHoras[[#This Row],[Jan/2019]:[Mar/2019]]) -> 20.743222 | U45: =SUM(BaseHoras[[#This Row],[Abr/2019]:[Jun/2019]]) -> 0 | V45: =SUM(BaseHoras[[#This Row],[Jul/2019]:[Set/2019]]) -> 0 | W45: =SUM(BaseHoras[[#This Row],[Out/2019]:[Dez/2019]]) -> 0
A46: CLIENTE | B46: BOTICÁRIO | C46: BOTICA 214 2019 | D46: RICARDO MINERVINO FILHO | E46: ANFORAS COLECIONAVEIS | F46: 0 | G46: 74.189896 | H46: 13.975295 | I46: 0 | J46: 0 | K46: 0 | L46: 0 | M46: 0 | N46: 0 | O46: 0 | P46: 0 | Q46: 0 | R46: 0 | S46: 88.165191 | T46: =SUM(BaseHoras[[#This Row],[Jan/2019]:[Mar/2019]]) -> 88.165191 | U46: =SUM(BaseHoras[[#This Row],[Abr/2019]:[Jun/2019]]) -> 0 | V46: =SUM(BaseHoras[[#This Row],[Jul/2019]:[Set/2019]]) -> 0 | W46: =SUM(BaseHoras[[#This Row],[Out/2019]:[Dez/2019]]) -> 0
A47: CLIENTE | B47: BOTICÁRIO | C47: BOTICA 214 2019 | D47: ROSE CLEIDE SOARES RIBEIRO | E47: ANFORAS COLECIONAVEIS | F47: 0 | G47: 0 | H47: 0 | I47: 0 | J47: 0 | K47: 0 | L47: 0 | M47: 0 | N47: 0 | O47: 0 | P47: 7.2654831 | Q47: 0 | R47: 0 | S47: 7.2654831 | T47: =SUM(BaseHoras[[#This Row],[Jan/2019]:[Mar/2019]]) -> 0 | U47: =SUM(BaseHoras[[#This Row],[Abr/2019]:[Jun/2019]]) -> 0 | V47: =SUM(BaseHoras[[#This Row],[Jul/2019]:[Set/2019]]) -> 0 | W47: =SUM(BaseHoras[[#This Row],[Out/2019]:[Dez/2019]]) -> 7.2654831
A48: CLIENTE | B48: BOTICÁRIO | C48: BOTICA 214 2019 | D48: VITOR HUGO FAVERO PIZA | E48: ANFORAS COLECIONAVEIS | F48: 15.906451 | G48: 0 | H48: 0 | I48: 0 | J48: 0 | K48: 0 | L48: 0 | M48: 0 | N48: 0 | O48: 0 | P48: 0 | Q48: 0 | R48: 0 | S48: 15.906451 | T48: =SUM(BaseHoras[[#This Row],[Jan/2019]:[Mar/2019]]) -> 15.906451 | U48: =SUM(BaseHoras[[#This Row],[Abr/2019]:[Jun/2019]]) -> 0 | V48: =SUM(BaseHoras[[#This Row],[Jul/2019]:[Set/2019]]) -> 0 | W48: =SUM(BaseHoras[[#This Row],[Out/2019]:[Dez/2019]]) -> 0
A49: CLIENTE | B49: BOTICÁRIO | C49: BOTICÁRIO 2019 | D49: ANA CECILIA DA COSTA | E49: INSTITUCIONAL | F49: 0 | G49: 0 | H49: 0 | I49: .5 | J49: 0 | K49: 0 | L49: 0 | M49: 0 | N49: 0 | O49: 0 | P49: 0 | Q49: 0 | R49: 0 | S49: 0 | T49: =SUM(BaseHoras[[#This Row],[Jan/2019]:[Mar/2019]]) -> 0 | U49: =SUM(BaseHoras[[#This Row],[Abr/2019]:[Jun/2019]]) -> 0 | V49: =SUM(BaseHoras[[#This Row],[Jul/2019]:[Set/2019]]) -> 0 | W49: =SUM(BaseHoras[[#This Row],[Out/2019]:[Dez/2019]]) -> 0
A50: CLIENTE | B50: BOTICÁRIO | C50: BOTICÁRIO 2019 | D50: DANIEL JOSE CHAGAS MARTINS | E50: INSTITUCIONAL | F50: 0 | G50: 2556.7332 | H50: 0 | I50: 0 | J50: 0 | K50: 0 | L50: 0 | M50: 0 | N50: 0 | O50: 0 | P50: 0 | Q50: 0 | R50: 0 | S50: 2556.7332 | T50: =SUM(BaseHoras[[#This Row],[Jan/2019]:[Mar/2019]]) -> 2556.7332 | U50: =SUM(BaseHoras[[#This Row],[Abr/2019]:[Jun/2019]]) -> 0 | V50: =SUM(BaseHoras[[#This Row],[Jul/2019]:[Set/2019]]) -> 0 | W50: =SUM(BaseHoras[[#This Row],[Out/2019]:[Dez/2019]]) -> 0
A51: CLIENTE | B51: BOTICÁRIO | C51: BOTICÁRIO 2019 | D51: FLAVIA CASSIAS PEREIRA | E51: INSTITUCIONAL | F51: 0 | G51: 0 | H51: 0 | I51: 38.263136 | J51: 0 | K51: 0 | L51: 0 | M51: 0 | N51: 0 | O51: 0 | P51: 0 | Q51: 0 | R51: 0 | S51: 38.263136 | T51: =SUM(BaseHoras[[#This Row],[Jan/2019]:[Mar/2019]]) -> 0 | U51: =SUM(BaseHoras[[#This Row],[Abr/2019]:[Jun/2019]]) -> 38.263136 | V51: =SUM(BaseHoras[[#This Row],[Jul/2019]:[Set/2019]]) -> 0 | W51: =SUM(BaseHoras[[#This Row],[Out/2019]:[Dez/2019]]) -> 0
A52: CLIENTE | B52: BOTICÁRIO | C52: BOTICÁRIO 2019 | D52: HELIO SILVA BALBI | E52: INSTITUCIONAL | F52: 0 | G52: 0 | H52: 0 | I52: 0 | J52: 0 | K52: 0 | L52: 0 | M52: 0 | N52: 0 | O52: 0 | P52: 0 | Q52: 5.6339498 | R52: 0 | S52: 5.6339498 | T52: =SUM(BaseHoras[[#This Row],[Jan/2019]:[Mar/2019]]) -> 0 | U52: =SUM(BaseHoras[[#This Row],[Abr/2019]:[Jun/2019]]) -> 0 | V52: =SUM(BaseHoras[[#This Row],[Jul/2019]:[Set/2019]]) -> 0 | W52: =SUM(BaseHoras[[#This Row],[Out/2019]:[Dez/2019]]) -> 5.6339498
A53: CLIENTE | B53: BOTICÁRIO | C53: BOTICÁRIO 2019 | D53: LERYNDA MARCIA DA SILVA LIMA | E53: INSTITUCIONAL | F53: 0 | G53: 0 | H53: 0 | I53: 0 | J53: 0 | K53: 0 | L53: 0 | M53: 0 | N53: 0 | O53: 0 | P53: 55.578349 | Q53: 0 | R53: 0 | S53: 55.578349 | T53: =SUM(BaseHoras[[#This Row],[Jan/2019]:[Mar/2019]]) -> 0 | U53: =SUM(BaseHoras[[#This Row],[Abr/2019]:[Jun/2019]]) -> 0 | V53: =SUM(BaseHoras[[#This Row],[Jul/2019]:[Set/2019]]) -> 0 | W53: =SUM(BaseHoras[[#This Row],[Out/2019]:[Dez/2019]]) -> 55.578349
A54: CLIENTE | B54: BOTICÁRIO | C54: BOTICÁRIO 2019 | D54: REINALDO APARECIDO MACEDO | E54: INSTITUCIONAL | F54: 333.21112 | G54: 0 | H54: 0 | I54: 0 | J54: 0 | K54: 0 | L54: 0 | M54: 0 | N54: 0 | O54: 0 | P54: 0 | Q54: 0 | R54: 0 | S54: 333.21112 | T54: =SUM(BaseHoras[[#This Row],[Jan/2019]:[Mar/2019]]) -> 333.21112 | U54: =SUM(BaseHoras[[#This Row],[Abr/2019]:[Jun/2019]]) -> 0 | V54: =SUM(BaseHoras[[#This Row],[Jul/2019]:[Set/2019]]) -> 0 | W54: =SUM(BaseHoras[[#This Row],[Out/2019]:[Dez/2019]]) -> 0
A55: CLIENTE | B55: BOTICÁRIO | C55: BOTICÁRIO 2019 | D55: SANDRO JUNQUEIRA DE FREITAS | E55: INSTITUCIONAL | F55: 0 | G55: 0 | H55: 0 | I55: 1355.5032 | J55: 1807.4321 | K55: 586.44175 | L55: 0 | M55: 0 | N55: 0 | O55: 0 | P55: 0 | Q55: 0 | R55: 0 | S55: 3749.3771 | T55: =SUM(BaseHoras[[#This Row],[Jan/2019]:[Mar/2019]]) -> 0 | U55: =SUM(BaseHoras[[#This Row],[Abr/2019]:[Jun/2019]]) -> 3749.3771 | V55: =SUM(BaseHoras[[#This Row],[Jul/2019]:[Set/2019]]) -> 0 | W55: =SUM(BaseHoras[[#This Row],[Out/2019]:[Dez/2019]]) -> 0
A56: CLIENTE | B56: BOTICÁRIO | C56: BOTICÁRIO 2019 | D56: TAIS CONCEICAO DOS SANTOS | E56: INSTITUCIONAL | F56: 0 | G56: 0 | H56: 0 | I56: 0 | J56: 0 | K56: 0 | L56: 0 | M56: 0 | N56: 57.230503 | O56: 0 | P56: 0 | Q56: 0 | R56: 0 | S56: 57.230503 | T56: =SUM(BaseHoras[[#This Row],[Jan/2019]:[Mar/2019]]) -> 0 | U56: =SUM(BaseHoras[[#This Row],[Abr/2019]:[Jun/2019]]) -> 0 | V56: =SUM(BaseHoras[[#This Row],[Jul/2019]:[Set/2019]]) -> 57.230503 | W56: =SUM(BaseHoras[[#This Row],[Out/2019]:[Dez/2019]]) -> 0
A57: CLIENTE | B57: BOTICÁRIO | C57: BOTICÁRIO 2019 | D57: TATIANA ANGELIM MARTINS | E57: INSTITUCIONAL | F57: 0 | G57: 0 | H57: 39.909461 | I57: 122.92638 | J57: 0 | K57: 0 | L57: 0 | M57: 0 | N57: 0 | O57: 0 | P57: 0 | Q57: 0 | R57: 0 | S57: 162.83584 | T57: =SUM(BaseHoras[[#This Row],[Jan/2019]:[Mar/2019]]) -> 39.909461 | U57: =SUM(BaseHoras[[#This Row],[Abr/2019]:[Jun/2019]]) -> 122.92638 | V57: =SUM(BaseHoras[[#This Row],[Jul/2019]:[Set/2019]]) -> 0 | W57: =SUM(BaseHoras[[#This Row],[Out/2019]:[Dez/2019]]) -> 0
A58: CLIENTE | B58: BOTICÁRIO | C58: BOTICÁRIO 2019 | D58: VERA APARECIDA JACINTO | E58: INSTITUCIONAL | F58: 0 | G58: 0 | H58: 0 | I58: 0 | J58: 0 | K58: 106.08261 | L58: 37.823957 | M58: 0 | N58: 0 | O58: 0 | P58: 0 | Q58: 0 | R58: 0 | S58: 143.90657 | T58: =SUM(BaseHoras[[#This Row],[Jan/2019]:[Mar/2019]]) -> 0 | U58: =SUM(BaseHoras[[#This Row],[Abr/2019]:[Jun/2019]]) -> 106.08261 | V58: =SUM(BaseHoras[[#This Row],[Jul/2019]:[Set/2019]]) -> 37.823957 | W58: =SUM(BaseHoras[[#This Row],[Out/2019]:[Dez/2019]]) -> 0
A59: CLIENTE | B59: BOTICÁRIO | C59: Boti Conecta | D59: FLAVIA CASSIAS PEREIRA | E59: INSTITUCIONAL | F59: 0 | G59: 0 | H59: 0 | I59: 0 | J59: 0 | K59: 0 | L59: 0 | M59: 0 | N59: 0 | O59: 0 | P59: 0 | Q59: 29.501575 | R59: 0 | S59: 29.501575 | T59: =SUM(BaseHoras[[#This Row],[Jan/2019]:[Mar/2019]]) -> 0 | U59: =SUM(BaseHoras[[#This Row],[Abr/2019]:[Jun/2019]]) -> 0 | V59: =SUM(BaseHoras[[#This Row],[Jul/2019]:[Set/2019]]) -> 0 | W59: =SUM(BaseHoras[[#This Row],[Out/2019]:[Dez/2019]]) -> 29.501575
A60: CLIENTE | B60: BOTICÁRIO | C60: Boti Promo | D60: VINICIUS ZELLER | E60: FLORATTA | F60: 104.23359 | G60: 0 | H60: 0 | I60: 0 | J60: 0 | K60: 0 | L60: 0 | M60: 0 | N60: 0 | O60: 0 | P60: 0 | Q60: 0 | R60: 0 | S60: 104.23359 | T60: =SUM(BaseHoras[[#This Row],[Jan/2019]:[Mar/2019]]) -> 104.23359 | U60: =SUM(BaseHoras[[#This Row],[Abr/2019]:[Jun/2019]]) -> 0 | V60: =SUM(BaseHoras[[#This Row],[Jul/2019]:[Set/2019]]) -> 0 | W60: =SUM(BaseHoras[[#This Row],[Out/2019]:[Dez/2019]]) -> 0
A61: CLIENTE | B61: BOTICÁRIO | C61: BotiCollection 2019 | D61: FABIO AUGUSTO DE CAMARGO GIRARDI | E61: ANFORAS COLECIONAVEIS | F61: 0 | G61: 0 | H61: 0 | I61: 36.154873 | J61: 0 | K61: 0 | L61: 0 | M61: 0 | N61: 0 | O61: 0 | P61: 0 | Q61: 0 | R61: 0 | S61: 36.154873 | T61: =SUM(BaseHoras[[#This Row],[Jan/2019]:[Mar/2019]]) -> 0 | U61: =SUM(BaseHoras[[#This Row],[Abr/2019]:[Jun/2019]]) -> 36.154873 | V61: =SUM(BaseHoras[[#This Row],[Jul/2019]:[Set/2019]]) -> 0 | W61: =SUM(BaseHoras[[#This Row],[Out/2019]:[Dez/2019]]) -> 0
...

Sheet Report - Aula
B3: Produto | C3: Campanha | D3: Horas Q1 | E3: Horas Q2 | F3: Horas Q3 | G3: Horas Q4 | H3: Total | I3: Part
B4: ARBO | C4: Todas | I4: =IFERROR(H4/$H$16,0) -> 0
B5: EGEO | C5: Todas | I5: =IFERROR(H5/$H$16,0) -> 0
B6: ELYSEE | C6: Todas | I6: =IFERROR(H6/$H$16,0) -> 0
B7: FLORATTA | C7: Todas | I7: =IFERROR(H7/$H$16,0) -> 0
B8: GLAMOUR | C8: Todas | I8: =IFERROR(H8/$H$16,0) -> 0
B9: MAKE B | C9: Todas | I9: =IFERROR(H9/$H$16,0) -> 0
B10: QUASAR | C10: Todas | I10: =IFERROR(H10/$H$16,0) -> 0
B11: NATAL | C11: Todas | I11: =IFERROR(H11/$H$16,0) -> 0
B12: INSTITUCIONAL | C12: Análise de Comunicação | I12: =IFERROR(H12/$H$16,0) -> 0
B13: INSTITUCIONAL | C13: Avaliações de Projetos | I13: =IFERROR(H13/$H$16,0) -> 0
B14: INSTITUCIONAL | C14: Eventos | I14: =IFERROR(H14/$H$16,0) -> 0
B15: INSTITUCIONAL | C15: Planejamento 2019 | I15: =IFERROR(H15/$H$16,0) -> 0
D16: =SUM(D4:D15) -> 0 | E16: =SUM(E4:E15) -> 0 | F16: =SUM(F4:F15) -> 0 | G16: =SUM(G4:G15) -> 0 | H16: =SUM(H4:H15) -> 0 | I16: =IFERROR(H16/$H$16,0) -> 0
B22: ="Relatório atualizado em: " & TEXT(NOW(),"dd/MM/aaaa HH:mm") -> Relatório atualizado em: 29/01/2020 20:31

Sheet Report - Final
B3: Produto | C3: Campanha | D3: Horas Q1 | E3: Horas Q2 | F3: Horas Q3 | G3: Horas Q4 | H3: Total | I3: Part
B4: ARBO | C4: Todas | D4: =SUMIF(Base!$E:$E,'Report - Final'!$B4,Base!T:T) -> 15787.684 | E4: =SUMIF(Base!$E:$E,'Report - Final'!$B4,Base!U:U) -> 0 | F4: =SUMIF(Base!$E:$E,'Report - Final'!$B4,Base!V:V) -> 56.737484 | G4: =SUMIF(Base!$E:$E,'Report - Final'!$B4,Base!W:W) -> 325.62722 | H4: =SUMIF(Base!$E:E,'Report - Final'!B4,Base!S:S) -> 16170.048 | I4: =H4/$H$16 -> 0.047969395
B5: EGEO | C5: Todas | D5: =SUMIF(BaseHoras[Produto],'Report - Final'!$B5,BaseHoras[Q1]) -> 819.46014 | E5: =SUMIF(BaseHoras[Produto],'Report - Final'!$B5,BaseHoras[Q2]) -> 10632.295 | F5: =SUMIF(BaseHoras[Produto],'Report - Final'!$B5,BaseHoras[Q3]) -> 1133.9243 | G5: =SUMIF(BaseHoras[Produto],'Report - Final'!$B5,BaseHoras[Q4]) -> 14694.769 | H5: =SUMIF(BaseHoras[Produto],'Report - Final'!$B5,BaseHoras[Total]) -> 27280.449 | I5: =H5/$H$16 -> 0.080929048
B6: ELYSEE | C6: Todas | D6: =SUMIF(BaseHoras[Produto],'Report - Final'!$B6,BaseHoras[Q1]) -> 6388.811 | E6: =SUMIF(BaseHoras[Produto],'Report - Final'!$B6,BaseHoras[Q2]) -> 9619.4976 | F6: =SUMIF(BaseHoras[Produto],'Report - Final'!$B6,BaseHoras[Q3]) -> 1749.5173 | G6: =SUMIF(BaseHoras[Produto],'Report - Final'!$B6,BaseHoras[Q4]) -> 0 | H6: =SUMIF(BaseHoras[Produto],'Report - Final'!$B6,BaseHoras[Total]) -> 17757.826 | I6: =H6/$H$16 -> 0.05267963
B7: FLORATTA | C7: Todas | D7: =SUMIF(BaseHoras[Produto],'Report - Final'!$B7,BaseHoras[Q1]) -> 4635.5715 | E7: =SUMIF(BaseHoras[Produto],'Report - Final'!$B7,BaseHoras[Q2]) -> 721.27271 | F7: =SUMIF(BaseHoras[Produto],'Report - Final'!$B7,BaseHoras[Q3]) -> 7350.2472 | G7: =SUMIF(BaseHoras[Produto],'Report - Final'!$B7,BaseHoras[Q4]) -> 10823.106 | H7: =SUMIF(BaseHoras[Produto],'Report - Final'!$B7,BaseHoras[Total]) -> 23530.197 | I7: =H7/$H$16 -> 0.069803707
B8: GLAMOUR | C8: Todas | D8: =SUMIF(BaseHoras[Produto],'Report - Final'!$B8,BaseHoras[Q1]) -> 0 | E8: =SUMIF(BaseHoras[Produto],'Report - Final'!$B8,BaseHoras[Q2]) -> 1015.3539 | F8: =SUMIF(BaseHoras[Produto],'Report - Final'!$B8,BaseHoras[Q3]) -> 0 | G8: =SUMIF(BaseHoras[Produto],'Report - Final'!$B8,BaseHoras[Q4]) -> 22.961847 | H8: =SUMIF(BaseHoras[Produto],'Report - Final'!$B8,BaseHoras[Total]) -> 1038.3157 | I8: =H8/$H$16 -> 0.0030802244
B9: MAKE B | C9: Todas | D9: =SUMIF(BaseHoras[Produto],'Report - Final'!$B9,BaseHoras[Q1]) -> 55174.898 | E9: =SUMIF(BaseHoras[Produto],'Report - Final'!$B9,BaseHoras[Q2]) -> 17203.69 | F9: =SUMIF(BaseHoras[Produto],'Report - Final'!$B9,BaseHoras[Q3]) -> 56581.752 | G9: =SUMIF(BaseHoras[Produto],'Report - Final'!$B9,BaseHoras[Q4]) -> 31086.776 | H9: =SUMIF(BaseHoras[Produto],'Report - Final'!$B9,BaseHoras[Total]) -> 160047.12 | I9: =H9/$H$16 -> 0.47478914
B10: QUASAR | C10: Todas | D10: =SUMIF(BaseHoras[Produto],'Report - Final'!$B10,BaseHoras[Q1]) -> 32.70772 | E10: =SUMIF(BaseHoras[Produto],'Report - Final'!$B10,BaseHoras[Q2]) -> 73.630613 | F10: =SUMIF(BaseHoras[Produto],'Report - Final'!$B10,BaseHoras[Q3]) -> 0 | G10: =SUMIF(BaseHoras[Produto],'Report - Final'!$B10,BaseHoras[Q4]) -> 4273.0802 | H10: =SUMIF(BaseHoras[Produto],'Report - Final'!$B10,BaseHoras[Total]) -> 4379.4185 | I10: =H10/$H$16 -> 0.012991801
B11: NATAL | C11: Todas | D11: =SUMIF(BaseHoras[Produto],'Report - Final'!$B11,BaseHoras[Q1]) -> 3.7254173 | E11: =SUMIF(BaseHoras[Produto],'Report - Final'!$B11,BaseHoras[Q2]) -> 0 | F11: =SUMIF(BaseHoras[Produto],'Report - Final'!$B11,BaseHoras[Q3]) -> 125.02388 | G11: =SUMIF(BaseHoras[Produto],'Report - Final'!$B11,BaseHoras[Q4]) -> 4529.0042 | H11: =SUMIF(BaseHoras[Produto],'Report - Final'!$B11,BaseHoras[Total]) -> 4657.7535 | I11: =H11/$H$16 -> 0.013817498
B12: INSTITUCIONAL | C12: Análise de Comunicação | D12: =SUMIFS(BaseHoras[Q1],BaseHoras[Produto],'Report - Final'!$B12,BaseHoras[Campanha],'Report - Final'!$C12) -> 0 | E12: =SUMIFS(BaseHoras[Q2],BaseHoras[Produto],'Report - Final'!$B12,BaseHoras[Campanha],'Report - Final'!$C12) -> 406.4514 | F12: =SUMIFS(BaseHoras[Q3],BaseHoras[Produto],'Report - Final'!$B12,BaseHoras[Campanha],'Report - Final'!C$12) -> 1143.0293 | G12: =SUMIFS(BaseHoras[Q4],BaseHoras[Produto],'Report - Final'!$B12,BaseHoras[Campanha],'Report - Final'!$C12) -> 0 | H12: =SUMIFS(BaseHoras[Total],BaseHoras[Produto],'Report - Final'!$B12,BaseHoras[Campanha],'Report - Final'!$C12) -> 1549.4807 | I12: =H12/$H$16 -> 0.0045966252
B13: INSTITUCIONAL | C13: Avaliações de Projetos | D13: =SUMIFS(BaseHoras[Q1],BaseHoras[Produto],'Report - Final'!$B13,BaseHoras[Campanha],'Report - Final'!$C13) -> 101.14837 | E13: =SUMIFS(BaseHoras[Q2],BaseHoras[Produto],'Report - Final'!$B13,BaseHoras[Campanha],'Report - Final'!$C13) -> 0 | F13: =SUMIFS(BaseHoras[Q3],BaseHoras[Produto],'Report - Final'!$B13,BaseHoras[Campanha],'Report - Final'!C$13) -> 48.276268 | G13: =SUMIFS(BaseHoras[Q4],BaseHoras[Produto],'Report - Final'!$B13,BaseHoras[Campanha],'Report - Final'!$C13) -> 32.705933 | H13: =SUMIFS(BaseHoras[Total],BaseHoras[Produto],'Report - Final'!$B13,BaseHoras[Campanha],'Report - Final'!$C13) -> 182.13057 | I13: =H13/$H$16 -> 0.00054030101
B14: INSTITUCIONAL | C14: Eventos | D14: =SUMIFS(BaseHoras[Q1],BaseHoras[Produto],'Report - Final'!$B14,BaseHoras[Campanha],'Report - Final'!$C14) -> 866.36808 | E14: =SUMIFS(BaseHoras[Q2],BaseHoras[Produto],'Report - Final'!$B14,BaseHoras[Campanha],'Report - Final'!$C14) -> 0 | F14: =SUMIFS(BaseHoras[Q3],BaseHoras[Produto],'Report - Final'!$B14,BaseHoras[Campanha],'Report - Final'!C$14) -> 0 | G14: =SUMIFS(BaseHoras[Q4],BaseHoras[Produto],'Report - Final'!$B14,BaseHoras[Campanha],'Report - Final'!$C14) -> 0 | H14: =SUMIFS(BaseHoras[Total],BaseHoras[Produto],'Report - Final'!$B14,BaseHoras[Campanha],'Report - Final'!$C14) -> 866.36808 | I14: =H14/$H$16 -> 0.0025701316
B15: INSTITUCIONAL | C15: Planejamento 2019 | D15: =SUMIFS(BaseHoras[Q1],BaseHoras[Produto],'Report - Final'!$B15,BaseHoras[Campanha],'Report - Final'!$C15) -> 65796.371 | E15: =SUMIFS(BaseHoras[Q2],BaseHoras[Produto],'Report - Final'!$B15,BaseHoras[Campanha],'Report - Final'!$C15) -> 6869.1846 | F15: =SUMIFS(BaseHoras[Q3],BaseHoras[Produto],'Report - Final'!$B15,BaseHoras[Campanha],'Report - Final'!C$15) -> 4646.4417 | G15: =SUMIFS(BaseHoras[Q4],BaseHoras[Produto],'Report - Final'!$B15,BaseHoras[Campanha],'Report - Final'!$C15) -> 2319.8383 | H15: =SUMIFS(BaseHoras[Total],BaseHoras[Produto],'Report - Final'!$B15,BaseHoras[Campanha],'Report - Final'!$C15) -> 79631.836 | I15: =H15/$H$16 -> 0.2362325
D16: =SUM(D4:D15) -> 149606.75 | E16: =SUM(E4:E15) -> 46541.376 | F16: =SUM(F4:F15) -> 72834.949 | G16: =SUM(G4:G15) -> 68107.869 | H16: =SUM(H4:H15) -> 337090.94 | I16: =H16/$H$16 -> 1
B22: ="Relatório atualizado em: " & TEXT(NOW(),"dd/MM/aaaa HH:mm") -> Relatório atualizado em: 29/01/2020 20:31
