Workbook

Sheet Resumo
B1: PLANO DE MÍDIA Dezembro / 2021 V1
B5: ESTRATÉGIA
B6: Veiculação de anúncios divulgando a marca Gran Cursos Online com o objetivo de gerar receita no site, trabalhando a comunicação com o usuário potencial durante a jornada de conversão.
B9: Objetivo | C9: Receita Site GCO
B10: KPI'S Primário | C10: Receita e ROI
B11: Período | C11: 01/12/021 a 31/12/2021
B12: Budget Líquido | C12: 1100000
B13: Fee | C13: =C12*10% -> 110000
B14: Budget Bruto | C14: =SUM(C12:C13) -> 1210000
B16: METAS
B17: Receita Site | C17: 15179262
B18: Participação de Mídia Paga % | C18: 0.45
B19: Receita Mídia Paga | C19: =C17*C18 -> 6830667.9
B21: PROJEÇÕES de resultado no GA*
B22: Receita Site | C22: =C24/C18 -> 8828554.6
B23: Receita estimada Site % | C23: =C22/C17 -> 0.58161949
B24: Receita Mídia Paga | C24: ='Projeções Dezembro_2021'!O61 -> 3972849.6
B25: Receita estimada Mídia Paga % | C25: =C24/C19 -> 0.58161949
B26: *Dados estimados, não garantidos
B29: CANAIS DE MÍDIA | C29: OBJETIVO DOS CANAIS | D29: Budget | E29: Share
B30: Bing | C30: Cobertura dos principais termos relacionados ao nome da marca e tipos de produtos | D30: ='Projeções Dezembro_2021'!D56 -> 30000 | E30: =D30/$D$40 -> 0.010714286
B31: Criteo | C31: Remarketing dinâmico de acordo com a navegação do usuário | D31: ='Projeções Dezembro_2021'!D46 -> 40000 | E31: =D31/$D$40 -> 0.014285714
B32: Facebook / Instagram | C32: Campanhas de engajamento com post patrocinados para promover engajamento da marca | D32: =SUM('Projeções Dezembro_2021'!D38:D42,'Projeções Dezembro_2021'!D49:D49,'Projeções Dezembro_2021'!D57:D58) -> 285000 | E32: =D32/$D$40 -> 0.10178571
B33: Google Display | C33: Exibição de banners para clusters específicos e Remarketing para reforço de marca. | D33: =SUM('Projeções Dezembro_2021'!D30+'Projeções Dezembro_2021'!D31+'Projeções Dezembro_2021'!D32+'Projeções Dezembro_2021'!D33+'Projeções Dezembro_2021'!D34+'Projeções Dezembro_2021'!D35) -> 460000 | E33: =D33/$D$40 -> 0.16428571
B34: Google Search | C34: Cobertura dos principais termos relacionados ao nome da marca e tipos de produtos | D34: =SUM('Projeções Dezembro_2021'!D37,'Projeções Dezembro_2021'!D51:D55)+'Projeções Dezembro_2021'!D36 -> 1285000 | E34: =D34/$D$40 -> 0.45892857
B35: TikTok | C35: Formato interativo de vídeo. | D35: ='Projeções Dezembro_2021'!D44 -> 100000 | E35: =D35/$D$40 -> 0.035714286
B36: Blue | C36: Remarketing dinâmico de acordo com a navegação do usuário | D36: ='Projeções Dezembro_2021'!D47 -> 60000 | E36: =D36/$D$40 -> 0.021428571
B37: RTB House | C37: Remarketing dinâmico de acordo com a navegação do usuário | D37: ='Projeções Dezembro_2021'!D48 -> 40000 | E37: =D37/$D$40 -> 0.014285714
B38: UOL | C38: Branded Content e formatos de impacto na sessão Educação, Empregos, Carreiras e Concursos | E38: =D38/$D$40 -> 0
B39: YouTube | C39: Veiculação de vídeos promovidos no formato true view para cluster específicos / Teste de Discovery Ads | D39: =SUM('Projeções Dezembro_2021'!D19:D29) -> 500000 | E39: =D39/$D$40 -> 0.17857143
D40: =SUM(D30:D39) -> 2800000 | E40: =SUM(E30:E39) -> 1

Sheet Projeções Dezembro_2021
A1: Plano de Mídia Dezembro - V1
A7: Estratégia do Funil | B7: Veículo | C7: Tipo de Campanha | D7: Budget | E7: % | F7: CPC | G7: Cliques | H7: CTR | I7: CPM | J7: CPV | K7: Views | L7: Impressões | M7: Visitas (Sessões) | N7: Taxa de Conversão (GA) | O7: Projeção de Receita | P7: Ticket Médio | Q7: % da Receita | R7: Vendas | S7: Projeção ROI
A9: Impacto | B9: YouTube | C9: True View | E9: =D9/$D$61 -> 0 | F9: - | G9: - | H9: - | I9: 5 | J9: 0.07 | K9: =D9/J9 -> 0 | L9: =D9/I9*1000 -> 0 | M9: =IFERROR(G9*90%,"-") -> - | N9: 0 | O9: =IFERROR(R9*55,"-") -> - | Q9: =IFERROR(O9/$R$61,"-") -> - | R9: =IFERROR(M9*N9,"-") -> - | S9: =IFERROR(O9/D9,"-") -> -
B10: YouTube | C10: Bumper | E10: =D10/$D$61 -> 0 | F10: - | G10: - | H10: - | I10: 5 | J10: 0.07 | K10: =D10/J10 -> 0 | L10: =D10/I10*1000 -> 0 | M10: =IFERROR(G10*90%,"-") -> - | N10: 0 | O10: =IFERROR(R10*55,"-") -> - | Q10: =IFERROR(O10/$R$61,"-") -> - | R10: =IFERROR(M10*N10,"-") -> - | S10: =IFERROR(O10/D10,"-") -> -
B11: Outbrain | C11: Conteúdo | E11: =D11/$D$61 -> 0
B12: DBM | C12: Banner | E12: =D12/$D$61 -> 0
C13: Video | E13: =D13/$D$61 -> 0
B14: Facebook / Instagram | C14: Instagram GCO | E14: =D14/$D$61 -> 0
C15: Facebook GCO | E15: =D15/$D$61 -> 0
B16: Google | C16: GDN/GSP | E16: =D16/$D$61 -> 0
B17: UOL | C17: Branded Content + Display | D17: 0 | E17: =D17/$D$61 -> 0 | F17: - | G17: =IFERROR(D17/F17,"-") -> - | H17: - | I17: =D17/L17*1000 -> #DIV/0! | J17: - | K17: =IFERROR(D17/J17,"-") -> - | L17: 0 | M17: - | N17: - | O17: =IFERROR(R17*55,"-") -> - | Q17: =IFERROR(O17/$O$61,"-") -> - | R17: =IFERROR(M17*N17,"-") -> - | S17: =IFERROR(O17/D17,"-") -> -
B18: Total | D18: =SUM(D9:D17) -> 0 | E18: =D18/$D$61 -> 0 | F18: =F17 -> - | G18: =G17 -> - | H18: =H17 -> - | I18: =I17 -> #DIV/0! | J18: =J17 -> - | K18: =K17 -> - | L18: =L17 -> 0 | M18: =M17 -> - | ... O18: =O17 -> - | Q18: =Q17 -> - | R18: =R17 -> - | S18: =S17 -> -
A19: Consideração | B19: Youtube | C19: YT - NU - Assinatura Ilimitada - Bumper - 6seg | D19: 0 | E19: - | F19: - | G19: =IFERROR(D19/F19,"-") -> - | H19: - | J19: - | K19: =IFERROR(D19/J19,"-") -> - | L19: - | M19: =IFERROR(G19*70%,"-") -> - | N19: - | O19: =IFERROR(R19*55,"-") -> - | Q19: =IFERROR(O19/$O$61,"-") -> - | R19: =IFERROR(M19*N19,"-") -> - | S19: =IFERROR(O19/D19,"-") -> -
C20: YT - RMKT - Assinatura Ilimitada - Bumper - 6seg | E20: =D20/$D$61 -> 0 | F20: - | G20: =IFERROR(D20/F20,"-") -> - | H20: - | J20: - | K20: =IFERROR(D20/J20,"-") -> - | M20: =IFERROR(G20*70%,"-") -> - | N20: - | O20: =IFERROR(R20*55,"-") -> - | Q20: =IFERROR(O20/$O$61,"-") -> - | R20: =IFERROR(M20*N20,"-") -> - | S20: =IFERROR(O20/D20,"-") -> -
C21: YT - True View 4Action - NU - Assinatura Ilimitada | E21: - | F21: - | G21: =IFERROR(D21/F21,"-") -> - | H21: - | L21: - | M21: =IFERROR(G21*70%,"-") -> - | N21: - | O21: =IFERROR(R21*55,"-") -> - | Q21: =IFERROR(O21/$O$61,"-") -> - | R21: =IFERROR(M21*N21,"-") -> - | S21: =IFERROR(O21/D21,"-") -> -
C22: YT - True View 4Action - RMKT - Assinatura Ilimitada | E22: =D22/$D$61 -> 0 | F22: - | G22: =IFERROR(D22/F22,"-") -> - | H22: - | K22: =IFERROR(D22/J22,"-") -> - | M22: =IFERROR(G22*70%,"-") -> - | N22: - | O22: =IFERROR(R22*55,"-") -> - | Q22: =IFERROR(O22/$O$61,"-") -> - | R22: =IFERROR(M22*N22,"-") -> - | S22: =IFERROR(O22/D22,"-") -> -
C23: YT - True View Action - RMKT - Curso | E23: =D23/$D$61 -> 0 | F23: - | G23: =IFERROR(D23/F23,"-") -> - | H23: - | K23: =IFERROR(D23/J23,"-") -> - | M23: =IFERROR(G23*70%,"-") -> - | N23: - | O23: =IFERROR(R23*55,"-") -> - | Q23: =IFERROR(O23/$O$61,"-") -> - | R23: =IFERROR(M23*N23,"-") -> - | S23: =IFERROR(O23/D23,"-") -> -
C24: VAC | D24: 100000 | E24: =D24/$D$61 -> 0.035714286 | F24: 1.95 | G24: =IFERROR(D24/F24,"-") -> 51282.051 | H24: 0.0027 | I24: 13.8 | J24: 0.07 | K24: =IFERROR(D24/J24,"-") -> 1428571.4 | L24: =D24/I24*1000 -> 7246376.8 | M24: =IFERROR(G24*70%,"-") -> 35897.436 | N24: 0.0031 | O24: =P24*R24 -> 66769.231 | P24: 600 | Q24: =IFERROR(O24/$O$61,"-") -> 0.016806383 | R24: =IFERROR(M24*N24,"-") -> 111.28205 | S24: =IFERROR(O24/D24,"-") -> 0.66769231
C25: VREC | D25: 300000 | E25: =D25/$D$61 -> 0.10714286 | F25: - | G25: =IFERROR(D25/F25,"-") -> - | H25: - | I25: 2.65 | J25: 0.01 | K25: =IFERROR(D25/J25,"-") -> 30000000 | L25: =D25/I25*1000 -> 1.1320755e+08 | M25: - | N25: - | O25: =IFERROR(R25*55,"-") -> 0
C26: Discovery Home | D26: 70000 | E26: =D26/$D$61 -> 0.025 | F26: 0.76 | G26: =IFERROR(D26/F26,"-") -> 92105.263 | H26: - | I26: 1.64 | J26: =IFERROR(C26/I26,"-") -> - | K26: =IFERROR(D26/J26,"-") -> - | L26: =D26/I26*1000 -> 42682927 | M26: =IFERROR(G26*70%,"-") -> 64473.684 | N26: 0.0014 | O26: =P26*R26 -> 54157.895 | P26: 600 | Q26: =IFERROR(O26/$O$61,"-") -> 0.013632002 | R26: =IFERROR(M26*N26,"-") -> 90.263158 | S26: =IFERROR(O26/D26,"-") -> 0.77368421
C27: Discovery Institucional | D27: 10000 | E27: =D27/$D$61 -> 0.0035714286 | F27: - | G27: =IFERROR(D27/F27,"-") -> - | H27: - | I27: 1.48 | J27: =IFERROR(C27/I27,"-") -> - | K27: =IFERROR(D27/J27,"-") -> - | L27: =D27/I27*1000 -> 6756756.8 | M27: =IFERROR(G27*70%,"-") -> - | N27: - | O27: =IFERROR(R27*55,"-") -> - | Q27: =IFERROR(O27/$O$61,"-") -> - | R27: =IFERROR(M27*N27,"-") -> - | S27: =IFERROR(O27/D27,"-") -> -
C28: Discovery Genérico | D28: 10000 | E28: - | F28: - | G28: =IFERROR(D28/F28,"-") -> - | H28: - | I28: 1.48 | J28: =IFERROR(C28/I28,"-") -> - | K28: =IFERROR(D28/J28,"-") -> - | L28: =D28/I28*1000 -> 6756756.8
C29: Discovery Cursos | D29: 10000 | I29: 1.49 | L29: =D29/I29*1000 -> 6711409.4
B30: Google | C30: Smart Campaign | D30: 70000 | E30: =D30/$D$61 -> 0.025 | F30: 0.77 | G30: =IFERROR(D30/F30,"-") -> 90909.091 | H30: 0.0085 | I30: 2.45 | J30: - | K30: =IFERROR(D30/J30,"-") -> - | L30: =IFERROR(G30/H30,"-") -> 10695187 | M30: =IFERROR(G30*80%,"-") -> 72727.273 | N30: 0.0008 | O30: =P30*R30 -> 32000 | P30: 550 | Q30: =IFERROR(O30/$O$63,"-") -> 0.013460867 | R30: =IFERROR(M30*N30,"-") -> 58.181818 | S30: =IFERROR(O30/D30,"-") -> 0.45714286
C31: GDN - Dynamic Prospecting | D31: 300000 | E31: =D31/$D$61 -> 0.10714286 | F31: 0.25 | G31: =IFERROR(D31/F31,"-") -> 1200000 | H31: 0.0032 | I31: 2.45 | J31: - | K31: =IFERROR(D31/J31,"-") -> - | L31: =IFERROR(G31/H31,"-") -> 375000000 | M31: =IFERROR(G31*80%,"-") -> 960000 | N31: - | O31: - | P31: - | Q31: =IFERROR(O31/$O$63,"-") -> - | R31: =IFERROR(M31*N31,"-") -> - | S31: =IFERROR(O31/D31,"-") -> -
C32: GDN Remarketing | D32: 70000 | E32: =D32/$D$61 -> 0.025 | F32: 0.51 | G32: =IFERROR(D32/F32,"-") -> 137254.9 | H32: 0.0076 | I32: 2.45 | J32: - | K32: =IFERROR(D32/J32,"-") -> - | L32: =IFERROR(G32/H32,"-") -> 18059856 | M32: =IFERROR(G32*80%,"-") -> 109803.92 | N32: 0.0009 | O32: =P32*R32 -> 54352.941 | P32: 550 | Q32: =IFERROR(O32/$O$63,"-") -> 0.022863679 | R32: =IFERROR(M32*N32,"-") -> 98.823529 | S32: =IFERROR(O32/D32,"-") -> 0.77647059
C33: GDN - Cursos para Concursos - NU | D33: 10000 | E33: =D33/$D$61 -> 0.0035714286 | F33: 0.41 | G33: =IFERROR(D33/F33,"-") -> 24390.244 | H33: 0.0055 | I33: 2.9 | J33: - | K33: =IFERROR(D33/J33,"-") -> - | L33: =IFERROR(G33/H33,"-") -> 4434589.8 | M33: =IFERROR(G33*80%,"-") -> 19512.195 | N33: - | O33: - | P33: - | Q33: - | R33: =IFERROR(M33*N33,"-") -> - | S33: =IFERROR(O33/D33,"-") -> -
C34: GDN - Cursos Gratuitos | D34: 5000 | E34: =D34/$D$61 -> 0.0017857143 | F34: 0.55 | G34: =IFERROR(D34/F34,"-") -> 9090.9091 | H34: 0.0058 | I34: 2.9 | J34: - | K34: =IFERROR(D34/J34,"-") -> - | L34: =IFERROR(G34/H34,"-") -> 1567398.1 | M34: =IFERROR(G34*80%,"-") -> 7272.7273 | N34: - | O34: - | P34: - | Q34: - | R34: =IFERROR(M34*N34,"-") -> - | S34: =IFERROR(O34/D34,"-") -> -
C35: Vocacional | D35: 5000 | E35: =D35/$D$61 -> 0.0017857143 | F35: 0.54 | G35: =IFERROR(D35/F35,"-") -> 9259.2593 | H35: 0.0063 | I35: 2.9 | J35: - | K35: =IFERROR(D35/J35,"-") -> - | L35: =IFERROR(G35/H35,"-") -> 1469723.7 | M35: =IFERROR(G35*80%,"-") -> 7407.4074 | N35: - | O35: - | P35: - | Q35: - | R35: =IFERROR(M35*N35,"-") -> - | S35: =IFERROR(O35/D35,"-") -> -
C36: Search Não Institucional | E36: - | F36: - | G36: - | H36: - | I36: - | J36: - | K36: =IFERROR(D36/J36,"-") -> - | N36: - | O36: - | P36: - | Q36: - | R36: =IFERROR(M36*N36,"-") -> - | S36: =IFERROR(O36/D36,"-") -> -
C37: Gratuito | D37: - | E37: - | F37: - | G37: =IFERROR(D37/F37,"-") -> - | H37: - | I37: - | J37: - | K37: =IFERROR(D37/J37,"-") -> - | L37: =IFERROR(G37/H37,"-") -> - | M37: =IFERROR(G37*110%,"-") -> - | N37: - | O37: - | P37: - | Q37: - | R37: =IFERROR(M37*N37,"-") -> - | S37: =IFERROR(O37/D37,"-") -> -
B38: Facebook | C38: Marca | D38: 30000 | E38: =D38/$D$61 -> 0.010714286 | F38: 0.89 | G38: =IFERROR(D38/F38,"-") -> 33707.865 | H38: 0.0078 | I38: - | J38: - | K38: =IFERROR(D38/J38,"-") -> - | L38: =IFERROR(G38/H38,"-") -> 4321521.2 | M38: =IFERROR(G38*110%,"-") -> 37078.652 | N38: - | O38: - | P38: - | Q38: - | R38: =IFERROR(M38*N38,"-") -> - | S38: =IFERROR(O38/D38,"-") -> -
E39: - | F39: - | G39: =IFERROR(D39/F39,"-") -> - | H39: - | K39: =IFERROR(D39/J39,"-") -> - | L39: - | M39: =IFERROR(G39*70%,"-") -> - | N39: - | O39: =IFERROR(R39*55,"-") -> - | Q39: =IFERROR(O39/$O$61,"-") -> - | R39: =IFERROR(M39*N39,"-") -> - | S39: =IFERROR(O39/D39,"-") -> -
C40: Leads - Materiais | D40: 25000 | E40: =D40/$D$61 -> 0.0089285714 | F40: 0.98 | G40: =IFERROR(D40/F40,"-") -> 25510.204 | H40: 0.0075 | I40: - | J40: - | K40: =IFERROR(D40/J40,"-") -> - | L40: =IFERROR(G40/H40,"-") -> 3401360.5 | M40: =IFERROR(G40*100%,"-") -> 25510.204 | N40: - | O40: =IFERROR(R40*55,"-") -> - | Q40: =IFERROR(O40/$O$61,"-") -> - | R40: =IFERROR(M40*N40,"-") -> - | S40: =IFERROR(O40/D40,"-") -> -
C41: Reach | D41: 40000 | E41: =D41/$D$61 -> 0.014285714
C42: Content - Assinatura | D42: 40000 | E42: =D42/$D$61 -> 0.014285714 | F42: 0.65 | G42: =IFERROR(D42/F42,"-") -> 61538.462 | H42: 0.0098 | I42: 4 | J42: - | K42: =IFERROR(D42/J42,"-") -> - | L42: =IFERROR(G42/H42,"-") -> 6279434.9 | M42: =IFERROR(G42*100%,"-") -> 61538.462 | N42: - | O42: =IFERROR(R42*55,"-") -> - | Q42: =IFERROR(O42/$O$61,"-") -> - | R42: =IFERROR(M42*N42,"-") -> - | S42: =IFERROR(O42/D42,"-") -> -
B43: Teads | C43: Tráfego | E43: =D43/$D$61 -> 0 | F43: - | G43: - | H43: - | I43: 31 | L43: =D43/I43*1000 -> 0 | M43: - | N43: - | O43: - | P43: -
B44: Tittok | C44: Tiktok | D44: 100000 | E44: =D44/$D$61 -> 0.035714286 | J44: - | K44: =IFERROR(D44/J44,"-") -> - | L44: =IFERROR(G44/H44,"-") -> - | M44: - | N44: - | O44: =IFERROR(R44*55,"-") -> - | Q44: =IFERROR(O44/$O$61,"-") -> - | R44: =IFERROR(M44*N44,"-") -> - | S44: =IFERROR(O44/D44,"-") -> -
B45: Total | D45: =SUM(D19:D44) -> 1195000 | E45: =D45/$D$61 -> 0.42678571 | F45: =D45/G45 -> 0.72512154 | G45: =SUM(G19:G39) -> 1647999.6 | H45: =G45/L45 -> 0.0039658439 | I45: =D45/L45*1000 -> 2.8757188 | K45: =SUM(K19:K39) -> 31428571 | L45: =SUM(L30:L39) -> 4.1554828e+08 | M45: =SUM(M30:M39) -> 1213802.2 | O45: =SUM(O19:O39) -> 207280.07 | Q45: =IFERROR(O45/$O$61,"-") -> 0.052174154 | R45: =SUM(R19:R39) -> 358.55056 | S45: =O45/D45 -> 0.17345612
A46: Ação | B46: Criteo | C46: Lower Funnel | D46: 40000 | E46: =D46/$D$61 -> 0.014285714 | F46: 0.78 | G46: =IFERROR(D46/F46,"-") -> 51282.051 | H46: 0.0065 | I46: =IFERROR(D46/L46*1000,"-") -> 5.07 | J46: - | K46: - | L46: =IFERROR(G46/H46,"-") -> 7889546.4 | M46: =IFERROR(G46*100%,"-") -> 51282.051 | N46: 0.0028 | O46: =P46*R46 -> 64615.385 | P46: 450 | Q46: =IFERROR(O46/$O$61,"-") -> 0.016264241 | R46: =IFERROR(M46*N46,"-") -> 143.58974 | S46: =IFERROR(O46/D46,"-") -> 1.6153846
...

Sheet Planilha1

Sheet PROPOSTA 170K
A1: PROPOSTA COMERCIAL
B2: CLIENTE: | C2: Gran Cursos Online
B3: PRODUTO: | G3: ESPECÍFICAÇÃO DOS FORMATOS
B4: AGÊNCIA: | C4: Blinks
B5: PERÍODO: | C5: 3 meses (Set, Out, Nov) | G5: https://anuncie.uol.com.br/formatos.htm
B6: RESPONSÁVEL PROPOSTA: | C6: Luís Gustavo Fernandes
B7: DATA PROPOSTA: | C7: 8 de Agosto de 2018
B8: VERBA SUGERIDA R$: | C8: =L26 -> 170300
B9: FORMATO | C9: ESTAÇÃO / PROJETO | D9: UNIDADE DE VENDA | E9: TABELA (JAN/18) | F9: IMPRESSÕES OU CLIQUES | G9: PERÍODO CAMPANHA (Dias) | H9: VISITAS GARANTIADAS OU IMPRESSÕES TOTAIS | I9: DESCONTO | J9: VALOR TABELA | K9: VALOR NEGOCIADO | L9: VALOR NEGOCIADO TOTAL | M9: ctr | N9: cliques | O9: visitas | P9: cpv
A10: BRANDED CONTENT SETEMBRO | B10: Brand Content 1 Publieditorial com texto e foto | C10: UOL NETWORK | Nacional ou Sul e Sudeste | BT Educação, Empregos, Carreiras e Concursos | D10: Projeto | E10: 60000 | F10: --- | G10: 30 | H10: 50k de Visitas Garantidas | I10: 0.72 | J10: =E10 -> 60000 | K10: =(1-I10)*E10 -> 16800 | L10: =K10+K12 -> 70700 | O10: 50000 | P10: =L10/O10 -> 1.414
B11: NATIVES DE CONTEÚDO (Internas - Sustentação) | F11: 30000 | G11: 30
B12: NATIVE CARROSSEL 100% (HOMEPAGE) | C12: UOL NACIONAL - HOMEPAGE | D12: DIÁRIA | E12: 192500 | F12: 20000000 | G12: 1 | J12: =E12 -> 192500 | K12: =(1-I10)*E12 -> 53900
B13: (DISPLAY) HALF PAGE E/OU SUPER BANNER E/OU RETANGULO SETEMBRO | C13: UOL NETWORK | Nacional ou Sul e Sudeste | BT Educação, Empregos, Carreiras e Concursos | D13: CPM | E13: 15 | F13: =H13/G13 -> 100000 | G13: 30 | H13: 3000000 | I13: 0.7 | J13: =(E13*H13)/1000 -> 45000 | K13: =(1-I13)*E13 -> 4.5 | L13: =(K13*H13)/1000 -> 13500 | M13: 0.0009 | N13: =H13*M13 -> 2700 | O13: =N13*70% -> 1890 | P13: =L13/O13 -> 7.1428571
A14: MÍDIA OUTUBRO | B14: (DISPLAY) HALF PAGE 300X600 | C14: UOL NETWORK | Nacional ou Sul e Sudeste | BT Educação, Empregos, Carreiras e Concursos | D14: CPM | E14: 15 | F14: =H14/G14 -> 100000 | G14: 30 | H14: 3000000 | I14: 0.7 | J14: =(E14*H14)/1000 -> 45000 | K14: =(1-I14)*E14 -> 4.5 | L14: =(K14*H14)/1000 -> 13500 | M14: 0.0009 | N14: =H14*M14 -> 2700 | O14: =N14*70% -> 1890 | P14: =L14/O14 -> 7.1428571
B15: (DISPLAY) BILLBOARD 970X250 | C15: UOL NETWORK | Nacional ou Sul e Sudeste | BT Educação, Empregos, Carreiras e Concursos | D15: CPM | E15: 20 | F15: =H15/G15 -> 66666.667 | G15: 30 | H15: 2000000 | I15: 0.7 | J15: =(E15*H15)/1000 -> 40000 | K15: =(1-I15)*E15 -> 6 | L15: =(K15*H15)/1000 -> 12000 | M15: 0.0009 | N15: =H15*M15 -> 1800 | O15: =N15*70% -> 1260 | P15: =L15/O15 -> 9.5238095
B16: NATIVE DE OFERTAS | C16: UOL | Nacional ou Sul e Sudeste | BT Educação, Empregos, Carreiras e Concursos | D16: CPC | E16: 1.5 | F16: =H16/G16 -> 1000 | G16: 30 | H16: 30000 | I16: 0.7 | J16: =(E16*H16) -> 45000 | K16: =(1-I16)*E16 -> 0.45 | L16: =H16*K16 -> 13500 | N16: =H16 -> 30000 | O16: =N16*70% -> 21000 | P16: =L16/O16 -> 0.64285714
A17: MÍDIA NOVEMBRO | B17: (DISPLAY) HALF PAGE 300X600 | C17: UOL NETWORK | Nacional ou Sul e Sudeste | BT Educação, Empregos, Carreiras e Concursos | D17: CPM | E17: 15 | F17: =H17/G17 -> 66666.667 | G17: 30 | H17: 2000000 | I17: 0.7 | J17: =(E17*H17)/1000 -> 30000 | K17: =(1-I17)*E17 -> 4.5 | L17: =(K17*H17)/1000 -> 9000 | M17: 0.0009 | N17: =H17*M17 -> 1800 | O17: =N17*70% -> 1260 | P17: =L17/O17 -> 7.1428571
B18: (DISPLAY) RETANGULO 300X250 | C18: UOL NETWORK | Nacional ou Sul e Sudeste | BT Educação, Empregos, Carreiras e Concursos | D18: CPM | E18: 15 | F18: =H18/G18 -> 66666.667 | G18: 30 | H18: 2000000 | I18: 0.7 | J18: =(E18*H18)/1000 -> 30000 | K18: =(1-I18)*E18 -> 4.5 | L18: =(K18*H18)/1000 -> 9000 | M18: 0.0009 | N18: =H18*M18 -> 1800 | O18: =N18*70% -> 1260 | P18: =L18/O18 -> 7.1428571
B19: (DISPLAY) BILLBOARD 970X250 | C19: UOL NETWORK | Nacional ou Sul e Sudeste | BT Educação, Empregos, Carreiras e Concursos | D19: CPM | E19: 20 | F19: =H19/G19 -> 66666.667 | G19: 30 | H19: 2000000 | I19: 0.7 | J19: =(E19*H19)/1000 -> 40000 | K19: =(1-I19)*E19 -> 6 | L19: =(K19*H19)/1000 -> 12000 | M19: 0.0009 | N19: =H19*M19 -> 1800 | O19: =N19*70% -> 1260 | P19: =L19/O19 -> 9.5238095
B20: NATIVE DE OFERTAS | C20: UOL | Nacional ou Sul e Sudeste | BT Educação, Empregos, Carreiras e Concursos | D20: CPC | E20: 1.5 | F20: =H20/G20 -> 1266.6667 | G20: 30 | H20: 38000 | I20: 0.7 | J20: =(E20*H20) -> 57000 | K20: =(1-I20)*E20 -> 0.45 | L20: =H20*K20 -> 17100 | N20: =H20 -> 38000 | O20: =N20*70% -> 26600 | P20: =L20/O20 -> 0.64285714
A21: BONIFICAÇÃO | B21: VIDEOS 15´´ou 30" floating na home, in article e pre roll | C21: UOL NETWORK | Nacional ou Sul e Sudeste | BT Educação, Empregos, Carreiras e Concursos | D21: CPV | E21: 0.2 | F21: =H21/G21 -> 3333.3333 | G21: 30 | H21: 100000 | I21: 1 | J21: =(E21*H21) -> 20000 | K21: =(1-I21)*E21 -> 0 | L21: =(K21*H21) -> 0 | M21: 0.016 | N21: =H21*M21 -> 1600 | O21: =N21*70% -> 1120 | P21: =L21/O21 -> 0
B22: NATIVE DE OFERTAS | C22: UOL | Nacional ou Sul e Sudeste | BT Educação, Empregos, Carreiras e Concursos | D22: CPC | E22: 1.5 | F22: =H22/G22 -> 333.33333 | G22: 30 | H22: 10000 | I22: 1 | J22: =(E22*H22) -> 15000 | K22: =(1-I22)*E22 -> 0 | L22: =H22*K22 -> 0 | N22: =H22 -> 10000 | O22: =N22*70% -> 7000 | P22: =L22/O22 -> 0
G23: TOTAL DE IMPRESSÕES / IMPACTOS | L23: =H13+H14+H15+H17+H18+H19+H21+F12+((F11+H16+H20+H22)/0.01) -> 44900000 | M23: Total | O23: =SUM(O10:O22) -> 114540 | P23: =L26/O23 -> 1.4868168
G24: CUSTO TABELA | L24: =SUM(J13:J20)+E10+E12+J21+J22 -> 619500
G25: DESCONTO | L25: =1-(L26/L24) -> 0.72510089
G26: INVESTIMENTO BRUTO NEGOCIADO | L26: =SUM(L10:L20) -> 170300
B29: Informações Gerais:
B30: 1. Proposta sujeita a aprovação dos cadastros do anunciante e agência pelo departamento financeiro do UOL S/A.
B31: 2. O UOL S/A reserva-se ao direito de apenas inserir materiais publicitários que estejam dentro das suas normas e padrões de qualidade. [http://download.uol.com.br/publicidade/Termos-e-condicoes-070206.pdf]
B32: 3. Após a inserção da campanha estarão disponíveis para acompanhamento, mediante a utilização de senha, os números de impressões e de clicks efetuados nos formatos de publicidade convencionais. Sendo este relatório o único válido para a aferição da entrega da mídia contratada.
B33: 4. A programação nas estações e canais será definida de acordo com a disponibilidade de inventário. É importante observar que o número de impressões poderá esgotar-se antes do período acordado devido a eventuais variações de audiência.
B34: 5. No caso de não se completar o total de impressões no período contratado, o UOL S/A se compromete a ENTREGAR o saldo residual em até 3 meses após o fim da campanha.
B35: 6. A publicidade no UOL é faturada com base no Pedido de Inserção (PI) do cliente. Pode-se faturar de acordo com a mídia efetivamente veiculada dentro do mês mediante solicitação expressa do cliente na PI. Se a veiculação não ocorrer devido a atraso ou falha no envio de materiais, desistência ou outras razões de responsabilidade do cliente, o UOL reserva-se o direito de faturar normalmente, sem direito a compensação.
B36: 7. Validade da proposta: 30 dias a partir da data descrita no cabeçalho
B37: 8. Prazo de Pagamento: 15 DFM
B38: 9. Todo e qualquer formato que envolva tecnologia de 3º deve ter o custo tratado diretamente com o 3º. O UOL não se responsabiliza por este custo.
B39: 10. Acréscimo de 20% por critério de segmentação
B40: Ps: A entrega da campanha será de acordo com os relatórios do sistema do UOL

Sheet Tático
B1: Veículo | C1: Estratégia | D1: Plano de Ação (Blinks) | E1: Pendências Gran Cursos Online
A2: Consideração | C2: Search / Termos de Awareness | D2: * Acompanhamento da parcela de impressão; * Inclusão de anúncios responsivos em todos os grupos. | E2: NA
C3: GDN - Novos Usuários | D3: * Smart Campaign de Assinatura Ilimitada; * Captação de leads para a Black Friday. | E3: * 3 variações de PPL para nova campanha de Assinatura; * 3 variações de PPL para captação de leads para a BF 2018; * LP para captação de leads; * 3 variações de PPL para Dia do Servidor.
C4: TrueView e Bumper | D4: * Ampliação da estrutura de Discovery (busca no YouTube); * Novo vídeo de Assinatura Ilimitada, onde impactaremos novos usuários com as versões de 1min e 30seg; * Bumper Ads de quem viu os vídeos de Assinatura e para quem entrou na página de Assinatura; * YouTube 4 Action para Assinatura, com comunicação de preço. | E4: * Banner complementar de Assinatura Ilimitada; * Corte do vídeo de Assinatura Ilimitada com comunicação de preço.
C5: Vídeo | D5: * Assinatura Ilimitada (novo mote) | Foco em novos usuários para construir base para BF em Novembro. | E5: * Cortes do novo vídeo de Assinatura Ilimitada; * Corte do vídeo de Assinatura Ilimitada com comunicação de preço.
C6: Lead Ads | D6: * Campanha genérica e outra focada em captar uma base aquecida para BF. | E6: * 3 variações de PPL para captação de leads para a BF 2018; * Stories para captação de leads para BF 2018.
B8: Veículo | C8: Estratégia | D8: Plano de Ação (Blinks) | E8: Pendências Gran Cursos Online
A9: Prefeência | C9: RMKT Estático | D9: * Diminuição da meta de CPA, para escalarmos a campanha para Dia do Servidor; * Implementação da lista de quem viu os vídeos de Assinatura Ilimitada. | E9: * Peças novas de Assinatura Ilimitada; * Troca da KV das peças de carrinho de 20%; * Peças para Dia do Servidor.
C10: DRA | D10: * Diminuição da meta de CPA, para escalarmos a campanha para Dia do Servidor; * Implementação da lista de quem viu os vídeos de Assinatura Ilimitada; * Implementação de anúncios responsivos para Dia do Servidor. | E10: * Automatização do feed (Rodrigo).
C11: DA/Cupom | D11: * Nova campanha para LP de Descontos. * Troca de KV para Cupom 20% OFF. | E11: *Troca de KV e peças para nova campanha de LP de Descontos.
C12: Retargeting | D12: * Aumento da meta de COS, para escalarmos a campanha. | E12: * Peças novas de Assinatura Ilimitada; * Novo Logozone de Assinatura; * Peças para Dia do Servidor.
C13: Retargeting | D13: * Acompanhamento diário dos resultados e ajustes no CPC; * Aumento de CPC na última semana para Dia do Servidor e BF. | E13: * Peças novas de Assinatura Ilimitada; * Peças para Dia do Servidor.
B15: Veículo | C15: Estratégia | D15: Plano de Ação (Blinks) | E15: Pendências Gran Cursos Online
A16: Ação | C16: Search Institucional | D16: * Acompanhamento do CPC e IS diariamente; * Teste de anúncio responsivo; * Teste de novo argumento de Assinatura Ilimitada; * Antecipação de anúncios para Dia do Servidor. | E16: NA
C17: Search Não Institucional | D17: * Distribuição do budget não será entregue de forma linear, priorizando a última quinzena do mês; * Acompanhamento da receita assistida por curso; * Implementação da lista de quem viu os vídeos de Assinatura Ilimitada; * Continuar a implementação de anúncios responsivos nas campanhas de cursos; * Inclusão de novas palavras que trazem mais impressão no SEO em LongTail; * Início da campanha de BF apenas para RLSA; * Antecipação de anúncios para Dia do Servidor; * Antecipação da campanha de PRF; * Otimizações para melhorar o CTR. | E17: * Lista com os principais concursos do mês.
C18: Search | D18: * Acelerar conta com base no resultados por campanha; * Cobertura atual de 89% (ampliação da estrutura). | E18: NA
C19: Purchase | D19: * Planejar campanha do Dia do Servidor. * Blasts em dias específicos para LP de Descontos e Assinatura Ilimitada; * Antecipação da campanha de PRF. | E19: * Peças para campanha do Dia do Servidor. * Peças para campanha de LP de Descontos; * 3 variações de PPL para nova campanha de Assinatura.

Sheet 2017
B2: Histórico Julho / 2017
B5: Origem/mídia | C5: Receita GA | D5: Receita Real GA | E5: Observações
B7: facebook / cpc | C7: 263302.7 | D7: =C7-29529.5 -> 233773.2
B8: / email | C8: 824476.24 | D8: =C8 -> 824476.24
B9: google / cpc | C9: 363751.56 | D9: =C9 -> 363751.56
B10: (direct) / (none) | C10: 272351.98 | D10: =C10 -> 272351.98
B11: google / organic | C11: 133102.23 | D11: =C11 -> 133102.23
B12: Demais origens | C12: =C14-SUM(C7:C11) -> 249544.07 | D12: =C12 -> 249544.07
B14: Total | C14: 2106528.8 | D14: =SUM(D7:D12) -> 2076999.3
B20: Origem/mídia | C20: Investimento | D20: Receita Real | E20: ROI | F20: Transações | G20: Ticket Médio
B21: google / cpc | C21: 69682.6 | D21: =D9 -> 363751.56 | E21: =D21/C21 -> 5.2201204 | F21: 7999 | G21: =D21/F21 -> 45.474629
B22: facebook / cpc | C22: 81546.69 | D22: =D7 -> 233773.2 | E22: =D22/C22 -> 2.8667405 | F22: 12717 | G22: =D22/F22 -> 18.382732
B25: Representatividade | C25: =SUM(D21:D22) -> 597524.76
B26: Mídia Paga 2017 | C26: =C25/D14 -> 0.28768655
B28: Crescimento Mídia Paga | C28: ='[1]Plano de Mídia Junho'!Q34 -> 702151.04
B29: Receita YoY - Meta 2018 | C29: =C28/C25-1 -> 0.1750995
