Workbook

Sheet Menu Principal (2)

Sheet Framework COBIT

Sheet Instruções
N1: Instruções
B2: Olá!
B4: Ficamos felizes e parabenizamos pelo seu interesse em avaliar o Nível de Maturidade da sua TI!
B6: Este material foi elaborado seguindo os princípios da metodologia COBIT e tem como objetivo ajudar os profissionais de TI avaliarem e assim proporem uma transformação para sua TI.
B7: Seguem Instruções para que você consiga fazer a avaliação no menor tempo possível e com muita assetividade:
B9: 1) No menu Principal você encontrará links (botões) para abrir cada um dos 4 Domínios da metodologia
B10: 2) Cada domínio é composto de perguntas, para cada pergunta você deverá atribuir uma nota entre 0-5 para situação ATUAL e META desejada
B11: 3) Nas celulas de atribuição das notas você encontrará explicações para a avaliação e atribuição dos pontos
B12: 4) Caso você não tenha resposta para todas as perguntas, faça entrevistas com os respectivos responsáveis para que lhe ajudem na atribuição das notas, você também poderá incluir comentários
B13: 5) Consulte o framework do COBIT clicando na imagem do COBIT no menu principal
B14: 6) Tempo estimado para cada Domínio:
B15: Planejar e Organizar = 20 Min
B16: Adquirir e Implementar = 15 Min
... B25: Contatos:
B26: email: | C26: sidnei.goncalves@up2place.com.br
B27: Fone: | C27: (11) 3198-3696
B28: Chat: | C28: www.up2place.com.br
B30: Boa Avaliação!
B32: Sidnei Gonçalves
B33: Co-Fundador UP2Place

Sheet Quadro Geral
A1: ACME
A2: Levantamento do Nível de Maturidade de TI
C4: Abrangência | S4: Total Objetos Ctrl
A5: Domínio | B5: ID/ Processo | C5: 1 | D5: 2 | E5: 3 | F5: 4 | G5: 5 | H5: 6 | I5: 7 | J5: 8 | K5: 9 | L5: 10 | M5: 11 | N5: 12 | O5: 13 | P5: 14 | Q5: 15 | R5: Maturidade Avaliada | S5: Total Objetivos Ctrl | T5: 0 - Inexistente | U5: 1- Inicial | V5: 2- Repetitivo/Intuitivo | W5: 3- Definidos | X5: 4- Gerenciados | Y5: 5- Otimizados | Z5: META ESTABELECIDA
A6: PO | B6: Planejar e Organizar
B7: PO1 - Definir um Plano Estratégico de TI | C7: =+'PO - Questionário'!D5 -> 0 | D7: =+'PO - Questionário'!D6 -> 0 | E7: =+'PO - Questionário'!D7 -> 0 | F7: =+'PO - Questionário'!D8 -> 0 | G7: =+'PO - Questionário'!D9 -> 0 | H7: =+'PO - Questionário'!D10 -> 0 | R7: =+SUM(C7:Q7)/S7 -> 0 | S7: =COUNTA(C7:Q7) -> 6 | T7: =IF($R7<1,"X","") -> X | U7: =IF( AND($R7>=1,$R7<2),"X","") | V7: =IF( AND($R7>=2,$R7<3),"X","") | W7: =IF( AND($R7>=3,$R7<4),"X","") | X7: =IF( AND($R7>=4,$R7<5),"X","") | Y7: =IF( $R7>=5,"X","") | Z7: ='PO - Questionário'!E11 -> 0
B8: PO2 - Definir a Arquitetura da Informação | C8: =+'PO - Questionário'!D15 -> 0 | D8: =+'PO - Questionário'!D16 -> 0 | E8: =+'PO - Questionário'!D17 -> 0 | F8: =+'PO - Questionário'!D18 -> 0 | R8: =+SUM(C8:Q8)/S8 -> 0 | S8: =COUNTA(C8:Q8) -> 4 | T8: =IF($R8<1,"X","") -> X | U8: =IF( AND($R8>=1,$R8<2),"X","") | V8: =IF( AND($R8>=2,$R8<3),"X","") | W8: =IF( AND($R8>=3,$R8<4),"X","") | X8: =IF( AND($R8>=4,$R8<5),"X","") | Y8: =IF( $R8>=5,"X","") | Z8: ='PO - Questionário'!E19 -> 0
B9: PO3 - Determinar o Direcionamento Tecnológico | C9: =+'PO - Questionário'!D23 -> 0 | D9: =+'PO - Questionário'!D24 -> 0 | E9: =+'PO - Questionário'!D25 -> 0 | F9: =+'PO - Questionário'!D26 -> 0 | G9: =+'PO - Questionário'!D27 -> 0 | R9: =+SUM(C9:Q9)/S9 -> 0 | S9: =COUNTA(C9:Q9) -> 5 | T9: =IF($R9<1,"X","") -> X | U9: =IF( AND($R9>=1,$R9<2),"X","") | V9: =IF( AND($R9>=2,$R9<3),"X","") | W9: =IF( AND($R9>=3,$R9<4),"X","") | X9: =IF( AND($R9>=4,$R9<5),"X","") | Y9: =IF( $R9>=5,"X","") | Z9: ='PO - Questionário'!E28 -> 0
B10: PO4 - Definir os Processos, Organização e os Relacionamentos de TI | C10: =+'PO - Questionário'!D32 -> 0 | D10: =+'PO - Questionário'!D33 -> 0 | E10: =+'PO - Questionário'!D34 -> 0 | F10: =+'PO - Questionário'!D35 -> 0 | G10: =+'PO - Questionário'!D36 -> 0 | H10: =+'PO - Questionário'!D37 -> 0 | I10: =+'PO - Questionário'!D38 -> 0 | J10: =+'PO - Questionário'!D39 -> 0 | K10: =+'PO - Questionário'!D40 -> 0 | L10: =+'PO - Questionário'!D41 -> 0 | M10: =+'PO - Questionário'!D42 -> 0 | N10: =+'PO - Questionário'!D43 -> 0 | O10: =+'PO - Questionário'!D44 -> 0 | P10: =+'PO - Questionário'!D45 -> 0 | Q10: =+'PO - Questionário'!D46 -> 0 | R10: =+SUM(C10:Q10)/S10 -> 0 | S10: =COUNTA(C10:Q10) -> 15 | T10: =IF($R10<1,"X","") -> X | U10: =IF( AND($R10>=1,$R10<2),"X","") | V10: =IF( AND($R10>=2,$R10<3),"X","") | W10: =IF( AND($R10>=3,$R10<4),"X","") | X10: =IF( AND($R10>=4,$R10<5),"X","") | Y10: =IF( $R10>=5,"X","") | Z10: ='PO - Questionário'!E47 -> 0
B11: PO5 - Gerenciar o Investimento de TI | C11: =+'PO - Questionário'!D51 -> 0 | D11: =+'PO - Questionário'!D52 -> 0 | E11: =+'PO - Questionário'!D53 -> 0 | F11: =+'PO - Questionário'!D54 -> 0 | G11: =+'PO - Questionário'!D55 -> 0 | R11: =+SUM(C11:Q11)/S11 -> 0 | S11: =COUNTA(C11:Q11) -> 5 | T11: =IF($R11<1,"X","") -> X | U11: =IF( AND($R11>=1,$R11<2),"X","") | V11: =IF( AND($R11>=2,$R11<3),"X","") | W11: =IF( AND($R11>=3,$R11<4),"X","") | X11: =IF( AND($R11>=4,$R11<5),"X","") | Y11: =IF( $R11>=5,"X","") | Z11: ='PO - Questionário'!E56 -> 0
B12: PO6 - Comunicar as Diretrizes e Expectativas da Diretoria | C12: =+'PO - Questionário'!D60 -> 0 | D12: =+'PO - Questionário'!D61 -> 0 | E12: =+'PO - Questionário'!D62 -> 0 | F12: =+'PO - Questionário'!D63 -> 0 | G12: =+'PO - Questionário'!D64 -> 0 | R12: =+SUM(C12:Q12)/S12 -> 0 | S12: =COUNTA(C12:Q12) -> 5 | T12: =IF($R12<1,"X","") -> X | U12: =IF( AND($R12>=1,$R12<2),"X","") | V12: =IF( AND($R12>=2,$R12<3),"X","") | W12: =IF( AND($R12>=3,$R12<4),"X","") | X12: =IF( AND($R12>=4,$R12<5),"X","") | Y12: =IF( $R12>=5,"X","") | Z12: ='PO - Questionário'!E65 -> 0
B13: PO7 - Gerenciar os Recursos Humanos de TI | C13: =+'PO - Questionário'!D69 -> 0 | D13: =+'PO - Questionário'!D70 -> 0 | E13: =+'PO - Questionário'!D71 -> 0 | F13: =+'PO - Questionário'!D72 -> 0 | G13: =+'PO - Questionário'!D73 -> 0 | H13: =+'PO - Questionário'!D74 -> 0 | I13: =+'PO - Questionário'!D75 -> 0 | J13: =+'PO - Questionário'!D76 -> 0 | R13: =+SUM(C13:Q13)/S13 -> 0 | S13: =COUNTA(C13:Q13) -> 8 | T13: =IF($R13<1,"X","") -> X | U13: =IF( AND($R13>=1,$R13<2),"X","") | V13: =IF( AND($R13>=2,$R13<3),"X","") | W13: =IF( AND($R13>=3,$R13<4),"X","") | X13: =IF( AND($R13>=4,$R13<5),"X","") | Y13: =IF( $R13>=5,"X","") | Z13: ='PO - Questionário'!E77 -> 0
B14: PO8 - Gerenciar a Qualidade | C14: =+'PO - Questionário'!D81 -> 0 | D14: =+'PO - Questionário'!D82 -> 0 | E14: =+'PO - Questionário'!D83 -> 0 | F14: =+'PO - Questionário'!D84 -> 0 | G14: =+'PO - Questionário'!D85 -> 0 | H14: =+'PO - Questionário'!D86 -> 0 | R14: =+SUM(C14:Q14)/S14 -> 0 | S14: =COUNTA(C14:Q14) -> 6 | T14: =IF($R14<1,"X","") -> X | U14: =IF( AND($R14>=1,$R14<2),"X","") | V14: =IF( AND($R14>=2,$R14<3),"X","") | W14: =IF( AND($R14>=3,$R14<4),"X","") | X14: =IF( AND($R14>=4,$R14<5),"X","") | Y14: =IF( $R14>=5,"X","") | Z14: ='PO - Questionário'!E87 -> 0
B15: PO9 - Avaliar e Gerenciar os Riscos de TI | C15: =+'PO - Questionário'!D91 -> 0 | D15: =+'PO - Questionário'!D92 -> 0 | E15: =+'PO - Questionário'!D93 -> 0 | F15: =+'PO - Questionário'!D94 -> 0 | G15: =+'PO - Questionário'!D95 -> 0 | H15: =+'PO - Questionário'!D96 -> 0 | R15: =+SUM(C15:Q15)/S15 -> 0 | S15: =COUNTA(C15:Q15) -> 6 | T15: =IF($R15<1,"X","") -> X | U15: =IF( AND($R15>=1,$R15<2),"X","") | V15: =IF( AND($R15>=2,$R15<3),"X","") | W15: =IF( AND($R15>=3,$R15<4),"X","") | X15: =IF( AND($R15>=4,$R15<5),"X","") | Y15: =IF( $R15>=5,"X","") | Z15: ='PO - Questionário'!E97 -> 0
B16: PO10 - Gerenciar Projetos | C16: =+'PO - Questionário'!D101 -> 0 | D16: =+'PO - Questionário'!D102 -> 0 | E16: =+'PO - Questionário'!D103 -> 0 | F16: =+'PO - Questionário'!D104 -> 0 | G16: =+'PO - Questionário'!D105 -> 0 | H16: =+'PO - Questionário'!D106 -> 0 | I16: =+'PO - Questionário'!D107 -> 0 | J16: =+'PO - Questionário'!D108 -> 0 | K16: =+'PO - Questionário'!D109 -> 0 | L16: =+'PO - Questionário'!D110 -> 0 | M16: =+'PO - Questionário'!D111 -> 0 | N16: =+'PO - Questionário'!D112 -> 0 | O16: =+'PO - Questionário'!D113 -> 0 | P16: =+'PO - Questionário'!D114 -> 0 | R16: =+SUM(C16:Q16)/S16 -> 0 | S16: =COUNTA(C16:Q16) -> 14 | T16: =IF($R16<1,"X","") -> X | U16: =IF( AND($R16>=1,$R16<2),"X","") | V16: =IF( AND($R16>=2,$R16<3),"X","") | W16: =IF( AND($R16>=3,$R16<4),"X","") | X16: =IF( AND($R16>=4,$R16<5),"X","") | Y16: =IF( $R16>=5,"X","") | Z16: ='PO - Questionário'!E115 -> 0
A17: AI | B17: Adquirir e Implementar
B18: AI1 - Identificar Solução Automatizadas | C18: =+'AI - Questionário'!$D6 -> 0 | D18: =+'AI - Questionário'!D7 -> 0 | E18: =+'AI - Questionário'!D8 -> 0 | F18: =+'AI - Questionário'!D9 -> 0 | R18: =+SUM(C18:Q18)/S18 -> 0 | S18: =COUNTA(C18:Q18) -> 4 | T18: =IF($R18<1,"X","") -> X | U18: =IF( AND($R18>=1,$R18<2),"X","") | V18: =IF( AND($R18>=2,$R18<3),"X","") | W18: =IF( AND($R18>=3,$R18<4),"X","") | X18: =IF( AND($R18>=4,$R18<5),"X","") | Y18: =IF( $R18>=5,"X","") | Z18: ='AI - Questionário'!E10 -> 0
B19: AI2 - Adquirir e Manter Software Aplicativo | C19: =+'AI - Questionário'!D14 -> 0 | D19: =+'AI - Questionário'!D15 -> 0 | E19: =+'AI - Questionário'!D16 -> 0 | F19: =+'AI - Questionário'!D17 -> 0 | G19: =+'AI - Questionário'!D18 -> 0 | H19: =+'AI - Questionário'!D19 -> 0 | I19: =+'AI - Questionário'!D20 -> 0 | J19: =+'AI - Questionário'!D21 -> 0 | K19: =+'AI - Questionário'!D22 -> 0 | L19: =+'AI - Questionário'!D23 -> 0 | R19: =+SUM(C19:Q19)/S19 -> 0 | S19: =COUNTA(C19:Q19) -> 10 | T19: =IF($R19<1,"X","") -> X | U19: =IF( AND($R19>=1,$R19<2),"X","") | V19: =IF( AND($R19>=2,$R19<3),"X","") | W19: =IF( AND($R19>=3,$R19<4),"X","") | X19: =IF( AND($R19>=4,$R19<5),"X","") | Y19: =IF( $R19>=5,"X","") | Z19: ='AI - Questionário'!E24 -> 0
B20: AI3 - Adquirir e Manter Infraestrutura de Tecnologia | C20: =+'AI - Questionário'!D28 -> 0 | D20: =+'AI - Questionário'!D29 -> 0 | E20: =+'AI - Questionário'!D30 -> 0 | F20: =+'AI - Questionário'!D31 -> 0 | R20: =+SUM(C20:Q20)/S20 -> 0 | S20: =COUNTA(C20:Q20) -> 4 | T20: =IF($R20<1,"X","") -> X | U20: =IF( AND($R20>=1,$R20<2),"X","") | V20: =IF( AND($R20>=2,$R20<3),"X","") | W20: =IF( AND($R20>=3,$R20<4),"X","") | X20: =IF( AND($R20>=4,$R20<5),"X","") | Y20: =IF( $R20>=5,"X","") | Z20: ='AI - Questionário'!E32 -> 0
B21: AI4 - Habilitar Operação e Uso | C21: =+'AI - Questionário'!D36 -> 0 | D21: =+'AI - Questionário'!D37 -> 0 | E21: =+'AI - Questionário'!D38 -> 0 | F21: =+'AI - Questionário'!D39 -> 0 | R21: =+SUM(C21:Q21)/S21 -> 0 | S21: =COUNTA(C21:Q21) -> 4 | T21: =IF($R21<1,"X","") -> X | U21: =IF( AND($R21>=1,$R21<2),"X","") | V21: =IF( AND($R21>=2,$R21<3),"X","") | W21: =IF( AND($R21>=3,$R21<4),"X","") | X21: =IF( AND($R21>=4,$R21<5),"X","") | Y21: =IF( $R21>=5,"X","") | Z21: ='AI - Questionário'!E40 -> 0
B22: AI5 - Adquirir Recursos de TI | C22: =+'AI - Questionário'!D44 -> 0 | D22: =+'AI - Questionário'!D45 -> 0 | E22: =+'AI - Questionário'!D46 -> 0 | F22: =+'AI - Questionário'!D47 -> 0 | R22: =+SUM(C22:Q22)/S22 -> 0 | S22: =COUNTA(C22:Q22) -> 4 | T22: =IF($R22<1,"X","") -> X | U22: =IF( AND($R22>=1,$R22<2),"X","") | V22: =IF( AND($R22>=2,$R22<3),"X","") | W22: =IF( AND($R22>=3,$R22<4),"X","") | X22: =IF( AND($R22>=4,$R22<5),"X","") | Y22: =IF( $R22>=5,"X","") | Z22: ='AI - Questionário'!E48 -> 0
B23: AI6 - Gerenciar Mudanças | C23: =+'AI - Questionário'!D52 -> 0 | D23: =+'AI - Questionário'!D53 -> 0 | E23: =+'AI - Questionário'!D54 -> 0 | F23: =+'AI - Questionário'!D55 -> 0 | G23: =+'AI - Questionário'!D56 -> 0 | R23: =+SUM(C23:Q23)/S23 -> 0 | S23: =COUNTA(C23:Q23) -> 5 | T23: =IF($R23<1,"X","") -> X | U23: =IF( AND($R23>=1,$R23<2),"X","") | V23: =IF( AND($R23>=2,$R23<3),"X","") | W23: =IF( AND($R23>=3,$R23<4),"X","") | X23: =IF( AND($R23>=4,$R23<5),"X","") | Y23: =IF( $R23>=5,"X","") | Z23: ='AI - Questionário'!E57 -> 0
B24: AI7 - Instalar e Homologar Soluções e Mudanças | C24: =+'AI - Questionário'!D61 -> 0 | D24: =+'AI - Questionário'!D62 -> 0 | E24: =+'AI - Questionário'!D63 -> 0 | F24: =+'AI - Questionário'!D64 -> 0 | G24: =+'AI - Questionário'!D65 -> 0 | H24: =+'AI - Questionário'!D66 -> 0 | I24: =+'AI - Questionário'!D67 -> 0 | J24: =+'AI - Questionário'!D68 -> 0 | K24: =+'AI - Questionário'!D69 -> 0 | R24: =+SUM(C24:Q24)/S24 -> 0 | S24: =COUNTA(C24:Q24) -> 9 | T24: =IF($R24<1,"X","") -> X | U24: =IF( AND($R24>=1,$R24<2),"X","") | V24: =IF( AND($R24>=2,$R24<3),"X","") | W24: =IF( AND($R24>=3,$R24<4),"X","") | X24: =IF( AND($R24>=4,$R24<5),"X","") | Y24: =IF( $R24>=5,"X","") | Z24: ='AI - Questionário'!E70 -> 0
A25: DS | B25: Entregar Suportar
B26: DS1 - Definir e Gerenciar Níveis de Serviços | C26: =+'DS - Questionário'!D6 -> 0 | D26: =+'DS - Questionário'!D7 -> 0 | E26: =+'DS - Questionário'!D8 -> 0 | F26: =+'DS - Questionário'!D9 -> 0 | G26: =+'DS - Questionário'!D10 -> 0 | H26: =+'DS - Questionário'!D11 -> 0 | R26: =+SUM(C26:Q26)/S26 -> 0 | S26: =COUNTA(C26:Q26) -> 6 | T26: =IF($R26<1,"X","") -> X | U26: =IF( AND($R26>=1,$R26<2),"X","") | V26: =IF( AND($R26>=2,$R26<3),"X","") | W26: =IF( AND($R26>=3,$R26<4),"X","") | X26: =IF( AND($R26>=4,$R26<5),"X","") | Y26: =IF( $R26>=5,"X","") | Z26: ='DS - Questionário'!E12 -> 0
B27: DS2 - Gerenciar Serviços de Terceiros | C27: =+'DS - Questionário'!D16 -> 0 | D27: =+'DS - Questionário'!D17 -> 0 | E27: =+'DS - Questionário'!D18 -> 0 | F27: =+'DS - Questionário'!D19 -> 0 | R27: =+SUM(C27:Q27)/S27 -> 0 | S27: =COUNTA(C27:Q27) -> 4 | T27: =IF($R27<1,"X","") -> X | U27: =IF( AND($R27>=1,$R27<2),"X","") | V27: =IF( AND($R27>=2,$R27<3),"X","") | W27: =IF( AND($R27>=3,$R27<4),"X","") | X27: =IF( AND($R27>=4,$R27<5),"X","") | Y27: =IF( $R27>=5,"X","") | Z27: ='DS - Questionário'!E20 -> 0
B28: DS3 - Gerenciar Capacidade e Desempenho | C28: =+'DS - Questionário'!D24 -> 0 | D28: =+'DS - Questionário'!D25 -> 0 | E28: =+'DS - Questionário'!D26 -> 0 | F28: =+'DS - Questionário'!D27 -> 0 | G28: =+'DS - Questionário'!D28 -> 0 | R28: =+SUM(C28:Q28)/S28 -> 0 | S28: =COUNTA(C28:Q28) -> 5 | T28: =IF($R28<1,"X","") -> X | U28: =IF( AND($R28>=1,$R28<2),"X","") | V28: =IF( AND($R28>=2,$R28<3),"X","") | W28: =IF( AND($R28>=3,$R28<4),"X","") | X28: =IF( AND($R28>=4,$R28<5),"X","") | Y28: =IF( $R28>=5,"X","") | Z28: ='DS - Questionário'!E29 -> 0
B29: DS4 - Assegurar Continuidade de Serviços: | C29: =+'DS - Questionário'!D33 -> 0 | D29: =+'DS - Questionário'!D34 -> 0 | E29: =+'DS - Questionário'!D35 -> 0 | F29: =+'DS - Questionário'!D36 -> 0 | G29: =+'DS - Questionário'!D37 -> 0 | H29: =+'DS - Questionário'!D38 -> 0 | I29: =+'DS - Questionário'!D39 -> 0 | J29: =+'DS - Questionário'!D41 -> 0 | K29: =+'DS - Questionário'!D42 -> 0 | R29: =+SUM(C29:Q29)/S29 -> 0 | S29: =COUNTA(C29:Q29) -> 9 | T29: =IF($R29<1,"X","") -> X | U29: =IF( AND($R29>=1,$R29<2),"X","") | V29: =IF( AND($R29>=2,$R29<3),"X","") | W29: =IF( AND($R29>=3,$R29<4),"X","") | X29: =IF( AND($R29>=4,$R29<5),"X","") | Y29: =IF( $R29>=5,"X","") | Z29: ='DS - Questionário'!E43 -> 0
B30: DS5 - Assegurar a Segurança dos Serviços | C30: =+'DS - Questionário'!D47 -> 0 | D30: =+'DS - Questionário'!D48 -> 0 | E30: =+'DS - Questionário'!D49 -> 0 | F30: =+'DS - Questionário'!D50 -> 0 | G30: =+'DS - Questionário'!D51 -> 0 | H30: =+'DS - Questionário'!D52 -> 0 | I30: =+'DS - Questionário'!D53 -> 0 | J30: =+'DS - Questionário'!D54 -> 0 | K30: =+'DS - Questionário'!D55 -> 0 | L30: =+'DS - Questionário'!D56 -> 0 | M30: =+'DS - Questionário'!D57 -> 0 | R30: =+SUM(C30:Q30)/S30 -> 0 | S30: =COUNTA(C30:Q30) -> 11 | T30: =IF($R30<1,"X","") -> X | U30: =IF( AND($R30>=1,$R30<2),"X","") | V30: =IF( AND($R30>=2,$R30<3),"X","") | W30: =IF( AND($R30>=3,$R30<4),"X","") | X30: =IF( AND($R30>=4,$R30<5),"X","") | Y30: =IF( $R30>=5,"X","") | Z30: ='DS - Questionário'!E58 -> 0
B31: DS6 - Identificar e Alocar Custos | C31: =+'DS - Questionário'!D62 -> 0 | D31: =+'DS - Questionário'!D63 -> 0 | E31: =+'DS - Questionário'!D64 -> 0 | F31: =+'DS - Questionário'!D65 -> 0 | R31: =+SUM(C31:Q31)/S31 -> 0 | S31: =COUNTA(C31:Q31) -> 4 | T31: =IF($R31<1,"X","") -> X | U31: =IF( AND($R31>=1,$R31<2),"X","") | V31: =IF( AND($R31>=2,$R31<3),"X","") | W31: =IF( AND($R31>=3,$R31<4),"X","") | X31: =IF( AND($R31>=4,$R31<5),"X","") | Y31: =IF( $R31>=5,"X","") | Z31: ='DS - Questionário'!E66 -> 0
B32: DS7 - Educar e Treinar os Usuários | C32: =+'DS - Questionário'!D70 -> 0 | D32: =+'DS - Questionário'!D71 -> 0 | E32: =+'DS - Questionário'!D72 -> 0 | R32: =+SUM(C32:Q32)/S32 -> 0 | S32: =COUNTA(C32:Q32) -> 3 | T32: =IF($R32<1,"X","") -> X | U32: =IF( AND($R32>=1,$R32<2),"X","") | V32: =IF( AND($R32>=2,$R32<3),"X","") | W32: =IF( AND($R32>=3,$R32<4),"X","") | X32: =IF( AND($R32>=4,$R32<5),"X","") | Y32: =IF( $R32>=5,"X","") | Z32: ='DS - Questionário'!E73 -> 0
B33: DS8 - Gerenciar a Central de Serviço e os Incidentes | C33: =+'DS - Questionário'!D77 -> 0 | D33: =+'DS - Questionário'!D78 -> 0 | E33: =+'DS - Questionário'!D79 -> 0 | F33: =+'DS - Questionário'!D80 -> 0 | G33: =+'DS - Questionário'!D81 -> 0 | R33: =+SUM(C33:Q33)/S33 -> 0 | S33: =COUNTA(C33:Q33) -> 5 | T33: =IF($R33<1,"X","") -> X | U33: =IF( AND($R33>=1,$R33<2),"X","") | V33: =IF( AND($R33>=2,$R33<3),"X","") | W33: =IF( AND($R33>=3,$R33<4),"X","") | X33: =IF( AND($R33>=4,$R33<5),"X","") | Y33: =IF( $R33>=5,"X","") | Z33: ='DS - Questionário'!E82 -> 0
B34: DS9 - Gerenciar a Configuração | C34: =+'DS - Questionário'!D86 -> 0 | D34: =+'DS - Questionário'!D87 -> 0 | E34: =+'DS - Questionário'!D88 -> 0 | R34: =+SUM(C34:Q34)/S34 -> 0 | S34: =COUNTA(C34:Q34) -> 3 | T34: =IF($R34<1,"X","") -> X | U34: =IF( AND($R34>=1,$R34<2),"X","") | V34: =IF( AND($R34>=2,$R34<3),"X","") | W34: =IF( AND($R34>=3,$R34<4),"X","") | X34: =IF( AND($R34>=4,$R34<5),"X","") | Y34: =IF( $R34>=5,"X","") | Z34: ='DS - Questionário'!E89 -> 0
B35: DS10 - Gerenciar os Problemas | C35: =+'DS - Questionário'!D93 -> 0 | D35: =+'DS - Questionário'!D94 -> 0 | R35: =+SUM(C35:Q35)/S35 -> 0 | S35: =COUNTA(C35:Q35) -> 2 | T35: =IF($R35<1,"X","") -> X | U35: =IF( AND($R35>=1,$R35<2),"X","") | V35: =IF( AND($R35>=2,$R35<3),"X","") | W35: =IF( AND($R35>=3,$R35<4),"X","") | X35: =IF( AND($R35>=4,$R35<5),"X","") | Y35: =IF( $R35>=5,"X","") | Z35: ='DS - Questionário'!E95 -> 0
B36: DS11 - Gerenciar Dados | C36: =+'DS - Questionário'!D99 -> 0 | D36: =+'DS - Questionário'!D100 -> 0 | E36: =+'DS - Questionário'!D101 -> 0 | F36: =+'DS - Questionário'!D102 -> 0 | G36: =+'DS - Questionário'!D103 -> 0 | H36: =+'DS - Questionário'!D104 -> 0 | R36: =+SUM(C36:Q36)/S36 -> 0 | S36: =COUNTA(C36:Q36) -> 6 | T36: =IF($R36<1,"X","") -> X | U36: =IF( AND($R36>=1,$R36<2),"X","") | V36: =IF( AND($R36>=2,$R36<3),"X","") | W36: =IF( AND($R36>=3,$R36<4),"X","") | X36: =IF( AND($R36>=4,$R36<5),"X","") | Y36: =IF( $R36>=5,"X","") | Z36: ='DS - Questionário'!E105 -> 0
B37: DS12- Gerenciar Ambiente Físico | C37: =+'DS - Questionário'!D109 -> 0 | D37: =+'DS - Questionário'!D110 -> 0 | E37: =+'DS - Questionário'!D111 -> 0 | F37: =+'DS - Questionário'!D112 -> 0 | G37: =+'DS - Questionário'!D113 -> 0 | R37: =+SUM(C37:Q37)/S37 -> 0 | S37: =COUNTA(C37:Q37) -> 5 | T37: =IF($R37<1,"X","") -> X | U37: =IF( AND($R37>=1,$R37<2),"X","") | V37: =IF( AND($R37>=2,$R37<3),"X","") | W37: =IF( AND($R37>=3,$R37<4),"X","") | X37: =IF( AND($R37>=4,$R37<5),"X","") | Y37: =IF( $R37>=5,"X","") | Z37: ='DS - Questionário'!E114 -> 0
B38: DS13 - Gerenciar operações | C38: =+'DS - Questionário'!D118 -> 0 | D38: =+'DS - Questionário'!D119 -> 0 | E38: =+'DS - Questionário'!D120 -> 0 | F38: =+'DS - Questionário'!D121 -> 0 | G38: =+'DS - Questionário'!D122 -> 0 | R38: =+SUM(C38:Q38)/S38 -> 0 | S38: =COUNTA(C38:Q38) -> 5 | T38: =IF($R38<1,"X","") -> X | U38: =IF( AND($R38>=1,$R38<2),"X","") | V38: =IF( AND($R38>=2,$R38<3),"X","") | W38: =IF( AND($R38>=3,$R38<4),"X","") | X38: =IF( AND($R38>=4,$R38<5),"X","") | Y38: =IF( $R38>=5,"X","") | Z38: ='DS - Questionário'!E123 -> 0
A39: MA | B39: Monitorar e Avaliar
B40: MA1 - Monitorar e Avaliar o Desempenho | C40: =+'MA - Questionário'!D7 -> 0 | D40: =+'MA - Questionário'!D8 -> 0 | E40: =+'MA - Questionário'!D9 -> 0 | F40: =+'MA - Questionário'!D10 -> 0 | G40: =+'MA - Questionário'!D11 -> 0 | H40: =+'MA - Questionário'!D12 -> 0 | R40: =+SUM(C40:Q40)/S40 -> 0 | S40: =COUNTA(C40:Q40) -> 6 | T40: =IF($R40<1,"X","") -> X | U40: =IF( AND($R40>=1,$R40<2),"X","") | V40: =IF( AND($R40>=2,$R40<3),"X","") | W40: =IF( AND($R40>=3,$R40<4),"X","") | X40: =IF( AND($R40>=4,$R40<5),"X","") | Y40: =IF( $R40>=5,"X","") | Z40: ='MA - Questionário'!E13 -> 0
B41: MA2 - Monitorar e Avaliar os Controles Internos | C41: =+'MA - Questionário'!D17 -> 0 | D41: =+'MA - Questionário'!D18 -> 0 | E41: =+'MA - Questionário'!D19 -> 0 | F41: =+'MA - Questionário'!D20 -> 0 | G41: =+'MA - Questionário'!D21 -> 0 | H41: =+'MA - Questionário'!D22 -> 0 | I41: =+'MA - Questionário'!D23 -> 0 | R41: =+SUM(C41:Q41)/S41 -> 0 | S41: =COUNTA(C41:Q41) -> 7 | T41: =IF($R41<1,"X","") -> X | U41: =IF( AND($R41>=1,$R41<2),"X","") | V41: =IF( AND($R41>=2,$R41<3),"X","") | W41: =IF( AND($R41>=3,$R41<4),"X","") | X41: =IF( AND($R41>=4,$R41<5),"X","") | Y41: =IF( $R41>=5,"X","") | Z41: ='MA - Questionário'!E24 -> 0
...

Sheet PO - Questionário
A3: PO1 | B3: Definir um plano estratégico de TI | D3: Atual | E3: Meta
A4: Objetivos Controle | C4: Pergunta | D4: (0-5) | E4: (0-5) | F4: Comentários
A5: 1 | B5: Gerenciamento do valor de TI | C5: Há um alinhamento da estratégia de TI com a estratégia da empresa? Se sim esta estratégia é avaliada periodicamente? | D5: 0 | E5: 0
A6: 2 | B6: Alinhamento entre TI e Negócio | C6: As prioridades de negócio estão alinhadas com as prioridades de TI? | D6: 0 | E6: 0
A7: 3 | B7: Avaliação da Capacidade e Desempenho Correntes | C7: De acordo com o plano de negócios atual TI consegue entregar os produtos esperados e possui capacidade de planejamento para demandas futuras fruto do crescimento do negócio? | D7: 0 | E7: 0
A8: 4 | B8: Plano Estratégico de TI | C8: Existe um plano estratégico de TI de forma que TI contribua com os objetivos de negócio da empresa? | D8: 0 | E8: 0
A9: 5 | B9: Planos Táticos de TI | C9: Há um plano tático que direcionem os projetos e por consequencia as iniciativas e recursos necessários para implantação dos mesmos? | D9: 0 | E9: 0
A10: 6 | B10: Gerenciamento do Portfólio de TI | C10: Há uma gestão do portfólio de projetos de TI alinhada com os objetivos de negócio e priorizados conforme a sua relevância para este objetivos? | D10: 0 | E10: 0
A11: Maturidade do Processo | D11: =+SUM(D5:D10)/COUNTA(D5:D10) -> 0 | E11: =+SUM(E5:E10)/COUNTA(E5:E10) -> 0
A13: PO2 | B13: Definir a arquitetura da informação
A14: Objetivos Controle | C14: Pergunta | D14: (0-5) | E14: (0-5) | F14: Comentários
A15: 1 | B15: Modelo de Arquitetura da Informação da XP | C15: Existe uma aqruitetura definida que permita o desenvolvimento de aplicações que suportem a tomada de decisão de negócios provendo suporte a segurança da informação? | D15: 0 | E15: 0
A16: 2 | B16: Dicionário de Dados corporativo e regras de sintaxe de dados | C16: Há um dicionário de dados e regras de sintaxe definidas que permita o compartilhamento por toda a organização previnindo a duplicidade de dados? | D16: 0 | E16: 0
A17: 3 | B17: Esquema de Classificação de Dados | C17: Os dados são classificados quanto ao acesso (público, confidencial e restrito) e há a definição do proprietário da informação e das permissãoes de acesso? | D17: 0 | E17: 0
A18: 4 | B18: Gerenciamento de Integridade | C18: Existem procedimentos que garantam a integridade e a concistência dos dados de forma eletrônica independente do método utilizado? | D18: 0 | E18: 0
A19: Maturidade do Processo | D19: =+SUM(D15:D18)/COUNTA(D15:D18) -> 0 | E19: =+SUM(E15:E18)/COUNTA(E15:E18) -> 0
A21: PO3 | B21: Determinar Direção Tecnológica
A22: Objetivos Controle | C22: Pergunta | D22: (0-5) | E22: (0-5) | F22: Comentários
A23: 1 | B23: Planejamento da Diretriz Tecnológica | C23: Há um processo de análise das tecnologias existentes e emergentes no sentido de direcionar o planejamento da área de tecnologia para suportar o negócio? | D23: 0 | E23: 0
A24: 2 | B24: Plano de Infraestrutura Tecnológica | C24: Há um processo que considera mudanças no ambiente competitivo, economia de escala em investimento em pessoal e sistemas, bem como melhorias na interoperabilidade entre plataformas e aplicações? Elas objetivam proporcionar contingência e um plano de aquisições? | D24: 0 | E24: 0
A25: 3 | B25: Monitoramento, Regulamentos e Tendências Futuras | C25: Há um processo para monitorar as tendências das áreas de negócio, tecnologia, infraestrutura, legal e regulatória visando antecipar impactos em TI? As consequências dessas tendências são incorporadas ao desenvolvimento do plano de infraestrutura de tecnologia de TI? | D25: 0 | E25: 0
A26: 4 | B26: Padrões tecnológicos | C26: Existe processo para prover soluções tecnológicas seguras, eficazes e consistentes, em toda a organização? Há um fórum de tecnologia para prover diretrizes tecnológicas, aconselhamento sobre a infraestrutura de produtos, orientação na seleção da tecnologia e avaliar a conformidade com estes padrões e diretrizes? | D26: 0 | E26: 0
A27: 5 | B27: Conselho de Arquitetura de TI | C27: Foi estabelecido um conselho de arquitetura de TI para prover diretrizes de arquitetura, orientar as aplicações e verificar a conformidade? | D27: 0 | E27: 0
A28: Maturidade do Processo | D28: =+SUM(D23:D27)/COUNTA(D23:D27) -> 0 | E28: =+SUM(E23:E27)/COUNTA(E23:E27) -> 0
D29: 0
A30: PO4 | B30: Definir os Processos, Organização e Relacionamentos de TI | D30: 0
A31: Objetivos Controle | C31: Pergunta | D31: (0-5) | E31: (0-5) | F31: Comentários
A32: 1 | B32: Estrutura de Processos de TI | C32: Há uma estrutura de processos e relacionamentos de TI (por exemplo, gerenciar falhas ou interposições de processos), definição de um proprietário, maturidade, medição de desempenho, melhorias, conformidade, metas de qualidade e planos para atingi-las? | D32: 0 | E32: 0
A33: 2 | B33: Comitê Estratégico de TI | C33: Foi estabelecido um comitê estratégico de TI em nível de Diretoria que assegure que a governança de TI seja devidamente considerada como parte da governança corporativa, aconselha sobre o direcionamento estratégico e analisa os principais investimentos em nome de toda a Direção? | D33: 0 | E33: 0
A34: 3 | B34: Comitê Executivo de TI | C34: Já foi estabelecido um comitê executivo (ou equivalente) composto pelas Diretorias Executiva, Negócios e TI para Determinar prioridades dos programas de investimentos em TI em linha com as estratégias e prioridades do negócio? Monitorar o estado atual dos projetos e resolver conflitos de recursos? | D34: 0 | E34: 0
A35: 4 | B35: Posicionamento Organizacional da área de TI | C35: Já foi realizado um posicionamento da área de TI na estrutura geral organizacional através de um modelo que efetivamente considere sua importância e as necessidades de contingência, considerando a importância da TI para a estratégia de negócio e o nível de dependência operacional? | D35: 0 | E35: 0
A36: 5 | B36: Estrutura Organizacional de TI | C36: Há uma estrutura organizacional interna e externa de TI que reflita as necessidades do negócio? Há um processo para revisar periodicamente a estrutura organizacional de TI e ajustar os requisitos de pessoal e estratégias de fornecimento para atender aos objetivos de negócio esperados e a possíveis situações de mudança? | D36: 0 | E36: 0
A37: 6 | B37: Definição de Papéis e Responsabilidades | C37: Estão claros,para o pessoal de TI e usuários finais, seus respectivos papéis e responsabilidades, que especifiquem a autoridade, responsabilidade e responsabilização, com o objetivo de atender às necessidades da organização? | D37: 0 | E37: 0
A38: 7 | B38: Responsabilidade pela Garantia de Qualidade | C38: É atribuida a pelo menos um colaborador a responsabilidade pelo desempenho da função de garantia de qualidade (QA, quality assurance)? | D38: 0 | E38: 0
A39: 8 | B39: Responsabilidade por Riscos, Segurança e Conformidade | C39: Há um papel definido para realizar o gerenciamento dos riscos de TI, incluindo a responsabilidade específica pela segurança da informação, segurança física e conformidade? | D39: 0 | E39: 0
A40: 9 | B40: Proprietários de Dados e Sistemas | C40: Foram estabelecidos os procedimentos e disponibilizadas as ferramentas que possibilitem tratar as responsabilidades dos proprietários dos dados e sistemas de informação? Os proprietários tomam decisões sobre a classificação da informação, dos sistemas e os protegem determinando direitos de acesso em conformidade com essa classificação? | D40: 0 | E40: 0
A41: 10 | B41: Supervisão | C41: Foram implementadas técnicas de supervisão adequadas na área de TI para assegurar que os papéis e as responsabilidades sejam adequadamente exercidos? Também é possível avaliar se todo o pessoal tem autoridade e recursos suficientes para exercer seus papéis e responsabilidades e revisar de forma geral os indicadores-chave de desempenho? | D41: 0 | E41: 0
A42: 11 | B42: Segregação de Funções | C42: Foi implementada uma separação de papéis e responsabilidades que reduza a possibilidade de um único indivíduo comprometer um processo crítico ou comprometer a segurança operacional? A gerência tem como garantir que o pessoal esteja executando apenas tarefas autorizadas relevantes aos seus respectivos cargos e posições? | D42: 0 | E42: 0
A43: 12 | B43: Recrutamento de pessoal de TI | C43: Existe um processo para avaliar os requisitos de recrutamento regularmente ou com base em grandes mudanças nos ambientes de TI, operacional ou de negócio para garantir que a área de TI tenha quantidade suficiente de pessoal para suportar de forma adequada os objetivos e metas de negócios? | D43: 0 | E43: 0
... A46: 15 | B46: Relacionamentos | C46: Já foi estabelecida uma estrutura otimizada de coordenação, comunicação e conexão entre a função de TI e diversos outros interesses dentro ou fora da área de TI; por exemplo, Diretoria, unidades de negócios, usuários individuais, fornecedores, profissionais de segurança, gerentes de risco, gerenciamento de pessoal terceirizado e externo e o grupo de conformidade corporativa (compliance)? | D46: 0 | E46: 0
...

Sheet AI - Questionário
A4: AI1 | B4: Identificar Soluções Automatizadas | D4: Atual | E4: Meta
A5: Objetivos Controle | C5: Pergunta | D5: (0-5) | E5: (0-5) | F5: Comentários
A6: 1 | B6: Definição e Manutenção de Requisitos Técnicos e Funcionais de Negócio | C6: Como são Identificados, priorizados, especificados e pactuados os requisitos técnicos e funcionais do negócio ? | D6: 0 | E6: 0
A7: 2 | B7: Relatório de Análise de Risco | C7: Como são Identificados, documentados e analisados os riscos associados aos requisitos de negócio e desenho de soluções como parte do processo de desenvolvimento dos requisitos da organização? | D7: 0 | E7: 0
A8: 3 | B8: Estudo de Viabilidade e Formulação de Ações Alternativas | C8: É realizado um estudo de viabilidade que examine a possibilidade de implementar os requisitos? O gerenciamento de negócios, suportado pela área de TI, avalia a viabilidade e as ações alternativas e faz recomendações ao patrocinador do negócio? | D8: 0 | E8: 0
A9: 4 | B9: Decisão e Aprovação de Requisitos e Estudo de Viabilidade | C9: O patrocinador do negócio analisa e aprova os requisitos técnicos e funcionais do negócio, bem como os relatórios de estudo de viabilidade em estágios-chave predeterminados? | D9: 0 | E9: 0
A10: Maturidade do Processo | D10: =+SUM(D6:D9)/COUNTA(D6:D9) -> 0 | E10: =+SUM(E6:E9)/COUNTA(E6:E9) -> 0
A12: AI2 | B12: Adquirir e Manter Software Aplicativo
A13: Objetivos Controle | C13: Pergunta | D13: (0-5) | E13: (0-5) | F13: Comentários
A14: 1 | B14: Projeto em Nível Macro | C14: Os requisitos de negócio são traduzidos em especificações de projeto em nível macro para o desenvolvimento de software, levando em consideração o direcionamento tecnológico e a arquitetura de informação da organização? O gerenciamento aprova asespecificações de projeto para assegurar que o projeto de alto nível atenda aos requisitos? | D14: 0 | E14: 0
A15: 2 | B15: Projeto Detalhado | C15: São detalhados os requisitos técnicos e de projeto dos softwares aplicativos a serem desenvolvidos? São definidos os critérios de aceitação dos requisitos? Como? São aprovados os requisitos para assegurar que eles correspondam ao projeto em nível macro? | D15: 0 | E15: 0
A16: 3 | B16: Controle e Auditabilidade do Aplicativo | C16: São criados dispositivos do tipo log, trilhas de auditoria dos sistemas quanto as suas funcionalidades, acessos concedidos e conteúdo acessado? Há ferramentas para recuperação e análise destas informações e as mesmas podem ser recuperadas de forma rápida em casos de emergência? | D16: 0 | E16: 0
A17: 4 | B17: Segurança e Disponibilidade do Aplicativo | C17: Como são considerados os requisitos de segurança e disponibilidade em resposta aos riscos identificados? Estão em linha com a classificação de sensibilidade dos dados, com a arquitetura de segurança da informação e o perfil de tolerância a riscos da organização? | D17: 0 | E17: 0
A18: 5 | B18: Configuração e Implementação de Software Aplicativo Adquirido | C18: São Customizadas e implementadas as funcionalidades automatizadas adquiridas para alcançar os objetivos de negócios? | D18: 0 | E18: 0
A19: 6 | B19: Principais Atualizações dos Sistemas Existentes | C19: É seguido um processo de desenvolvimento similar ao de desenvolvimento de novos sistemas quando ocorrer grandes mudanças nos sistemas existentes que possam resultar em mudanças significativas nos projetos e/ou funcionalidades atuais? | D19: 0 | E19: 0
A20: 7 | B20: Desenvolvimento de Software Aplicativo | C20: É garantido que as funcionalidades automatizadas sejam desenvolvidas em conformidade com as especificações de projeto, padrões de desenvolvimento e documentação e requisitos de qualidade e de autorização? Além disso é assegurado que todos os aspectos contratuais e legais sejam identificados e considerados nos softwares aplicativos desenvolvidos por terceiros? | D20: 0 | E20: 0
A21: 8 | B21: Garantia de Qualidade de Software | C21: Desenvolver e executar o plano de garantia de qualidade de software para obter a qualidade especificada na definição dos requisitos de projeto e nos procedimentos e políticas de qualidade da organização? | D21: 0 | E21: 0
A22: 9 | B22: Gestão dos Requisitos das Aplicações | C22: É acompanhada a situação individual dos requisitos (incluindo rejeição de requisitos) durante o desenho, o desenvolvimento e a implementação e garantir que as mudanças nos requisitos sejam aprovadas através de um processo de gerenciamento de mudanças? | D22: 0 | E22: 0
A23: 10 | B23: Manutenção de Software Aplicativo | C23: Foi desenvolvida uma estratégia e um plano de manutenção de software aplicativo? | D23: 0 | E23: 0
A24: Maturidade do Processo | D24: =+SUM(D14:D23)/COUNTA(D14:D23) -> 0 | E24: =+SUM(E14:E23)/COUNTA(E14:E23) -> 0
A26: AI3 | B26: Adquirir e Manter Infraestrutura de Tecnologia
A27: Objetivos Controle | C27: Pergunta | D27: (0-5) | E27: (0-5) | F27: Comentários
A28: 1 | B28: Plano de Aquisição de Infraestrutura Tecnológica | C28: É preparado um plano para aquisição, implementação e manutenção da infraestrutura tecnológica que satisfaça aos requisitos técnicos e funcionais estabelecidos do negócio e esteja de acordo com a direção tecnológica da organização? | D28: 0 | E28: 0
A29: 2 | B29: Infraestrutura de Recursos, Proteção e Disponibilidade | C29: Foram ou estão sendo implementados controles internos, medidas de segurança e auditabilidade durante a configuração, integração e manutenção de hardware e software da infraestrutura para proteger os recursos e assegurar disponibilidade e integridade? | D29: 0 | E29: 0
A30: 3 | B30: Manutenção da Infraestrutura | C30: Foi ou está sendo implementada uma estratégia e um plano para manutenção da infraestrutura e para assegurar que as mudanças sejam controladas em alinhamento com os procedimentos de gerenciamento de mudança da organização? | D30: 0 | E30: 0
A31: 4 | B31: Viabilidade do Ambiente de Teste | C31: Há um ambiente de desenvolvimento e de teste para proporcionar eficiência e eficácia nos testes de viabilidade e integração dos componentes da infraestrutura? | D31: 0 | E31: 0
A32: Maturidade do Processo | D32: =+SUM(D28:D31)/COUNTA(D28:D31) -> 0 | E32: =+SUM(E28:E31)/COUNTA(E28:E31) -> 0
D33: 5 | E33: 5
A34: AI4 | B34: Habilitar Operação e Uso | D34: 5 | E34: 5
A35: Objetivos Controle | C35: Pergunta | D35: (0-5) | E35: (0-5) | F35: Comentários
A36: 1 | B36: Planejamento para Soluções Operacionais | C36: Háum plano para identificar e documentar todos os aspectos técnicos, a capacidade operacional e os níveis de serviços necessários para que todos que irão operar, utilizar e manter as soluções automatizadas possam exercer suas responsabilidades? | D36: 0 | E36: 0
A37: 2 | B37: Transferência de Conhecimento ao Gerenciamento do Negócio | C37: É transferido o conhecimento ao gerenciamento do negócio para permitir que este assuma a propriedade do sistema e dados, bem como exerça suas responsabilidades nos processos de entrega, qualidade de serviço, controles internos e administração da aplicação? | D37: 0 | E37: 0
A38: 3 | B38: Transferência de Conhecimento aos Usuários Finais | C38: É transferido o conhecimento e habilidades para permitir aos usuários o uso efetivo e eficiente dos sistemas aplicativos que sustentam processos de negócio? | D38: 0 | E38: 0
A39: 4 | B39: Transferência de Conhecimento às Equipes de Operações e Suporte | C39: Há transferência de conhecimento e habilidades para permitir que as equipes de operações e suporte técnico entreguem, suportem e mantenham os sistemas e a infraestrutura associada de forma eficaz e eficiente? | D39: 0 | E39: 0
A40: Maturidade do Processo | D40: =+SUM(D36:D39)/COUNTA(D36:D39) -> 0 | E40: =+SUM(E36:E39)/COUNTA(E36:E39) -> 0
A42: AI5 | B42: Adquirir Recursos de TI
A43: Objetivos Controle | C43: Pergunta | D43: (0-5) | E43: (0-5) | F43: Comentários
A44: 1 | B44: Controle de Aquisição | C44: Existe um conjunto de procedimentos e padrões consistentes com o processo e a estratégia corporativa de aquisição para assegurar que a aquisição de infraestrutura, instalações, hardware, software e serviços satisfaça aos requisitos de negócio? | D44: 0 | E44: 0
A45: 2 | B45: Gerenciamento de Contratos de Fornecedores | C45: Há um procedimento para estabelecer, modificar e rescindir contratos com todos os fornecedores? Se sim, o procedimento contempla as formalidades legais, financeiras, organizacionais, documentais, de desempenho, de segurança e de propriedade intelectual e as responsabilidades e obrigações legais em casos de cancelamento (incluindo cláusulas de penalidades)? | D45: 0 | E45: 0
A46: 3 | B46: Seleção de Fornecedores | C46: Ao selecionar fornecedores de acordo há uma prática formal e justa que assegure a melhor opção viável com base nos requisitos definidos a partir de informações dadas por fornecedores em potencial e acordadas entre fornecedores internos e clientes? | D46: 0 | E46: 0
...

Sheet DS - Questionário
A4: DS1 | B4: Definir e Gerenciar Níveis de Serviço | D4: Atual | E4: Meta | G4: 1
A5: Objetivos Controle | C5: Pergunta | D5: (0-5) | E5: (0-5) | F5: Comentários | G5: 2
A6: 1 | B6: Estrutura de Gestão de Níveis de Serviço | C6: Existe um modelo que fornece um processo formalizado de gerenciamento de níveis de serviço entre o cliente e o provedor de serviço? Se sim, esse modelo mantém um contínuo alinhamento com os requisitos de negócio e suas prioridades e facilita um entendimento comum entre o cliente e o(s) provedor(es)? | D6: 0 | E6: 0 | G6: 3
A7: 2 | B7: Definição de Serviços | C7: Os serviços de TI são baseados nas características de serviços e requisitos do negócio, organizados e armazenados centralmente por meio da implementação de uma abordagem de catálogo/portfólio de serviços? | D7: 0 | E7: 0 | G7: 4
A8: 3 | B8: Acordos de Nível de Serviço | C8: São definidos os acordos de nível de serviço para todos os serviços críticos de TI com base nos requisitos do cliente e na capacidade de entrega por parte da TI? | D8: 0 | E8: 0 | G8: 5
A9: 4 | B9: Acordos de Nível Operacional | C9: É garantido que os acordos de nível operacional (OLAs) expliquem como os serviços serão realizados tecnicamente de modo a apoiar o(s) SLA(s) adequadamente? | D9: 0 | E9: 0
A10: 5 | B10: Monitoramento e Relatório de Realizações de Nível de Serviço | C10: É comum monitorar continuamente os critérios de desempenho dos níveis de serviço especificados.? Os relatórios são disponibilizados em um formato compreensível às partes interessadas em termos de realização de níveis de serviço? | D10: 0 | E10: 0
A11: 6 | B11: Revisão dos Acordos de Nível de Serviço e dos Contratos | C11: É feita regularmente a análise crítica dos acordos de nível de serviço e dos contratos com provedores de serviço internos e externos para assegurar que sejam eficazes e atualizados e que as mudanças em requisitos tenham sido consideradas? | D11: 0 | E11: 0
A12: Maturidade do Processo | D12: =+SUM(D6:D11)/COUNTA(D6:D11) -> 0 | E12: =+SUM(E6:E11)/COUNTA(E6:E11) -> 0
A14: DS2 | B14: Gerenciar Serviços Terceirizados
A15: Objetivos Controle | C15: Pergunta | D15: (0-5) | E15: (0-5) | F15: Comentários
A16: 1 | B16: Identificação do Relacionamento com Todos os Fornecedores | C16: Todos os serviços terceirizados estão identificados e categorizados de acordo com o tipo, a importância e a criticidade? É usual manter documentação formal dos relacionamentos técnicos e organizacionais contemplando papéis e responsabilidades, metas, produtos esperados e as credenciais dos representantes desses fornecedores? | D16: 0 | E16: 0
A17: 2 | B17: Gestão do Relacionamento com Fornecedores | C17: É norma formalizar o processo de gestão do relacionamento com cada fornecedor estabelecendo a ligação entre os clientes e os negócios dos fornecedores e garantindo a qualidade do relacionamento com base na confiança e na transparência (por exemplo, através dos acordos de nível de serviço)? | D17: 0 | E17: 0
A18: 3 | B18: Gerenciamento de Riscos do Fornecedor | C18: É usual identificar e minimizar os riscos relacionados à capacidade dos fornecedores de prestação efetiva de serviços de maneira contínua, segura e eficiente, garantindo que os contratos estejam em conformidade com os padrões universais de negócios e de acordo com as exigências legais e regulamentares, acordos de confidencialidade (NDA)? | D18: 0 | E18: 0
A19: 4 | B19: Monitoramento de Desempenho do Fornecedor | C19: Já foi estabelecido um processo para monitorar a prestação do serviço de modo a assegurar que o fornecedor atenda aos requisitos atuais do negócio, obedecendo os contratos e acordos de nível de serviço firmados, e que seu desempenho seja competitivo com outros prestadores e condições do mercado? | D19: 0 | E19: 0
A20: Maturidade do Processo | D20: =+SUM(D16:D19)/COUNTA(D16:D19) -> 0 | E20: =+SUM(E16:E19)/COUNTA(E16:E19) -> 0
A22: DS3 | B22: Gerenciar o Desempenho e a Capacidade
A23: Objetivos Controle | C23: Pergunta | D23: (0-5) | E23: (0-5) | F23: Comentários
A24: 1 | B24: Desempenho e Planejamento de Capacidade | C24: Foi estabelecido um processo de planejamento para a realização de análise crítica do desempenho e da capacidade dos recursos de TI, de forma a assegurar que com custos justificáveis o desempenho e a capacidade estejam disponíveis para processar a carga de serviço acordada conforme determinam os acordos de nível de serviço? | D24: 0 | E24: 0
A25: 2 | B25: Capacidade e Desempenho Atuais | C25: Foi estebelecido um processo para realizar a análise crítica do desempenho e a capacidade atual dos recursos de TI de forma a determinar se existe capacidade e desempenho suficientes para atendimento conforme os níveis de serviço acordados? | D25: 0 | E25: 0
A26: 3 | B26: Capacidade e Desempenho Futuros | C26: É conduzida regularmente a previsão de desempenho e capacidade dos recursos de TI para minimizar o risco de interrupção de serviços devido a capacidade insuficiente ou degradação do desempenho? São identificados também o excesso de capacidade para possível remanejamento? | D26: 0 | E26: 0
A27: 4 | B27: Disponibilidade de Recursos de TI | C27: Fornece a capacidade e o desempenho necessários, levando em consideração aspectos como cargas normais de trabalho, contingências, requisitos de armazenamento e ciclos de vida de recurso de TI? | D27: 0 | E27: 0
A28: 5 | B28: Monitoramento e Relatórios | C28: Ha monitoramento constante do desempenho e da capacidade dos recursos de TI? Os dados acumulados permitem manter e sintonizar o desempenho atual no ambiente de TI e tratar questões como capacidade de recuperação, contingência, cargas de trabalho atuais e previstas, planejamento de armazenamento e aquisição de recursos? | D28: 0 | E28: 0
A29: Maturidade do Processo | D29: =+SUM(D24:D28)/COUNTA(D24:D28) -> 0 | E29: =+SUM(E24:E28)/COUNTA(E24:E28) -> 0
A31: DS4 | B31: Assegurar a Continuidade dos Serviços
A32: Objetivos Controle | C32: Pergunta | D32: (0-5) | E32: (0-5) | F32: Comentários
A33: 1 | B33: Estrutura de Continuidade | C33: Foi desenvolvido um modelo para continuidade de TI a fim de apoiar o gerenciamento da continuidade do negócio de toda a empresa através de um processo consistente? Este modelo apoia a determinação das necessidades de capacitação em recuperação da infraestrutura e conduzir o desenvolvimento dos planos de contingência de TI e recuperação de desastres? | D33: 0 | E33: 0
A34: 2 | B34: Planos de Continuidade de TI | C34: Foram desenvolvidos planos de continuidade de TI com base na estrutura e projetados para reduzir o impacto de uma grande interrupção de funções e processos de negócio fundamentais? | D34: 0 | E34: 0
A35: 3 | B35: Recursos Críticos de TI | C35: É dada uma atenção especial aos itens mais críticos no plano de continuidade de TI para assegurar a capacidade de restabelecimento e definir prioridades em situações de recuperação? | D35: 0 | E35: 0
A36: 4 | B36: Manutenção do Plano de Continuidade de TI | C36: A gerência de TI é encorajada a definir e executar procedimentos de controle de mudança para assegurar que o plano de continuidade de TI seja mantido atualizado e reflita sempre os requisitos de negócios atuais? | D36: 0 | E36: 0
A37: 5 | B37: Teste do Plano de Continuidade de TI | C37: O plano de continuidade de TI é testado regularmente para assegurar que os sistemas de TI possam ser efetivamente recuperados, que desvios sejam tratados e que o plano se mantenha relevante? | D37: 0 | E37: 0
A38: 6 | B38: Treinamento do Plano de Continuidade de TI | C38: Há um processo para assegurar que todas as partes envolvidas recebam treinamento regular sobre os procedimentos, papéis e respectivas responsabilidades no caso de um incidente ou desastre. Com qual intensidade e frequencia? | D38: 0 | E38: 0
A39: 7 | B39: Distribuição do Plano de Continuidade | C39: Está definida uma estratégia de distribuição para assegurar que os planos sejam seguramente distribuídos e que estejam apropriadamente disponíveis às partes interessadas e autorizados quando e onde necessário? | D39: 0 | E39: 0
A40: 8 | B40: Recuperação e Retomada dos Serviços de TI | C40: São planejadas as ações a serem executadas nos momentos de recuperação e retomada dos serviços de TI. Isto pode incluir ativação de backup sites, iniciação de processamento alternativo, comunicação para as partes interessadas e os clientes, procedimentos de retorno à produção, etc? | D40: 0 | E40: 0
A41: 9 | B41: Armazenamento de Cópias de Segurança em Locais Remotos | C41: São armazenadas remotamente todas as mídias de cópias de segurança críticas, documentação e outros recursos de TI necessários para a recuperação da TI e os planos de continuidade de negócio? | D41: 0 | E41: 0
A42: 10 | B42: Revisão Pós-Retomada dos Serviços | C42: Após a retomada bem-sucedida da função de TI depois de um desastre, é são aplicados procedimentos para avaliar a adequação do plano atual e realizar sua atualização, se necessário? | D42: 0 | E42: 0
A43: Maturidade do Processo | D43: =+SUM(D33:D42)/COUNTA(D33:D42) -> 0 | E43: =+SUM(E33:E42)/COUNTA(E33:E42) -> 0
A45: DS5 | B45: Garantir a Segurança dos Sistemas
A46: Objetivos Controle | C46: Pergunta | D46: (0-5) | E46: (0-5) | F46: Comentários
A47: 1 | B47: Gestão da Segurança de TI | C47: A segurança de TI é gerenciada no mais alto nível organizacional da empresa de modo que a gestão das ações de segurança esteja em alinhamento com os requisitos do negócio? | D47: 0 | E47: 0
...

Sheet MA - Questionário
F2: Gerente de Sistemas | G2: 0
A5: MA1 | B5: Monitorar e Avaliar o Desempenho de TI | D5: Atual | E5: Meta | G5: 1
A6: Objetivos Controle | C6: Pergunta | D6: (0-5) | E6: (0-5) | F6: Comentários | G6: 2
A7: 1 | B7: Abordagem de Monitoramento | C7: Existe uma abordagem e uma estrutura de monitoramento geral que definam o escopo, a metodologia e o processo a serem seguidos para avaliar a entrega de soluções e serviços de TI e monitorar a contribuição da TI para os resultados do negócio? A estrutura deve está integrada com o sistema de gestão de desempenho corporativo? | D7: 0 | E7: 0 | G7: 3
A8: 2 | B8: Definição e Coleta dos Dados de Monitoramento | C8: Há integração com a área de negócios na definição de um conjunto equilibrado de metas de performance que sejam aprovadas pelas áreas de negócio e demais partes interessadas relevantes? | D8: 0 | E8: 0 | G8: 4
A9: 3 | B9: Método de Monitoramento | C9: Há um método de monitoramento de performance (por exemplo, balanced scorecard) que registre as metas, capture as medições, apresente uma visão ampla e sucinta do desempenho da TI e se ajuste ao sistema de monitoramento corporativo (PL)? | D9: 0 | E9: 0 | G9: 5
A10: 4 | B10: Avaliação de Desempenho | C10: É analisado periodicamente o desempenho com base nas metas, executando a análise de causa-raiz dos problemas e iniciando ação corretiva para tratar as causas ocultas ou pouco claras? | D10: 0 | E10: 0
A11: 5 | B11: Relatórios para a Alta Direção | C11: São disponibilizados informes para a Alta Direção sobre a contribuição de TI para o negócio, especialmente em termos de desempenho do portfólio da organização, programas de investimentos em TI e soluções e serviços de cada programa? | D11: 0 | E11: 0
A12: 6 | B12: Ações Corretivas | C12: São implementadas ações corretivas com base no monitoramento, na avaliação e nos relatórios de desempenho? Isso inclui acompanhamento de todo o processo de monitoramento, relatórios e avaliações com: · Análise crítica, negociação e estabelecimento de respostas da gerência · Atribuição de responsabilidade pelas correções · Verificação dos resultados das ações acordadas | D12: 0 | E12: 0
A13: Maturidade do Processo | D13: =+SUM(D7:D12)/COUNTA(D7:D12) -> 0 | E13: =+SUM(E7:E12)/COUNTA(E7:E12) -> 0
A15: MA2 | B15: Monitorar e Avaliar os Controles Internos
A16: Objetivos Controle | C16: Pergunta | D16: (0-5) | E16: (0-5) | F16: Comentários
A17: 1 | B17: Monitoramento da Estrutura de Controles Internos | C17: A gerencia e diretoria monitoram os controles internos dos seus colaboradores? De que forma? | D17: 0 | E17: 0
A18: 2 | B18: Revisão Gerencial | C18: Há um processo de revisão e melhoria dos controles internos por parte dos níveis gerenciais? | D18: 0 | E18: 0
A19: 3 | B19: Exceções aos Controles | C19: São identificadas todas as exceções aos controles,assegurando que seja feita uma análise crítica das causas-raiz? São encaminhardas e reportadas adequadamente as exceções às partes interessadas.? | D19: 0 | E19: 0
A20: 4 | B20: Autoavaliação dos Controles | C20: Qual o grau de abrangência e a efetividade dos controles internos sobre os processos, as políticas e os contratos de TI através de um programa contínuo de autoavaliação? | D20: 0 | E20: 0
A21: 5 | B21: Garantia dos Controles Internos | C21: É possível obter maior garantia da abrangência e da eficácia dos controles internos através de avaliações de das áreas usuárias? | D21: 0 | E21: 0
A22: 6 | B22: Controles Internos Aplicados a Terceiros | C22: É possível avaliar o status dos controles internos aplicados a cada fornecedor de serviço, certificando-se de que fornecedores externos de serviço atendem às exigências legais e regulatórias e às obrigações contratuais? | D22: 0 | E22: 0
A23: 7 | B23: Ações Corretivas | C23: É possível identificar, iniciar, monitorar e implementar ações corretivas com base nas avaliações e nos relatórios de controle? | D23: 0 | E23: 0
A24: Maturidade do Processo | D24: =+SUM(D17:D23)/COUNTA(D17:D23) -> 0 | E24: =+SUM(E17:E23)/COUNTA(E17:E23) -> 0
A26: MA3 | B26: Assegurar a Conformidade com Requisitos Externos
A27: Objetivos Controle | C27: Pergunta | D27: (0-5) | E27: (0-5) | F27: Comentários
A28: 1 | B28: Identificação dos Requisitos de Conformidade com Leis, Regulamentações e Contratos Externos | C28: Há um processo que permita continuamente identificar as exigências de leis, regulamentos e contratos locais e internacionais que precisam ser atendidos para a inclusão em políticas, padrões, procedimentos e metodologias de TI? | D28: 0 | E28: 0
A29: 2 | B29: Otimização da Resposta aos Requisitos Externos | C29: É usual revisar e ajustar políticas, padrões, procedimentos e metodologias de TI para assegurar que os requisitos legais, regulatórios e contratuais sejam atendidos e comunicados? | D29: 0 | E29: 0
A30: 3 | B30: Avaliação da Conformidade com Requisitos Externos | C30: Há um processo para confirmar a conformidade de políticas, padrões, procedimentos e metodologias de TI com os requisitos legais e regulatórios? | D30: 0 | E30: 0
A31: 4 | B31: Assegurar a Conformidade | C31: Ha um processo para obter e assegurar a conformidade e adesão a todas as políticas internas derivadas de diretrizes legais internas ou externas e requisitos regulatórios ou contratuais externos, confirmando que ações corretivas foram tomadas oportunamente para resolver quaisquer desvios de conformidade pelos proprietário do processo? | D31: 0 | E31: 0
A32: 5 | B32: Informes Integrados | C32: Estão integrados os informes de TI sobre requisitos legais, regulatórios e contratuais aos informes similares de outras funções do negócio? | D32: 0 | E32: 0
A33: Maturidade do Processo | D33: =+SUM(D28:D32)/COUNTA(D28:D32) -> 0 | E33: =+SUM(E28:E32)/COUNTA(E28:E32) -> 0
D34: 3 | E34: 3
A35: MA4 | B35: Prover Governança de TI
A36: Objetivos Controle | C36: Pergunta | D36: (0-5) | E36: (0-5) | F36: Comentários
A37: 1 | B37: Estabelecimento de uma Estrutura de Governança de TI | C37: Define, estabelece e alinha a estrutura de governança de TI com a governança organizacional e o ambiente de controle? Basear a estrutura em processos e modelos de controle de TI adequados e implementar práticas e responsabilidades claras para evitar falhas de controle interno e supervisão. | D37: 0 | E37: 0
A38: 2 | B38: Alinhamento Estratégico | C38: A Alta Direção está habilitada no entendimento das questões estratégicas de TI, tais como os papéis de TI, as capacidades e os conhecimentos tecnológicos? Certificar-se de que há um entendimento compartilhado entre o negócio e a TI quanto ao potencial de contribuição de TI com a estratégia de negócio. | D38: 0 | E38: 0
A39: 3 | B39: Entrega de Valor | C39: Gerenciar os programas de investimentos e demais recursos e serviços de TI para assegurar que eles forneçam o maior valor possível no suporte aos objetivos e estratégia do negócio. Assegurar que sejam alcançados os resultados esperados pelo negócio quanto aos investimentos de TI, que o escopo completo de esforços necessários para o alcance desses resultados seja entendido, que estudos de caso abrangentes e consistentes sejam criados e aprovados pelas partes interessadas | D39: 0 | E39: 0
A40: 4 | B40: Gerenciamento de Recursos | C40: É supervisionar o investimento, o uso e a alocação dos recursos de TI por meio de avaliações periódicas das iniciativas e operações de TI, visando assegurar a existência recursos suficientes e o alinhamento com objetivos estratégicos e necessidades de negócios atuais e futuras? | D40: 0 | E40: 0
A41: 5 | B41: Gestão de Riscos | C41: Trabalhar com o conselho diretor para definir o apetite corporativo por riscos de TI e obter uma razoável segurança de que as práticas de gerenciamento de riscos de TI são adequadas para assegurar que os riscos atuais de TI não excedem o apetite de risco da Alta Direção. | D41: 0 | E41: 0
A42: 6 | B42: Medição de Desempenho | C42: Confirmar se os objetivos acordados de TI foram atingidos ou excedidos ou se o progresso na direção dos objetivos de TI atende as expectativas. | D42: 0 | E42: 0
A43: 7 | B43: Avaliação Independente | C43: É Obtido avaliação independente (interna ou externa) sobre a conformidade de TI com leis e regulamentos relevantes, com políticas padrões e procedimentos organizacionais, com práticas geralmente aceitas e a efetiva e eficiente performance de TI? | D43: 0 | E43: 0
A44: Maturidade do Processo | D44: =+SUM(D37:D43)/COUNTA(D37:D43) -> 0 | E44: =+SUM(E37:E43)/COUNTA(E37:E43) -> 0

Sheet Gráficos Maturidade
A1: Banchmark de Maturidade : Brazil Infrastructure Maturity X-Ray 2011 (Accenture e IDC)
R2: Processos | S2: Maturidade Apurada | T2: META Estabelecida
A3: Processos | B3: Maturidade Apurada | C3: META Estabelecida | R3: DS1 | S3: =+'DS - Questionário'!D12 -> 0 | T3: =+'DS - Questionário'!E12 -> 0
A4: PO1 | B4: =+'PO - Questionário'!D11 -> 0 | C4: =+'PO - Questionário'!E11 -> 0 | R4: DS2 | S4: =+'DS - Questionário'!D20 -> 0 | T4: =+'DS - Questionário'!E20 -> 0
A5: PO2 | B5: =+'PO - Questionário'!D19 -> 0 | C5: =+'PO - Questionário'!E19 -> 0 | R5: DS3 | S5: =+'DS - Questionário'!D29 -> 0 | T5: =+'DS - Questionário'!E29 -> 0
A6: PO3 | B6: =+'PO - Questionário'!D28 -> 0 | C6: =+'PO - Questionário'!E28 -> 0 | R6: DS4 | S6: =+'DS - Questionário'!D43 -> 0 | T6: =+'DS - Questionário'!E43 -> 0
A8: PO4 | B8: =+'PO - Questionário'!D47 -> 0 | C8: =+'PO - Questionário'!E47 -> 0 | R8: DS5 | S8: =+'DS - Questionário'!D58 -> 0 | T8: =+'DS - Questionário'!E58 -> 0
A9: PO5 | B9: =+'PO - Questionário'!D56 -> 0 | C9: =+'PO - Questionário'!E56 -> 0 | R9: DS6 | S9: =+'DS - Questionário'!D66 -> 0 | T9: =+'DS - Questionário'!E66 -> 0
A10: PO6 | B10: =+'PO - Questionário'!D65 -> 0 | C10: =+'PO - Questionário'!E65 -> 0 | R10: DS7 | S10: =+'DS - Questionário'!D73 -> 0 | T10: =+'DS - Questionário'!E73 -> 0
A11: PO7 | B11: =+'PO - Questionário'!D77 -> 0 | C11: =+'PO - Questionário'!E77 -> 0 | R11: DS8 | S11: =+'DS - Questionário'!D82 -> 0 | T11: =+'DS - Questionário'!E82 -> 0
A12: PO8 | B12: =+'PO - Questionário'!D87 -> 0 | C12: =+'PO - Questionário'!E87 -> 0 | R12: DS9 | S12: =+'DS - Questionário'!D89 -> 0 | T12: =+'DS - Questionário'!E89 -> 0
A13: PO9 | B13: =+'PO - Questionário'!D97 -> 0 | C13: =+'PO - Questionário'!E97 -> 0 | R13: DS10 | S13: =+'DS - Questionário'!D95 -> 0 | T13: =+'DS - Questionário'!E95 -> 0
A14: PO10 | B14: =+'PO - Questionário'!D115 -> 0 | C14: =+'PO - Questionário'!E115 -> 0 | R14: DS11 | S14: =+'DS - Questionário'!D105 -> 0 | T14: =+'DS - Questionário'!E105 -> 0
A15: Média | B15: =MEDIAN(B4:B14) -> 0 | C15: =MEDIAN(C4:C14) -> 0 | R15: DS12 | S15: =+'DS - Questionário'!D114 -> 0 | T15: =+'DS - Questionário'!E114 -> 0
R16: DS13 | S16: =+'DS - Questionário'!D123 -> 0 | T16: =+'DS - Questionário'!E123 -> 0
A26: Processos | B26: Maturidade Apurada | C26: META Estabelecida
A27: AI1 | B27: =+'AI - Questionário'!D10 -> 0 | C27: =+'AI - Questionário'!E10 -> 0
A28: AI2 | B28: =+'AI - Questionário'!D24 -> 0 | C28: =+'AI - Questionário'!E24 -> 0
A29: AI3 | B29: =+'AI - Questionário'!D32 -> 0 | C29: =+'AI - Questionário'!E32 -> 0
A30: AI4 | B30: =+'AI - Questionário'!D40 -> 0 | C30: =+'AI - Questionário'!E40 -> 0
A31: AI5 | B31: =+'AI - Questionário'!D48 -> 0 | C31: =+'AI - Questionário'!E48 -> 0
A32: AI6 | B32: =+'AI - Questionário'!D57 -> 0 | C32: =+'AI - Questionário'!E57 -> 0
A33: AI7 | B33: =+'AI - Questionário'!D70 -> 0 | C33: =+'AI - Questionário'!E70 -> 0
R46: Processos | S46: Maturidade Apurada | T46: META Estabelecida
R47: PO1 | S47: =+B4 -> 0 | T47: =+C4 -> 0
R48: PO2 | S48: =+B5 -> 0 | T48: =+C5 -> 0
