Workbook

Sheet Dashboards

Sheet Pré Implantação
A1: ID | B1: Planejamento | C1: Final do Planejamento | D1: Plano de Retorno \ Rollback | E1: Atualização do Inventário OCS | F1: Catálogo de Serviços Tprocess | G1: Atualização de Monitoração NOC | H1: Backup Definido | I1: Gravação Ativa | J1: SLA Definido \ Conhecido | K1: Contrato Conhecido | L1: Existe Contingência? | M1: Book Atualizado | N1: Avaliação Desenho x Solução
A2: Média | D2: =AVERAGE(D3:D421) -> 0.97 | E2: =AVERAGE(E3:E421) -> 0.61666667 | F2: =AVERAGE(F3:F421) -> 0.76666667 | G2: =AVERAGE(G3:G421) -> 0.6 | H2: =AVERAGE(H3:H421) -> 0.75714286 | I2: =AVERAGE(I3:I421) -> 0.48333333 | J2: =AVERAGE(J3:J421) -> 0.92 | K2: =AVERAGE(K3:K421) -> 0.4 | ... N2: =AVERAGE(N3:N421) -> 0.56666667
A3: 12345 | B3: Produção TI | C3: 42569.658 | D3: 1 | E3: N/A | F3: 1 | G3: 0.9 | H3: 0.7 | I3: 0 | J3: N/A | K3: N/A | L3: N/A | M3: 0.7 | N3: N/A
A4: 12346 | B4: CSE Microsoft | C4: 42568.792 | D4: 1 | E4: N/A | F4: N/A | G4: 1 | H4: 0.5 | I4: 1 | J4: 0.9 | K4: N/A | L4: 0.9 | M4: N/A | N4: 1
A5: 12347 | B5: CSC Service Desk | C5: 42564.5 | D5: 1 | E5: 0.2 | F5: 0.9 | G5: 0 | H5: N/A | I5: 0.2 | J5: N/A | K5: N/A | L5: 1 | M5: N/A | N5: 0.5
A6: 12348 | B6: CSE Telecom | C6: 42573.41 | D6: 1 | E6: N/A | F6: 0.5 | G6: N/A | H6: N/A | I6: N/A | J6: N/A | K6: N/A | L6: N/A | M6: N/A | N6: N/A
A7: 12349 | B7: Infraestrutura | C7: 42561.083 | D7: 1 | E7: 1 | F7: 1 | G7: 0.8 | H7: 1 | I7: 1 | J7: 1 | K7: 0.2 | L7: 1 | M7: 1 | N7: 0.6
A8: 12350 | B8: URA | C8: 42570.583 | D8: 1 | E8: 0.7 | F8: N/A | G8: 0 | H8: 0.7 | I8: N/A | J8: 0.9 | K8: N/A | L8: N/A | M8: N/A | N8: N/A
A9: 12351 | B9: CSE Microsoft | C9: 42562.229 | D9: 0.7 | E9: N/A | F9: N/A | G9: 0.7 | H9: 0.8 | I9: N/A | J9: N/A | K9: N/A | L9: N/A | M9: N/A | N9: 0.2
A10: 12352 | B10: URA | C10: 42574.458 | D10: 1 | E10: 0.9 | F10: N/A | G10: N/A | H10: N/A | I10: N/A | J10: N/A | K10: N/A | L10: 0.5 | M10: N/A | N10: N/A
A11: 12353 | B11: CSE Telecom | C11: 42568.021 | D11: 1 | E11: N/A | F11: N/A | G11: N/A | H11: N/A | I11: 0 | J11: N/A | K11: N/A | L11: 1 | M11: N/A | N11: N/A
A12: 12354 | B12: CSE Microsoft | C12: 42569.802 | D12: 1 | E12: 0.5 | F12: 1 | G12: 0.8 | H12: 1 | I12: 0.7 | J12: 1 | K12: 1 | L12: 1 | M12: 1 | N12: 1
A13: 12355 | B13: URA | C13: 42569.667 | D13: N/A | E13: 0.4 | F13: 0.2 | G13: N/A | H13: 0.6 | I13: N/A | J13: 0.8 | K13: 0 | L13: N/A | M13: N/A | N13: 0.1

Sheet Pós Implantação
A1: ID | B1: Planejamento | C1: Prazo Final | D1: Plano de Retorno \ Rollback | E1: Atualização do Inventário OCS | F1: Catálogo de Serviços Tprocess | G1: Atualização de Monitoração NOC | H1: Backup Definido | I1: Gravação Ativa | J1: SLA Definido \ Conhecido | K1: Contrato Conhecido | L1: Existe Contingência? | M1: Book Atualizado | N1: Avaliação Desenho x Solução
A2: Média | D2: =AVERAGE(D3:D421) -> 0.97 | E2: =AVERAGE(E3:E421) -> 0.93333333 | F2: =AVERAGE(F3:F421) -> 1 | G2: =AVERAGE(G3:G421) -> 1 | H2: =AVERAGE(H3:H421) -> 0.84285714 | I2: =AVERAGE(I3:I421) -> 0.85 | J2: =AVERAGE(J3:J421) -> 0.94 | K2: =AVERAGE(K3:K421) -> 0.65 | ... N2: =AVERAGE(N3:N421) -> 0.76666667
A3: ='Pré Implantação'!A3 -> 12345 | B3: ='Pré Implantação'!B3 -> Produção TI | C3: =IF('Pré Implantação'!C3=0,"0",'Pré Implantação'!C3+10) -> 42579.658 | D3: 1 | E3: N/A | F3: 1 | G3: 1 | H3: 0.9 | I3: 1 | J3: N/A | K3: N/A | L3: N/A | M3: 0.7 | N3: N/A
A4: ='Pré Implantação'!A4 -> 12346 | B4: ='Pré Implantação'!B4 -> CSE Microsoft | C4: =IF('Pré Implantação'!C4=0,"0",'Pré Implantação'!C4+10) -> 42578.792 | D4: 1 | E4: N/A | F4: N/A | G4: 1 | H4: 0.7 | I4: 1 | J4: 0.9 | K4: N/A | L4: 1 | M4: N/A | N4: 1
A5: ='Pré Implantação'!A5 -> 12347 | B5: ='Pré Implantação'!B5 -> CSC Service Desk | C5: =IF('Pré Implantação'!C5=0,"0",'Pré Implantação'!C5+10) -> 42574.5 | D5: 1 | E5: 1 | F5: 1 | G5: 1 | H5: N/A | I5: 0.8 | J5: N/A | K5: N/A | L5: 1 | M5: N/A | N5: 0.6
A6: ='Pré Implantação'!A6 -> 12348 | B6: ='Pré Implantação'!B6 -> CSE Telecom | C6: =IF('Pré Implantação'!C6=0,"0",'Pré Implantação'!C6+10) -> 42583.41 | D6: 1 | E6: N/A | F6: 1 | G6: N/A | H6: N/A | I6: N/A | J6: N/A | K6: N/A | L6: N/A | M6: N/A | N6: N/A
A7: ='Pré Implantação'!A7 -> 12349 | B7: ='Pré Implantação'!B7 -> Infraestrutura | C7: =IF('Pré Implantação'!C7=0,"0",'Pré Implantação'!C7+10) -> 42571.083 | D7: 1 | E7: 1 | F7: 1 | G7: 1 | H7: 1 | I7: 1 | J7: 1 | K7: 0.2 | L7: 1 | M7: 1 | N7: 0.6
A8: ='Pré Implantação'!A8 -> 12350 | B8: ='Pré Implantação'!B8 -> URA | C8: =IF('Pré Implantação'!C8=0,"0",'Pré Implantação'!C8+10) -> 42580.583 | D8: 1 | E8: 1 | F8: N/A | G8: 1 | H8: 0.7 | I8: N/A | J8: 1 | K8: N/A | L8: N/A | M8: N/A | N8: N/A
A9: ='Pré Implantação'!A9 -> 12351 | B9: ='Pré Implantação'!B9 -> CSE Microsoft | C9: =IF('Pré Implantação'!C9=0,"0",'Pré Implantação'!C9+10) -> 42572.229 | D9: 0.7 | E9: N/A | F9: N/A | G9: 1 | H9: 0.8 | I9: N/A | J9: N/A | K9: N/A | L9: N/A | M9: N/A | N9: 1
A10: ='Pré Implantação'!A10 -> 12352 | B10: ='Pré Implantação'!B10 -> URA | C10: =IF('Pré Implantação'!C10=0,"0",'Pré Implantação'!C10+10) -> 42584.458 | D10: 1 | E10: 0.9 | F10: N/A | G10: N/A | H10: N/A | I10: N/A | J10: N/A | K10: N/A | L10: 0.5 | M10: N/A | N10: N/A
A11: ='Pré Implantação'!A11 -> 12353 | B11: ='Pré Implantação'!B11 -> CSE Telecom | C11: =IF('Pré Implantação'!C11=0,"0",'Pré Implantação'!C11+10) -> 42578.021 | D11: 1 | E11: N/A | F11: N/A | G11: N/A | H11: N/A | I11: 0.3 | J11: N/A | K11: N/A | L11: 1 | M11: N/A | N11: N/A
A12: ='Pré Implantação'!A12 -> 12354 | B12: ='Pré Implantação'!B12 -> CSE Microsoft | C12: =IF('Pré Implantação'!C12=0,"0",'Pré Implantação'!C12+10) -> 42579.802 | D12: 1 | E12: 1 | F12: 1 | G12: 1 | H12: 1 | I12: 1 | J12: 1 | K12: 1 | L12: 1 | M12: 1 | N12: 1
A13: ='Pré Implantação'!A13 -> 12355 | B13: ='Pré Implantação'!B13 -> URA | C13: =IF('Pré Implantação'!C13=0,"0",'Pré Implantação'!C13+10) -> 42579.667 | D13: N/A | E13: 0.7 | F13: 1 | G13: N/A | H13: 0.8 | I13: N/A | J13: 0.8 | K13: 0.75 | L13: N/A | M13: N/A | N13: 0.4
A14: ='Pré Implantação'!A14 -> 0 | B14: ='Pré Implantação'!B14 -> 0 | C14: =IF('Pré Implantação'!C14=0,"0",'Pré Implantação'!C14+10) -> 0
A15: ='Pré Implantação'!A15 -> 0 | B15: ='Pré Implantação'!B15 -> 0 | C15: =IF('Pré Implantação'!C15=0,"0",'Pré Implantação'!C15+10) -> 0
A16: ='Pré Implantação'!A16 -> 0 | B16: ='Pré Implantação'!B16 -> 0 | C16: =IF('Pré Implantação'!C16=0,"0",'Pré Implantação'!C16+10) -> 0
A17: ='Pré Implantação'!A17 -> 0 | B17: ='Pré Implantação'!B17 -> 0 | C17: =IF('Pré Implantação'!C17=0,"0",'Pré Implantação'!C17+10) -> 0
A18: ='Pré Implantação'!A18 -> 0 | B18: ='Pré Implantação'!B18 -> 0 | C18: =IF('Pré Implantação'!C18=0,"0",'Pré Implantação'!C18+10) -> 0
A19: ='Pré Implantação'!A19 -> 0 | B19: ='Pré Implantação'!B19 -> 0 | C19: =IF('Pré Implantação'!C19=0,"0",'Pré Implantação'!C19+10) -> 0
A20: ='Pré Implantação'!A20 -> 0 | B20: ='Pré Implantação'!B20 -> 0 | C20: =IF('Pré Implantação'!C20=0,"0",'Pré Implantação'!C20+10) -> 0
A21: ='Pré Implantação'!A21 -> 0 | B21: ='Pré Implantação'!B21 -> 0 | C21: =IF('Pré Implantação'!C21=0,"0",'Pré Implantação'!C21+10) -> 0
A22: ='Pré Implantação'!A22 -> 0 | B22: ='Pré Implantação'!B22 -> 0 | C22: =IF('Pré Implantação'!C22=0,"0",'Pré Implantação'!C22+10) -> 0
A23: ='Pré Implantação'!A23 -> 0 | B23: ='Pré Implantação'!B23 -> 0 | C23: =IF('Pré Implantação'!C23=0,"0",'Pré Implantação'!C23+10) -> 0
A24: ='Pré Implantação'!A24 -> 0 | B24: ='Pré Implantação'!B24 -> 0 | C24: =IF('Pré Implantação'!C24=0,"0",'Pré Implantação'!C24+10) -> 0
A25: ='Pré Implantação'!A25 -> 0 | B25: ='Pré Implantação'!B25 -> 0 | C25: =IF('Pré Implantação'!C25=0,"0",'Pré Implantação'!C25+10) -> 0
... A421: ='Pré Implantação'!A421 -> 0 | B421: ='Pré Implantação'!B421 -> 0 | C421: =IF('Pré Implantação'!C421=0,"0",'Pré Implantação'!C421+10) -> 0

Sheet Entrega Pré Implantação
A1: ID | B1: Final do Planejamento | C1: Produção TI | D1: CSC Service Desk | E1: CSC NOC | F1: CSE Gravadores | G1: CSC | H1: Operações \ Negócio | I1: Projetos | J1: Engenharia | K1: URA | L1: CSE Microsoft | M1: CSE Telecom | N1: Site Suporte de Campo | O1: Infraestrutura
A2: Média de Entrega | C2: =IFERROR(AVERAGE(C3:C421),"") -> 0.68888889 | D2: =IFERROR(AVERAGE(D3:D421),"") -> 0.77777778 | E2: =IFERROR(AVERAGE(E3:E421),"") -> 0.6 | F2: =IFERROR(AVERAGE(F3:F421),"") -> 0.48333333 | G2: =IFERROR(AVERAGE(G3:G421),"") -> 0.92 | H2: =IFERROR(AVERAGE(H3:H421),"") -> 0.4 | I2: =IFERROR(AVERAGE(I3:I421),"") -> 0.9 | J2: =IFERROR(AVERAGE(J3:J421),"") -> 0.56666667 | ... O2: =IFERROR(AVERAGE(O3:O421),"") -> 1
A3: ='Pré Implantação'!A3 -> 12345 | B3: ='Pré Implantação'!C3 -> 42569.658 | C3: =IFERROR(IF('Pré Implantação'!B3="Produção TI",AVERAGE('Pré Implantação'!D3,'Pré Implantação'!L3,'Pré Implantação'!E3,'Pré Implantação'!H3),AVERAGE('Pré Implantação'!E3,'Pré Implantação'!H3)),"") -> 0.85 | D3: =IFERROR(IF('Pré Implantação'!B3="CSC Service Desk",AVERAGE('Pré Implantação'!D3,'Pré Implantação'!L3,'Pré Implantação'!F3),AVERAGE('Pré Implantação'!F3)),"") -> 1 | E3: =IFERROR(IF('Pré Implantação'!B3="CSC NOC",AVERAGE('Pré Implantação'!D3,'Pré Implantação'!L3,'Pré Implantação'!G3),AVERAGE('Pré Implantação'!G3)),"") -> 0.9 | F3: =IFERROR(IF('Pré Implantação'!B3="CSE Gravadores",AVERAGE('Pré Implantação'!D3,'Pré Implantação'!L3,'Pré Implantação'!I3),AVERAGE('Pré Implantação'!I3)),"") -> 0 | G3: =IFERROR(IF('Pré Implantação'!B3="CSC",AVERAGE('Pré Implantação'!D3,'Pré Implantação'!L3,'Pré Implantação'!J3),AVERAGE('Pré Implantação'!J3)),"") | H3: =IFERROR(IF('Pré Implantação'!B3="Operações \ Negócio",AVERAGE('Pré Implantação'!D3,'Pré Implantação'!L3,'Pré Implantação'!K3),AVERAGE('Pré Implantação'!K3)),"") | I3: =IFERROR(IF('Pré Implantação'!B3="Projetos",AVERAGE('Pré Implantação'!D3,'Pré Implantação'!L3,'Pré Implantação'!M3),AVERAGE('Pré Implantação'!M3)),"") -> 0.7 | J3: =IFERROR(IF('Pré Implantação'!B3="Engenharia",AVERAGE('Pré Implantação'!D3,'Pré Implantação'!L3,'Pré Implantação'!N3),AVERAGE('Pré Implantação'!N3)),"") | K3: =IFERROR(IF('Pré Implantação'!B3="URA",AVERAGE('Pré Implantação'!D3,'Pré Implantação'!L3),""),"") | L3: =IFERROR(IF('Pré Implantação'!B3="CSE Microsoft",AVERAGE('Pré Implantação'!D3,'Pré Implantação'!L3),""),"") | M3: =IFERROR(IF('Pré Implantação'!B3="CSE Telecom",AVERAGE('Pré Implantação'!D3,'Pré Implantação'!L3),""),"") | N3: =IFERROR(IF('Pré Implantação'!B3="Site Suporte de Campo",AVERAGE('Pré Implantação'!D3,'Pré Implantação'!L3),""),"") | O3: =IFERROR(IF('Pré Implantação'!B3="Infraestrutura",AVERAGE('Pré Implantação'!D3,'Pré Implantação'!L3),""),"")
A4: ='Pré Implantação'!A4 -> 12346 | B4: ='Pré Implantação'!C4 -> 42568.792 | C4: =IFERROR(IF('Pré Implantação'!B4="Produção TI",AVERAGE('Pré Implantação'!D4,'Pré Implantação'!L4,'Pré Implantação'!E4,'Pré Implantação'!H4),AVERAGE('Pré Implantação'!E4,'Pré Implantação'!H4)),"") -> 0.5 | D4: =IFERROR(IF('Pré Implantação'!B4="CSC Service Desk",AVERAGE('Pré Implantação'!D4,'Pré Implantação'!L4,'Pré Implantação'!F4),AVERAGE('Pré Implantação'!F4)),"") | E4: =IFERROR(IF('Pré Implantação'!B4="CSC NOC",AVERAGE('Pré Implantação'!D4,'Pré Implantação'!L4,'Pré Implantação'!G4),AVERAGE('Pré Implantação'!G4)),"") -> 1 | F4: =IFERROR(IF('Pré Implantação'!B4="CSE Gravadores",AVERAGE('Pré Implantação'!D4,'Pré Implantação'!L4,'Pré Implantação'!I4),AVERAGE('Pré Implantação'!I4)),"") -> 1 | G4: =IFERROR(IF('Pré Implantação'!B4="CSC",AVERAGE('Pré Implantação'!D4,'Pré Implantação'!L4,'Pré Implantação'!J4),AVERAGE('Pré Implantação'!J4)),"") -> 0.9 | H4: =IFERROR(IF('Pré Implantação'!B4="Operações \ Negócio",AVERAGE('Pré Implantação'!D4,'Pré Implantação'!L4,'Pré Implantação'!K4),AVERAGE('Pré Implantação'!K4)),"") | I4: =IFERROR(IF('Pré Implantação'!B4="Projetos",AVERAGE('Pré Implantação'!D4,'Pré Implantação'!L4,'Pré Implantação'!M4),AVERAGE('Pré Implantação'!M4)),"") | J4: =IFERROR(IF('Pré Implantação'!B4="Engenharia",AVERAGE('Pré Implantação'!D4,'Pré Implantação'!L4,'Pré Implantação'!N4),AVERAGE('Pré Implantação'!N4)),"") -> 1 | K4: =IFERROR(IF('Pré Implantação'!B4="URA",AVERAGE('Pré Implantação'!D4,'Pré Implantação'!L4),""),"") | L4: =IFERROR(IF('Pré Implantação'!B4="CSE Microsoft",AVERAGE('Pré Implantação'!D4,'Pré Implantação'!L4),""),"") -> 0.95 | M4: =IFERROR(IF('Pré Implantação'!B4="CSE Telecom",AVERAGE('Pré Implantação'!D4,'Pré Implantação'!L4),""),"") | N4: =IFERROR(IF('Pré Implantação'!B4="Site Suporte de Campo",AVERAGE('Pré Implantação'!D4,'Pré Implantação'!L4),""),"") | O4: =IFERROR(IF('Pré Implantação'!B4="Infraestrutura",AVERAGE('Pré Implantação'!D4,'Pré Implantação'!L4),""),"")
A5: ='Pré Implantação'!A5 -> 12347 | B5: ='Pré Implantação'!C5 -> 42564.5 | C5: =IFERROR(IF('Pré Implantação'!B5="Produção TI",AVERAGE('Pré Implantação'!D5,'Pré Implantação'!L5,'Pré Implantação'!E5,'Pré Implantação'!H5),AVERAGE('Pré Implantação'!E5,'Pré Implantação'!H5)),"") -> 0.2 | D5: =IFERROR(IF('Pré Implantação'!B5="CSC Service Desk",AVERAGE('Pré Implantação'!D5,'Pré Implantação'!L5,'Pré Implantação'!F5),AVERAGE('Pré Implantação'!F5)),"") -> 0.96666667 | E5: =IFERROR(IF('Pré Implantação'!B5="CSC NOC",AVERAGE('Pré Implantação'!D5,'Pré Implantação'!L5,'Pré Implantação'!G5),AVERAGE('Pré Implantação'!G5)),"") -> 0 | F5: =IFERROR(IF('Pré Implantação'!B5="CSE Gravadores",AVERAGE('Pré Implantação'!D5,'Pré Implantação'!L5,'Pré Implantação'!I5),AVERAGE('Pré Implantação'!I5)),"") -> 0.2 | G5: =IFERROR(IF('Pré Implantação'!B5="CSC",AVERAGE('Pré Implantação'!D5,'Pré Implantação'!L5,'Pré Implantação'!J5),AVERAGE('Pré Implantação'!J5)),"") | H5: =IFERROR(IF('Pré Implantação'!B5="Operações \ Negócio",AVERAGE('Pré Implantação'!D5,'Pré Implantação'!L5,'Pré Implantação'!K5),AVERAGE('Pré Implantação'!K5)),"") | I5: =IFERROR(IF('Pré Implantação'!B5="Projetos",AVERAGE('Pré Implantação'!D5,'Pré Implantação'!L5,'Pré Implantação'!M5),AVERAGE('Pré Implantação'!M5)),"") | J5: =IFERROR(IF('Pré Implantação'!B5="Engenharia",AVERAGE('Pré Implantação'!D5,'Pré Implantação'!L5,'Pré Implantação'!N5),AVERAGE('Pré Implantação'!N5)),"") -> 0.5 | K5: =IFERROR(IF('Pré Implantação'!B5="URA",AVERAGE('Pré Implantação'!D5,'Pré Implantação'!L5),""),"") | L5: =IFERROR(IF('Pré Implantação'!B5="CSE Microsoft",AVERAGE('Pré Implantação'!D5,'Pré Implantação'!L5),""),"") | M5: =IFERROR(IF('Pré Implantação'!B5="CSE Telecom",AVERAGE('Pré Implantação'!D5,'Pré Implantação'!L5),""),"") | N5: =IFERROR(IF('Pré Implantação'!B5="Site Suporte de Campo",AVERAGE('Pré Implantação'!D5,'Pré Implantação'!L5),""),"") | O5: =IFERROR(IF('Pré Implantação'!B5="Infraestrutura",AVERAGE('Pré Implantação'!D5,'Pré Implantação'!L5),""),"")
A6: ='Pré Implantação'!A6 -> 12348 | B6: ='Pré Implantação'!C6 -> 42573.41 | C6: =IFERROR(IF('Pré Implantação'!B6="Produção TI",AVERAGE('Pré Implantação'!D6,'Pré Implantação'!L6,'Pré Implantação'!E6,'Pré Implantação'!H6),AVERAGE('Pré Implantação'!E6,'Pré Implantação'!H6)),"") | D6: =IFERROR(IF('Pré Implantação'!B6="CSC Service Desk",AVERAGE('Pré Implantação'!D6,'Pré Implantação'!L6,'Pré Implantação'!F6),AVERAGE('Pré Implantação'!F6)),"") -> 0.5 | E6: =IFERROR(IF('Pré Implantação'!B6="CSC NOC",AVERAGE('Pré Implantação'!D6,'Pré Implantação'!L6,'Pré Implantação'!G6),AVERAGE('Pré Implantação'!G6)),"") | F6: =IFERROR(IF('Pré Implantação'!B6="CSE Gravadores",AVERAGE('Pré Implantação'!D6,'Pré Implantação'!L6,'Pré Implantação'!I6),AVERAGE('Pré Implantação'!I6)),"") | G6: =IFERROR(IF('Pré Implantação'!B6="CSC",AVERAGE('Pré Implantação'!D6,'Pré Implantação'!L6,'Pré Implantação'!J6),AVERAGE('Pré Implantação'!J6)),"") | H6: =IFERROR(IF('Pré Implantação'!B6="Operações \ Negócio",AVERAGE('Pré Implantação'!D6,'Pré Implantação'!L6,'Pré Implantação'!K6),AVERAGE('Pré Implantação'!K6)),"") | I6: =IFERROR(IF('Pré Implantação'!B6="Projetos",AVERAGE('Pré Implantação'!D6,'Pré Implantação'!L6,'Pré Implantação'!M6),AVERAGE('Pré Implantação'!M6)),"") | J6: =IFERROR(IF('Pré Implantação'!B6="Engenharia",AVERAGE('Pré Implantação'!D6,'Pré Implantação'!L6,'Pré Implantação'!N6),AVERAGE('Pré Implantação'!N6)),"") | K6: =IFERROR(IF('Pré Implantação'!B6="URA",AVERAGE('Pré Implantação'!D6,'Pré Implantação'!L6),""),"") | L6: =IFERROR(IF('Pré Implantação'!B6="CSE Microsoft",AVERAGE('Pré Implantação'!D6,'Pré Implantação'!L6),""),"") | M6: =IFERROR(IF('Pré Implantação'!B6="CSE Telecom",AVERAGE('Pré Implantação'!D6,'Pré Implantação'!L6),""),"") -> 1 | N6: =IFERROR(IF('Pré Implantação'!B6="Site Suporte de Campo",AVERAGE('Pré Implantação'!D6,'Pré Implantação'!L6),""),"") | O6: =IFERROR(IF('Pré Implantação'!B6="Infraestrutura",AVERAGE('Pré Implantação'!D6,'Pré Implantação'!L6),""),"")
A7: ='Pré Implantação'!A7 -> 12349 | B7: ='Pré Implantação'!C7 -> 42561.083 | C7: =IFERROR(IF('Pré Implantação'!B7="Produção TI",AVERAGE('Pré Implantação'!D7,'Pré Implantação'!L7,'Pré Implantação'!E7,'Pré Implantação'!H7),AVERAGE('Pré Implantação'!E7,'Pré Implantação'!H7)),"") -> 1 | D7: =IFERROR(IF('Pré Implantação'!B7="CSC Service Desk",AVERAGE('Pré Implantação'!D7,'Pré Implantação'!L7,'Pré Implantação'!F7),AVERAGE('Pré Implantação'!F7)),"") -> 1 | E7: =IFERROR(IF('Pré Implantação'!B7="CSC NOC",AVERAGE('Pré Implantação'!D7,'Pré Implantação'!L7,'Pré Implantação'!G7),AVERAGE('Pré Implantação'!G7)),"") -> 0.8 | F7: =IFERROR(IF('Pré Implantação'!B7="CSE Gravadores",AVERAGE('Pré Implantação'!D7,'Pré Implantação'!L7,'Pré Implantação'!I7),AVERAGE('Pré Implantação'!I7)),"") -> 1 | G7: =IFERROR(IF('Pré Implantação'!B7="CSC",AVERAGE('Pré Implantação'!D7,'Pré Implantação'!L7,'Pré Implantação'!J7),AVERAGE('Pré Implantação'!J7)),"") -> 1 | H7: =IFERROR(IF('Pré Implantação'!B7="Operações \ Negócio",AVERAGE('Pré Implantação'!D7,'Pré Implantação'!L7,'Pré Implantação'!K7),AVERAGE('Pré Implantação'!K7)),"") -> 0.2 | I7: =IFERROR(IF('Pré Implantação'!B7="Projetos",AVERAGE('Pré Implantação'!D7,'Pré Implantação'!L7,'Pré Implantação'!M7),AVERAGE('Pré Implantação'!M7)),"") -> 1 | J7: =IFERROR(IF('Pré Implantação'!B7="Engenharia",AVERAGE('Pré Implantação'!D7,'Pré Implantação'!L7,'Pré Implantação'!N7),AVERAGE('Pré Implantação'!N7)),"") -> 0.6 | K7: =IFERROR(IF('Pré Implantação'!B7="URA",AVERAGE('Pré Implantação'!D7,'Pré Implantação'!L7),""),"") | L7: =IFERROR(IF('Pré Implantação'!B7="CSE Microsoft",AVERAGE('Pré Implantação'!D7,'Pré Implantação'!L7),""),"") | M7: =IFERROR(IF('Pré Implantação'!B7="CSE Telecom",AVERAGE('Pré Implantação'!D7,'Pré Implantação'!L7),""),"") | N7: =IFERROR(IF('Pré Implantação'!B7="Site Suporte de Campo",AVERAGE('Pré Implantação'!D7,'Pré Implantação'!L7),""),"") | O7: =IFERROR(IF('Pré Implantação'!B7="Infraestrutura",AVERAGE('Pré Implantação'!D7,'Pré Implantação'!L7),""),"") -> 1
A8: ='Pré Implantação'!A8 -> 12350 | B8: ='Pré Implantação'!C8 -> 42570.583 | C8: =IFERROR(IF('Pré Implantação'!B8="Produção TI",AVERAGE('Pré Implantação'!D8,'Pré Implantação'!L8,'Pré Implantação'!E8,'Pré Implantação'!H8),AVERAGE('Pré Implantação'!E8,'Pré Implantação'!H8)),"") -> 0.7 | D8: =IFERROR(IF('Pré Implantação'!B8="CSC Service Desk",AVERAGE('Pré Implantação'!D8,'Pré Implantação'!L8,'Pré Implantação'!F8),AVERAGE('Pré Implantação'!F8)),"") | E8: =IFERROR(IF('Pré Implantação'!B8="CSC NOC",AVERAGE('Pré Implantação'!D8,'Pré Implantação'!L8,'Pré Implantação'!G8),AVERAGE('Pré Implantação'!G8)),"") -> 0 | F8: =IFERROR(IF('Pré Implantação'!B8="CSE Gravadores",AVERAGE('Pré Implantação'!D8,'Pré Implantação'!L8,'Pré Implantação'!I8),AVERAGE('Pré Implantação'!I8)),"") | G8: =IFERROR(IF('Pré Implantação'!B8="CSC",AVERAGE('Pré Implantação'!D8,'Pré Implantação'!L8,'Pré Implantação'!J8),AVERAGE('Pré Implantação'!J8)),"") -> 0.9 | H8: =IFERROR(IF('Pré Implantação'!B8="Operações \ Negócio",AVERAGE('Pré Implantação'!D8,'Pré Implantação'!L8,'Pré Implantação'!K8),AVERAGE('Pré Implantação'!K8)),"") | I8: =IFERROR(IF('Pré Implantação'!B8="Projetos",AVERAGE('Pré Implantação'!D8,'Pré Implantação'!L8,'Pré Implantação'!M8),AVERAGE('Pré Implantação'!M8)),"") | J8: =IFERROR(IF('Pré Implantação'!B8="Engenharia",AVERAGE('Pré Implantação'!D8,'Pré Implantação'!L8,'Pré Implantação'!N8),AVERAGE('Pré Implantação'!N8)),"") | K8: =IFERROR(IF('Pré Implantação'!B8="URA",AVERAGE('Pré Implantação'!D8,'Pré Implantação'!L8),""),"") -> 1 | L8: =IFERROR(IF('Pré Implantação'!B8="CSE Microsoft",AVERAGE('Pré Implantação'!D8,'Pré Implantação'!L8),""),"") | M8: =IFERROR(IF('Pré Implantação'!B8="CSE Telecom",AVERAGE('Pré Implantação'!D8,'Pré Implantação'!L8),""),"") | N8: =IFERROR(IF('Pré Implantação'!B8="Site Suporte de Campo",AVERAGE('Pré Implantação'!D8,'Pré Implantação'!L8),""),"") | O8: =IFERROR(IF('Pré Implantação'!B8="Infraestrutura",AVERAGE('Pré Implantação'!D8,'Pré Implantação'!L8),""),"")
A9: ='Pré Implantação'!A9 -> 12351 | B9: ='Pré Implantação'!C9 -> 42562.229 | C9: =IFERROR(IF('Pré Implantação'!B9="Produção TI",AVERAGE('Pré Implantação'!D9,'Pré Implantação'!L9,'Pré Implantação'!E9,'Pré Implantação'!H9),AVERAGE('Pré Implantação'!E9,'Pré Implantação'!H9)),"") -> 0.8 | D9: =IFERROR(IF('Pré Implantação'!B9="CSC Service Desk",AVERAGE('Pré Implantação'!D9,'Pré Implantação'!L9,'Pré Implantação'!F9),AVERAGE('Pré Implantação'!F9)),"") | E9: =IFERROR(IF('Pré Implantação'!B9="CSC NOC",AVERAGE('Pré Implantação'!D9,'Pré Implantação'!L9,'Pré Implantação'!G9),AVERAGE('Pré Implantação'!G9)),"") -> 0.7 | F9: =IFERROR(IF('Pré Implantação'!B9="CSE Gravadores",AVERAGE('Pré Implantação'!D9,'Pré Implantação'!L9,'Pré Implantação'!I9),AVERAGE('Pré Implantação'!I9)),"") | G9: =IFERROR(IF('Pré Implantação'!B9="CSC",AVERAGE('Pré Implantação'!D9,'Pré Implantação'!L9,'Pré Implantação'!J9),AVERAGE('Pré Implantação'!J9)),"") | H9: =IFERROR(IF('Pré Implantação'!B9="Operações \ Negócio",AVERAGE('Pré Implantação'!D9,'Pré Implantação'!L9,'Pré Implantação'!K9),AVERAGE('Pré Implantação'!K9)),"") | I9: =IFERROR(IF('Pré Implantação'!B9="Projetos",AVERAGE('Pré Implantação'!D9,'Pré Implantação'!L9,'Pré Implantação'!M9),AVERAGE('Pré Implantação'!M9)),"") | J9: =IFERROR(IF('Pré Implantação'!B9="Engenharia",AVERAGE('Pré Implantação'!D9,'Pré Implantação'!L9,'Pré Implantação'!N9),AVERAGE('Pré Implantação'!N9)),"") -> 0.2 | K9: =IFERROR(IF('Pré Implantação'!B9="URA",AVERAGE('Pré Implantação'!D9,'Pré Implantação'!L9),""),"") | L9: =IFERROR(IF('Pré Implantação'!B9="CSE Microsoft",AVERAGE('Pré Implantação'!D9,'Pré Implantação'!L9),""),"") -> 0.7 | M9: =IFERROR(IF('Pré Implantação'!B9="CSE Telecom",AVERAGE('Pré Implantação'!D9,'Pré Implantação'!L9),""),"") | N9: =IFERROR(IF('Pré Implantação'!B9="Site Suporte de Campo",AVERAGE('Pré Implantação'!D9,'Pré Implantação'!L9),""),"") | O9: =IFERROR(IF('Pré Implantação'!B9="Infraestrutura",AVERAGE('Pré Implantação'!D9,'Pré Implantação'!L9),""),"")
A10: ='Pré Implantação'!A10 -> 12352 | B10: ='Pré Implantação'!C10 -> 42574.458 | C10: =IFERROR(IF('Pré Implantação'!B10="Produção TI",AVERAGE('Pré Implantação'!D10,'Pré Implantação'!L10,'Pré Implantação'!E10,'Pré Implantação'!H10),AVERAGE('Pré Implantação'!E10,'Pré Implantação'!H10)),"") -> 0.9 | D10: =IFERROR(IF('Pré Implantação'!B10="CSC Service Desk",AVERAGE('Pré Implantação'!D10,'Pré Implantação'!L10,'Pré Implantação'!F10),AVERAGE('Pré Implantação'!F10)),"") | E10: =IFERROR(IF('Pré Implantação'!B10="CSC NOC",AVERAGE('Pré Implantação'!D10,'Pré Implantação'!L10,'Pré Implantação'!G10),AVERAGE('Pré Implantação'!G10)),"") | F10: =IFERROR(IF('Pré Implantação'!B10="CSE Gravadores",AVERAGE('Pré Implantação'!D10,'Pré Implantação'!L10,'Pré Implantação'!I10),AVERAGE('Pré Implantação'!I10)),"") | G10: =IFERROR(IF('Pré Implantação'!B10="CSC",AVERAGE('Pré Implantação'!D10,'Pré Implantação'!L10,'Pré Implantação'!J10),AVERAGE('Pré Implantação'!J10)),"") | H10: =IFERROR(IF('Pré Implantação'!B10="Operações \ Negócio",AVERAGE('Pré Implantação'!D10,'Pré Implantação'!L10,'Pré Implantação'!K10),AVERAGE('Pré Implantação'!K10)),"") | I10: =IFERROR(IF('Pré Implantação'!B10="Projetos",AVERAGE('Pré Implantação'!D10,'Pré Implantação'!L10,'Pré Implantação'!M10),AVERAGE('Pré Implantação'!M10)),"") | J10: =IFERROR(IF('Pré Implantação'!B10="Engenharia",AVERAGE('Pré Implantação'!D10,'Pré Implantação'!L10,'Pré Implantação'!N10),AVERAGE('Pré Implantação'!N10)),"") | K10: =IFERROR(IF('Pré Implantação'!B10="URA",AVERAGE('Pré Implantação'!D10,'Pré Implantação'!L10),""),"") -> 0.75 | L10: =IFERROR(IF('Pré Implantação'!B10="CSE Microsoft",AVERAGE('Pré Implantação'!D10,'Pré Implantação'!L10),""),"") | M10: =IFERROR(IF('Pré Implantação'!B10="CSE Telecom",AVERAGE('Pré Implantação'!D10,'Pré Implantação'!L10),""),"") | N10: =IFERROR(IF('Pré Implantação'!B10="Site Suporte de Campo",AVERAGE('Pré Implantação'!D10,'Pré Implantação'!L10),""),"") | O10: =IFERROR(IF('Pré Implantação'!B10="Infraestrutura",AVERAGE('Pré Implantação'!D10,'Pré Implantação'!L10),""),"")
A11: ='Pré Implantação'!A11 -> 12353 | B11: ='Pré Implantação'!C11 -> 42568.021 | C11: =IFERROR(IF('Pré Implantação'!B11="Produção TI",AVERAGE('Pré Implantação'!D11,'Pré Implantação'!L11,'Pré Implantação'!E11,'Pré Implantação'!H11),AVERAGE('Pré Implantação'!E11,'Pré Implantação'!H11)),"") | D11: =IFERROR(IF('Pré Implantação'!B11="CSC Service Desk",AVERAGE('Pré Implantação'!D11,'Pré Implantação'!L11,'Pré Implantação'!F11),AVERAGE('Pré Implantação'!F11)),"") | E11: =IFERROR(IF('Pré Implantação'!B11="CSC NOC",AVERAGE('Pré Implantação'!D11,'Pré Implantação'!L11,'Pré Implantação'!G11),AVERAGE('Pré Implantação'!G11)),"") | F11: =IFERROR(IF('Pré Implantação'!B11="CSE Gravadores",AVERAGE('Pré Implantação'!D11,'Pré Implantação'!L11,'Pré Implantação'!I11),AVERAGE('Pré Implantação'!I11)),"") -> 0 | G11: =IFERROR(IF('Pré Implantação'!B11="CSC",AVERAGE('Pré Implantação'!D11,'Pré Implantação'!L11,'Pré Implantação'!J11),AVERAGE('Pré Implantação'!J11)),"") | H11: =IFERROR(IF('Pré Implantação'!B11="Operações \ Negócio",AVERAGE('Pré Implantação'!D11,'Pré Implantação'!L11,'Pré Implantação'!K11),AVERAGE('Pré Implantação'!K11)),"") | I11: =IFERROR(IF('Pré Implantação'!B11="Projetos",AVERAGE('Pré Implantação'!D11,'Pré Implantação'!L11,'Pré Implantação'!M11),AVERAGE('Pré Implantação'!M11)),"") | J11: =IFERROR(IF('Pré Implantação'!B11="Engenharia",AVERAGE('Pré Implantação'!D11,'Pré Implantação'!L11,'Pré Implantação'!N11),AVERAGE('Pré Implantação'!N11)),"") | K11: =IFERROR(IF('Pré Implantação'!B11="URA",AVERAGE('Pré Implantação'!D11,'Pré Implantação'!L11),""),"") | L11: =IFERROR(IF('Pré Implantação'!B11="CSE Microsoft",AVERAGE('Pré Implantação'!D11,'Pré Implantação'!L11),""),"") | M11: =IFERROR(IF('Pré Implantação'!B11="CSE Telecom",AVERAGE('Pré Implantação'!D11,'Pré Implantação'!L11),""),"") -> 1 | N11: =IFERROR(IF('Pré Implantação'!B11="Site Suporte de Campo",AVERAGE('Pré Implantação'!D11,'Pré Implantação'!L11),""),"") | O11: =IFERROR(IF('Pré Implantação'!B11="Infraestrutura",AVERAGE('Pré Implantação'!D11,'Pré Implantação'!L11),""),"")
A12: ='Pré Implantação'!A12 -> 12354 | B12: ='Pré Implantação'!C12 -> 42569.802 | C12: =IFERROR(IF('Pré Implantação'!B12="Produção TI",AVERAGE('Pré Implantação'!D12,'Pré Implantação'!L12,'Pré Implantação'!E12,'Pré Implantação'!H12),AVERAGE('Pré Implantação'!E12,'Pré Implantação'!H12)),"") -> 0.75 | D12: =IFERROR(IF('Pré Implantação'!B12="CSC Service Desk",AVERAGE('Pré Implantação'!D12,'Pré Implantação'!L12,'Pré Implantação'!F12),AVERAGE('Pré Implantação'!F12)),"") -> 1 | E12: =IFERROR(IF('Pré Implantação'!B12="CSC NOC",AVERAGE('Pré Implantação'!D12,'Pré Implantação'!L12,'Pré Implantação'!G12),AVERAGE('Pré Implantação'!G12)),"") -> 0.8 | F12: =IFERROR(IF('Pré Implantação'!B12="CSE Gravadores",AVERAGE('Pré Implantação'!D12,'Pré Implantação'!L12,'Pré Implantação'!I12),AVERAGE('Pré Implantação'!I12)),"") -> 0.7 | G12: =IFERROR(IF('Pré Implantação'!B12="CSC",AVERAGE('Pré Implantação'!D12,'Pré Implantação'!L12,'Pré Implantação'!J12),AVERAGE('Pré Implantação'!J12)),"") -> 1 | H12: =IFERROR(IF('Pré Implantação'!B12="Operações \ Negócio",AVERAGE('Pré Implantação'!D12,'Pré Implantação'!L12,'Pré Implantação'!K12),AVERAGE('Pré Implantação'!K12)),"") -> 1 | I12: =IFERROR(IF('Pré Implantação'!B12="Projetos",AVERAGE('Pré Implantação'!D12,'Pré Implantação'!L12,'Pré Implantação'!M12),AVERAGE('Pré Implantação'!M12)),"") -> 1 | J12: =IFERROR(IF('Pré Implantação'!B12="Engenharia",AVERAGE('Pré Implantação'!D12,'Pré Implantação'!L12,'Pré Implantação'!N12),AVERAGE('Pré Implantação'!N12)),"") -> 1 | K12: =IFERROR(IF('Pré Implantação'!B12="URA",AVERAGE('Pré Implantação'!D12,'Pré Implantação'!L12),""),"") | L12: =IFERROR(IF('Pré Implantação'!B12="CSE Microsoft",AVERAGE('Pré Implantação'!D12,'Pré Implantação'!L12),""),"") -> 1 | M12: =IFERROR(IF('Pré Implantação'!B12="CSE Telecom",AVERAGE('Pré Implantação'!D12,'Pré Implantação'!L12),""),"") | N12: =IFERROR(IF('Pré Implantação'!B12="Site Suporte de Campo",AVERAGE('Pré Implantação'!D12,'Pré Implantação'!L12),""),"") | O12: =IFERROR(IF('Pré Implantação'!B12="Infraestrutura",AVERAGE('Pré Implantação'!D12,'Pré Implantação'!L12),""),"")
A13: ='Pré Implantação'!A13 -> 12355 | B13: ='Pré Implantação'!C13 -> 42569.667 | C13: =IFERROR(IF('Pré Implantação'!B13="Produção TI",AVERAGE('Pré Implantação'!D13,'Pré Implantação'!L13,'Pré Implantação'!E13,'Pré Implantação'!H13),AVERAGE('Pré Implantação'!E13,'Pré Implantação'!H13)),"") -> 0.5 | D13: =IFERROR(IF('Pré Implantação'!B13="CSC Service Desk",AVERAGE('Pré Implantação'!D13,'Pré Implantação'!L13,'Pré Implantação'!F13),AVERAGE('Pré Implantação'!F13)),"") -> 0.2 | E13: =IFERROR(IF('Pré Implantação'!B13="CSC NOC",AVERAGE('Pré Implantação'!D13,'Pré Implantação'!L13,'Pré Implantação'!G13),AVERAGE('Pré Implantação'!G13)),"") | F13: =IFERROR(IF('Pré Implantação'!B13="CSE Gravadores",AVERAGE('Pré Implantação'!D13,'Pré Implantação'!L13,'Pré Implantação'!I13),AVERAGE('Pré Implantação'!I13)),"") | G13: =IFERROR(IF('Pré Implantação'!B13="CSC",AVERAGE('Pré Implantação'!D13,'Pré Implantação'!L13,'Pré Implantação'!J13),AVERAGE('Pré Implantação'!J13)),"") -> 0.8 | H13: =IFERROR(IF('Pré Implantação'!B13="Operações \ Negócio",AVERAGE('Pré Implantação'!D13,'Pré Implantação'!L13,'Pré Implantação'!K13),AVERAGE('Pré Implantação'!K13)),"") -> 0 | I13: =IFERROR(IF('Pré Implantação'!B13="Projetos",AVERAGE('Pré Implantação'!D13,'Pré Implantação'!L13,'Pré Implantação'!M13),AVERAGE('Pré Implantação'!M13)),"") | J13: =IFERROR(IF('Pré Implantação'!B13="Engenharia",AVERAGE('Pré Implantação'!D13,'Pré Implantação'!L13,'Pré Implantação'!N13),AVERAGE('Pré Implantação'!N13)),"") -> 0.1 | K13: =IFERROR(IF('Pré Implantação'!B13="URA",AVERAGE('Pré Implantação'!D13,'Pré Implantação'!L13),""),"") | L13: =IFERROR(IF('Pré Implantação'!B13="CSE Microsoft",AVERAGE('Pré Implantação'!D13,'Pré Implantação'!L13),""),"") | M13: =IFERROR(IF('Pré Implantação'!B13="CSE Telecom",AVERAGE('Pré Implantação'!D13,'Pré Implantação'!L13),""),"") | N13: =IFERROR(IF('Pré Implantação'!B13="Site Suporte de Campo",AVERAGE('Pré Implantação'!D13,'Pré Implantação'!L13),""),"") | O13: =IFERROR(IF('Pré Implantação'!B13="Infraestrutura",AVERAGE('Pré Implantação'!D13,'Pré Implantação'!L13),""),"")
A14: ='Pré Implantação'!A14 -> 0 | B14: ='Pré Implantação'!C14 -> 0 | C14: =IFERROR(IF('Pré Implantação'!B14="Produção TI",AVERAGE('Pré Implantação'!D14,'Pré Implantação'!L14,'Pré Implantação'!E14,'Pré Implantação'!H14),AVERAGE('Pré Implantação'!E14,'Pré Implantação'!H14)),"") | D14: =IFERROR(IF('Pré Implantação'!B14="CSC Service Desk",AVERAGE('Pré Implantação'!D14,'Pré Implantação'!L14,'Pré Implantação'!F14),AVERAGE('Pré Implantação'!F14)),"") | E14: =IFERROR(IF('Pré Implantação'!B14="CSC NOC",AVERAGE('Pré Implantação'!D14,'Pré Implantação'!L14,'Pré Implantação'!G14),AVERAGE('Pré Implantação'!G14)),"") | F14: =IFERROR(IF('Pré Implantação'!B14="CSE Gravadores",AVERAGE('Pré Implantação'!D14,'Pré Implantação'!L14,'Pré Implantação'!I14),AVERAGE('Pré Implantação'!I14)),"") | G14: =IFERROR(IF('Pré Implantação'!B14="CSC",AVERAGE('Pré Implantação'!D14,'Pré Implantação'!L14,'Pré Implantação'!J14),AVERAGE('Pré Implantação'!J14)),"") | H14: =IFERROR(IF('Pré Implantação'!B14="Operações \ Negócio",AVERAGE('Pré Implantação'!D14,'Pré Implantação'!L14,'Pré Implantação'!K14),AVERAGE('Pré Implantação'!K14)),"") | I14: =IFERROR(IF('Pré Implantação'!B14="Projetos",AVERAGE('Pré Implantação'!D14,'Pré Implantação'!L14,'Pré Implantação'!M14),AVERAGE('Pré Implantação'!M14)),"") | J14: =IFERROR(IF('Pré Implantação'!B14="Engenharia",AVERAGE('Pré Implantação'!D14,'Pré Implantação'!L14,'Pré Implantação'!N14),AVERAGE('Pré Implantação'!N14)),"") | K14: =IFERROR(IF('Pré Implantação'!B14="URA",AVERAGE('Pré Implantação'!D14,'Pré Implantação'!L14),""),"") | L14: =IFERROR(IF('Pré Implantação'!B14="CSE Microsoft",AVERAGE('Pré Implantação'!D14,'Pré Implantação'!L14),""),"") | M14: =IFERROR(IF('Pré Implantação'!B14="CSE Telecom",AVERAGE('Pré Implantação'!D14,'Pré Implantação'!L14),""),"") | N14: =IFERROR(IF('Pré Implantação'!B14="Site Suporte de Campo",AVERAGE('Pré Implantação'!D14,'Pré Implantação'!L14),""),"") | O14: =IFERROR(IF('Pré Implantação'!B14="Infraestrutura",AVERAGE('Pré Implantação'!D14,'Pré Implantação'!L14),""),"")
... A421: ='Pré Implantação'!A421 -> 0 | B421: ='Pré Implantação'!C421 -> 0 | C421: =IFERROR(IF('Pré Implantação'!B421="Produção TI",AVERAGE('Pré Implantação'!D421,'Pré Implantação'!L421,'Pré Implantação'!E421,'Pré Implantação'!H421),AVERAGE('Pré Implantação'!E421,'Pré Implantação'!H421)),"") | D421: =IFERROR(IF('Pré Implantação'!B421="CSC Service Desk",AVERAGE('Pré Implantação'!D421,'Pré Implantação'!L421,'Pré Implantação'!F421),AVERAGE('Pré Implantação'!F421)),"") | E421: =IFERROR(IF('Pré Implantação'!B421="CSC NOC",AVERAGE('Pré Implantação'!D421,'Pré Implantação'!L421,'Pré Implantação'!G421),AVERAGE('Pré Implantação'!G421)),"") | F421: =IFERROR(IF('Pré Implantação'!B421="CSE Gravadores",AVERAGE('Pré Implantação'!D421,'Pré Implantação'!L421,'Pré Implantação'!I421),AVERAGE('Pré Implantação'!I421)),"") | G421: =IFERROR(IF('Pré Implantação'!B421="CSC",AVERAGE('Pré Implantação'!D421,'Pré Implantação'!L421,'Pré Implantação'!J421),AVERAGE('Pré Implantação'!J421)),"") | H421: =IFERROR(IF('Pré Implantação'!B421="Operações \ Negócio",AVERAGE('Pré Implantação'!D421,'Pré Implantação'!L421,'Pré Implantação'!K421),AVERAGE('Pré Implantação'!K421)),"") | I421: =IFERROR(IF('Pré Implantação'!B421="Projetos",AVERAGE('Pré Implantação'!D421,'Pré Implantação'!L421,'Pré Implantação'!M421),AVERAGE('Pré Implantação'!M421)),"") | J421: =IFERROR(IF('Pré Implantação'!B421="Engenharia",AVERAGE('Pré Implantação'!D421,'Pré Implantação'!L421,'Pré Implantação'!N421),AVERAGE('Pré Implantação'!N421)),"") | K421: =IFERROR(IF('Pré Implantação'!B421="URA",AVERAGE('Pré Implantação'!D421,'Pré Implantação'!L421),""),"") | L421: =IFERROR(IF('Pré Implantação'!B421="CSE Microsoft",AVERAGE('Pré Implantação'!D421,'Pré Implantação'!L421),""),"") | M421: =IFERROR(IF('Pré Implantação'!B421="CSE Telecom",AVERAGE('Pré Implantação'!D421,'Pré Implantação'!L421),""),"") | N421: =IFERROR(IF('Pré Implantação'!B421="Site Suporte de Campo",AVERAGE('Pré Implantação'!D421,'Pré Implantação'!L421),""),"") | O421: =IFERROR(IF('Pré Implantação'!B421="Infraestrutura",AVERAGE('Pré Implantação'!D421,'Pré Implantação'!L421),""),"")

Sheet Entrega Pós Implantação
A1: ID | B1: Final do Planejamento | C1: Produção TI | D1: CSC Service Desk | E1: CSC NOC | F1: CSE Gravadores | G1: CSC | H1: Operações \ Negócio | I1: Projetos | J1: Engenharia | K1: URA | L1: CSE Microsoft | M1: CSE Telecom | N1: Site Suporte de Campo | O1: Infraestrutura
A2: Média de Entrega | C2: =IFERROR(AVERAGE(C3:C421),"") -> 0.7 | D2: =IFERROR(AVERAGE(D3:D421),"") -> 1 | E2: =IFERROR(AVERAGE(E3:E421),"") -> 1 | F2: =IFERROR(AVERAGE(F3:F421),"") -> 0.85 | G2: =IFERROR(AVERAGE(G3:G421),"") -> 0.94 | H2: =IFERROR(AVERAGE(H3:H421),"") -> 0.65 | I2: =IFERROR(AVERAGE(I3:I421),"") -> 0.9 | J2: =IFERROR(AVERAGE(J3:J421),"") -> 0.76666667 | ... O2: =IFERROR(AVERAGE(O3:O421),"") -> 1
A3: ='Pré Implantação'!A3 -> 12345 | B3: ='Pós Implantação'!C3 -> 42579.658 | C3: =IFERROR(IF('Pré Implantação'!B3="Produção TI",AVERAGE('Pós Implantação'!D3,'Pós Implantação'!E3,'Pós Implantação'!L3,'Pós Implantação'!H3),AVERAGE('Pré Implantação'!E3,'Pré Implantação'!H3)),"") -> 0.95 | D3: =IFERROR(IF('Pós Implantação'!B3="CSC Service Desk",AVERAGE('Pós Implantação'!D3,'Pós Implantação'!L3,'Pós Implantação'!F3),AVERAGE('Pós Implantação'!F3)),"") -> 1 | E3: =IFERROR(IF('Pós Implantação'!B3="CSC NOC",AVERAGE('Pós Implantação'!D3,'Pós Implantação'!L3,'Pós Implantação'!G3),AVERAGE('Pós Implantação'!G3)),"") -> 1 | F3: =IFERROR(IF('Pós Implantação'!B3="CSE Gravadores",AVERAGE('Pós Implantação'!D3,'Pós Implantação'!L3,'Pós Implantação'!I3),AVERAGE('Pós Implantação'!I3)),"") -> 1 | G3: =IFERROR(IF('Pós Implantação'!B3="CSC",AVERAGE('Pós Implantação'!D3,'Pós Implantação'!L3,'Pós Implantação'!J3),AVERAGE('Pós Implantação'!J3)),"") | H3: =IFERROR(IF('Pós Implantação'!B3="Operações \ Negócio",AVERAGE('Pós Implantação'!D3,'Pós Implantação'!L3,'Pós Implantação'!K3),AVERAGE('Pós Implantação'!K3)),"") | I3: =IFERROR(IF('Pós Implantação'!B3="Projetos",AVERAGE('Pós Implantação'!D3,'Pós Implantação'!L3,'Pós Implantação'!M3),AVERAGE('Pós Implantação'!M3)),"") -> 0.7 | J3: =IFERROR(IF('Pós Implantação'!B3="Engenharia",AVERAGE('Pós Implantação'!D3,'Pós Implantação'!L3,'Pós Implantação'!N3),AVERAGE('Pós Implantação'!N3)),"") | K3: =IFERROR(IF('Pós Implantação'!B3="URA",AVERAGE('Pós Implantação'!D3,'Pós Implantação'!L3),""),"") | L3: =IFERROR(IF('Pós Implantação'!B3="CSE Microsoft",AVERAGE('Pós Implantação'!D3,'Pós Implantação'!L3),""),"") | M3: =IFERROR(IF('Pós Implantação'!B3="CSE Telecom",AVERAGE('Pós Implantação'!D3,'Pós Implantação'!L3),""),"") | N3: =IFERROR(IF('Pós Implantação'!B3="Site Suporte de Campo",AVERAGE('Pós Implantação'!D3,'Pós Implantação'!L3),""),"") | O3: =IFERROR(IF('Pós Implantação'!B3="Infraestrutura",AVERAGE('Pós Implantação'!D3,'Pós Implantação'!L3),""),"")
A4: ='Pré Implantação'!A4 -> 12346 | B4: ='Pós Implantação'!C4 -> 42578.792 | C4: =IFERROR(IF('Pré Implantação'!B4="Produção TI",AVERAGE('Pós Implantação'!D4,'Pós Implantação'!E4,'Pós Implantação'!L4,'Pós Implantação'!H4),AVERAGE('Pré Implantação'!E4,'Pré Implantação'!H4)),"") -> 0.5 | D4: =IFERROR(IF('Pós Implantação'!B4="CSC Service Desk",AVERAGE('Pós Implantação'!D4,'Pós Implantação'!L4,'Pós Implantação'!F4),AVERAGE('Pós Implantação'!F4)),"") | E4: =IFERROR(IF('Pós Implantação'!B4="CSC NOC",AVERAGE('Pós Implantação'!D4,'Pós Implantação'!L4,'Pós Implantação'!G4),AVERAGE('Pós Implantação'!G4)),"") -> 1 | F4: =IFERROR(IF('Pós Implantação'!B4="CSE Gravadores",AVERAGE('Pós Implantação'!D4,'Pós Implantação'!L4,'Pós Implantação'!I4),AVERAGE('Pós Implantação'!I4)),"") -> 1 | G4: =IFERROR(IF('Pós Implantação'!B4="CSC",AVERAGE('Pós Implantação'!D4,'Pós Implantação'!L4,'Pós Implantação'!J4),AVERAGE('Pós Implantação'!J4)),"") -> 0.9 | H4: =IFERROR(IF('Pós Implantação'!B4="Operações \ Negócio",AVERAGE('Pós Implantação'!D4,'Pós Implantação'!L4,'Pós Implantação'!K4),AVERAGE('Pós Implantação'!K4)),"") | I4: =IFERROR(IF('Pós Implantação'!B4="Projetos",AVERAGE('Pós Implantação'!D4,'Pós Implantação'!L4,'Pós Implantação'!M4),AVERAGE('Pós Implantação'!M4)),"") | J4: =IFERROR(IF('Pós Implantação'!B4="Engenharia",AVERAGE('Pós Implantação'!D4,'Pós Implantação'!L4,'Pós Implantação'!N4),AVERAGE('Pós Implantação'!N4)),"") -> 1 | K4: =IFERROR(IF('Pós Implantação'!B4="URA",AVERAGE('Pós Implantação'!D4,'Pós Implantação'!L4),""),"") | L4: =IFERROR(IF('Pós Implantação'!B4="CSE Microsoft",AVERAGE('Pós Implantação'!D4,'Pós Implantação'!L4),""),"") -> 1 | M4: =IFERROR(IF('Pós Implantação'!B4="CSE Telecom",AVERAGE('Pós Implantação'!D4,'Pós Implantação'!L4),""),"") | N4: =IFERROR(IF('Pós Implantação'!B4="Site Suporte de Campo",AVERAGE('Pós Implantação'!D4,'Pós Implantação'!L4),""),"") | O4: =IFERROR(IF('Pós Implantação'!B4="Infraestrutura",AVERAGE('Pós Implantação'!D4,'Pós Implantação'!L4),""),"")
A5: ='Pré Implantação'!A5 -> 12347 | B5: ='Pós Implantação'!C5 -> 42574.5 | C5: =IFERROR(IF('Pré Implantação'!B5="Produção TI",AVERAGE('Pós Implantação'!D5,'Pós Implantação'!E5,'Pós Implantação'!L5,'Pós Implantação'!H5),AVERAGE('Pré Implantação'!E5,'Pré Implantação'!H5)),"") -> 0.2 | D5: =IFERROR(IF('Pós Implantação'!B5="CSC Service Desk",AVERAGE('Pós Implantação'!D5,'Pós Implantação'!L5,'Pós Implantação'!F5),AVERAGE('Pós Implantação'!F5)),"") -> 1 | E5: =IFERROR(IF('Pós Implantação'!B5="CSC NOC",AVERAGE('Pós Implantação'!D5,'Pós Implantação'!L5,'Pós Implantação'!G5),AVERAGE('Pós Implantação'!G5)),"") -> 1 | F5: =IFERROR(IF('Pós Implantação'!B5="CSE Gravadores",AVERAGE('Pós Implantação'!D5,'Pós Implantação'!L5,'Pós Implantação'!I5),AVERAGE('Pós Implantação'!I5)),"") -> 0.8 | G5: =IFERROR(IF('Pós Implantação'!B5="CSC",AVERAGE('Pós Implantação'!D5,'Pós Implantação'!L5,'Pós Implantação'!J5),AVERAGE('Pós Implantação'!J5)),"") | H5: =IFERROR(IF('Pós Implantação'!B5="Operações \ Negócio",AVERAGE('Pós Implantação'!D5,'Pós Implantação'!L5,'Pós Implantação'!K5),AVERAGE('Pós Implantação'!K5)),"") | I5: =IFERROR(IF('Pós Implantação'!B5="Projetos",AVERAGE('Pós Implantação'!D5,'Pós Implantação'!L5,'Pós Implantação'!M5),AVERAGE('Pós Implantação'!M5)),"") | J5: =IFERROR(IF('Pós Implantação'!B5="Engenharia",AVERAGE('Pós Implantação'!D5,'Pós Implantação'!L5,'Pós Implantação'!N5),AVERAGE('Pós Implantação'!N5)),"") -> 0.6 | K5: =IFERROR(IF('Pós Implantação'!B5="URA",AVERAGE('Pós Implantação'!D5,'Pós Implantação'!L5),""),"") | L5: =IFERROR(IF('Pós Implantação'!B5="CSE Microsoft",AVERAGE('Pós Implantação'!D5,'Pós Implantação'!L5),""),"") | M5: =IFERROR(IF('Pós Implantação'!B5="CSE Telecom",AVERAGE('Pós Implantação'!D5,'Pós Implantação'!L5),""),"") | N5: =IFERROR(IF('Pós Implantação'!B5="Site Suporte de Campo",AVERAGE('Pós Implantação'!D5,'Pós Implantação'!L5),""),"") | O5: =IFERROR(IF('Pós Implantação'!B5="Infraestrutura",AVERAGE('Pós Implantação'!D5,'Pós Implantação'!L5),""),"")
A6: ='Pré Implantação'!A6 -> 12348 | B6: ='Pós Implantação'!C6 -> 42583.41 | C6: =IFERROR(IF('Pré Implantação'!B6="Produção TI",AVERAGE('Pós Implantação'!D6,'Pós Implantação'!E6,'Pós Implantação'!L6,'Pós Implantação'!H6),AVERAGE('Pré Implantação'!E6,'Pré Implantação'!H6)),"") | D6: =IFERROR(IF('Pós Implantação'!B6="CSC Service Desk",AVERAGE('Pós Implantação'!D6,'Pós Implantação'!L6,'Pós Implantação'!F6),AVERAGE('Pós Implantação'!F6)),"") -> 1 | E6: =IFERROR(IF('Pós Implantação'!B6="CSC NOC",AVERAGE('Pós Implantação'!D6,'Pós Implantação'!L6,'Pós Implantação'!G6),AVERAGE('Pós Implantação'!G6)),"") | F6: =IFERROR(IF('Pós Implantação'!B6="CSE Gravadores",AVERAGE('Pós Implantação'!D6,'Pós Implantação'!L6,'Pós Implantação'!I6),AVERAGE('Pós Implantação'!I6)),"") | G6: =IFERROR(IF('Pós Implantação'!B6="CSC",AVERAGE('Pós Implantação'!D6,'Pós Implantação'!L6,'Pós Implantação'!J6),AVERAGE('Pós Implantação'!J6)),"") | H6: =IFERROR(IF('Pós Implantação'!B6="Operações \ Negócio",AVERAGE('Pós Implantação'!D6,'Pós Implantação'!L6,'Pós Implantação'!K6),AVERAGE('Pós Implantação'!K6)),"") | I6: =IFERROR(IF('Pós Implantação'!B6="Projetos",AVERAGE('Pós Implantação'!D6,'Pós Implantação'!L6,'Pós Implantação'!M6),AVERAGE('Pós Implantação'!M6)),"") | J6: =IFERROR(IF('Pós Implantação'!B6="Engenharia",AVERAGE('Pós Implantação'!D6,'Pós Implantação'!L6,'Pós Implantação'!N6),AVERAGE('Pós Implantação'!N6)),"") | K6: =IFERROR(IF('Pós Implantação'!B6="URA",AVERAGE('Pós Implantação'!D6,'Pós Implantação'!L6),""),"") | L6: =IFERROR(IF('Pós Implantação'!B6="CSE Microsoft",AVERAGE('Pós Implantação'!D6,'Pós Implantação'!L6),""),"") | M6: =IFERROR(IF('Pós Implantação'!B6="CSE Telecom",AVERAGE('Pós Implantação'!D6,'Pós Implantação'!L6),""),"") -> 1 | N6: =IFERROR(IF('Pós Implantação'!B6="Site Suporte de Campo",AVERAGE('Pós Implantação'!D6,'Pós Implantação'!L6),""),"") | O6: =IFERROR(IF('Pós Implantação'!B6="Infraestrutura",AVERAGE('Pós Implantação'!D6,'Pós Implantação'!L6),""),"")
A7: ='Pré Implantação'!A7 -> 12349 | B7: ='Pós Implantação'!C7 -> 42571.083 | C7: =IFERROR(IF('Pré Implantação'!B7="Produção TI",AVERAGE('Pós Implantação'!D7,'Pós Implantação'!E7,'Pós Implantação'!L7,'Pós Implantação'!H7),AVERAGE('Pré Implantação'!E7,'Pré Implantação'!H7)),"") -> 1 | D7: =IFERROR(IF('Pós Implantação'!B7="CSC Service Desk",AVERAGE('Pós Implantação'!D7,'Pós Implantação'!L7,'Pós Implantação'!F7),AVERAGE('Pós Implantação'!F7)),"") -> 1 | E7: =IFERROR(IF('Pós Implantação'!B7="CSC NOC",AVERAGE('Pós Implantação'!D7,'Pós Implantação'!L7,'Pós Implantação'!G7),AVERAGE('Pós Implantação'!G7)),"") -> 1 | F7: =IFERROR(IF('Pós Implantação'!B7="CSE Gravadores",AVERAGE('Pós Implantação'!D7,'Pós Implantação'!L7,'Pós Implantação'!I7),AVERAGE('Pós Implantação'!I7)),"") -> 1 | G7: =IFERROR(IF('Pós Implantação'!B7="CSC",AVERAGE('Pós Implantação'!D7,'Pós Implantação'!L7,'Pós Implantação'!J7),AVERAGE('Pós Implantação'!J7)),"") -> 1 | H7: =IFERROR(IF('Pós Implantação'!B7="Operações \ Negócio",AVERAGE('Pós Implantação'!D7,'Pós Implantação'!L7,'Pós Implantação'!K7),AVERAGE('Pós Implantação'!K7)),"") -> 0.2 | I7: =IFERROR(IF('Pós Implantação'!B7="Projetos",AVERAGE('Pós Implantação'!D7,'Pós Implantação'!L7,'Pós Implantação'!M7),AVERAGE('Pós Implantação'!M7)),"") -> 1 | J7: =IFERROR(IF('Pós Implantação'!B7="Engenharia",AVERAGE('Pós Implantação'!D7,'Pós Implantação'!L7,'Pós Implantação'!N7),AVERAGE('Pós Implantação'!N7)),"") -> 0.6 | K7: =IFERROR(IF('Pós Implantação'!B7="URA",AVERAGE('Pós Implantação'!D7,'Pós Implantação'!L7),""),"") | L7: =IFERROR(IF('Pós Implantação'!B7="CSE Microsoft",AVERAGE('Pós Implantação'!D7,'Pós Implantação'!L7),""),"") | M7: =IFERROR(IF('Pós Implantação'!B7="CSE Telecom",AVERAGE('Pós Implantação'!D7,'Pós Implantação'!L7),""),"") | N7: =IFERROR(IF('Pós Implantação'!B7="Site Suporte de Campo",AVERAGE('Pós Implantação'!D7,'Pós Implantação'!L7),""),"") | O7: =IFERROR(IF('Pós Implantação'!B7="Infraestrutura",AVERAGE('Pós Implantação'!D7,'Pós Implantação'!L7),""),"") -> 1
A8: ='Pré Implantação'!A8 -> 12350 | B8: ='Pós Implantação'!C8 -> 42580.583 | C8: =IFERROR(IF('Pré Implantação'!B8="Produção TI",AVERAGE('Pós Implantação'!D8,'Pós Implantação'!E8,'Pós Implantação'!L8,'Pós Implantação'!H8),AVERAGE('Pré Implantação'!E8,'Pré Implantação'!H8)),"") -> 0.7 | D8: =IFERROR(IF('Pós Implantação'!B8="CSC Service Desk",AVERAGE('Pós Implantação'!D8,'Pós Implantação'!L8,'Pós Implantação'!F8),AVERAGE('Pós Implantação'!F8)),"") | E8: =IFERROR(IF('Pós Implantação'!B8="CSC NOC",AVERAGE('Pós Implantação'!D8,'Pós Implantação'!L8,'Pós Implantação'!G8),AVERAGE('Pós Implantação'!G8)),"") -> 1 | F8: =IFERROR(IF('Pós Implantação'!B8="CSE Gravadores",AVERAGE('Pós Implantação'!D8,'Pós Implantação'!L8,'Pós Implantação'!I8),AVERAGE('Pós Implantação'!I8)),"") | G8: =IFERROR(IF('Pós Implantação'!B8="CSC",AVERAGE('Pós Implantação'!D8,'Pós Implantação'!L8,'Pós Implantação'!J8),AVERAGE('Pós Implantação'!J8)),"") -> 1 | H8: =IFERROR(IF('Pós Implantação'!B8="Operações \ Negócio",AVERAGE('Pós Implantação'!D8,'Pós Implantação'!L8,'Pós Implantação'!K8),AVERAGE('Pós Implantação'!K8)),"") | I8: =IFERROR(IF('Pós Implantação'!B8="Projetos",AVERAGE('Pós Implantação'!D8,'Pós Implantação'!L8,'Pós Implantação'!M8),AVERAGE('Pós Implantação'!M8)),"") | J8: =IFERROR(IF('Pós Implantação'!B8="Engenharia",AVERAGE('Pós Implantação'!D8,'Pós Implantação'!L8,'Pós Implantação'!N8),AVERAGE('Pós Implantação'!N8)),"") | K8: =IFERROR(IF('Pós Implantação'!B8="URA",AVERAGE('Pós Implantação'!D8,'Pós Implantação'!L8),""),"") -> 1 | L8: =IFERROR(IF('Pós Implantação'!B8="CSE Microsoft",AVERAGE('Pós Implantação'!D8,'Pós Implantação'!L8),""),"") | M8: =IFERROR(IF('Pós Implantação'!B8="CSE Telecom",AVERAGE('Pós Implantação'!D8,'Pós Implantação'!L8),""),"") | N8: =IFERROR(IF('Pós Implantação'!B8="Site Suporte de Campo",AVERAGE('Pós Implantação'!D8,'Pós Implantação'!L8),""),"") | O8: =IFERROR(IF('Pós Implantação'!B8="Infraestrutura",AVERAGE('Pós Implantação'!D8,'Pós Implantação'!L8),""),"")
A9: ='Pré Implantação'!A9 -> 12351 | B9: ='Pós Implantação'!C9 -> 42572.229 | C9: =IFERROR(IF('Pré Implantação'!B9="Produção TI",AVERAGE('Pós Implantação'!D9,'Pós Implantação'!E9,'Pós Implantação'!L9,'Pós Implantação'!H9),AVERAGE('Pré Implantação'!E9,'Pré Implantação'!H9)),"") -> 0.8 | D9: =IFERROR(IF('Pós Implantação'!B9="CSC Service Desk",AVERAGE('Pós Implantação'!D9,'Pós Implantação'!L9,'Pós Implantação'!F9),AVERAGE('Pós Implantação'!F9)),"") | E9: =IFERROR(IF('Pós Implantação'!B9="CSC NOC",AVERAGE('Pós Implantação'!D9,'Pós Implantação'!L9,'Pós Implantação'!G9),AVERAGE('Pós Implantação'!G9)),"") -> 1 | F9: =IFERROR(IF('Pós Implantação'!B9="CSE Gravadores",AVERAGE('Pós Implantação'!D9,'Pós Implantação'!L9,'Pós Implantação'!I9),AVERAGE('Pós Implantação'!I9)),"") | G9: =IFERROR(IF('Pós Implantação'!B9="CSC",AVERAGE('Pós Implantação'!D9,'Pós Implantação'!L9,'Pós Implantação'!J9),AVERAGE('Pós Implantação'!J9)),"") | H9: =IFERROR(IF('Pós Implantação'!B9="Operações \ Negócio",AVERAGE('Pós Implantação'!D9,'Pós Implantação'!L9,'Pós Implantação'!K9),AVERAGE('Pós Implantação'!K9)),"") | I9: =IFERROR(IF('Pós Implantação'!B9="Projetos",AVERAGE('Pós Implantação'!D9,'Pós Implantação'!L9,'Pós Implantação'!M9),AVERAGE('Pós Implantação'!M9)),"") | J9: =IFERROR(IF('Pós Implantação'!B9="Engenharia",AVERAGE('Pós Implantação'!D9,'Pós Implantação'!L9,'Pós Implantação'!N9),AVERAGE('Pós Implantação'!N9)),"") -> 1 | K9: =IFERROR(IF('Pós Implantação'!B9="URA",AVERAGE('Pós Implantação'!D9,'Pós Implantação'!L9),""),"") | L9: =IFERROR(IF('Pós Implantação'!B9="CSE Microsoft",AVERAGE('Pós Implantação'!D9,'Pós Implantação'!L9),""),"") -> 0.7 | M9: =IFERROR(IF('Pós Implantação'!B9="CSE Telecom",AVERAGE('Pós Implantação'!D9,'Pós Implantação'!L9),""),"") | N9: =IFERROR(IF('Pós Implantação'!B9="Site Suporte de Campo",AVERAGE('Pós Implantação'!D9,'Pós Implantação'!L9),""),"") | O9: =IFERROR(IF('Pós Implantação'!B9="Infraestrutura",AVERAGE('Pós Implantação'!D9,'Pós Implantação'!L9),""),"")
A10: ='Pré Implantação'!A10 -> 12352 | B10: ='Pós Implantação'!C10 -> 42584.458 | C10: =IFERROR(IF('Pré Implantação'!B10="Produção TI",AVERAGE('Pós Implantação'!D10,'Pós Implantação'!E10,'Pós Implantação'!L10,'Pós Implantação'!H10),AVERAGE('Pré Implantação'!E10,'Pré Implantação'!H10)),"") -> 0.9 | D10: =IFERROR(IF('Pós Implantação'!B10="CSC Service Desk",AVERAGE('Pós Implantação'!D10,'Pós Implantação'!L10,'Pós Implantação'!F10),AVERAGE('Pós Implantação'!F10)),"") | E10: =IFERROR(IF('Pós Implantação'!B10="CSC NOC",AVERAGE('Pós Implantação'!D10,'Pós Implantação'!L10,'Pós Implantação'!G10),AVERAGE('Pós Implantação'!G10)),"") | F10: =IFERROR(IF('Pós Implantação'!B10="CSE Gravadores",AVERAGE('Pós Implantação'!D10,'Pós Implantação'!L10,'Pós Implantação'!I10),AVERAGE('Pós Implantação'!I10)),"") | G10: =IFERROR(IF('Pós Implantação'!B10="CSC",AVERAGE('Pós Implantação'!D10,'Pós Implantação'!L10,'Pós Implantação'!J10),AVERAGE('Pós Implantação'!J10)),"") | H10: =IFERROR(IF('Pós Implantação'!B10="Operações \ Negócio",AVERAGE('Pós Implantação'!D10,'Pós Implantação'!L10,'Pós Implantação'!K10),AVERAGE('Pós Implantação'!K10)),"") | I10: =IFERROR(IF('Pós Implantação'!B10="Projetos",AVERAGE('Pós Implantação'!D10,'Pós Implantação'!L10,'Pós Implantação'!M10),AVERAGE('Pós Implantação'!M10)),"") | J10: =IFERROR(IF('Pós Implantação'!B10="Engenharia",AVERAGE('Pós Implantação'!D10,'Pós Implantação'!L10,'Pós Implantação'!N10),AVERAGE('Pós Implantação'!N10)),"") | K10: =IFERROR(IF('Pós Implantação'!B10="URA",AVERAGE('Pós Implantação'!D10,'Pós Implantação'!L10),""),"") -> 0.75 | L10: =IFERROR(IF('Pós Implantação'!B10="CSE Microsoft",AVERAGE('Pós Implantação'!D10,'Pós Implantação'!L10),""),"") | M10: =IFERROR(IF('Pós Implantação'!B10="CSE Telecom",AVERAGE('Pós Implantação'!D10,'Pós Implantação'!L10),""),"") | N10: =IFERROR(IF('Pós Implantação'!B10="Site Suporte de Campo",AVERAGE('Pós Implantação'!D10,'Pós Implantação'!L10),""),"") | O10: =IFERROR(IF('Pós Implantação'!B10="Infraestrutura",AVERAGE('Pós Implantação'!D10,'Pós Implantação'!L10),""),"")
A11: ='Pré Implantação'!A11 -> 12353 | B11: ='Pós Implantação'!C11 -> 42578.021 | C11: =IFERROR(IF('Pré Implantação'!B11="Produção TI",AVERAGE('Pós Implantação'!D11,'Pós Implantação'!E11,'Pós Implantação'!L11,'Pós Implantação'!H11),AVERAGE('Pré Implantação'!E11,'Pré Implantação'!H11)),"") | D11: =IFERROR(IF('Pós Implantação'!B11="CSC Service Desk",AVERAGE('Pós Implantação'!D11,'Pós Implantação'!L11,'Pós Implantação'!F11),AVERAGE('Pós Implantação'!F11)),"") | E11: =IFERROR(IF('Pós Implantação'!B11="CSC NOC",AVERAGE('Pós Implantação'!D11,'Pós Implantação'!L11,'Pós Implantação'!G11),AVERAGE('Pós Implantação'!G11)),"") | F11: =IFERROR(IF('Pós Implantação'!B11="CSE Gravadores",AVERAGE('Pós Implantação'!D11,'Pós Implantação'!L11,'Pós Implantação'!I11),AVERAGE('Pós Implantação'!I11)),"") -> 0.3 | G11: =IFERROR(IF('Pós Implantação'!B11="CSC",AVERAGE('Pós Implantação'!D11,'Pós Implantação'!L11,'Pós Implantação'!J11),AVERAGE('Pós Implantação'!J11)),"") | H11: =IFERROR(IF('Pós Implantação'!B11="Operações \ Negócio",AVERAGE('Pós Implantação'!D11,'Pós Implantação'!L11,'Pós Implantação'!K11),AVERAGE('Pós Implantação'!K11)),"") | I11: =IFERROR(IF('Pós Implantação'!B11="Projetos",AVERAGE('Pós Implantação'!D11,'Pós Implantação'!L11,'Pós Implantação'!M11),AVERAGE('Pós Implantação'!M11)),"") | J11: =IFERROR(IF('Pós Implantação'!B11="Engenharia",AVERAGE('Pós Implantação'!D11,'Pós Implantação'!L11,'Pós Implantação'!N11),AVERAGE('Pós Implantação'!N11)),"") | K11: =IFERROR(IF('Pós Implantação'!B11="URA",AVERAGE('Pós Implantação'!D11,'Pós Implantação'!L11),""),"") | L11: =IFERROR(IF('Pós Implantação'!B11="CSE Microsoft",AVERAGE('Pós Implantação'!D11,'Pós Implantação'!L11),""),"") | M11: =IFERROR(IF('Pós Implantação'!B11="CSE Telecom",AVERAGE('Pós Implantação'!D11,'Pós Implantação'!L11),""),"") -> 1 | N11: =IFERROR(IF('Pós Implantação'!B11="Site Suporte de Campo",AVERAGE('Pós Implantação'!D11,'Pós Implantação'!L11),""),"") | O11: =IFERROR(IF('Pós Implantação'!B11="Infraestrutura",AVERAGE('Pós Implantação'!D11,'Pós Implantação'!L11),""),"")
A12: ='Pré Implantação'!A12 -> 12354 | B12: ='Pós Implantação'!C12 -> 42579.802 | C12: =IFERROR(IF('Pré Implantação'!B12="Produção TI",AVERAGE('Pós Implantação'!D12,'Pós Implantação'!E12,'Pós Implantação'!L12,'Pós Implantação'!H12),AVERAGE('Pré Implantação'!E12,'Pré Implantação'!H12)),"") -> 0.75 | D12: =IFERROR(IF('Pós Implantação'!B12="CSC Service Desk",AVERAGE('Pós Implantação'!D12,'Pós Implantação'!L12,'Pós Implantação'!F12),AVERAGE('Pós Implantação'!F12)),"") -> 1 | E12: =IFERROR(IF('Pós Implantação'!B12="CSC NOC",AVERAGE('Pós Implantação'!D12,'Pós Implantação'!L12,'Pós Implantação'!G12),AVERAGE('Pós Implantação'!G12)),"") -> 1 | F12: =IFERROR(IF('Pós Implantação'!B12="CSE Gravadores",AVERAGE('Pós Implantação'!D12,'Pós Implantação'!L12,'Pós Implantação'!I12),AVERAGE('Pós Implantação'!I12)),"") -> 1 | G12: =IFERROR(IF('Pós Implantação'!B12="CSC",AVERAGE('Pós Implantação'!D12,'Pós Implantação'!L12,'Pós Implantação'!J12),AVERAGE('Pós Implantação'!J12)),"") -> 1 | H12: =IFERROR(IF('Pós Implantação'!B12="Operações \ Negócio",AVERAGE('Pós Implantação'!D12,'Pós Implantação'!L12,'Pós Implantação'!K12),AVERAGE('Pós Implantação'!K12)),"") -> 1 | I12: =IFERROR(IF('Pós Implantação'!B12="Projetos",AVERAGE('Pós Implantação'!D12,'Pós Implantação'!L12,'Pós Implantação'!M12),AVERAGE('Pós Implantação'!M12)),"") -> 1 | J12: =IFERROR(IF('Pós Implantação'!B12="Engenharia",AVERAGE('Pós Implantação'!D12,'Pós Implantação'!L12,'Pós Implantação'!N12),AVERAGE('Pós Implantação'!N12)),"") -> 1 | K12: =IFERROR(IF('Pós Implantação'!B12="URA",AVERAGE('Pós Implantação'!D12,'Pós Implantação'!L12),""),"") | L12: =IFERROR(IF('Pós Implantação'!B12="CSE Microsoft",AVERAGE('Pós Implantação'!D12,'Pós Implantação'!L12),""),"") -> 1 | M12: =IFERROR(IF('Pós Implantação'!B12="CSE Telecom",AVERAGE('Pós Implantação'!D12,'Pós Implantação'!L12),""),"") | N12: =IFERROR(IF('Pós Implantação'!B12="Site Suporte de Campo",AVERAGE('Pós Implantação'!D12,'Pós Implantação'!L12),""),"") | O12: =IFERROR(IF('Pós Implantação'!B12="Infraestrutura",AVERAGE('Pós Implantação'!D12,'Pós Implantação'!L12),""),"")
A13: ='Pré Implantação'!A13 -> 12355 | B13: ='Pós Implantação'!C13 -> 42579.667 | C13: =IFERROR(IF('Pré Implantação'!B13="Produção TI",AVERAGE('Pós Implantação'!D13,'Pós Implantação'!E13,'Pós Implantação'!L13,'Pós Implantação'!H13),AVERAGE('Pré Implantação'!E13,'Pré Implantação'!H13)),"") -> 0.5 | D13: =IFERROR(IF('Pós Implantação'!B13="CSC Service Desk",AVERAGE('Pós Implantação'!D13,'Pós Implantação'!L13,'Pós Implantação'!F13),AVERAGE('Pós Implantação'!F13)),"") -> 1 | E13: =IFERROR(IF('Pós Implantação'!B13="CSC NOC",AVERAGE('Pós Implantação'!D13,'Pós Implantação'!L13,'Pós Implantação'!G13),AVERAGE('Pós Implantação'!G13)),"") | F13: =IFERROR(IF('Pós Implantação'!B13="CSE Gravadores",AVERAGE('Pós Implantação'!D13,'Pós Implantação'!L13,'Pós Implantação'!I13),AVERAGE('Pós Implantação'!I13)),"") | G13: =IFERROR(IF('Pós Implantação'!B13="CSC",AVERAGE('Pós Implantação'!D13,'Pós Implantação'!L13,'Pós Implantação'!J13),AVERAGE('Pós Implantação'!J13)),"") -> 0.8 | H13: =IFERROR(IF('Pós Implantação'!B13="Operações \ Negócio",AVERAGE('Pós Implantação'!D13,'Pós Implantação'!L13,'Pós Implantação'!K13),AVERAGE('Pós Implantação'!K13)),"") -> 0.75 | I13: =IFERROR(IF('Pós Implantação'!B13="Projetos",AVERAGE('Pós Implantação'!D13,'Pós Implantação'!L13,'Pós Implantação'!M13),AVERAGE('Pós Implantação'!M13)),"") | J13: =IFERROR(IF('Pós Implantação'!B13="Engenharia",AVERAGE('Pós Implantação'!D13,'Pós Implantação'!L13,'Pós Implantação'!N13),AVERAGE('Pós Implantação'!N13)),"") -> 0.4 | K13: =IFERROR(IF('Pós Implantação'!B13="URA",AVERAGE('Pós Implantação'!D13,'Pós Implantação'!L13),""),"") | L13: =IFERROR(IF('Pós Implantação'!B13="CSE Microsoft",AVERAGE('Pós Implantação'!D13,'Pós Implantação'!L13),""),"") | M13: =IFERROR(IF('Pós Implantação'!B13="CSE Telecom",AVERAGE('Pós Implantação'!D13,'Pós Implantação'!L13),""),"") | N13: =IFERROR(IF('Pós Implantação'!B13="Site Suporte de Campo",AVERAGE('Pós Implantação'!D13,'Pós Implantação'!L13),""),"") | O13: =IFERROR(IF('Pós Implantação'!B13="Infraestrutura",AVERAGE('Pós Implantação'!D13,'Pós Implantação'!L13),""),"")
A14: ='Pré Implantação'!A14 -> 0 | B14: ='Pós Implantação'!C14 -> 0 | C14: =IFERROR(IF('Pré Implantação'!B14="Produção TI",AVERAGE('Pós Implantação'!D14,'Pós Implantação'!E14,'Pós Implantação'!L14,'Pós Implantação'!H14),AVERAGE('Pré Implantação'!E14,'Pré Implantação'!H14)),"") | D14: =IFERROR(IF('Pós Implantação'!B14="CSC Service Desk",AVERAGE('Pós Implantação'!D14,'Pós Implantação'!L14,'Pós Implantação'!F14),AVERAGE('Pós Implantação'!F14)),"") | E14: =IFERROR(IF('Pós Implantação'!B14="CSC NOC",AVERAGE('Pós Implantação'!D14,'Pós Implantação'!L14,'Pós Implantação'!G14),AVERAGE('Pós Implantação'!G14)),"") | F14: =IFERROR(IF('Pós Implantação'!B14="CSE Gravadores",AVERAGE('Pós Implantação'!D14,'Pós Implantação'!L14,'Pós Implantação'!I14),AVERAGE('Pós Implantação'!I14)),"") | G14: =IFERROR(IF('Pós Implantação'!B14="CSC",AVERAGE('Pós Implantação'!D14,'Pós Implantação'!L14,'Pós Implantação'!J14),AVERAGE('Pós Implantação'!J14)),"") | H14: =IFERROR(IF('Pós Implantação'!B14="Operações \ Negócio",AVERAGE('Pós Implantação'!D14,'Pós Implantação'!L14,'Pós Implantação'!K14),AVERAGE('Pós Implantação'!K14)),"") | I14: =IFERROR(IF('Pós Implantação'!B14="Projetos",AVERAGE('Pós Implantação'!D14,'Pós Implantação'!L14,'Pós Implantação'!M14),AVERAGE('Pós Implantação'!M14)),"") | J14: =IFERROR(IF('Pós Implantação'!B14="Engenharia",AVERAGE('Pós Implantação'!D14,'Pós Implantação'!L14,'Pós Implantação'!N14),AVERAGE('Pós Implantação'!N14)),"") | K14: =IFERROR(IF('Pós Implantação'!B14="URA",AVERAGE('Pós Implantação'!D14,'Pós Implantação'!L14),""),"") | L14: =IFERROR(IF('Pós Implantação'!B14="CSE Microsoft",AVERAGE('Pós Implantação'!D14,'Pós Implantação'!L14),""),"") | M14: =IFERROR(IF('Pós Implantação'!B14="CSE Telecom",AVERAGE('Pós Implantação'!D14,'Pós Implantação'!L14),""),"") | N14: =IFERROR(IF('Pós Implantação'!B14="Site Suporte de Campo",AVERAGE('Pós Implantação'!D14,'Pós Implantação'!L14),""),"") | O14: =IFERROR(IF('Pós Implantação'!B14="Infraestrutura",AVERAGE('Pós Implantação'!D14,'Pós Implantação'!L14),""),"")
