Workbook

Sheet Campaign Name
B1: Mandatory Fields | I1: Optional | M1: CAMPAIGN NAME
A2: ID | B2: Country (List) | C2: Campaign Name Description (FF) | D2: Merchant Code (List) | E2: Date (List) | F2: PO# (FF) | G2: Sponsorship | H2: Activity | I2: Campaign Objective (List) | J2: U1 | K2: U2 | L2: U3
B3: Brazil | C3: DOTZ | D3: None | E3: 20Q1 | F3: 5020004460 | G3: N/A | H3: Client Marketing | I3: Consideration | M3: =CONCATENATE("MK|",(VLOOKUP(B3,Dictionary!$A:$B,2,FALSE)),"_CN|",SUBSTITUTE(SUBSTITUTE(IF(C3="","NONE",C3),"_","-"),"|","-"),"_MN|",(VLOOKUP(D3,Dictionary!$D:$E,2,0)),"_YQ|",(VLOOKUP(E3,Dictionary!$AR:$AR,1,0)),"_CP|",SUBSTITUTE(SUBSTITUTE(IF(F3="","NONE",F3),"_","-"),"|","-"),"_SP|",(VLOOKUP(G3,Dictionary!$AY:$AZ,2,0)),"_AC|",(VLOOKUP(H3,Dictionary!$BA:$BB,2,0)),IF(I3="","",CONCATENATE("_OB|",(VLOOKUP(I3,Dictionary!$AS:$AT,2,0)))),IF(J3="","",CONCATENATE("_U1|",SUBSTITUTE(SUBSTITUTE(J3,"_","-"),"|","-"))),IF(K3="","",CONCATENATE("_U2|",SUBSTITUTE(SUBSTITUTE(K3,"_","-"),"|","-"))),IF(L3="","",CONCATENATE("_U3|",SUBSTITUTE(SUBSTITUTE(L3,"_","-"),"|","-")))) -> MK|BR_CN|DOTZ_MN|NONE_YQ|20Q1_CP|5020004460_SP|NA_AC|CMKT_OB|CON
B4: Brazil | C4: DOTZ | D4: None | E4: 20Q1Q4 | F4: 5020004460 | G4: N/A | H4: Client Marketing | M4: =CONCATENATE("MK|",(VLOOKUP(B4,Dictionary!$A:$B,2,FALSE)),"_CN|",SUBSTITUTE(SUBSTITUTE(IF(C4="","NONE",C4),"_","-"),"|","-"),"_MN|",(VLOOKUP(D4,Dictionary!$D:$E,2,0)),"_YQ|",(VLOOKUP(E4,Dictionary!$AR:$AR,1,0)),"_CP|",SUBSTITUTE(SUBSTITUTE(IF(F4="","NONE",F4),"_","-"),"|","-"),"_SP|",(VLOOKUP(G4,Dictionary!$AY:$AZ,2,0)),"_AC|",(VLOOKUP(H4,Dictionary!$BA:$BB,2,0)),IF(I4="","",CONCATENATE("_OB|",(VLOOKUP(I4,Dictionary!$AS:$AT,2,0)))),IF(J4="","",CONCATENATE("_U1|",SUBSTITUTE(SUBSTITUTE(J4,"_","-"),"|","-"))),IF(K4="","",CONCATENATE("_U2|",SUBSTITUTE(SUBSTITUTE(K4,"_","-"),"|","-"))),IF(L4="","",CONCATENATE("_U3|",SUBSTITUTE(SUBSTITUTE(L4,"_","-"),"|","-")))) -> MK|BR_CN|DOTZ_MN|NONE_YQ|20Q1Q4_CP|5020004460_SP|NA_AC|CMKT
B5: Brazil | C5: DOTZ | D5: None | E5: 20Q2Q4 | F5: 5020004460 | G5: N/A | H5: Client Marketing | I5: Acquisition | M5: =CONCATENATE("MK|",(VLOOKUP(B5,Dictionary!$A:$B,2,FALSE)),"_CN|",SUBSTITUTE(SUBSTITUTE(IF(C5="","NONE",C5),"_","-"),"|","-"),"_MN|",(VLOOKUP(D5,Dictionary!$D:$E,2,0)),"_YQ|",(VLOOKUP(E5,Dictionary!$AR:$AR,1,0)),"_CP|",SUBSTITUTE(SUBSTITUTE(IF(F5="","NONE",F5),"_","-"),"|","-"),"_SP|",(VLOOKUP(G5,Dictionary!$AY:$AZ,2,0)),"_AC|",(VLOOKUP(H5,Dictionary!$BA:$BB,2,0)),IF(I5="","",CONCATENATE("_OB|",(VLOOKUP(I5,Dictionary!$AS:$AT,2,0)))),IF(J5="","",CONCATENATE("_U1|",SUBSTITUTE(SUBSTITUTE(J5,"_","-"),"|","-"))),IF(K5="","",CONCATENATE("_U2|",SUBSTITUTE(SUBSTITUTE(K5,"_","-"),"|","-"))),IF(L5="","",CONCATENATE("_U3|",SUBSTITUTE(SUBSTITUTE(L5,"_","-"),"|","-")))) -> MK|BR_CN|DOTZ_MN|NONE_YQ|20Q2Q4_CP|5020004460_SP|NA_AC|CMKT_OB|ACQ
B6: Brazil | C6: FWWC | D6: None | E6: 19Q1Q4 | F6: NONE | G6: N/A | H6: Cash Conversion | I6: Acquisition | M6: =CONCATENATE("MK|",(VLOOKUP(B6,Dictionary!$A:$B,2,FALSE)),"_CN|",SUBSTITUTE(SUBSTITUTE(IF(C6="","NONE",C6),"_","-"),"|","-"),"_MN|",(VLOOKUP(D6,Dictionary!$D:$E,2,0)),"_YQ|",(VLOOKUP(E6,Dictionary!$AR:$AR,1,0)),"_CP|",SUBSTITUTE(SUBSTITUTE(IF(F6="","NONE",F6),"_","-"),"|","-"),"_SP|",(VLOOKUP(G6,Dictionary!$AY:$AZ,2,0)),"_AC|",(VLOOKUP(H6,Dictionary!$BA:$BB,2,0)),IF(I6="","",CONCATENATE("_OB|",(VLOOKUP(I6,Dictionary!$AS:$AT,2,0)))),IF(J6="","",CONCATENATE("_U1|",SUBSTITUTE(SUBSTITUTE(J6,"_","-"),"|","-"))),IF(K6="","",CONCATENATE("_U2|",SUBSTITUTE(SUBSTITUTE(K6,"_","-"),"|","-"))),IF(L6="","",CONCATENATE("_U3|",SUBSTITUTE(SUBSTITUTE(L6,"_","-"),"|","-")))) -> MK|BR_CN|FWWC_MN|NONE_YQ|19Q1Q4_CP|NONE_SP|NA_AC|CC_OB|ACQ
M17: =CONCATENATE("MK|",(VLOOKUP(B17,Dictionary!$A:$B,2,FALSE)),"_CN|",SUBSTITUTE(SUBSTITUTE(IF(C17="","NONE",C17),"_","-"),"|","-"),"_MN|",(VLOOKUP(D17,Dictionary!$D:$E,2,0)),"_YQ|",(VLOOKUP(E17,Dictionary!$AR:$AR,1,0)),"_CP|",SUBSTITUTE(SUBSTITUTE(IF(F17="","NONE",F17),"_","-"),"|","-"),"_SP|",(VLOOKUP(G17,Dictionary!$AY:$AZ,2,0)),"_AC|",(VLOOKUP(H17,Dictionary!$BA:$BB,2,0)),IF(I17="","",CONCATENATE("_OB|",(VLOOKUP(I17,Dictionary!$AS:$AT,2,0)))),IF(J17="","",CONCATENATE("_U1|",SUBSTITUTE(SUBSTITUTE(J17,"_","-"),"|","-"))),IF(K17="","",CONCATENATE("_U2|",SUBSTITUTE(SUBSTITUTE(K17,"_","-"),"|","-"))),IF(L17="","",CONCATENATE("_U3|",SUBSTITUTE(SUBSTITUTE(L17,"_","-"),"|","-")))) -> #N/A
M18: =CONCATENATE("MK|",(VLOOKUP(B18,Dictionary!$A:$B,2,FALSE)),"_CN|",SUBSTITUTE(SUBSTITUTE(IF(C18="","NONE",C18),"_","-"),"|","-"),"_MN|",(VLOOKUP(D18,Dictionary!$D:$E,2,0)),"_YQ|",(VLOOKUP(E18,Dictionary!$AR:$AR,1,0)),"_CP|",SUBSTITUTE(SUBSTITUTE(IF(F18="","NONE",F18),"_","-"),"|","-"),"_SP|",(VLOOKUP(G18,Dictionary!$AY:$AZ,2,0)),"_AC|",(VLOOKUP(H18,Dictionary!$BA:$BB,2,0)),IF(I18="","",CONCATENATE("_OB|",(VLOOKUP(I18,Dictionary!$AS:$AT,2,0)))),IF(J18="","",CONCATENATE("_U1|",SUBSTITUTE(SUBSTITUTE(J18,"_","-"),"|","-"))),IF(K18="","",CONCATENATE("_U2|",SUBSTITUTE(SUBSTITUTE(K18,"_","-"),"|","-"))),IF(L18="","",CONCATENATE("_U3|",SUBSTITUTE(SUBSTITUTE(L18,"_","-"),"|","-")))) -> #N/A
M19: =CONCATENATE("MK|",(VLOOKUP(B19,Dictionary!$A:$B,2,FALSE)),"_CN|",SUBSTITUTE(SUBSTITUTE(IF(C19="","NONE",C19),"_","-"),"|","-"),"_MN|",(VLOOKUP(D19,Dictionary!$D:$E,2,0)),"_YQ|",(VLOOKUP(E19,Dictionary!$AR:$AR,1,0)),"_CP|",SUBSTITUTE(SUBSTITUTE(IF(F19="","NONE",F19),"_","-"),"|","-"),"_SP|",(VLOOKUP(G19,Dictionary!$AY:$AZ,2,0)),"_AC|",(VLOOKUP(H19,Dictionary!$BA:$BB,2,0)),IF(I19="","",CONCATENATE("_OB|",(VLOOKUP(I19,Dictionary!$AS:$AT,2,0)))),IF(J19="","",CONCATENATE("_U1|",SUBSTITUTE(SUBSTITUTE(J19,"_","-"),"|","-"))),IF(K19="","",CONCATENATE("_U2|",SUBSTITUTE(SUBSTITUTE(K19,"_","-"),"|","-"))),IF(L19="","",CONCATENATE("_U3|",SUBSTITUTE(SUBSTITUTE(L19,"_","-"),"|","-")))) -> #N/A
M20: =CONCATENATE("MK|",(VLOOKUP(B20,Dictionary!$A:$B,2,FALSE)),"_CN|",SUBSTITUTE(SUBSTITUTE(IF(C20="","NONE",C20),"_","-"),"|","-"),"_MN|",(VLOOKUP(D20,Dictionary!$D:$E,2,0)),"_YQ|",(VLOOKUP(E20,Dictionary!$AR:$AR,1,0)),"_CP|",SUBSTITUTE(SUBSTITUTE(IF(F20="","NONE",F20),"_","-"),"|","-"),"_SP|",(VLOOKUP(G20,Dictionary!$AY:$AZ,2,0)),"_AC|",(VLOOKUP(H20,Dictionary!$BA:$BB,2,0)),IF(I20="","",CONCATENATE("_OB|",(VLOOKUP(I20,Dictionary!$AS:$AT,2,0)))),IF(J20="","",CONCATENATE("_U1|",SUBSTITUTE(SUBSTITUTE(J20,"_","-"),"|","-"))),IF(K20="","",CONCATENATE("_U2|",SUBSTITUTE(SUBSTITUTE(K20,"_","-"),"|","-"))),IF(L20="","",CONCATENATE("_U3|",SUBSTITUTE(SUBSTITUTE(L20,"_","-"),"|","-")))) -> #N/A
M21: =CONCATENATE("MK|",(VLOOKUP(B21,Dictionary!$A:$B,2,FALSE)),"_CN|",SUBSTITUTE(SUBSTITUTE(IF(C21="","NONE",C21),"_","-"),"|","-"),"_MN|",(VLOOKUP(D21,Dictionary!$D:$E,2,0)),"_YQ|",(VLOOKUP(E21,Dictionary!$AR:$AR,1,0)),"_CP|",SUBSTITUTE(SUBSTITUTE(IF(F21="","NONE",F21),"_","-"),"|","-"),"_SP|",(VLOOKUP(G21,Dictionary!$AY:$AZ,2,0)),"_AC|",(VLOOKUP(H21,Dictionary!$BA:$BB,2,0)),IF(I21="","",CONCATENATE("_OB|",(VLOOKUP(I21,Dictionary!$AS:$AT,2,0)))),IF(J21="","",CONCATENATE("_U1|",SUBSTITUTE(SUBSTITUTE(J21,"_","-"),"|","-"))),IF(K21="","",CONCATENATE("_U2|",SUBSTITUTE(SUBSTITUTE(K21,"_","-"),"|","-"))),IF(L21="","",CONCATENATE("_U3|",SUBSTITUTE(SUBSTITUTE(L21,"_","-"),"|","-")))) -> #N/A
M22: =CONCATENATE("MK|",(VLOOKUP(B22,Dictionary!$A:$B,2,FALSE)),"_CN|",SUBSTITUTE(SUBSTITUTE(IF(C22="","NONE",C22),"_","-"),"|","-"),"_MN|",(VLOOKUP(D22,Dictionary!$D:$E,2,0)),"_YQ|",(VLOOKUP(E22,Dictionary!$AR:$AR,1,0)),"_CP|",SUBSTITUTE(SUBSTITUTE(IF(F22="","NONE",F22),"_","-"),"|","-"),"_SP|",(VLOOKUP(G22,Dictionary!$AY:$AZ,2,0)),"_AC|",(VLOOKUP(H22,Dictionary!$BA:$BB,2,0)),IF(I22="","",CONCATENATE("_OB|",(VLOOKUP(I22,Dictionary!$AS:$AT,2,0)))),IF(J22="","",CONCATENATE("_U1|",SUBSTITUTE(SUBSTITUTE(J22,"_","-"),"|","-"))),IF(K22="","",CONCATENATE("_U2|",SUBSTITUTE(SUBSTITUTE(K22,"_","-"),"|","-"))),IF(L22="","",CONCATENATE("_U3|",SUBSTITUTE(SUBSTITUTE(L22,"_","-"),"|","-")))) -> #N/A
M23: =CONCATENATE("MK|",(VLOOKUP(B23,Dictionary!$A:$B,2,FALSE)),"_CN|",SUBSTITUTE(SUBSTITUTE(IF(C23="","NONE",C23),"_","-"),"|","-"),"_MN|",(VLOOKUP(D23,Dictionary!$D:$E,2,0)),"_YQ|",(VLOOKUP(E23,Dictionary!$AR:$AR,1,0)),"_CP|",SUBSTITUTE(SUBSTITUTE(IF(F23="","NONE",F23),"_","-"),"|","-"),"_SP|",(VLOOKUP(G23,Dictionary!$AY:$AZ,2,0)),"_AC|",(VLOOKUP(H23,Dictionary!$BA:$BB,2,0)),IF(I23="","",CONCATENATE("_OB|",(VLOOKUP(I23,Dictionary!$AS:$AT,2,0)))),IF(J23="","",CONCATENATE("_U1|",SUBSTITUTE(SUBSTITUTE(J23,"_","-"),"|","-"))),IF(K23="","",CONCATENATE("_U2|",SUBSTITUTE(SUBSTITUTE(K23,"_","-"),"|","-"))),IF(L23="","",CONCATENATE("_U3|",SUBSTITUTE(SUBSTITUTE(L23,"_","-"),"|","-")))) -> #N/A
M24: =CONCATENATE("MK|",(VLOOKUP(B24,Dictionary!$A:$B,2,FALSE)),"_CN|",SUBSTITUTE(SUBSTITUTE(IF(C24="","NONE",C24),"_","-"),"|","-"),"_MN|",(VLOOKUP(D24,Dictionary!$D:$E,2,0)),"_YQ|",(VLOOKUP(E24,Dictionary!$AR:$AR,1,0)),"_CP|",SUBSTITUTE(SUBSTITUTE(IF(F24="","NONE",F24),"_","-"),"|","-"),"_SP|",(VLOOKUP(G24,Dictionary!$AY:$AZ,2,0)),"_AC|",(VLOOKUP(H24,Dictionary!$BA:$BB,2,0)),IF(I24="","",CONCATENATE("_OB|",(VLOOKUP(I24,Dictionary!$AS:$AT,2,0)))),IF(J24="","",CONCATENATE("_U1|",SUBSTITUTE(SUBSTITUTE(J24,"_","-"),"|","-"))),IF(K24="","",CONCATENATE("_U2|",SUBSTITUTE(SUBSTITUTE(K24,"_","-"),"|","-"))),IF(L24="","",CONCATENATE("_U3|",SUBSTITUTE(SUBSTITUTE(L24,"_","-"),"|","-")))) -> #N/A
M25: =CONCATENATE("MK|",(VLOOKUP(B25,Dictionary!$A:$B,2,FALSE)),"_CN|",SUBSTITUTE(SUBSTITUTE(IF(C25="","NONE",C25),"_","-"),"|","-"),"_MN|",(VLOOKUP(D25,Dictionary!$D:$E,2,0)),"_YQ|",(VLOOKUP(E25,Dictionary!$AR:$AR,1,0)),"_CP|",SUBSTITUTE(SUBSTITUTE(IF(F25="","NONE",F25),"_","-"),"|","-"),"_SP|",(VLOOKUP(G25,Dictionary!$AY:$AZ,2,0)),"_AC|",(VLOOKUP(H25,Dictionary!$BA:$BB,2,0)),IF(I25="","",CONCATENATE("_OB|",(VLOOKUP(I25,Dictionary!$AS:$AT,2,0)))),IF(J25="","",CONCATENATE("_U1|",SUBSTITUTE(SUBSTITUTE(J25,"_","-"),"|","-"))),IF(K25="","",CONCATENATE("_U2|",SUBSTITUTE(SUBSTITUTE(K25,"_","-"),"|","-"))),IF(L25="","",CONCATENATE("_U3|",SUBSTITUTE(SUBSTITUTE(L25,"_","-"),"|","-")))) -> #N/A
M26: =CONCATENATE("MK|",(VLOOKUP(B26,Dictionary!$A:$B,2,FALSE)),"_CN|",SUBSTITUTE(SUBSTITUTE(IF(C26="","NONE",C26),"_","-"),"|","-"),"_MN|",(VLOOKUP(D26,Dictionary!$D:$E,2,0)),"_YQ|",(VLOOKUP(E26,Dictionary!$AR:$AR,1,0)),"_CP|",SUBSTITUTE(SUBSTITUTE(IF(F26="","NONE",F26),"_","-"),"|","-"),"_SP|",(VLOOKUP(G26,Dictionary!$AY:$AZ,2,0)),"_AC|",(VLOOKUP(H26,Dictionary!$BA:$BB,2,0)),IF(I26="","",CONCATENATE("_OB|",(VLOOKUP(I26,Dictionary!$AS:$AT,2,0)))),IF(J26="","",CONCATENATE("_U1|",SUBSTITUTE(SUBSTITUTE(J26,"_","-"),"|","-"))),IF(K26="","",CONCATENATE("_U2|",SUBSTITUTE(SUBSTITUTE(K26,"_","-"),"|","-"))),IF(L26="","",CONCATENATE("_U3|",SUBSTITUTE(SUBSTITUTE(L26,"_","-"),"|","-")))) -> #N/A
M27: =CONCATENATE("MK|",(VLOOKUP(B27,Dictionary!$A:$B,2,FALSE)),"_CN|",SUBSTITUTE(SUBSTITUTE(IF(C27="","NONE",C27),"_","-"),"|","-"),"_MN|",(VLOOKUP(D27,Dictionary!$D:$E,2,0)),"_YQ|",(VLOOKUP(E27,Dictionary!$AR:$AR,1,0)),"_CP|",SUBSTITUTE(SUBSTITUTE(IF(F27="","NONE",F27),"_","-"),"|","-"),"_SP|",(VLOOKUP(G27,Dictionary!$AY:$AZ,2,0)),"_AC|",(VLOOKUP(H27,Dictionary!$BA:$BB,2,0)),IF(I27="","",CONCATENATE("_OB|",(VLOOKUP(I27,Dictionary!$AS:$AT,2,0)))),IF(J27="","",CONCATENATE("_U1|",SUBSTITUTE(SUBSTITUTE(J27,"_","-"),"|","-"))),IF(K27="","",CONCATENATE("_U2|",SUBSTITUTE(SUBSTITUTE(K27,"_","-"),"|","-"))),IF(L27="","",CONCATENATE("_U3|",SUBSTITUTE(SUBSTITUTE(L27,"_","-"),"|","-")))) -> #N/A
M28: =CONCATENATE("MK|",(VLOOKUP(B28,Dictionary!$A:$B,2,FALSE)),"_CN|",SUBSTITUTE(SUBSTITUTE(IF(C28="","NONE",C28),"_","-"),"|","-"),"_MN|",(VLOOKUP(D28,Dictionary!$D:$E,2,0)),"_YQ|",(VLOOKUP(E28,Dictionary!$AR:$AR,1,0)),"_CP|",SUBSTITUTE(SUBSTITUTE(IF(F28="","NONE",F28),"_","-"),"|","-"),"_SP|",(VLOOKUP(G28,Dictionary!$AY:$AZ,2,0)),"_AC|",(VLOOKUP(H28,Dictionary!$BA:$BB,2,0)),IF(I28="","",CONCATENATE("_OB|",(VLOOKUP(I28,Dictionary!$AS:$AT,2,0)))),IF(J28="","",CONCATENATE("_U1|",SUBSTITUTE(SUBSTITUTE(J28,"_","-"),"|","-"))),IF(K28="","",CONCATENATE("_U2|",SUBSTITUTE(SUBSTITUTE(K28,"_","-"),"|","-"))),IF(L28="","",CONCATENATE("_U3|",SUBSTITUTE(SUBSTITUTE(L28,"_","-"),"|","-")))) -> #N/A
... M337: =CONCATENATE("MK|",(VLOOKUP(B337,Dictionary!$A:$B,2,FALSE)),"_CN|",SUBSTITUTE(SUBSTITUTE(IF(C337="","NONE",C337),"_","-"),"|","-"),"_MN|",(VLOOKUP(D337,Dictionary!$D:$E,2,0)),"_YQ|",(VLOOKUP(E337,Dictionary!$AR:$AR,1,0)),"_CP|",SUBSTITUTE(SUBSTITUTE(IF(F337="","NONE",F337),"_","-"),"|","-"),"_SP|",(VLOOKUP(G337,Dictionary!$AY:$AZ,2,0)),"_AC|",(VLOOKUP(H337,Dictionary!$BA:$BB,2,0)),IF(I337="","",CONCATENATE("_OB|",(VLOOKUP(I337,Dictionary!$AS:$AT,2,0)))),IF(J337="","",CONCATENATE("_U1|",SUBSTITUTE(SUBSTITUTE(J337,"_","-"),"|","-"))),IF(K337="","",CONCATENATE("_U2|",SUBSTITUTE(SUBSTITUTE(K337,"_","-"),"|","-"))),IF(L337="","",CONCATENATE("_U3|",SUBSTITUTE(SUBSTITUTE(L337,"_","-"),"|","-")))) -> #N/A

Sheet ADSET Name
B1: Mandatory Fields | O1: Optional Fields
A2: ID | B2: Country (List) | C2: Media Channel | D2: Device(List) | E2: Publisher(List) | F2: Placement Type(List) | G2: Placement Rate Type(List) | H2: Placement Description(FF) | I2: Primary Target (List) | J2: Secondary Target (List) | K2: Target Description (FF) | L2: Placement Execution Size(List) | M2: Serving Method (List) | N2: Inventory Type (List) | O2: U1 | P2: U2 | Q2: U3
B3: Brazil | C3: SEM | D3: Cross Device/ Screen | E3: Google Adwords Search | F3: TEXT UNIT | G3: Cost per Click | H3: DOTZ-BENEFICIOS | I3: None | J3: None | L3: Text | M3: Adwords | N3: Search | R3: =IF(K3="----","#N/A",CONCATENATE("MK|",(VLOOKUP(B3,Dictionary!$A:$B,2,0)),"_CH|",(VLOOKUP(C3,Dictionary!$AV:$AW,2,0)),"_DT|",(VLOOKUP(D3,Dictionary!$P:$Q,2,0)),"_PB|",(VLOOKUP(E3,Dictionary!$G:$H,2,0)),"_FM|",(VLOOKUP(F3,Dictionary!$S:$T,2,0)),"_RT|",(VLOOKUP(G3,Dictionary!$V:$W,2,0)),"_PD|",SUBSTITUTE(SUBSTITUTE(IF(H3="","NONE",H3),"_","-"),"|","-"),"_TG|",(VLOOKUP(I3,Dictionary!$J:$K,2,0)),"_ST|",(VLOOKUP(J3,Dictionary!$M:$N,2,0)),"_TS|",SUBSTITUTE(SUBSTITUTE(IF(K3="","NONE",K3),"_","-"),"|","-"),"_SZ|",(VLOOKUP(L3,Dictionary!$Y:$Z,1,0)),"_AD|",(VLOOKUP(M3,Dictionary!$AB:$AC,2,0)),"_IT|",(VLOOKUP(N3,Dictionary!$BC:$BD,2,0)),IF(O3="","",CONCATENATE("_U1|",SUBSTITUTE(SUBSTITUTE(O3,"_","-"),"|","-"))),IF(P3="","",CONCATENATE("_U2|",SUBSTITUTE(SUBSTITUTE(P3,"_","-"),"|","-"))),IF(Q3="","",CONCATENATE("_U3|",SUBSTITUTE(SUBSTITUTE(Q3,"_","-"),"|","-"))))) -> MK|BR_CH|SEM_DT|CROSS_PB|GADS_FM|TXT_RT|CPC_PD|DOTZ-BENEFICIOS_TG|NON_ST|NON_TS|NONE_SZ|Text_AD|ADW_IT|SEM
B4: Brazil | C4: Paid Social Display | D4: Cross Device/ Screen | E4: Facebook | F4: SOCIAL POSTS | G4: Cost per Acquisition | H4: DOTZ-BENEFICIOS | I4: Contextual | J4: Behavioral | K4: VIAGENS | L4: 1X1 | M4: Site-Served w/ DCM Tracking | N4: Social | R4: =IF(K4="----","#N/A",CONCATENATE("MK|",(VLOOKUP(B4,Dictionary!$A:$B,2,0)),"_CH|",(VLOOKUP(C4,Dictionary!$AV:$AW,2,0)),"_DT|",(VLOOKUP(D4,Dictionary!$P:$Q,2,0)),"_PB|",(VLOOKUP(E4,Dictionary!$G:$H,2,0)),"_FM|",(VLOOKUP(F4,Dictionary!$S:$T,2,0)),"_RT|",(VLOOKUP(G4,Dictionary!$V:$W,2,0)),"_PD|",SUBSTITUTE(SUBSTITUTE(IF(H4="","NONE",H4),"_","-"),"|","-"),"_TG|",(VLOOKUP(I4,Dictionary!$J:$K,2,0)),"_ST|",(VLOOKUP(J4,Dictionary!$M:$N,2,0)),"_TS|",SUBSTITUTE(SUBSTITUTE(IF(K4="","NONE",K4),"_","-"),"|","-"),"_SZ|",(VLOOKUP(L4,Dictionary!$Y:$Z,1,0)),"_AD|",(VLOOKUP(M4,Dictionary!$AB:$AC,2,0)),"_IT|",(VLOOKUP(N4,Dictionary!$BC:$BD,2,0)),IF(O4="","",CONCATENATE("_U1|",SUBSTITUTE(SUBSTITUTE(O4,"_","-"),"|","-"))),IF(P4="","",CONCATENATE("_U2|",SUBSTITUTE(SUBSTITUTE(P4,"_","-"),"|","-"))),IF(Q4="","",CONCATENATE("_U3|",SUBSTITUTE(SUBSTITUTE(Q4,"_","-"),"|","-"))))) -> MK|BR_CH|PSD_DT|CROSS_PB|FCBK_FM|SPOST_RT|CPA_PD|DOTZ-BENEFICIOS_TG|CON_ST|BHV_TS|VIAGENS_SZ|1X1_AD|CM1_IT|SOC
B5: Brazil | C5: Programmatic Display | D5: Cross Device/ Screen | E5: Google DV360 | F5: Banner | G5: Cost per Acquisition | H5: DOTZ-BENEFICIOS | I5: Contextual | J5: None | K5: VIAGENS | L5: None | M5: DCM Ad Served | N5: Programmatic Open Exchange | R5: =IF(K5="----","#N/A",CONCATENATE("MK|",(VLOOKUP(B5,Dictionary!$A:$B,2,0)),"_CH|",(VLOOKUP(C5,Dictionary!$AV:$AW,2,0)),"_DT|",(VLOOKUP(D5,Dictionary!$P:$Q,2,0)),"_PB|",(VLOOKUP(E5,Dictionary!$G:$H,2,0)),"_FM|",(VLOOKUP(F5,Dictionary!$S:$T,2,0)),"_RT|",(VLOOKUP(G5,Dictionary!$V:$W,2,0)),"_PD|",SUBSTITUTE(SUBSTITUTE(IF(H5="","NONE",H5),"_","-"),"|","-"),"_TG|",(VLOOKUP(I5,Dictionary!$J:$K,2,0)),"_ST|",(VLOOKUP(J5,Dictionary!$M:$N,2,0)),"_TS|",SUBSTITUTE(SUBSTITUTE(IF(K5="","NONE",K5),"_","-"),"|","-"),"_SZ|",(VLOOKUP(L5,Dictionary!$Y:$Z,1,0)),"_AD|",(VLOOKUP(M5,Dictionary!$AB:$AC,2,0)),"_IT|",(VLOOKUP(N5,Dictionary!$BC:$BD,2,0)),IF(O5="","",CONCATENATE("_U1|",SUBSTITUTE(SUBSTITUTE(O5,"_","-"),"|","-"))),IF(P5="","",CONCATENATE("_U2|",SUBSTITUTE(SUBSTITUTE(P5,"_","-"),"|","-"))),IF(Q5="","",CONCATENATE("_U3|",SUBSTITUTE(SUBSTITUTE(Q5,"_","-"),"|","-"))))) -> MK|BR_CH|PD_DT|CROSS_PB|DV36_FM|BAN_RT|CPA_PD|DOTZ-BENEFICIOS_TG|CON_ST|NON_TS|VIAGENS_SZ|None_AD|CM_IT|POE
B6: Brazil | C6: Programmatic Display | D6: Cross Device/ Screen | E6: Google DV360 | F6: Banner | G6: Cost per Acquisition | H6: DOTZ-BENEFICIOS | I6: Contextual | J6: None | K6: FINANCE | L6: None | M6: DCM Ad Served | N6: Programmatic Open Exchange | R6: =IF(K6="----","#N/A",CONCATENATE("MK|",(VLOOKUP(B6,Dictionary!$A:$B,2,0)),"_CH|",(VLOOKUP(C6,Dictionary!$AV:$AW,2,0)),"_DT|",(VLOOKUP(D6,Dictionary!$P:$Q,2,0)),"_PB|",(VLOOKUP(E6,Dictionary!$G:$H,2,0)),"_FM|",(VLOOKUP(F6,Dictionary!$S:$T,2,0)),"_RT|",(VLOOKUP(G6,Dictionary!$V:$W,2,0)),"_PD|",SUBSTITUTE(SUBSTITUTE(IF(H6="","NONE",H6),"_","-"),"|","-"),"_TG|",(VLOOKUP(I6,Dictionary!$J:$K,2,0)),"_ST|",(VLOOKUP(J6,Dictionary!$M:$N,2,0)),"_TS|",SUBSTITUTE(SUBSTITUTE(IF(K6="","NONE",K6),"_","-"),"|","-"),"_SZ|",(VLOOKUP(L6,Dictionary!$Y:$Z,1,0)),"_AD|",(VLOOKUP(M6,Dictionary!$AB:$AC,2,0)),"_IT|",(VLOOKUP(N6,Dictionary!$BC:$BD,2,0)),IF(O6="","",CONCATENATE("_U1|",SUBSTITUTE(SUBSTITUTE(O6,"_","-"),"|","-"))),IF(P6="","",CONCATENATE("_U2|",SUBSTITUTE(SUBSTITUTE(P6,"_","-"),"|","-"))),IF(Q6="","",CONCATENATE("_U3|",SUBSTITUTE(SUBSTITUTE(Q6,"_","-"),"|","-"))))) -> MK|BR_CH|PD_DT|CROSS_PB|DV36_FM|BAN_RT|CPA_PD|DOTZ-BENEFICIOS_TG|CON_ST|NON_TS|FINANCE_SZ|None_AD|CM_IT|POE
B7: Brazil | C7: Programmatic Display | D7: Cross Device/ Screen | E7: Google DV360 | F7: Banner | G7: Cost per Acquisition | H7: DOTZ-BENEFICIOS | I7: Contextual | J7: None | K7: SHOPPERS | L7: None | M7: DCM Ad Served | N7: Programmatic Open Exchange | R7: =IF(K7="----","#N/A",CONCATENATE("MK|",(VLOOKUP(B7,Dictionary!$A:$B,2,0)),"_CH|",(VLOOKUP(C7,Dictionary!$AV:$AW,2,0)),"_DT|",(VLOOKUP(D7,Dictionary!$P:$Q,2,0)),"_PB|",(VLOOKUP(E7,Dictionary!$G:$H,2,0)),"_FM|",(VLOOKUP(F7,Dictionary!$S:$T,2,0)),"_RT|",(VLOOKUP(G7,Dictionary!$V:$W,2,0)),"_PD|",SUBSTITUTE(SUBSTITUTE(IF(H7="","NONE",H7),"_","-"),"|","-"),"_TG|",(VLOOKUP(I7,Dictionary!$J:$K,2,0)),"_ST|",(VLOOKUP(J7,Dictionary!$M:$N,2,0)),"_TS|",SUBSTITUTE(SUBSTITUTE(IF(K7="","NONE",K7),"_","-"),"|","-"),"_SZ|",(VLOOKUP(L7,Dictionary!$Y:$Z,1,0)),"_AD|",(VLOOKUP(M7,Dictionary!$AB:$AC,2,0)),"_IT|",(VLOOKUP(N7,Dictionary!$BC:$BD,2,0)),IF(O7="","",CONCATENATE("_U1|",SUBSTITUTE(SUBSTITUTE(O7,"_","-"),"|","-"))),IF(P7="","",CONCATENATE("_U2|",SUBSTITUTE(SUBSTITUTE(P7,"_","-"),"|","-"))),IF(Q7="","",CONCATENATE("_U3|",SUBSTITUTE(SUBSTITUTE(Q7,"_","-"),"|","-"))))) -> MK|BR_CH|PD_DT|CROSS_PB|DV36_FM|BAN_RT|CPA_PD|DOTZ-BENEFICIOS_TG|CON_ST|NON_TS|SHOPPERS_SZ|None_AD|CM_IT|POE
R88: =IF(K88="----","#N/A",CONCATENATE("MK|",(VLOOKUP(B88,Dictionary!$A:$B,2,0)),"_CH|",(VLOOKUP(C88,Dictionary!$AV:$AW,2,0)),"_DT|",(VLOOKUP(D88,Dictionary!$P:$Q,2,0)),"_PB|",(VLOOKUP(E88,Dictionary!$G:$H,2,0)),"_FM|",(VLOOKUP(F88,Dictionary!$S:$T,2,0)),"_RT|",(VLOOKUP(G88,Dictionary!$V:$W,2,0)),"_PD|",SUBSTITUTE(SUBSTITUTE(IF(H88="","NONE",H88),"_","-"),"|","-"),"_TG|",(VLOOKUP(I88,Dictionary!$J:$K,2,0)),"_ST|",(VLOOKUP(J88,Dictionary!$M:$N,2,0)),"_TS|",SUBSTITUTE(SUBSTITUTE(IF(K88="","NONE",K88),"_","-"),"|","-"),"_SZ|",(VLOOKUP(L88,Dictionary!$Y:$Z,1,0)),"_AD|",(VLOOKUP(M88,Dictionary!$AB:$AC,2,0)),"_IT|",(VLOOKUP(N88,Dictionary!$BC:$BD,2,0)),IF(O88="","",CONCATENATE("_U1|",SUBSTITUTE(SUBSTITUTE(O88,"_","-"),"|","-"))),IF(P88="","",CONCATENATE("_U2|",SUBSTITUTE(SUBSTITUTE(P88,"_","-"),"|","-"))),IF(Q88="","",CONCATENATE("_U3|",SUBSTITUTE(SUBSTITUTE(Q88,"_","-"),"|","-"))))) -> #N/A
R89: =IF(K89="----","#N/A",CONCATENATE("MK|",(VLOOKUP(B89,Dictionary!$A:$B,2,0)),"_CH|",(VLOOKUP(C89,Dictionary!$AV:$AW,2,0)),"_DT|",(VLOOKUP(D89,Dictionary!$P:$Q,2,0)),"_PB|",(VLOOKUP(E89,Dictionary!$G:$H,2,0)),"_FM|",(VLOOKUP(F89,Dictionary!$S:$T,2,0)),"_RT|",(VLOOKUP(G89,Dictionary!$V:$W,2,0)),"_PD|",SUBSTITUTE(SUBSTITUTE(IF(H89="","NONE",H89),"_","-"),"|","-"),"_TG|",(VLOOKUP(I89,Dictionary!$J:$K,2,0)),"_ST|",(VLOOKUP(J89,Dictionary!$M:$N,2,0)),"_TS|",SUBSTITUTE(SUBSTITUTE(IF(K89="","NONE",K89),"_","-"),"|","-"),"_SZ|",(VLOOKUP(L89,Dictionary!$Y:$Z,1,0)),"_AD|",(VLOOKUP(M89,Dictionary!$AB:$AC,2,0)),"_IT|",(VLOOKUP(N89,Dictionary!$BC:$BD,2,0)),IF(O89="","",CONCATENATE("_U1|",SUBSTITUTE(SUBSTITUTE(O89,"_","-"),"|","-"))),IF(P89="","",CONCATENATE("_U2|",SUBSTITUTE(SUBSTITUTE(P89,"_","-"),"|","-"))),IF(Q89="","",CONCATENATE("_U3|",SUBSTITUTE(SUBSTITUTE(Q89,"_","-"),"|","-"))))) -> #N/A
R90: =IF(K90="----","#N/A",CONCATENATE("MK|",(VLOOKUP(B90,Dictionary!$A:$B,2,0)),"_CH|",(VLOOKUP(C90,Dictionary!$AV:$AW,2,0)),"_DT|",(VLOOKUP(D90,Dictionary!$P:$Q,2,0)),"_PB|",(VLOOKUP(E90,Dictionary!$G:$H,2,0)),"_FM|",(VLOOKUP(F90,Dictionary!$S:$T,2,0)),"_RT|",(VLOOKUP(G90,Dictionary!$V:$W,2,0)),"_PD|",SUBSTITUTE(SUBSTITUTE(IF(H90="","NONE",H90),"_","-"),"|","-"),"_TG|",(VLOOKUP(I90,Dictionary!$J:$K,2,0)),"_ST|",(VLOOKUP(J90,Dictionary!$M:$N,2,0)),"_TS|",SUBSTITUTE(SUBSTITUTE(IF(K90="","NONE",K90),"_","-"),"|","-"),"_SZ|",(VLOOKUP(L90,Dictionary!$Y:$Z,1,0)),"_AD|",(VLOOKUP(M90,Dictionary!$AB:$AC,2,0)),"_IT|",(VLOOKUP(N90,Dictionary!$BC:$BD,2,0)),IF(O90="","",CONCATENATE("_U1|",SUBSTITUTE(SUBSTITUTE(O90,"_","-"),"|","-"))),IF(P90="","",CONCATENATE("_U2|",SUBSTITUTE(SUBSTITUTE(P90,"_","-"),"|","-"))),IF(Q90="","",CONCATENATE("_U3|",SUBSTITUTE(SUBSTITUTE(Q90,"_","-"),"|","-"))))) -> #N/A
R91: =IF(K91="----","#N/A",CONCATENATE("MK|",(VLOOKUP(B91,Dictionary!$A:$B,2,0)),"_CH|",(VLOOKUP(C91,Dictionary!$AV:$AW,2,0)),"_DT|",(VLOOKUP(D91,Dictionary!$P:$Q,2,0)),"_PB|",(VLOOKUP(E91,Dictionary!$G:$H,2,0)),"_FM|",(VLOOKUP(F91,Dictionary!$S:$T,2,0)),"_RT|",(VLOOKUP(G91,Dictionary!$V:$W,2,0)),"_PD|",SUBSTITUTE(SUBSTITUTE(IF(H91="","NONE",H91),"_","-"),"|","-"),"_TG|",(VLOOKUP(I91,Dictionary!$J:$K,2,0)),"_ST|",(VLOOKUP(J91,Dictionary!$M:$N,2,0)),"_TS|",SUBSTITUTE(SUBSTITUTE(IF(K91="","NONE",K91),"_","-"),"|","-"),"_SZ|",(VLOOKUP(L91,Dictionary!$Y:$Z,1,0)),"_AD|",(VLOOKUP(M91,Dictionary!$AB:$AC,2,0)),"_IT|",(VLOOKUP(N91,Dictionary!$BC:$BD,2,0)),IF(O91="","",CONCATENATE("_U1|",SUBSTITUTE(SUBSTITUTE(O91,"_","-"),"|","-"))),IF(P91="","",CONCATENATE("_U2|",SUBSTITUTE(SUBSTITUTE(P91,"_","-"),"|","-"))),IF(Q91="","",CONCATENATE("_U3|",SUBSTITUTE(SUBSTITUTE(Q91,"_","-"),"|","-"))))) -> #N/A
R92: =IF(K92="----","#N/A",CONCATENATE("MK|",(VLOOKUP(B92,Dictionary!$A:$B,2,0)),"_CH|",(VLOOKUP(C92,Dictionary!$AV:$AW,2,0)),"_DT|",(VLOOKUP(D92,Dictionary!$P:$Q,2,0)),"_PB|",(VLOOKUP(E92,Dictionary!$G:$H,2,0)),"_FM|",(VLOOKUP(F92,Dictionary!$S:$T,2,0)),"_RT|",(VLOOKUP(G92,Dictionary!$V:$W,2,0)),"_PD|",SUBSTITUTE(SUBSTITUTE(IF(H92="","NONE",H92),"_","-"),"|","-"),"_TG|",(VLOOKUP(I92,Dictionary!$J:$K,2,0)),"_ST|",(VLOOKUP(J92,Dictionary!$M:$N,2,0)),"_TS|",SUBSTITUTE(SUBSTITUTE(IF(K92="","NONE",K92),"_","-"),"|","-"),"_SZ|",(VLOOKUP(L92,Dictionary!$Y:$Z,1,0)),"_AD|",(VLOOKUP(M92,Dictionary!$AB:$AC,2,0)),"_IT|",(VLOOKUP(N92,Dictionary!$BC:$BD,2,0)),IF(O92="","",CONCATENATE("_U1|",SUBSTITUTE(SUBSTITUTE(O92,"_","-"),"|","-"))),IF(P92="","",CONCATENATE("_U2|",SUBSTITUTE(SUBSTITUTE(P92,"_","-"),"|","-"))),IF(Q92="","",CONCATENATE("_U3|",SUBSTITUTE(SUBSTITUTE(Q92,"_","-"),"|","-"))))) -> #N/A
R93: =IF(K93="----","#N/A",CONCATENATE("MK|",(VLOOKUP(B93,Dictionary!$A:$B,2,0)),"_CH|",(VLOOKUP(C93,Dictionary!$AV:$AW,2,0)),"_DT|",(VLOOKUP(D93,Dictionary!$P:$Q,2,0)),"_PB|",(VLOOKUP(E93,Dictionary!$G:$H,2,0)),"_FM|",(VLOOKUP(F93,Dictionary!$S:$T,2,0)),"_RT|",(VLOOKUP(G93,Dictionary!$V:$W,2,0)),"_PD|",SUBSTITUTE(SUBSTITUTE(IF(H93="","NONE",H93),"_","-"),"|","-"),"_TG|",(VLOOKUP(I93,Dictionary!$J:$K,2,0)),"_ST|",(VLOOKUP(J93,Dictionary!$M:$N,2,0)),"_TS|",SUBSTITUTE(SUBSTITUTE(IF(K93="","NONE",K93),"_","-"),"|","-"),"_SZ|",(VLOOKUP(L93,Dictionary!$Y:$Z,1,0)),"_AD|",(VLOOKUP(M93,Dictionary!$AB:$AC,2,0)),"_IT|",(VLOOKUP(N93,Dictionary!$BC:$BD,2,0)),IF(O93="","",CONCATENATE("_U1|",SUBSTITUTE(SUBSTITUTE(O93,"_","-"),"|","-"))),IF(P93="","",CONCATENATE("_U2|",SUBSTITUTE(SUBSTITUTE(P93,"_","-"),"|","-"))),IF(Q93="","",CONCATENATE("_U3|",SUBSTITUTE(SUBSTITUTE(Q93,"_","-"),"|","-"))))) -> #N/A
R94: =IF(K94="----","#N/A",CONCATENATE("MK|",(VLOOKUP(B94,Dictionary!$A:$B,2,0)),"_CH|",(VLOOKUP(C94,Dictionary!$AV:$AW,2,0)),"_DT|",(VLOOKUP(D94,Dictionary!$P:$Q,2,0)),"_PB|",(VLOOKUP(E94,Dictionary!$G:$H,2,0)),"_FM|",(VLOOKUP(F94,Dictionary!$S:$T,2,0)),"_RT|",(VLOOKUP(G94,Dictionary!$V:$W,2,0)),"_PD|",SUBSTITUTE(SUBSTITUTE(IF(H94="","NONE",H94),"_","-"),"|","-"),"_TG|",(VLOOKUP(I94,Dictionary!$J:$K,2,0)),"_ST|",(VLOOKUP(J94,Dictionary!$M:$N,2,0)),"_TS|",SUBSTITUTE(SUBSTITUTE(IF(K94="","NONE",K94),"_","-"),"|","-"),"_SZ|",(VLOOKUP(L94,Dictionary!$Y:$Z,1,0)),"_AD|",(VLOOKUP(M94,Dictionary!$AB:$AC,2,0)),"_IT|",(VLOOKUP(N94,Dictionary!$BC:$BD,2,0)),IF(O94="","",CONCATENATE("_U1|",SUBSTITUTE(SUBSTITUTE(O94,"_","-"),"|","-"))),IF(P94="","",CONCATENATE("_U2|",SUBSTITUTE(SUBSTITUTE(P94,"_","-"),"|","-"))),IF(Q94="","",CONCATENATE("_U3|",SUBSTITUTE(SUBSTITUTE(Q94,"_","-"),"|","-"))))) -> #N/A
R95: =IF(K95="----","#N/A",CONCATENATE("MK|",(VLOOKUP(B95,Dictionary!$A:$B,2,0)),"_CH|",(VLOOKUP(C95,Dictionary!$AV:$AW,2,0)),"_DT|",(VLOOKUP(D95,Dictionary!$P:$Q,2,0)),"_PB|",(VLOOKUP(E95,Dictionary!$G:$H,2,0)),"_FM|",(VLOOKUP(F95,Dictionary!$S:$T,2,0)),"_RT|",(VLOOKUP(G95,Dictionary!$V:$W,2,0)),"_PD|",SUBSTITUTE(SUBSTITUTE(IF(H95="","NONE",H95),"_","-"),"|","-"),"_TG|",(VLOOKUP(I95,Dictionary!$J:$K,2,0)),"_ST|",(VLOOKUP(J95,Dictionary!$M:$N,2,0)),"_TS|",SUBSTITUTE(SUBSTITUTE(IF(K95="","NONE",K95),"_","-"),"|","-"),"_SZ|",(VLOOKUP(L95,Dictionary!$Y:$Z,1,0)),"_AD|",(VLOOKUP(M95,Dictionary!$AB:$AC,2,0)),"_IT|",(VLOOKUP(N95,Dictionary!$BC:$BD,2,0)),IF(O95="","",CONCATENATE("_U1|",SUBSTITUTE(SUBSTITUTE(O95,"_","-"),"|","-"))),IF(P95="","",CONCATENATE("_U2|",SUBSTITUTE(SUBSTITUTE(P95,"_","-"),"|","-"))),IF(Q95="","",CONCATENATE("_U3|",SUBSTITUTE(SUBSTITUTE(Q95,"_","-"),"|","-"))))) -> #N/A
R96: =IF(K96="----","#N/A",CONCATENATE("MK|",(VLOOKUP(B96,Dictionary!$A:$B,2,0)),"_CH|",(VLOOKUP(C96,Dictionary!$AV:$AW,2,0)),"_DT|",(VLOOKUP(D96,Dictionary!$P:$Q,2,0)),"_PB|",(VLOOKUP(E96,Dictionary!$G:$H,2,0)),"_FM|",(VLOOKUP(F96,Dictionary!$S:$T,2,0)),"_RT|",(VLOOKUP(G96,Dictionary!$V:$W,2,0)),"_PD|",SUBSTITUTE(SUBSTITUTE(IF(H96="","NONE",H96),"_","-"),"|","-"),"_TG|",(VLOOKUP(I96,Dictionary!$J:$K,2,0)),"_ST|",(VLOOKUP(J96,Dictionary!$M:$N,2,0)),"_TS|",SUBSTITUTE(SUBSTITUTE(IF(K96="","NONE",K96),"_","-"),"|","-"),"_SZ|",(VLOOKUP(L96,Dictionary!$Y:$Z,1,0)),"_AD|",(VLOOKUP(M96,Dictionary!$AB:$AC,2,0)),"_IT|",(VLOOKUP(N96,Dictionary!$BC:$BD,2,0)),IF(O96="","",CONCATENATE("_U1|",SUBSTITUTE(SUBSTITUTE(O96,"_","-"),"|","-"))),IF(P96="","",CONCATENATE("_U2|",SUBSTITUTE(SUBSTITUTE(P96,"_","-"),"|","-"))),IF(Q96="","",CONCATENATE("_U3|",SUBSTITUTE(SUBSTITUTE(Q96,"_","-"),"|","-"))))) -> #N/A
R97: =IF(K97="----","#N/A",CONCATENATE("MK|",(VLOOKUP(B97,Dictionary!$A:$B,2,0)),"_CH|",(VLOOKUP(C97,Dictionary!$AV:$AW,2,0)),"_DT|",(VLOOKUP(D97,Dictionary!$P:$Q,2,0)),"_PB|",(VLOOKUP(E97,Dictionary!$G:$H,2,0)),"_FM|",(VLOOKUP(F97,Dictionary!$S:$T,2,0)),"_RT|",(VLOOKUP(G97,Dictionary!$V:$W,2,0)),"_PD|",SUBSTITUTE(SUBSTITUTE(IF(H97="","NONE",H97),"_","-"),"|","-"),"_TG|",(VLOOKUP(I97,Dictionary!$J:$K,2,0)),"_ST|",(VLOOKUP(J97,Dictionary!$M:$N,2,0)),"_TS|",SUBSTITUTE(SUBSTITUTE(IF(K97="","NONE",K97),"_","-"),"|","-"),"_SZ|",(VLOOKUP(L97,Dictionary!$Y:$Z,1,0)),"_AD|",(VLOOKUP(M97,Dictionary!$AB:$AC,2,0)),"_IT|",(VLOOKUP(N97,Dictionary!$BC:$BD,2,0)),IF(O97="","",CONCATENATE("_U1|",SUBSTITUTE(SUBSTITUTE(O97,"_","-"),"|","-"))),IF(P97="","",CONCATENATE("_U2|",SUBSTITUTE(SUBSTITUTE(P97,"_","-"),"|","-"))),IF(Q97="","",CONCATENATE("_U3|",SUBSTITUTE(SUBSTITUTE(Q97,"_","-"),"|","-"))))) -> #N/A
R98: =IF(K98="----","#N/A",CONCATENATE("MK|",(VLOOKUP(B98,Dictionary!$A:$B,2,0)),"_CH|",(VLOOKUP(C98,Dictionary!$AV:$AW,2,0)),"_DT|",(VLOOKUP(D98,Dictionary!$P:$Q,2,0)),"_PB|",(VLOOKUP(E98,Dictionary!$G:$H,2,0)),"_FM|",(VLOOKUP(F98,Dictionary!$S:$T,2,0)),"_RT|",(VLOOKUP(G98,Dictionary!$V:$W,2,0)),"_PD|",SUBSTITUTE(SUBSTITUTE(IF(H98="","NONE",H98),"_","-"),"|","-"),"_TG|",(VLOOKUP(I98,Dictionary!$J:$K,2,0)),"_ST|",(VLOOKUP(J98,Dictionary!$M:$N,2,0)),"_TS|",SUBSTITUTE(SUBSTITUTE(IF(K98="","NONE",K98),"_","-"),"|","-"),"_SZ|",(VLOOKUP(L98,Dictionary!$Y:$Z,1,0)),"_AD|",(VLOOKUP(M98,Dictionary!$AB:$AC,2,0)),"_IT|",(VLOOKUP(N98,Dictionary!$BC:$BD,2,0)),IF(O98="","",CONCATENATE("_U1|",SUBSTITUTE(SUBSTITUTE(O98,"_","-"),"|","-"))),IF(P98="","",CONCATENATE("_U2|",SUBSTITUTE(SUBSTITUTE(P98,"_","-"),"|","-"))),IF(Q98="","",CONCATENATE("_U3|",SUBSTITUTE(SUBSTITUTE(Q98,"_","-"),"|","-"))))) -> #N/A
R99: =IF(K99="----","#N/A",CONCATENATE("MK|",(VLOOKUP(B99,Dictionary!$A:$B,2,0)),"_CH|",(VLOOKUP(C99,Dictionary!$AV:$AW,2,0)),"_DT|",(VLOOKUP(D99,Dictionary!$P:$Q,2,0)),"_PB|",(VLOOKUP(E99,Dictionary!$G:$H,2,0)),"_FM|",(VLOOKUP(F99,Dictionary!$S:$T,2,0)),"_RT|",(VLOOKUP(G99,Dictionary!$V:$W,2,0)),"_PD|",SUBSTITUTE(SUBSTITUTE(IF(H99="","NONE",H99),"_","-"),"|","-"),"_TG|",(VLOOKUP(I99,Dictionary!$J:$K,2,0)),"_ST|",(VLOOKUP(J99,Dictionary!$M:$N,2,0)),"_TS|",SUBSTITUTE(SUBSTITUTE(IF(K99="","NONE",K99),"_","-"),"|","-"),"_SZ|",(VLOOKUP(L99,Dictionary!$Y:$Z,1,0)),"_AD|",(VLOOKUP(M99,Dictionary!$AB:$AC,2,0)),"_IT|",(VLOOKUP(N99,Dictionary!$BC:$BD,2,0)),IF(O99="","",CONCATENATE("_U1|",SUBSTITUTE(SUBSTITUTE(O99,"_","-"),"|","-"))),IF(P99="","",CONCATENATE("_U2|",SUBSTITUTE(SUBSTITUTE(P99,"_","-"),"|","-"))),IF(Q99="","",CONCATENATE("_U3|",SUBSTITUTE(SUBSTITUTE(Q99,"_","-"),"|","-"))))) -> #N/A
... R347: =IF(K347="----","#N/A",CONCATENATE("MK|",(VLOOKUP(B347,Dictionary!$A:$B,2,0)),"_CH|",(VLOOKUP(C347,Dictionary!$AV:$AW,2,0)),"_DT|",(VLOOKUP(D347,Dictionary!$P:$Q,2,0)),"_PB|",(VLOOKUP(E347,Dictionary!$G:$H,2,0)),"_FM|",(VLOOKUP(F347,Dictionary!$S:$T,2,0)),"_RT|",(VLOOKUP(G347,Dictionary!$V:$W,2,0)),"_PD|",SUBSTITUTE(SUBSTITUTE(IF(H347="","NONE",H347),"_","-"),"|","-"),"_TG|",(VLOOKUP(I347,Dictionary!$J:$K,2,0)),"_ST|",(VLOOKUP(J347,Dictionary!$M:$N,2,0)),"_TS|",SUBSTITUTE(SUBSTITUTE(IF(K347="","NONE",K347),"_","-"),"|","-"),"_SZ|",(VLOOKUP(L347,Dictionary!$Y:$Z,1,0)),"_AD|",(VLOOKUP(M347,Dictionary!$AB:$AC,2,0)),"_IT|",(VLOOKUP(N347,Dictionary!$BC:$BD,2,0)),IF(O347="","",CONCATENATE("_U1|",SUBSTITUTE(SUBSTITUTE(O347,"_","-"),"|","-"))),IF(P347="","",CONCATENATE("_U2|",SUBSTITUTE(SUBSTITUTE(P347,"_","-"),"|","-"))),IF(Q347="","",CONCATENATE("_U3|",SUBSTITUTE(SUBSTITUTE(Q347,"_","-"),"|","-"))))) -> #N/A

Sheet Placement (DCM)
B1: Mandatory Fields | O1: Optional Fields
A2: ID | B2: Country (List) | C2: Media Channel | D2: Device(List) | E2: Publisher(List) | F2: Placement Type(List) | G2: Placement Rate Type(List) | H2: Placement Description(FF) | I2: Primary Target (List) | J2: Secondary Target (List) | K2: Target Description (FF) | L2: Placement Execution Size(List) | M2: Serving Method (List) | N2: Inventory Type (List) | O2: U1 | P2: U2 | Q2: U3
B3: Brazil | C3: Programmatic Display | D3: Mobile Web + In-App | E3: Verizon | F3: Native Display | G3: Cost per Thousand | H3: DOTZ-10MIL | I3: None | J3: None | L3: 627x627 | M3: Site-Served w/ DCM Tracking | N3: Owned & Operated | R3: =IF(K3="----","#N/A",CONCATENATE("MK|",(VLOOKUP(B3,Dictionary!$A:$B,2,0)),"_CH|",(VLOOKUP(C3,Dictionary!$AV:$AW,2,0)),"_DT|",(VLOOKUP(D3,Dictionary!$P:$Q,2,0)),"_PB|",(VLOOKUP(E3,Dictionary!$G:$H,2,0)),"_FM|",(VLOOKUP(F3,Dictionary!$S:$T,2,0)),"_RT|",(VLOOKUP(G3,Dictionary!$V:$W,2,0)),"_PD|",SUBSTITUTE(SUBSTITUTE(IF(H3="","NONE",H3),"_","-"),"|","-"),"_TG|",(VLOOKUP(I3,Dictionary!$J:$K,2,0)),"_ST|",(VLOOKUP(J3,Dictionary!$M:$N,2,0)),"_TS|",SUBSTITUTE(SUBSTITUTE(IF(K3="","NONE",K3),"_","-"),"|","-"),"_SZ|",(VLOOKUP(L3,Dictionary!$Y:$Z,1,0)),"_AD|",(VLOOKUP(M3,Dictionary!$AB:$AC,2,0)),"_IT|",(VLOOKUP(N3,Dictionary!$BC:$BD,2,0)),IF(O3="","",CONCATENATE("_U1|",SUBSTITUTE(SUBSTITUTE(O3,"_","-"),"|","-"))),IF(P3="","",CONCATENATE("_U2|",SUBSTITUTE(SUBSTITUTE(P3,"_","-"),"|","-"))),IF(Q3="","",CONCATENATE("_U3|",SUBSTITUTE(SUBSTITUTE(Q3,"_","-"),"|","-"))))) -> MK|BR_CH|PD_DT|MWIA_PB|VER_FM|NAT_RT|CPM_PD|DOTZ-10MIL_TG|NON_ST|NON_TS|NONE_SZ|627x627_AD|CM1_IT|OO
B4: Brazil | C4: Programmatic Display | D4: Cross Device/ Screen | E4: Verizon | F4: Native Display | G4: Cost per Thousand | H4: DOTZ-TAXA-ZERO | I4: None | J4: None | L4: 627x627 | M4: Site-Served w/ DCM Tracking | N4: Owned & Operated | R4: =IF(K4="----","#N/A",CONCATENATE("MK|",(VLOOKUP(B4,Dictionary!$A:$B,2,0)),"_CH|",(VLOOKUP(C4,Dictionary!$AV:$AW,2,0)),"_DT|",(VLOOKUP(D4,Dictionary!$P:$Q,2,0)),"_PB|",(VLOOKUP(E4,Dictionary!$G:$H,2,0)),"_FM|",(VLOOKUP(F4,Dictionary!$S:$T,2,0)),"_RT|",(VLOOKUP(G4,Dictionary!$V:$W,2,0)),"_PD|",SUBSTITUTE(SUBSTITUTE(IF(H4="","NONE",H4),"_","-"),"|","-"),"_TG|",(VLOOKUP(I4,Dictionary!$J:$K,2,0)),"_ST|",(VLOOKUP(J4,Dictionary!$M:$N,2,0)),"_TS|",SUBSTITUTE(SUBSTITUTE(IF(K4="","NONE",K4),"_","-"),"|","-"),"_SZ|",(VLOOKUP(L4,Dictionary!$Y:$Z,1,0)),"_AD|",(VLOOKUP(M4,Dictionary!$AB:$AC,2,0)),"_IT|",(VLOOKUP(N4,Dictionary!$BC:$BD,2,0)),IF(O4="","",CONCATENATE("_U1|",SUBSTITUTE(SUBSTITUTE(O4,"_","-"),"|","-"))),IF(P4="","",CONCATENATE("_U2|",SUBSTITUTE(SUBSTITUTE(P4,"_","-"),"|","-"))),IF(Q4="","",CONCATENATE("_U3|",SUBSTITUTE(SUBSTITUTE(Q4,"_","-"),"|","-"))))) -> MK|BR_CH|PD_DT|CROSS_PB|VER_FM|NAT_RT|CPM_PD|DOTZ-TAXA-ZERO_TG|NON_ST|NON_TS|NONE_SZ|627x627_AD|CM1_IT|OO
B5: Brazil | C5: Paid Social Display | D5: Cross Device/ Screen | E5: Facebook | F5: Link Ad | G5: Cost per Thousand | H5: DOTZ-10MIL-AZUL | I5: None | J5: None | L5: 1X1 | M5: Site-Served w/ DCM Tracking | N5: Social | R5: =IF(K5="----","#N/A",CONCATENATE("MK|",(VLOOKUP(B5,Dictionary!$A:$B,2,0)),"_CH|",(VLOOKUP(C5,Dictionary!$AV:$AW,2,0)),"_DT|",(VLOOKUP(D5,Dictionary!$P:$Q,2,0)),"_PB|",(VLOOKUP(E5,Dictionary!$G:$H,2,0)),"_FM|",(VLOOKUP(F5,Dictionary!$S:$T,2,0)),"_RT|",(VLOOKUP(G5,Dictionary!$V:$W,2,0)),"_PD|",SUBSTITUTE(SUBSTITUTE(IF(H5="","NONE",H5),"_","-"),"|","-"),"_TG|",(VLOOKUP(I5,Dictionary!$J:$K,2,0)),"_ST|",(VLOOKUP(J5,Dictionary!$M:$N,2,0)),"_TS|",SUBSTITUTE(SUBSTITUTE(IF(K5="","NONE",K5),"_","-"),"|","-"),"_SZ|",(VLOOKUP(L5,Dictionary!$Y:$Z,1,0)),"_AD|",(VLOOKUP(M5,Dictionary!$AB:$AC,2,0)),"_IT|",(VLOOKUP(N5,Dictionary!$BC:$BD,2,0)),IF(O5="","",CONCATENATE("_U1|",SUBSTITUTE(SUBSTITUTE(O5,"_","-"),"|","-"))),IF(P5="","",CONCATENATE("_U2|",SUBSTITUTE(SUBSTITUTE(P5,"_","-"),"|","-"))),IF(Q5="","",CONCATENATE("_U3|",SUBSTITUTE(SUBSTITUTE(Q5,"_","-"),"|","-"))))) -> MK|BR_CH|PSD_DT|CROSS_PB|FCBK_FM|LNK_RT|CPM_PD|DOTZ-10MIL-AZUL_TG|NON_ST|NON_TS|NONE_SZ|1X1_AD|CM1_IT|SOC
B6: Brazil | C6: Paid Social Display | D6: Cross Device/ Screen | E6: Facebook | F6: Link Ad | G6: Cost per Thousand | H6: DOTZ-10MIL-AZUL-QUAD | I6: None | J6: None | L6: 1X1 | M6: Site-Served w/ DCM Tracking | N6: Social | R6: =IF(K6="----","#N/A",CONCATENATE("MK|",(VLOOKUP(B6,Dictionary!$A:$B,2,0)),"_CH|",(VLOOKUP(C6,Dictionary!$AV:$AW,2,0)),"_DT|",(VLOOKUP(D6,Dictionary!$P:$Q,2,0)),"_PB|",(VLOOKUP(E6,Dictionary!$G:$H,2,0)),"_FM|",(VLOOKUP(F6,Dictionary!$S:$T,2,0)),"_RT|",(VLOOKUP(G6,Dictionary!$V:$W,2,0)),"_PD|",SUBSTITUTE(SUBSTITUTE(IF(H6="","NONE",H6),"_","-"),"|","-"),"_TG|",(VLOOKUP(I6,Dictionary!$J:$K,2,0)),"_ST|",(VLOOKUP(J6,Dictionary!$M:$N,2,0)),"_TS|",SUBSTITUTE(SUBSTITUTE(IF(K6="","NONE",K6),"_","-"),"|","-"),"_SZ|",(VLOOKUP(L6,Dictionary!$Y:$Z,1,0)),"_AD|",(VLOOKUP(M6,Dictionary!$AB:$AC,2,0)),"_IT|",(VLOOKUP(N6,Dictionary!$BC:$BD,2,0)),IF(O6="","",CONCATENATE("_U1|",SUBSTITUTE(SUBSTITUTE(O6,"_","-"),"|","-"))),IF(P6="","",CONCATENATE("_U2|",SUBSTITUTE(SUBSTITUTE(P6,"_","-"),"|","-"))),IF(Q6="","",CONCATENATE("_U3|",SUBSTITUTE(SUBSTITUTE(Q6,"_","-"),"|","-"))))) -> MK|BR_CH|PSD_DT|CROSS_PB|FCBK_FM|LNK_RT|CPM_PD|DOTZ-10MIL-AZUL-QUAD_TG|NON_ST|NON_TS|NONE_SZ|1X1_AD|CM1_IT|SOC
B7: Brazil | C7: Paid Social Display | D7: Cross Device/ Screen | E7: Facebook | F7: GIF | G7: Cost per Thousand | H7: DOTZ-10MIL-AZUL | I7: None | J7: None | L7: 1X1 | M7: Site-Served w/ DCM Tracking | N7: Social | R7: =IF(K7="----","#N/A",CONCATENATE("MK|",(VLOOKUP(B7,Dictionary!$A:$B,2,0)),"_CH|",(VLOOKUP(C7,Dictionary!$AV:$AW,2,0)),"_DT|",(VLOOKUP(D7,Dictionary!$P:$Q,2,0)),"_PB|",(VLOOKUP(E7,Dictionary!$G:$H,2,0)),"_FM|",(VLOOKUP(F7,Dictionary!$S:$T,2,0)),"_RT|",(VLOOKUP(G7,Dictionary!$V:$W,2,0)),"_PD|",SUBSTITUTE(SUBSTITUTE(IF(H7="","NONE",H7),"_","-"),"|","-"),"_TG|",(VLOOKUP(I7,Dictionary!$J:$K,2,0)),"_ST|",(VLOOKUP(J7,Dictionary!$M:$N,2,0)),"_TS|",SUBSTITUTE(SUBSTITUTE(IF(K7="","NONE",K7),"_","-"),"|","-"),"_SZ|",(VLOOKUP(L7,Dictionary!$Y:$Z,1,0)),"_AD|",(VLOOKUP(M7,Dictionary!$AB:$AC,2,0)),"_IT|",(VLOOKUP(N7,Dictionary!$BC:$BD,2,0)),IF(O7="","",CONCATENATE("_U1|",SUBSTITUTE(SUBSTITUTE(O7,"_","-"),"|","-"))),IF(P7="","",CONCATENATE("_U2|",SUBSTITUTE(SUBSTITUTE(P7,"_","-"),"|","-"))),IF(Q7="","",CONCATENATE("_U3|",SUBSTITUTE(SUBSTITUTE(Q7,"_","-"),"|","-"))))) -> MK|BR_CH|PSD_DT|CROSS_PB|FCBK_FM|GIF_RT|CPM_PD|DOTZ-10MIL-AZUL_TG|NON_ST|NON_TS|NONE_SZ|1X1_AD|CM1_IT|SOC
B8: Brazil | C8: Paid Social Display | D8: Cross Device/ Screen | E8: Facebook | F8: Carousel | G8: Cost per Thousand | H8: DOTZ-10MIL-AZUL | I8: None | J8: None | L8: 1X1 | M8: Site-Served w/ DCM Tracking | N8: Social | R8: =IF(K8="----","#N/A",CONCATENATE("MK|",(VLOOKUP(B8,Dictionary!$A:$B,2,0)),"_CH|",(VLOOKUP(C8,Dictionary!$AV:$AW,2,0)),"_DT|",(VLOOKUP(D8,Dictionary!$P:$Q,2,0)),"_PB|",(VLOOKUP(E8,Dictionary!$G:$H,2,0)),"_FM|",(VLOOKUP(F8,Dictionary!$S:$T,2,0)),"_RT|",(VLOOKUP(G8,Dictionary!$V:$W,2,0)),"_PD|",SUBSTITUTE(SUBSTITUTE(IF(H8="","NONE",H8),"_","-"),"|","-"),"_TG|",(VLOOKUP(I8,Dictionary!$J:$K,2,0)),"_ST|",(VLOOKUP(J8,Dictionary!$M:$N,2,0)),"_TS|",SUBSTITUTE(SUBSTITUTE(IF(K8="","NONE",K8),"_","-"),"|","-"),"_SZ|",(VLOOKUP(L8,Dictionary!$Y:$Z,1,0)),"_AD|",(VLOOKUP(M8,Dictionary!$AB:$AC,2,0)),"_IT|",(VLOOKUP(N8,Dictionary!$BC:$BD,2,0)),IF(O8="","",CONCATENATE("_U1|",SUBSTITUTE(SUBSTITUTE(O8,"_","-"),"|","-"))),IF(P8="","",CONCATENATE("_U2|",SUBSTITUTE(SUBSTITUTE(P8,"_","-"),"|","-"))),IF(Q8="","",CONCATENATE("_U3|",SUBSTITUTE(SUBSTITUTE(Q8,"_","-"),"|","-"))))) -> MK|BR_CH|PSD_DT|CROSS_PB|FCBK_FM|CAR_RT|CPM_PD|DOTZ-10MIL-AZUL_TG|NON_ST|NON_TS|NONE_SZ|1X1_AD|CM1_IT|SOC
B9: Brazil | C9: Paid Social Display | D9: Cross Device/ Screen | E9: Facebook | F9: Stories | G9: Cost per Thousand | H9: DOTZ-10MIL-AZUL-CAR | I9: None | J9: None | L9: 1X1 | M9: Site-Served w/ DCM Tracking | N9: Social | R9: =IF(K9="----","#N/A",CONCATENATE("MK|",(VLOOKUP(B9,Dictionary!$A:$B,2,0)),"_CH|",(VLOOKUP(C9,Dictionary!$AV:$AW,2,0)),"_DT|",(VLOOKUP(D9,Dictionary!$P:$Q,2,0)),"_PB|",(VLOOKUP(E9,Dictionary!$G:$H,2,0)),"_FM|",(VLOOKUP(F9,Dictionary!$S:$T,2,0)),"_RT|",(VLOOKUP(G9,Dictionary!$V:$W,2,0)),"_PD|",SUBSTITUTE(SUBSTITUTE(IF(H9="","NONE",H9),"_","-"),"|","-"),"_TG|",(VLOOKUP(I9,Dictionary!$J:$K,2,0)),"_ST|",(VLOOKUP(J9,Dictionary!$M:$N,2,0)),"_TS|",SUBSTITUTE(SUBSTITUTE(IF(K9="","NONE",K9),"_","-"),"|","-"),"_SZ|",(VLOOKUP(L9,Dictionary!$Y:$Z,1,0)),"_AD|",(VLOOKUP(M9,Dictionary!$AB:$AC,2,0)),"_IT|",(VLOOKUP(N9,Dictionary!$BC:$BD,2,0)),IF(O9="","",CONCATENATE("_U1|",SUBSTITUTE(SUBSTITUTE(O9,"_","-"),"|","-"))),IF(P9="","",CONCATENATE("_U2|",SUBSTITUTE(SUBSTITUTE(P9,"_","-"),"|","-"))),IF(Q9="","",CONCATENATE("_U3|",SUBSTITUTE(SUBSTITUTE(Q9,"_","-"),"|","-"))))) -> MK|BR_CH|PSD_DT|CROSS_PB|FCBK_FM|STRY_RT|CPM_PD|DOTZ-10MIL-AZUL-CAR_TG|NON_ST|NON_TS|NONE_SZ|1X1_AD|CM1_IT|SOC
B10: Brazil | C10: Paid Social Display | D10: Cross Device/ Screen | E10: Facebook | F10: Link Ad | G10: Cost per Thousand | H10: DOTZ-ZERO-ANUIDADE-AZUL | I10: None | J10: None | L10: 1X1 | M10: Site-Served w/ DCM Tracking | N10: Social | R10: =IF(K10="----","#N/A",CONCATENATE("MK|",(VLOOKUP(B10,Dictionary!$A:$B,2,0)),"_CH|",(VLOOKUP(C10,Dictionary!$AV:$AW,2,0)),"_DT|",(VLOOKUP(D10,Dictionary!$P:$Q,2,0)),"_PB|",(VLOOKUP(E10,Dictionary!$G:$H,2,0)),"_FM|",(VLOOKUP(F10,Dictionary!$S:$T,2,0)),"_RT|",(VLOOKUP(G10,Dictionary!$V:$W,2,0)),"_PD|",SUBSTITUTE(SUBSTITUTE(IF(H10="","NONE",H10),"_","-"),"|","-"),"_TG|",(VLOOKUP(I10,Dictionary!$J:$K,2,0)),"_ST|",(VLOOKUP(J10,Dictionary!$M:$N,2,0)),"_TS|",SUBSTITUTE(SUBSTITUTE(IF(K10="","NONE",K10),"_","-"),"|","-"),"_SZ|",(VLOOKUP(L10,Dictionary!$Y:$Z,1,0)),"_AD|",(VLOOKUP(M10,Dictionary!$AB:$AC,2,0)),"_IT|",(VLOOKUP(N10,Dictionary!$BC:$BD,2,0)),IF(O10="","",CONCATENATE("_U1|",SUBSTITUTE(SUBSTITUTE(O10,"_","-"),"|","-"))),IF(P10="","",CONCATENATE("_U2|",SUBSTITUTE(SUBSTITUTE(P10,"_","-"),"|","-"))),IF(Q10="","",CONCATENATE("_U3|",SUBSTITUTE(SUBSTITUTE(Q10,"_","-"),"|","-"))))) -> MK|BR_CH|PSD_DT|CROSS_PB|FCBK_FM|LNK_RT|CPM_PD|DOTZ-ZERO-ANUIDADE-AZUL_TG|NON_ST|NON_TS|NONE_SZ|1X1_AD|CM1_IT|SOC
B11: Brazil | C11: Paid Social Display | D11: Cross Device/ Screen | E11: Facebook | F11: Link Ad | G11: Cost per Thousand | H11: DOTZ-ZERO-ANUIDADE-AZUL-QUAD | I11: None | J11: None | L11: 1X1 | M11: Site-Served w/ DCM Tracking | N11: Social | R11: =IF(K11="----","#N/A",CONCATENATE("MK|",(VLOOKUP(B11,Dictionary!$A:$B,2,0)),"_CH|",(VLOOKUP(C11,Dictionary!$AV:$AW,2,0)),"_DT|",(VLOOKUP(D11,Dictionary!$P:$Q,2,0)),"_PB|",(VLOOKUP(E11,Dictionary!$G:$H,2,0)),"_FM|",(VLOOKUP(F11,Dictionary!$S:$T,2,0)),"_RT|",(VLOOKUP(G11,Dictionary!$V:$W,2,0)),"_PD|",SUBSTITUTE(SUBSTITUTE(IF(H11="","NONE",H11),"_","-"),"|","-"),"_TG|",(VLOOKUP(I11,Dictionary!$J:$K,2,0)),"_ST|",(VLOOKUP(J11,Dictionary!$M:$N,2,0)),"_TS|",SUBSTITUTE(SUBSTITUTE(IF(K11="","NONE",K11),"_","-"),"|","-"),"_SZ|",(VLOOKUP(L11,Dictionary!$Y:$Z,1,0)),"_AD|",(VLOOKUP(M11,Dictionary!$AB:$AC,2,0)),"_IT|",(VLOOKUP(N11,Dictionary!$BC:$BD,2,0)),IF(O11="","",CONCATENATE("_U1|",SUBSTITUTE(SUBSTITUTE(O11,"_","-"),"|","-"))),IF(P11="","",CONCATENATE("_U2|",SUBSTITUTE(SUBSTITUTE(P11,"_","-"),"|","-"))),IF(Q11="","",CONCATENATE("_U3|",SUBSTITUTE(SUBSTITUTE(Q11,"_","-"),"|","-"))))) -> MK|BR_CH|PSD_DT|CROSS_PB|FCBK_FM|LNK_RT|CPM_PD|DOTZ-ZERO-ANUIDADE-AZUL-QUAD_TG|NON_ST|NON_TS|NONE_SZ|1X1_AD|CM1_IT|SOC
B12: Brazil | C12: Paid Social Display | D12: Cross Device/ Screen | E12: Facebook | F12: GIF | G12: Cost per Thousand | H12: DOTZ-ZERO-ANUIDADE-AZUL | I12: None | J12: None | L12: 1X1 | M12: Site-Served w/ DCM Tracking | N12: Social | R12: =IF(K12="----","#N/A",CONCATENATE("MK|",(VLOOKUP(B12,Dictionary!$A:$B,2,0)),"_CH|",(VLOOKUP(C12,Dictionary!$AV:$AW,2,0)),"_DT|",(VLOOKUP(D12,Dictionary!$P:$Q,2,0)),"_PB|",(VLOOKUP(E12,Dictionary!$G:$H,2,0)),"_FM|",(VLOOKUP(F12,Dictionary!$S:$T,2,0)),"_RT|",(VLOOKUP(G12,Dictionary!$V:$W,2,0)),"_PD|",SUBSTITUTE(SUBSTITUTE(IF(H12="","NONE",H12),"_","-"),"|","-"),"_TG|",(VLOOKUP(I12,Dictionary!$J:$K,2,0)),"_ST|",(VLOOKUP(J12,Dictionary!$M:$N,2,0)),"_TS|",SUBSTITUTE(SUBSTITUTE(IF(K12="","NONE",K12),"_","-"),"|","-"),"_SZ|",(VLOOKUP(L12,Dictionary!$Y:$Z,1,0)),"_AD|",(VLOOKUP(M12,Dictionary!$AB:$AC,2,0)),"_IT|",(VLOOKUP(N12,Dictionary!$BC:$BD,2,0)),IF(O12="","",CONCATENATE("_U1|",SUBSTITUTE(SUBSTITUTE(O12,"_","-"),"|","-"))),IF(P12="","",CONCATENATE("_U2|",SUBSTITUTE(SUBSTITUTE(P12,"_","-"),"|","-"))),IF(Q12="","",CONCATENATE("_U3|",SUBSTITUTE(SUBSTITUTE(Q12,"_","-"),"|","-"))))) -> MK|BR_CH|PSD_DT|CROSS_PB|FCBK_FM|GIF_RT|CPM_PD|DOTZ-ZERO-ANUIDADE-AZUL_TG|NON_ST|NON_TS|NONE_SZ|1X1_AD|CM1_IT|SOC
B13: Brazil | C13: Paid Social Display | D13: Cross Device/ Screen | E13: Facebook | F13: Carousel | G13: Cost per Thousand | H13: DOTZ-ZERO-ANUIDADE-AZUL | I13: None | J13: None | L13: 1X1 | M13: Site-Served w/ DCM Tracking | N13: Social | R13: =IF(K13="----","#N/A",CONCATENATE("MK|",(VLOOKUP(B13,Dictionary!$A:$B,2,0)),"_CH|",(VLOOKUP(C13,Dictionary!$AV:$AW,2,0)),"_DT|",(VLOOKUP(D13,Dictionary!$P:$Q,2,0)),"_PB|",(VLOOKUP(E13,Dictionary!$G:$H,2,0)),"_FM|",(VLOOKUP(F13,Dictionary!$S:$T,2,0)),"_RT|",(VLOOKUP(G13,Dictionary!$V:$W,2,0)),"_PD|",SUBSTITUTE(SUBSTITUTE(IF(H13="","NONE",H13),"_","-"),"|","-"),"_TG|",(VLOOKUP(I13,Dictionary!$J:$K,2,0)),"_ST|",(VLOOKUP(J13,Dictionary!$M:$N,2,0)),"_TS|",SUBSTITUTE(SUBSTITUTE(IF(K13="","NONE",K13),"_","-"),"|","-"),"_SZ|",(VLOOKUP(L13,Dictionary!$Y:$Z,1,0)),"_AD|",(VLOOKUP(M13,Dictionary!$AB:$AC,2,0)),"_IT|",(VLOOKUP(N13,Dictionary!$BC:$BD,2,0)),IF(O13="","",CONCATENATE("_U1|",SUBSTITUTE(SUBSTITUTE(O13,"_","-"),"|","-"))),IF(P13="","",CONCATENATE("_U2|",SUBSTITUTE(SUBSTITUTE(P13,"_","-"),"|","-"))),IF(Q13="","",CONCATENATE("_U3|",SUBSTITUTE(SUBSTITUTE(Q13,"_","-"),"|","-"))))) -> MK|BR_CH|PSD_DT|CROSS_PB|FCBK_FM|CAR_RT|CPM_PD|DOTZ-ZERO-ANUIDADE-AZUL_TG|NON_ST|NON_TS|NONE_SZ|1X1_AD|CM1_IT|SOC
B14: Brazil | C14: Paid Social Display | D14: Cross Device/ Screen | E14: Facebook | F14: Stories | G14: Cost per Thousand | H14: DOTZ-ZERO-ANUIDADE-AZUL-CAR | I14: None | J14: None | L14: 1X1 | M14: Site-Served w/ DCM Tracking | N14: Social | R14: =IF(K14="----","#N/A",CONCATENATE("MK|",(VLOOKUP(B14,Dictionary!$A:$B,2,0)),"_CH|",(VLOOKUP(C14,Dictionary!$AV:$AW,2,0)),"_DT|",(VLOOKUP(D14,Dictionary!$P:$Q,2,0)),"_PB|",(VLOOKUP(E14,Dictionary!$G:$H,2,0)),"_FM|",(VLOOKUP(F14,Dictionary!$S:$T,2,0)),"_RT|",(VLOOKUP(G14,Dictionary!$V:$W,2,0)),"_PD|",SUBSTITUTE(SUBSTITUTE(IF(H14="","NONE",H14),"_","-"),"|","-"),"_TG|",(VLOOKUP(I14,Dictionary!$J:$K,2,0)),"_ST|",(VLOOKUP(J14,Dictionary!$M:$N,2,0)),"_TS|",SUBSTITUTE(SUBSTITUTE(IF(K14="","NONE",K14),"_","-"),"|","-"),"_SZ|",(VLOOKUP(L14,Dictionary!$Y:$Z,1,0)),"_AD|",(VLOOKUP(M14,Dictionary!$AB:$AC,2,0)),"_IT|",(VLOOKUP(N14,Dictionary!$BC:$BD,2,0)),IF(O14="","",CONCATENATE("_U1|",SUBSTITUTE(SUBSTITUTE(O14,"_","-"),"|","-"))),IF(P14="","",CONCATENATE("_U2|",SUBSTITUTE(SUBSTITUTE(P14,"_","-"),"|","-"))),IF(Q14="","",CONCATENATE("_U3|",SUBSTITUTE(SUBSTITUTE(Q14,"_","-"),"|","-"))))) -> MK|BR_CH|PSD_DT|CROSS_PB|FCBK_FM|STRY_RT|CPM_PD|DOTZ-ZERO-ANUIDADE-AZUL-CAR_TG|NON_ST|NON_TS|NONE_SZ|1X1_AD|CM1_IT|SOC
... B46: Brazil | C46: Paid Social Display | D46: Cross Device/ Screen | E46: Facebook | F46: Stories | G46: Cost per Thousand | H46: DOTZ-10MIL-AZUL | I46: None | J46: None | L46: 1X1 | M46: Site-Served w/ DCM Tracking | N46: Social | R46: =IF(K46="----","#N/A",CONCATENATE("MK|",(VLOOKUP(B46,Dictionary!$A:$B,2,0)),"_CH|",(VLOOKUP(C46,Dictionary!$AV:$AW,2,0)),"_DT|",(VLOOKUP(D46,Dictionary!$P:$Q,2,0)),"_PB|",(VLOOKUP(E46,Dictionary!$G:$H,2,0)),"_FM|",(VLOOKUP(F46,Dictionary!$S:$T,2,0)),"_RT|",(VLOOKUP(G46,Dictionary!$V:$W,2,0)),"_PD|",SUBSTITUTE(SUBSTITUTE(IF(H46="","NONE",H46),"_","-"),"|","-"),"_TG|",(VLOOKUP(I46,Dictionary!$J:$K,2,0)),"_ST|",(VLOOKUP(J46,Dictionary!$M:$N,2,0)),"_TS|",SUBSTITUTE(SUBSTITUTE(IF(K46="","NONE",K46),"_","-"),"|","-"),"_SZ|",(VLOOKUP(L46,Dictionary!$Y:$Z,1,0)),"_AD|",(VLOOKUP(M46,Dictionary!$AB:$AC,2,0)),"_IT|",(VLOOKUP(N46,Dictionary!$BC:$BD,2,0)),IF(O46="","",CONCATENATE("_U1|",SUBSTITUTE(SUBSTITUTE(O46,"_","-"),"|","-"))),IF(P46="","",CONCATENATE("_U2|",SUBSTITUTE(SUBSTITUTE(P46,"_","-"),"|","-"))),IF(Q46="","",CONCATENATE("_U3|",SUBSTITUTE(SUBSTITUTE(Q46,"_","-"),"|","-"))))) -> MK|BR_CH|PSD_DT|CROSS_PB|FCBK_FM|STRY_RT|CPM_PD|DOTZ-10MIL-AZUL_TG|NON_ST|NON_TS|NONE_SZ|1X1_AD|CM1_IT|SOC
B47: Brazil | C47: Paid Social Display | D47: Cross Device/ Screen | E47: Facebook | F47: Carousel | G47: Cost per Thousand | H47: DOTZ-10MIL-AZUL | I47: None | J47: None | L47: 1X1 | M47: Site-Served w/ DCM Tracking | N47: Social | O47: ESTATICO | R47: =IF(K47="----","#N/A",CONCATENATE("MK|",(VLOOKUP(B47,Dictionary!$A:$B,2,0)),"_CH|",(VLOOKUP(C47,Dictionary!$AV:$AW,2,0)),"_DT|",(VLOOKUP(D47,Dictionary!$P:$Q,2,0)),"_PB|",(VLOOKUP(E47,Dictionary!$G:$H,2,0)),"_FM|",(VLOOKUP(F47,Dictionary!$S:$T,2,0)),"_RT|",(VLOOKUP(G47,Dictionary!$V:$W,2,0)),"_PD|",SUBSTITUTE(SUBSTITUTE(IF(H47="","NONE",H47),"_","-"),"|","-"),"_TG|",(VLOOKUP(I47,Dictionary!$J:$K,2,0)),"_ST|",(VLOOKUP(J47,Dictionary!$M:$N,2,0)),"_TS|",SUBSTITUTE(SUBSTITUTE(IF(K47="","NONE",K47),"_","-"),"|","-"),"_SZ|",(VLOOKUP(L47,Dictionary!$Y:$Z,1,0)),"_AD|",(VLOOKUP(M47,Dictionary!$AB:$AC,2,0)),"_IT|",(VLOOKUP(N47,Dictionary!$BC:$BD,2,0)),IF(O47="","",CONCATENATE("_U1|",SUBSTITUTE(SUBSTITUTE(O47,"_","-"),"|","-"))),IF(P47="","",CONCATENATE("_U2|",SUBSTITUTE(SUBSTITUTE(P47,"_","-"),"|","-"))),IF(Q47="","",CONCATENATE("_U3|",SUBSTITUTE(SUBSTITUTE(Q47,"_","-"),"|","-"))))) -> MK|BR_CH|PSD_DT|CROSS_PB|FCBK_FM|CAR_RT|CPM_PD|DOTZ-10MIL-AZUL_TG|NON_ST|NON_TS|NONE_SZ|1X1_AD|CM1_IT|SOC_U1|ESTATICO
B48: Brazil | C48: Paid Social Display | D48: Cross Device/ Screen | E48: Facebook | F48: Carousel | G48: Cost per Thousand | H48: DOTZ-ZERO-ANUIDADE-AZUL | I48: None | J48: None | L48: 1X1 | M48: Site-Served w/ DCM Tracking | N48: Social | O48: ESTATICO | R48: =IF(K48="----","#N/A",CONCATENATE("MK|",(VLOOKUP(B48,Dictionary!$A:$B,2,0)),"_CH|",(VLOOKUP(C48,Dictionary!$AV:$AW,2,0)),"_DT|",(VLOOKUP(D48,Dictionary!$P:$Q,2,0)),"_PB|",(VLOOKUP(E48,Dictionary!$G:$H,2,0)),"_FM|",(VLOOKUP(F48,Dictionary!$S:$T,2,0)),"_RT|",(VLOOKUP(G48,Dictionary!$V:$W,2,0)),"_PD|",SUBSTITUTE(SUBSTITUTE(IF(H48="","NONE",H48),"_","-"),"|","-"),"_TG|",(VLOOKUP(I48,Dictionary!$J:$K,2,0)),"_ST|",(VLOOKUP(J48,Dictionary!$M:$N,2,0)),"_TS|",SUBSTITUTE(SUBSTITUTE(IF(K48="","NONE",K48),"_","-"),"|","-"),"_SZ|",(VLOOKUP(L48,Dictionary!$Y:$Z,1,0)),"_AD|",(VLOOKUP(M48,Dictionary!$AB:$AC,2,0)),"_IT|",(VLOOKUP(N48,Dictionary!$BC:$BD,2,0)),IF(O48="","",CONCATENATE("_U1|",SUBSTITUTE(SUBSTITUTE(O48,"_","-"),"|","-"))),IF(P48="","",CONCATENATE("_U2|",SUBSTITUTE(SUBSTITUTE(P48,"_","-"),"|","-"))),IF(Q48="","",CONCATENATE("_U3|",SUBSTITUTE(SUBSTITUTE(Q48,"_","-"),"|","-"))))) -> MK|BR_CH|PSD_DT|CROSS_PB|FCBK_FM|CAR_RT|CPM_PD|DOTZ-ZERO-ANUIDADE-AZUL_TG|NON_ST|NON_TS|NONE_SZ|1X1_AD|CM1_IT|SOC_U1|ESTATICO
B49: Brazil | C49: Paid Social Display | D49: Cross Device/ Screen | E49: Facebook | F49: Carousel | G49: Cost per Thousand | H49: DOTZ-TODOS-BENEFICIOS-AZUL | I49: None | J49: None | L49: 1X1 | M49: Site-Served w/ DCM Tracking | N49: Social | O49: ESTATICO | R49: =IF(K49="----","#N/A",CONCATENATE("MK|",(VLOOKUP(B49,Dictionary!$A:$B,2,0)),"_CH|",(VLOOKUP(C49,Dictionary!$AV:$AW,2,0)),"_DT|",(VLOOKUP(D49,Dictionary!$P:$Q,2,0)),"_PB|",(VLOOKUP(E49,Dictionary!$G:$H,2,0)),"_FM|",(VLOOKUP(F49,Dictionary!$S:$T,2,0)),"_RT|",(VLOOKUP(G49,Dictionary!$V:$W,2,0)),"_PD|",SUBSTITUTE(SUBSTITUTE(IF(H49="","NONE",H49),"_","-"),"|","-"),"_TG|",(VLOOKUP(I49,Dictionary!$J:$K,2,0)),"_ST|",(VLOOKUP(J49,Dictionary!$M:$N,2,0)),"_TS|",SUBSTITUTE(SUBSTITUTE(IF(K49="","NONE",K49),"_","-"),"|","-"),"_SZ|",(VLOOKUP(L49,Dictionary!$Y:$Z,1,0)),"_AD|",(VLOOKUP(M49,Dictionary!$AB:$AC,2,0)),"_IT|",(VLOOKUP(N49,Dictionary!$BC:$BD,2,0)),IF(O49="","",CONCATENATE("_U1|",SUBSTITUTE(SUBSTITUTE(O49,"_","-"),"|","-"))),IF(P49="","",CONCATENATE("_U2|",SUBSTITUTE(SUBSTITUTE(P49,"_","-"),"|","-"))),IF(Q49="","",CONCATENATE("_U3|",SUBSTITUTE(SUBSTITUTE(Q49,"_","-"),"|","-"))))) -> MK|BR_CH|PSD_DT|CROSS_PB|FCBK_FM|CAR_RT|CPM_PD|DOTZ-TODOS-BENEFICIOS-AZUL_TG|NON_ST|NON_TS|NONE_SZ|1X1_AD|CM1_IT|SOC_U1|ESTATICO
B50: Brazil | C50: Paid Social Display | D50: Cross Device/ Screen | E50: Facebook | F50: Carousel | G50: Cost per Thousand | H50: DOTZ-10MIL-AMARELO | I50: None | J50: None | L50: 1X1 | M50: Site-Served w/ DCM Tracking | N50: Social | O50: ESTATICO | R50: =IF(K50="----","#N/A",CONCATENATE("MK|",(VLOOKUP(B50,Dictionary!$A:$B,2,0)),"_CH|",(VLOOKUP(C50,Dictionary!$AV:$AW,2,0)),"_DT|",(VLOOKUP(D50,Dictionary!$P:$Q,2,0)),"_PB|",(VLOOKUP(E50,Dictionary!$G:$H,2,0)),"_FM|",(VLOOKUP(F50,Dictionary!$S:$T,2,0)),"_RT|",(VLOOKUP(G50,Dictionary!$V:$W,2,0)),"_PD|",SUBSTITUTE(SUBSTITUTE(IF(H50="","NONE",H50),"_","-"),"|","-"),"_TG|",(VLOOKUP(I50,Dictionary!$J:$K,2,0)),"_ST|",(VLOOKUP(J50,Dictionary!$M:$N,2,0)),"_TS|",SUBSTITUTE(SUBSTITUTE(IF(K50="","NONE",K50),"_","-"),"|","-"),"_SZ|",(VLOOKUP(L50,Dictionary!$Y:$Z,1,0)),"_AD|",(VLOOKUP(M50,Dictionary!$AB:$AC,2,0)),"_IT|",(VLOOKUP(N50,Dictionary!$BC:$BD,2,0)),IF(O50="","",CONCATENATE("_U1|",SUBSTITUTE(SUBSTITUTE(O50,"_","-"),"|","-"))),IF(P50="","",CONCATENATE("_U2|",SUBSTITUTE(SUBSTITUTE(P50,"_","-"),"|","-"))),IF(Q50="","",CONCATENATE("_U3|",SUBSTITUTE(SUBSTITUTE(Q50,"_","-"),"|","-"))))) -> MK|BR_CH|PSD_DT|CROSS_PB|FCBK_FM|CAR_RT|CPM_PD|DOTZ-10MIL-AMARELO_TG|NON_ST|NON_TS|NONE_SZ|1X1_AD|CM1_IT|SOC_U1|ESTATICO
B51: Brazil | C51: Paid Social Display | D51: Cross Device/ Screen | E51: Facebook | F51: Carousel | G51: Cost per Thousand | H51: DOTZ-ZERO-ANUIDADE-AMARELO | I51: None | J51: None | L51: 1X1 | M51: Site-Served w/ DCM Tracking | N51: Social | O51: ESTATICO | R51: =IF(K51="----","#N/A",CONCATENATE("MK|",(VLOOKUP(B51,Dictionary!$A:$B,2,0)),"_CH|",(VLOOKUP(C51,Dictionary!$AV:$AW,2,0)),"_DT|",(VLOOKUP(D51,Dictionary!$P:$Q,2,0)),"_PB|",(VLOOKUP(E51,Dictionary!$G:$H,2,0)),"_FM|",(VLOOKUP(F51,Dictionary!$S:$T,2,0)),"_RT|",(VLOOKUP(G51,Dictionary!$V:$W,2,0)),"_PD|",SUBSTITUTE(SUBSTITUTE(IF(H51="","NONE",H51),"_","-"),"|","-"),"_TG|",(VLOOKUP(I51,Dictionary!$J:$K,2,0)),"_ST|",(VLOOKUP(J51,Dictionary!$M:$N,2,0)),"_TS|",SUBSTITUTE(SUBSTITUTE(IF(K51="","NONE",K51),"_","-"),"|","-"),"_SZ|",(VLOOKUP(L51,Dictionary!$Y:$Z,1,0)),"_AD|",(VLOOKUP(M51,Dictionary!$AB:$AC,2,0)),"_IT|",(VLOOKUP(N51,Dictionary!$BC:$BD,2,0)),IF(O51="","",CONCATENATE("_U1|",SUBSTITUTE(SUBSTITUTE(O51,"_","-"),"|","-"))),IF(P51="","",CONCATENATE("_U2|",SUBSTITUTE(SUBSTITUTE(P51,"_","-"),"|","-"))),IF(Q51="","",CONCATENATE("_U3|",SUBSTITUTE(SUBSTITUTE(Q51,"_","-"),"|","-"))))) -> MK|BR_CH|PSD_DT|CROSS_PB|FCBK_FM|CAR_RT|CPM_PD|DOTZ-ZERO-ANUIDADE-AMARELO_TG|NON_ST|NON_TS|NONE_SZ|1X1_AD|CM1_IT|SOC_U1|ESTATICO
B52: Brazil | C52: Paid Social Display | D52: Cross Device/ Screen | E52: Facebook | F52: Carousel | G52: Cost per Thousand | H52: DOTZ-TODOS-BENEFICIOS-AMARELO | I52: None | J52: None | L52: 1X1 | M52: Site-Served w/ DCM Tracking | N52: Social | O52: ESTATICO | R52: =IF(K52="----","#N/A",CONCATENATE("MK|",(VLOOKUP(B52,Dictionary!$A:$B,2,0)),"_CH|",(VLOOKUP(C52,Dictionary!$AV:$AW,2,0)),"_DT|",(VLOOKUP(D52,Dictionary!$P:$Q,2,0)),"_PB|",(VLOOKUP(E52,Dictionary!$G:$H,2,0)),"_FM|",(VLOOKUP(F52,Dictionary!$S:$T,2,0)),"_RT|",(VLOOKUP(G52,Dictionary!$V:$W,2,0)),"_PD|",SUBSTITUTE(SUBSTITUTE(IF(H52="","NONE",H52),"_","-"),"|","-"),"_TG|",(VLOOKUP(I52,Dictionary!$J:$K,2,0)),"_ST|",(VLOOKUP(J52,Dictionary!$M:$N,2,0)),"_TS|",SUBSTITUTE(SUBSTITUTE(IF(K52="","NONE",K52),"_","-"),"|","-"),"_SZ|",(VLOOKUP(L52,Dictionary!$Y:$Z,1,0)),"_AD|",(VLOOKUP(M52,Dictionary!$AB:$AC,2,0)),"_IT|",(VLOOKUP(N52,Dictionary!$BC:$BD,2,0)),IF(O52="","",CONCATENATE("_U1|",SUBSTITUTE(SUBSTITUTE(O52,"_","-"),"|","-"))),IF(P52="","",CONCATENATE("_U2|",SUBSTITUTE(SUBSTITUTE(P52,"_","-"),"|","-"))),IF(Q52="","",CONCATENATE("_U3|",SUBSTITUTE(SUBSTITUTE(Q52,"_","-"),"|","-"))))) -> MK|BR_CH|PSD_DT|CROSS_PB|FCBK_FM|CAR_RT|CPM_PD|DOTZ-TODOS-BENEFICIOS-AMARELO_TG|NON_ST|NON_TS|NONE_SZ|1X1_AD|CM1_IT|SOC_U1|ESTATICO
B53: Brazil | C53: Paid Social Display | D53: Cross Device/ Screen | E53: Facebook | F53: Carousel | G53: Cost per Thousand | H53: DOTZ-CONVERSAO-AMARELO | I53: None | J53: None | L53: 1X1 | M53: Site-Served w/ DCM Tracking | N53: Social | O53: ESTATICO | R53: =IF(K53="----","#N/A",CONCATENATE("MK|",(VLOOKUP(B53,Dictionary!$A:$B,2,0)),"_CH|",(VLOOKUP(C53,Dictionary!$AV:$AW,2,0)),"_DT|",(VLOOKUP(D53,Dictionary!$P:$Q,2,0)),"_PB|",(VLOOKUP(E53,Dictionary!$G:$H,2,0)),"_FM|",(VLOOKUP(F53,Dictionary!$S:$T,2,0)),"_RT|",(VLOOKUP(G53,Dictionary!$V:$W,2,0)),"_PD|",SUBSTITUTE(SUBSTITUTE(IF(H53="","NONE",H53),"_","-"),"|","-"),"_TG|",(VLOOKUP(I53,Dictionary!$J:$K,2,0)),"_ST|",(VLOOKUP(J53,Dictionary!$M:$N,2,0)),"_TS|",SUBSTITUTE(SUBSTITUTE(IF(K53="","NONE",K53),"_","-"),"|","-"),"_SZ|",(VLOOKUP(L53,Dictionary!$Y:$Z,1,0)),"_AD|",(VLOOKUP(M53,Dictionary!$AB:$AC,2,0)),"_IT|",(VLOOKUP(N53,Dictionary!$BC:$BD,2,0)),IF(O53="","",CONCATENATE("_U1|",SUBSTITUTE(SUBSTITUTE(O53,"_","-"),"|","-"))),IF(P53="","",CONCATENATE("_U2|",SUBSTITUTE(SUBSTITUTE(P53,"_","-"),"|","-"))),IF(Q53="","",CONCATENATE("_U3|",SUBSTITUTE(SUBSTITUTE(Q53,"_","-"),"|","-"))))) -> MK|BR_CH|PSD_DT|CROSS_PB|FCBK_FM|CAR_RT|CPM_PD|DOTZ-CONVERSAO-AMARELO_TG|NON_ST|NON_TS|NONE_SZ|1X1_AD|CM1_IT|SOC_U1|ESTATICO
B54: Brazil | C54: Programmatic Display | D54: Cross Device/ Screen | E54: Google DV360 | F54: Banner | G54: Cost per Thousand | H54: DOTZ-10MIL-AZUL | I54: None | J54: None | L54: 120x600 | M54: DCM Ad Served | N54: Programmatic Open Exchange | R54: =IF(K54="----","#N/A",CONCATENATE("MK|",(VLOOKUP(B54,Dictionary!$A:$B,2,0)),"_CH|",(VLOOKUP(C54,Dictionary!$AV:$AW,2,0)),"_DT|",(VLOOKUP(D54,Dictionary!$P:$Q,2,0)),"_PB|",(VLOOKUP(E54,Dictionary!$G:$H,2,0)),"_FM|",(VLOOKUP(F54,Dictionary!$S:$T,2,0)),"_RT|",(VLOOKUP(G54,Dictionary!$V:$W,2,0)),"_PD|",SUBSTITUTE(SUBSTITUTE(IF(H54="","NONE",H54),"_","-"),"|","-"),"_TG|",(VLOOKUP(I54,Dictionary!$J:$K,2,0)),"_ST|",(VLOOKUP(J54,Dictionary!$M:$N,2,0)),"_TS|",SUBSTITUTE(SUBSTITUTE(IF(K54="","NONE",K54),"_","-"),"|","-"),"_SZ|",(VLOOKUP(L54,Dictionary!$Y:$Z,1,0)),"_AD|",(VLOOKUP(M54,Dictionary!$AB:$AC,2,0)),"_IT|",(VLOOKUP(N54,Dictionary!$BC:$BD,2,0)),IF(O54="","",CONCATENATE("_U1|",SUBSTITUTE(SUBSTITUTE(O54,"_","-"),"|","-"))),IF(P54="","",CONCATENATE("_U2|",SUBSTITUTE(SUBSTITUTE(P54,"_","-"),"|","-"))),IF(Q54="","",CONCATENATE("_U3|",SUBSTITUTE(SUBSTITUTE(Q54,"_","-"),"|","-"))))) -> MK|BR_CH|PD_DT|CROSS_PB|DV36_FM|BAN_RT|CPM_PD|DOTZ-10MIL-AZUL_TG|NON_ST|NON_TS|NONE_SZ|120x600_AD|CM_IT|POE
B55: Brazil | C55: Programmatic Display | D55: Cross Device/ Screen | E55: Google DV360 | F55: Banner | G55: Cost per Thousand | H55: DOTZ-10MIL-AZUL | I55: None | J55: None | L55: 160x600 | M55: DCM Ad Served | N55: Programmatic Open Exchange | R55: =IF(K55="----","#N/A",CONCATENATE("MK|",(VLOOKUP(B55,Dictionary!$A:$B,2,0)),"_CH|",(VLOOKUP(C55,Dictionary!$AV:$AW,2,0)),"_DT|",(VLOOKUP(D55,Dictionary!$P:$Q,2,0)),"_PB|",(VLOOKUP(E55,Dictionary!$G:$H,2,0)),"_FM|",(VLOOKUP(F55,Dictionary!$S:$T,2,0)),"_RT|",(VLOOKUP(G55,Dictionary!$V:$W,2,0)),"_PD|",SUBSTITUTE(SUBSTITUTE(IF(H55="","NONE",H55),"_","-"),"|","-"),"_TG|",(VLOOKUP(I55,Dictionary!$J:$K,2,0)),"_ST|",(VLOOKUP(J55,Dictionary!$M:$N,2,0)),"_TS|",SUBSTITUTE(SUBSTITUTE(IF(K55="","NONE",K55),"_","-"),"|","-"),"_SZ|",(VLOOKUP(L55,Dictionary!$Y:$Z,1,0)),"_AD|",(VLOOKUP(M55,Dictionary!$AB:$AC,2,0)),"_IT|",(VLOOKUP(N55,Dictionary!$BC:$BD,2,0)),IF(O55="","",CONCATENATE("_U1|",SUBSTITUTE(SUBSTITUTE(O55,"_","-"),"|","-"))),IF(P55="","",CONCATENATE("_U2|",SUBSTITUTE(SUBSTITUTE(P55,"_","-"),"|","-"))),IF(Q55="","",CONCATENATE("_U3|",SUBSTITUTE(SUBSTITUTE(Q55,"_","-"),"|","-"))))) -> MK|BR_CH|PD_DT|CROSS_PB|DV36_FM|BAN_RT|CPM_PD|DOTZ-10MIL-AZUL_TG|NON_ST|NON_TS|NONE_SZ|160x600_AD|CM_IT|POE
