Workbook

Sheet Resultado
B1: Nível de Maturidade Gerenciamento de Mudanças
B6: =IF(AND(Avaliação!G4>=0,Avaliação!G4<=0.99),Resultados!B2,IF(AND(Avaliação!G4>=1,Avaliação!G4<=1.99),Resultados!B3,IF(AND(Avaliação!G4>=2,Avaliação!G4<=2.99),Resultados!B4,IF(AND(Avaliação!G4>=3,Avaliação!G4<=3.99),Resultados!B5,IF(AND(Avaliação!G4>=4,Avaliação!G4<=4.99),Resultados!B6,IF(AND(Avaliação!G4>=5,Avaliação!G4<=5.99),Resultados!B7,"Erro! Confira a pontuação e tente novamente.")))))) -> Nível 0 - Processo Incompleto: O processo não foi implementado ou não atingiu seu objetivo. Nesse nível, há pouca ou nenhuma evidência de realização sistemática da finalidade do processo.
B11: Detalhamento:
B12: Atributo | E12: Descrição | M12: Valor Atual | O12: Objetivo | Q12: % Concluído | S12: Status
B13: PA 1.1 | E13: Desempenho do Processo | M13: =Avaliação!G5*100 -> 0 | O13: 100 | Q13: =Avaliação!B7 -> 0 | S13: =Avaliação!D5 -> Incompleto
B14: PA 2.1 | E14: Gestão do Desempenho | M14: =Avaliação!G8*100 -> 0 | O14: 50 | Q14: =Avaliação!B13 -> 0 | S14: =Avaliação!D8 -> Incompleto
B15: PA 2.2 | E15: Gestão dos Produtos de Trabalho | M15: =Avaliação!G14*100 -> 0 | O15: 50 | Q15: =Avaliação!B18 -> 0 | S15: =Avaliação!D14 -> Incompleto
B16: PA 3.1 | E16: Definição do Processo | M16: =Avaliação!G19*100 -> 0 | O16: 50 | Q16: =Avaliação!B24 -> 0 | S16: =Avaliação!D19 -> Incompleto
B17: PA 3.2 | E17: Implementação do Processo | M17: =Avaliação!G25*100 -> 0 | O17: 50 | Q17: =Avaliação!B31 -> 0 | S17: =Avaliação!D25 -> Incompleto
B18: PA 4.1 | E18: Gestão do Processo | M18: =Avaliação!G32*100 -> 0 | O18: 50 | Q18: =Avaliação!B37 -> 0 | S18: =Avaliação!D32 -> Incompleto
B19: PA 4.2 | E19: Controle do Processo | M19: =Avaliação!G38*100 -> 0 | O19: 50 | Q19: =Avaliação!B42 -> 0 | S19: =Avaliação!D38 -> Incompleto
B20: PA 5.1 | E20: Inovação do Processo | M20: =Avaliação!G43*100 -> 0 | O20: 50 | Q20: =Avaliação!B48 -> 0 | S20: =Avaliação!D43 -> Incompleto
B21: PA 5.2 | E21: Otimização do Processo | M21: =Avaliação!G49*100 -> 0 | O21: 50 | Q21: =Avaliação!B52 -> 0 | S21: =Avaliação!D49 -> Incompleto
B22: Observações:

Sheet Avaliação
B1: Legenda (Status)
B2: N - (Não Alcançado) - Há pouca ou nenhuma evidência de realização do atributo de processo no processo avaliado. P - (Parcialmente alcançado) - Há alguma evidência de realização do atributo de processo no processo avaliado. Alguns aspectos da realização do atributo podem ser imprevisíveis. A - (Amplamente alcançado) - Há evidências de uma realização significativa do atributo de processo no processo avaliado. Algumas fraquezas relacionadas a este atributo podem existir no processo avaliado. T - (Totalmente alcançado) - Há evidências de uma realização completa do atributo de processo no processo avaliado. Não há deficiências significativas associadas a este atributo no processo avaliado.
B4: Atributo | C4: Descrição | D4: Status | E4: % | F4: Valor | G4: =SUM(F5,F8,F14,F19,F25,F32,F38,F43,F49) -> 0
B5: PA 1.1 | C5: Desempenho do Processo: Avalia se o processo atinge o seu objetivo. É avaliado se as atividades básicas e os produtos de trabalho do processo são executados de alguma forma, não sendo necessária a formalização e documentação dos mesmos. | D5: =IF(G6+G7=1,"OK","Incompleto") -> Incompleto | F5: =IF(AND(G6+G7=1),1,0) -> 0 | G5: =SUM(G6:G7) -> 0
C6: Atividades Básicas são executadas | D6: N | E6: =IF(AND(D6="N"),0%,IF(AND(D6="P"),30%,IF(AND(D6="A"),65%,IF(AND(D6="T"),100%,0%)))) -> 0 | F6: 0.5 | G6: =E6*F6 -> 0
B7: =AVERAGE(E6:E7) -> 0 | C7: Eprodutos de trabalho do Processo são executados | D7: N | E7: =IF(AND(D7="N"),0%,IF(AND(D7="P"),30%,IF(AND(D7="A"),65%,IF(AND(D7="T"),100%,0%)))) -> 0 | F7: 0.5 | G7: =E7*F7 -> 0
B8: PA2.1 | C8: Gestão do Desempenho: Avalia se o desempenho do processo é gerenciado. Como resultado da plena realização desse atributo: | D8: =IF(G9+G10+G11+G12+G13=0.5,"OK","Incompleto") -> Incompleto | F8: =IF(AND(F5=1,G9+G10+G11+G12+G13=0.5),0.5,0) -> 0 | G8: =SUM(G9:G13) -> 0
C9: Os objetivos de desempenho do processo estão definidos | D9: N | E9: =IF(AND(D9="N"),0%,IF(AND(D9="P"),30%,IF(AND(D9="A"),65%,IF(AND(D9="T"),100%,0%)))) -> 0 | F9: 0.1 | G9: =E9*F9 -> 0
C10: O desempenho do processo está planejado, monitorado e ajustado para atingir o planejado | D10: N | E10: =IF(AND(D10="N"),0%,IF(AND(D10="P"),30%,IF(AND(D10="A"),65%,IF(AND(D10="T"),100%,0%)))) -> 0 | F10: 0.1 | G10: =E10*F10 -> 0
C11: As responsabilidades para execução do processo estão definidas, atribuídas e comunicadas | D11: N | E11: =IF(AND(D11="N"),0%,IF(AND(D11="P"),30%,IF(AND(D11="A"),65%,IF(AND(D11="T"),100%,0%)))) -> 0 | F11: 0.1 | G11: =E11*F11 -> 0
C12: Os recursos e informações necessárias para executar o processo estão identificados, disponíveis, alocados e utilizados. | D12: N | E12: =IF(AND(D12="N"),0%,IF(AND(D12="P"),30%,IF(AND(D12="A"),65%,IF(AND(D12="T"),100%,0%)))) -> 0 | F12: 0.1 | G12: =E12*F12 -> 0
B13: =AVERAGE(E9:E13) -> 0 | C13: A interface entre as partes envolvidas no processo são gerenciadas para garantir a eficácia na comunicação e clareza na definição de responsabilidades. | D13: N | E13: =IF(AND(D13="N"),0%,IF(AND(D13="P"),30%,IF(AND(D13="A"),65%,IF(AND(D13="T"),100%,0%)))) -> 0 | F13: 0.1 | G13: =E13*F13 -> 0
B14: PA2.2 | C14: Gestão dos Produtos de Trabalho: Avalia se os produtos de trabalho produzido pelo processo são apropriadamente gerenciados. Como resultado da plena realização desse atributo: | D14: =IF(G15+G16+G17+G18=0.5,"OK","Incompleto") -> Incompleto | F14: =IF(AND(F5=1,G15+G16+G17+G18=0.5),0.5,0) -> 0 | G14: =SUM(G15:G18) -> 0
C15: Os requisitos para os produtos de trabalho do processo estão definidos | D15: N | E15: =IF(AND(D15="N"),0%,IF(AND(D15="P"),30%,IF(AND(D15="A"),65%,IF(AND(D15="T"),100%,0%)))) -> 0 | F15: 0.12 | G15: =E15*F15 -> 0
C16: Os requisitos para documentação e controle dos produtos de trabalho estão definidos | D16: N | E16: =IF(AND(D16="N"),0%,IF(AND(D16="P"),30%,IF(AND(D16="A"),65%,IF(AND(D16="T"),100%,0%)))) -> 0 | F16: 0.13 | G16: =E16*F16 -> 0
C17: Os produtos de trabalho do processo são devidamente identificados e controlados | D17: N | E17: =IF(AND(D17="N"),0%,IF(AND(D17="P"),30%,IF(AND(D17="A"),65%,IF(AND(D17="T"),100%,0%)))) -> 0 | F17: 0.12 | G17: =E17*F17 -> 0
B18: =AVERAGE(E15:E18) -> 0 | C18: Os produtos de trabalho do processo são revisados de acordo com os critérios definidos e ajustados para atender aos requisitos. | D18: N | E18: =IF(AND(D18="N"),0%,IF(AND(D18="P"),30%,IF(AND(D18="A"),65%,IF(AND(D18="T"),100%,0%)))) -> 0 | F18: 0.13 | G18: =E18*F18 -> 0
B19: PA3.1 | C19: Definição do Processo: busca avaliar se um processo padrão é mantido de forma que auxilie a implantação de um processo definido. Como resultado da plena realização desse atributo: | D19: =IF(G20+G21+G22+G23+G24=0.5,"OK","Incompleto") -> Incompleto | F19: =IF(AND(F5=1,F8=0.5,F14=0.5,G20+G21+G22+G23+G24=0.5),0.5,0) -> 0 | G19: =SUM(G20:G24) -> 0
C20: Um processo padrão, incluindo orientações para adaptação, é definido e descreve os elementos fundamentais que devem ser incorporados a um processo definido; | D20: N | E20: =IF(AND(D20="N"),0%,IF(AND(D20="P"),30%,IF(AND(D20="A"),65%,IF(AND(D20="T"),100%,0%)))) -> 0 | F20: 0.1 | G20: =E20*F20 -> 0
C21: A sequência e interação do processo padrão com outros processos estão determinadas | D21: N | E21: =IF(AND(D21="N"),0%,IF(AND(D21="P"),30%,IF(AND(D21="A"),65%,IF(AND(D21="T"),100%,0%)))) -> 0 | F21: 0.1 | G21: =E21*F21 -> 0
C22: Os papéis e competências necessárias para a realização de um processo são identificados como parte do processo padrão | D22: N | E22: =IF(AND(D22="N"),0%,IF(AND(D22="P"),30%,IF(AND(D22="A"),65%,IF(AND(D22="T"),100%,0%)))) -> 0 | F22: 0.1 | G22: =E22*F22 -> 0
C23: A infraestrutura necessária e ambiente de trabalho para a realização do processo estão identificados | D23: N | E23: =IF(AND(D23="N"),0%,IF(AND(D23="P"),30%,IF(AND(D23="A"),65%,IF(AND(D23="T"),100%,0%)))) -> 0 | F23: 0.1 | G23: =E23*F23 -> 0
B24: =AVERAGE(E20:E24) -> 0 | C24: Métodos para monitorar a eficácia e adequação do processo estão determinados | D24: N | E24: =IF(AND(D24="N"),0%,IF(AND(D24="P"),30%,IF(AND(D24="A"),65%,IF(AND(D24="T"),100%,0%)))) -> 0 | F24: 0.1 | G24: =E24*F24 -> 0
B25: PA3.2 | C25: Implementação do Processo: busca avaliar se um processo padrão é eficientemente implantado como um processo definido. Como resultado da plena realização desse atributo: | D25: =IF(G26+G27+G28+G29+G30+G31=0.5,"OK","Incompleto") -> Incompleto | F25: =IF(AND(F5=1,F8=0.5,F14=0.5,G26+G27+G28+G29+G30+G31=0.5),0.5,0) -> 0 | G25: =SUM(G26:G31) -> 0
C26: Um processo definido é implantado baseado na escolha e adequação de um processo padrão | D26: N | E26: =IF(AND(D26="N"),0%,IF(AND(D26="P"),30%,IF(AND(D26="A"),65%,IF(AND(D26="T"),100%,0%)))) -> 0 | F26: 0.08 | G26: =E26*F26 -> 0
C27: Papéis e responsabilidades para executar o processo definido são alocados e comunicados | D27: N | E27: =IF(AND(D27="N"),0%,IF(AND(D27="P"),30%,IF(AND(D27="A"),65%,IF(AND(D27="T"),100%,0%)))) -> 0 | F27: 0.08 | G27: =E27*F27 -> 0
C28: Os atores do processo definido possuem experiência e estão adequadamente treinados | D28: N | E28: =IF(AND(D28="N"),0%,IF(AND(D28="P"),30%,IF(AND(D28="A"),65%,IF(AND(D28="T"),100%,0%)))) -> 0 | F28: 0.09 | G28: =E28*F28 -> 0
C29: Os recursos e informações necessárias para a execução do processo definido estão disponíveis, alocados e são utilizados | D29: N | E29: =IF(AND(D29="N"),0%,IF(AND(D29="P"),30%,IF(AND(D29="A"),65%,IF(AND(D29="T"),100%,0%)))) -> 0 | F29: 0.09 | G29: =E29*F29 -> 0
C30: A infraestrutura e ambientes necessários para a execução do processo definido estão disponíveis, são gerenciados e mantidos | D30: N | E30: =IF(AND(D30="N"),0%,IF(AND(D30="P"),30%,IF(AND(D30="A"),65%,IF(AND(D30="T"),100%,0%)))) -> 0 | F30: 0.08 | G30: =E30*F30 -> 0
B31: =AVERAGE(E26:E31) -> 0 | C31: Os dados apropriados são coletados e analisados para entendimento do comportamento, demonstração da efetividade e avaliação de melhorias contínuas do processo definido | D31: N | E31: =IF(AND(D31="N"),0%,IF(AND(D31="P"),30%,IF(AND(D31="A"),65%,IF(AND(D31="T"),100%,0%)))) -> 0 | F31: 0.08 | G31: =E31*F31 -> 0
B32: PA4.1 | C32: Gestão do Processo: busca avaliar se resultados de medição de desempenho do processo são utilizados para garantir o atingimento de objetivos do processo, em suporte a metas de negócio. Como resultado da plena realização desse atributo: | D32: =IF(G33+G34+G35+G36+G37=0.5,"OK","Incompleto") -> Incompleto | F32: =IF(AND(F5=1,F8=0.5,F14=0.5,F19=0.5,F25=0.5,G33+G34+G35+G36+G37=0.5),0.5,0) -> 0 | G32: =SUM(G33:G37) -> 0
C33: As necessidades de informação do processo estão definidas de acordo com os objetivos de negócio | D33: N | E33: =IF(AND(D33="N"),0%,IF(AND(D33="P"),30%,IF(AND(D33="A"),65%,IF(AND(D33="T"),100%,0%)))) -> 0 | F33: 0.1 | G33: =E33*F33 -> 0
C34: Os objetivos de medição do processo são derivados da necessidade de informação do mesmo | D34: N | E34: =IF(AND(D34="N"),0%,IF(AND(D34="P"),30%,IF(AND(D34="A"),65%,IF(AND(D34="T"),100%,0%)))) -> 0 | F34: 0.1 | G34: =E34*F34 -> 0
C35: Os objetivos quantitativos para o desempenho do processo são estabelecidos de acordo com as necessidades do negócio | D35: N | E35: =IF(AND(D35="N"),0%,IF(AND(D35="P"),30%,IF(AND(D35="A"),65%,IF(AND(D35="T"),100%,0%)))) -> 0 | F35: 0.1 | G35: =E35*F35 -> 0
C36: As medidas e frequência de medição são identificadas e definidas de acordo com os objetivos de medição do processo e os objetivos quantitativos para o desempenho do processo | D36: N | E36: =IF(AND(D36="N"),0%,IF(AND(D36="P"),30%,IF(AND(D36="A"),65%,IF(AND(D36="T"),100%,0%)))) -> 0 | F36: 0.1 | G36: =E36*F36 -> 0
B37: =AVERAGE(E33:E37) -> 0 | C37: Os resultados de medição são coletados, analisados e reportados a fim de avaliar e os objetivos quantitativos do processo são atingidos | D37: N | E37: =IF(AND(D37="N"),0%,IF(AND(D37="P"),30%,IF(AND(D37="A"),65%,IF(AND(D37="T"),100%,0%)))) -> 0 | F37: 0.1 | G37: =E37*F37 -> 0
B38: PA4.2 | C38: Controle do Processo: busca avaliar se o processo é quantitativamente gerenciado, de modo que seja estável e previsível dentro de limites preestabelecidos. Como resultado da plena realização desse atributo: | D38: =IF(G39+G40+G41+G42=0.5,"OK","Incompleto") -> Incompleto | F38: =IF(AND(F5=1,F8=0.5,F14=0.5,F19=0.5,F25=0.5,G39+G40+G41+G42=0.5),0.5,0) -> 0 | G38: =SUM(G39:G42) -> 0
C39: As técnicas de controle e análise estão definidas e aplicadas | D39: N | E39: =IF(AND(D39="N"),0%,IF(AND(D39="P"),30%,IF(AND(D39="A"),65%,IF(AND(D39="T"),100%,0%)))) -> 0 | F39: 0.13 | G39: =E39*F39 -> 0
C40: Os limites de variação do processo são definidos para uma performance normal do processo | D40: N | E40: =IF(AND(D40="N"),0%,IF(AND(D40="P"),30%,IF(AND(D40="A"),65%,IF(AND(D40="T"),100%,0%)))) -> 0 | F40: 0.12 | G40: =E40*F40 -> 0
C41: Os dados de medição são analisados para causas especiais de variação | D41: N | E41: =IF(AND(D41="N"),0%,IF(AND(D41="P"),30%,IF(AND(D41="A"),65%,IF(AND(D41="T"),100%,0%)))) -> 0 | F41: 0.12 | G41: =E41*F41 -> 0
...

Sheet Resultados
B2: Nível 0 - Processo Incompleto: O processo não foi implementado ou não atingiu seu objetivo. Nesse nível, há pouca ou nenhuma evidência de realização sistemática da finalidade do processo.
B3: Nível 1 - Processo Executado: O processo está implementado e atinge seu objetivo. PA1.1 – Desempenho do Processo (Process Performance)
B4: Nível 2 - Processo Gerenciado: O processo realizado anteriormente descrito é implementado de forma gerenciada (planejado, monitorado e ajustado) e seus produtos de trabalho estão devidamente estabelecidos, controlados e mantidos. PA2.1 – Gerenciamento de Desempenho (Performance Management) PA2.2 – Gerenciamento de Produto de Trabalho (Work Product Management)
B5: Nível 3 - Processo Estabelecido: O processo gerenciado anteriormente descrito é implementado usando um processo definido que é capaz de alcançar os seus resultados de processo. PA3.1 – Definição de Processo (Process Definition) PA3.2 – Implementação de Processo (Process Deployment)
B6: Nível 4 - Processo Previsível: O processo estabelecido anteriormente descrito opera dentro de limites definidos para alcançar seus resultados de processo. PA4.1 – Gerenciamento do Processo (Process Management) PA4.2 – Controle do Processo (Process Control)
B7: Nível 5 - Processo Otimizado: O processo previsível anteriormente descrito é continuamente melhorado para atender aos objetivos corporativos. PA5.1 – Inovação de Processo (Process Innovation) PA5.2 – Otimização de Processo (Process Optimization)
