Workbook
Name a: [1]Validações!$B$42:$B$48
Name a: '[2]Custo MOD'!$D$27
Name ABAP: Listas!$A$193
Name AREA: #REF!
Name AREA: #REF!
Name AREA: #REF!
Name as: [3]Piloto!$A:$J,[3]Piloto!#REF!
Name as: [3]Piloto!$A:$J,[3]Piloto!#REF!
Name Avaliacao_Gerencial: #REF!
Name Avaliacao_Gerencial: #REF!
Name Avaliacao_Gerencial: #REF!
Name base_instalada: [4]Análise!$Z$3
Name C_Ad_BI: '[4]Custo MOD'!$D$27
Name C_Ad_CRM: '[4]Custo MOD'!$D$28
Name C_Ad_Funcional: '[4]Custo MOD'!$D$29
Name C_Ad_Out_Loc: '[4]Custo MOD'!$D$30
Name C_Ad_Out_Rem: '[4]Custo MOD'!$D$31
Name C_Ad_Outsourcing: '[5]Custo MOD'!$D$29
Name C_Ad_Tec_Fab: '[4]Custo MOD'!$D$32
Name C_Ad_Tec_Prj: '[4]Custo MOD'!$D$33
Name C_Ad_Tecnologia: '[5]Custo MOD'!$D$30
Name Classificacao: [6]Legendas!$R$2:$R$3
Name comissão: [4]Análise!$Z$2
Name const: #REF!
Name const: #REF!
Name const: #REF!
Name custo: [4]Análise!$AG$34
Name Custo_Admin_BI: '[4]Custo MOD'!$C$27
Name Custo_Admin_CRM: '[4]Custo MOD'!$C$28
Name Custo_Admin_Funcional: '[4]Custo MOD'!$C$29
Name Custo_Admin_Out_Loc: '[4]Custo MOD'!$C$30
Name Custo_Admin_Out_Rem: '[4]Custo MOD'!$C$31
Name Custo_Admin_Outsourcing: '[5]Custo MOD'!$C$29
Name Custo_Admin_Tec_Fab: '[4]Custo MOD'!$C$32
Name Custo_Admin_Tec_Prj: '[4]Custo MOD'!$C$33
Name Custo_Admin_Tecnologia: '[5]Custo MOD'!$C$30
Name d: [2]Análise!$AC$3
Name diaria: '[4]Desp.não Reemb.'!$E$39
Name Dimensão: [7]Validações!$B$42:$B$48
Name ds: #REF!
Name ds: #REF!
Name esp: #REF!
Name esp: #REF!
Name esp: #REF!
Name Excel_BuiltIn_Print_Titles_1: '[3]Bsc_corp BF'!$A:$K,'[3]Bsc_corp BF'!#REF!
Name Excel_BuiltIn_Print_Titles_1: '[3]Bsc_corp BF'!$A:$K,'[3]Bsc_corp BF'!#REF!
Name Excel_BuiltIn_Print_Titles_1: '[3]Bsc_corp BF'!$A:$K,'[3]Bsc_corp BF'!#REF!
Name Excel_BuiltIn_Print_Titles_2: [3]Piloto!$A:$J,[3]Piloto!#REF!
Name Excel_BuiltIn_Print_Titles_2: [3]Piloto!$A:$J,[3]Piloto!#REF!
Name Excel_BuiltIn_Print_Titles_2: [3]Piloto!$A:$J,[3]Piloto!#REF!
Name Faturamento_total: [4]Análise!$Y$37
Name Horas_dia: [4]Análise!$U$7
Name IRPJ_CSSL: [4]Análise!$Z$4
Name ISS: [4]Análise!$Z$6
Name L_ABAP: Listas!$B$193:$B$200
Name listax: Listas!$C$3:$C$20
Name MLiquida: '[4]Ref-Tx.Venda'!$F$1
Name Modulos: #REF!
Name Modulos: #REF!
Name o: '[3]Bsc_corp BF'!$A:$K,'[3]Bsc_corp BF'!#REF!

Sheet Instruções Preenchimento
A1: Instruções para Preenchimento
A2: Abaixo, estão as instruções e a indicação do responsável pelo preenchimento das planilhas e seus respectivos campos para abertura/seguimento das demandas.
A3: Os dados já preenchidos nas demais planilhas são apenas exemplos e devem ser eliminados ANTES do início do preenchimento.
A5: Planilha Briefing_Req | B5: Responsável
A6: Campo | B6: Preenchimento | C6: Conteúdo
A7: ID | B7: GRP/MD | C7: Número Sequencial do Requisito
A8: Tipo de Requisito | B8: GRP/MD | C8: Funcional ou Não-Funcional
A9: Requisito | B9: GRP/MD | C9: Descrever os seguintes níveis e tipos de Requisitos : 1-Requisito Funcional: Descreve o comportamento observável que será demonstrado pelo sistema e as informações que ele gerenciará. Define o que o sistema fará, ações e resposta do sistema. Para o levantamento, devem ser considerados as seguintes características: Caminho Feliz, Caminho Não feliz (exceção), Analítico, Controle (SOX, ISO, etc), Gestão da Informação, Automatismo, Conversão e Convivência. 1.1 Requisitos de negócio: são os requisitos de mais alto nível da solução. Indicam o escopo a ser desenvolvido : 1) As razões por que um projeto é iniciado. 2) As métricas que serão usadas para medir o seu sucesso. 3) Os resultados que o projeto deve alcançar (marcro-funcionaldiades). 4) As razões por que um sistema existe. 1.2 Requisitos das partes interessadas: descrevem as necessidades de uma classe específica de usuários e servem para fazer a ponte entre os requisitos de negócio e da solução. Neste caso, podem ser informado as recomendações de change management (riscos, treinamento, comunicação, mudanças de estrutura, tecnologia ou processo, etc). Não necessariamente todos os projetos terão este tipo de requisito, portanto cabe ao GRP avaliar se há uma necessidade específica para a demanda em questão. 2-Requisito Não Funcional: Indicam características que o sistema deve ter ou como deve ser. Devem ser considerados : Performance/Disponibilidade (e suas metas), Compatibilidade (Adaptação Browsers, Interação com outros Aplicativos), Portabilidade, Arquivamento (considerando a volumetria esperada para os registros, novos ou existentes de uso intensificados, expectativa de crescimento e necessidade de retenção), Segurança de Informação, Usabilidade e Manutenibilidade (aplicativo testado com facilidade e seus problemas podem ser propriamente diagnosticados). Será também necessário preencher as informações percentual de crescimento por ano da informação e tempo de retenção on-line.
A10: Premissas | B10: GRP/MD | C10: Quais são as premissas (Premissas são fatores que, para fins de planejamento, são considerados verdadeiros, reais ou certos, sem prova ou demonstração) que devem ser declaradas para atendimento do requisito.
A11: Restrições | B11: GRP/MD | C11: Quais são as restrições (Restrições são fatores que limitam as opções da equipe) que devem ser declaradas para atendimento do requisito.
A12: Solicitado Por (Parceiro de Negócio) | B12: GRP/MD | C12: Nome Completo do patrocinador da demanda
A13: Key-User Validador | B13: GRP/MD | C13: Nome Completo do Key user
A14: Publico Alvo | B14: GRP/MD | C14: Qual o publico que será impactado pela execução e implantação do requisito
A15: Prioridade | B15: GRP/MD | C15: Definir a prioridade, sendo (1 - Alta 2 - Média 3 - Baixa)
A16: Processo de Negócio | B16: Líder de TD da demanda (Aplicações ou Infra) | C16: Qual processo de negócio Natura solicitante
A17: Sub-processo | B17: Líder de TD da demanda (Aplicações ou Infra) | C17: Qual o sub-processo de negócio Natura solicitante
... A20: Saidas | B20: Líder de TD da demanda (Aplicações ou Infra) | C20: Saidas que são esperadas pelo atendimento do requisito
A22: Planilha Estimativa Funcionalidades | B22: Responsável
A23: Campo | B23: Preenchimento | C23: Conteúdo
A24: Requisito Relacionado | B24: Líder de TD da demanda (Aplicações ou Infra) | C24: Numero sequencial do requisito utilizado como referência
A25: Tipo de Requisito | B25: Líder de TD da demanda (Aplicações ou Infra) | C25: Funcional ou Não funcional
A26: Descrição do Requisito | B26: Líder de TD da demanda (Aplicações ou Infra) | C26: Descrição do Requisito relacionado
A27: Atendimento | B27: Líder de TD da demanda (Aplicações ou Infra) | C27: Informa se o mesmo requisito é atendido por alguma funcionalidade (Atende, Atende Parcial, Não Atende)
A28: Id da Funcionalidade | B28: Líder de TD da demanda (Aplicações ou Infra) | C28: Numero sequencial das funcionalidades utilizada como referência
A29: Descrição Funcionalidade | B29: Líder de TD da demanda (Aplicações ou Infra) | C29: Decreva um breve texto do que é a Funcionalidade a ser realizada de acordo com solicitação do usuário
A30: Sinergias com outras iniciativas | B30: Líder de TD da demanda (Aplicações ou Infra) | C30: Descrever o escopo das sinergias técnicas de outras iniciativas
A31: Edital/Consultoria | B31: Líder de TD da demanda (Aplicações ou Infra) | C31: Especificar se deverá ocorrer edital e quais consultorias que participarão.
A32: Responsável pela entrega | B32: Líder de TD da demanda (Aplicações ou Infra) | C32: Descreva o nome do líder do núcleo responsável pela entrega.
A33: Sistema ou Módulo Relacionado | B33: Líder de TD da demanda (Aplicações ou Infra) | C33: Descreva o sistema ou módulo que se trata a avaliação de estimativa concretizada pelo fornecedor
A34: Forma de Atendimento | B34: Líder de TD da demanda (Aplicações ou Infra) | C34: Indicar a forma como é realizado atendimento do requisito através da funcionalidade (1 = Desenvolvimento; 2 = Solução de Parceiros; 3 = Configuração Complexa; 4 = Configuração Simples; 5 = Solução Standard (pacote))
... A39: Horas Detalhadas | B39: Líder de TD da demanda (Aplicações ou Infra) | C39: Relação de Horas por fase de projeto: Analise,Desenho,Construção,Teste Produto

Sheet Necessidades SI
A1: Necessidades de Segurança de Informação
A4: Qual a quantidade estimada de usuários da solução? | B4: Haverá criação de novos perfis? [criação, alteração, NA]
A5: 1- Área de Planejamento (responsável para reserva de estoque) - 5 Usuários
A6: 2- Atendimento - 150 Usuários
A7: 2- Força de vendas - 1000 Usuários
A8: ...

Sheet Briefing_Req
C2: Requisitos
A4: # | B4: Tipo Requisitos | C4: Requisitos | D4: Premissas | E4: Restrições | F4: Solicitado Por (Parceiro de Negocio) | G4: Key-User validador | H4: Publico Alvo | I4: Prioridade 1 - Alta 2 - Média 3 - Baixa | J4: Processo de Negocio | K4: Sub-Processo | L4: Entradas | M4: Detalhe do requisito | N4: Saídas
A5: 1 | B5: Funcional-Negócio | C5: Para materiais que tenham venda como baseline e fazem parte do kit início, é necessário garantir que não haja INA de kit devido a falta de estoque | D5: A lista dos componentes que compõe o Kit inicio deve ser informada pela área Comercial | E5: Esta Iniciativa precisará ser implementada para atender a Estratégia de Natal. | F5: Josie Romero | G5: Tobias Favero | H5: Novas CNs | I5: 1 | J5: O&L | K5: Planejamento | L5: Lista de Códigos de Materiais que compõem o Kit Inicio | M5: Garantir disponibilidade de estoque dos materiais que compõem kit início, permitindo que um material tenha sua venda priorizada para o kit (em detrimento a venda baseline) | N5: Códigos de Materiais que compõe o Kit Inicio priorizados | O5: Cadastro | P5: Juliana Delgado
A6: 2 | B6: Funcional-Partes Interessadas | C6: Criar uma consulta que permita filtro por código de material, e o resultado seja Código de Material, Descrição do Material, Qde Resevada, Qde Empenhada e Qde Total em Estoque | D6: A consulta irá apresentar as informações do dia, não apresentando o histórico de períodos passados | E6: Esta funcionalidade deverá estar disponível apenas para SP Capital | F6: Josie Romero | G6: Tobias Favero | H6: Novas CNs | I6: 2 | J6: O&L | K6: Planejamento | L6: Necessidade de gerenciar estoques e informações dos materiais que compõe o Kit Inicio | M6: Tela com filtro para selecionar o código de material definidos na Funcionalidade 1.1. Resultado da consulta deve trazer código de material, descrição, quantidade reservada, quantidade total de estoque. O resultado da consulta deverá ter um botão que permita o usuário exportar para um arquivo xls. | N6: Lista de itens do Kit Inicio com informações para gestão de estoque | O6: CRM Marketing | P6: Silvana Neves
A7: ... | O7: Comercial | P7: Alexsandra Reis
A8: 4 | B8: Não Funcional | C8: A consulta do ID2 deve ter tempo de esposta menor que 2 seg. | F8: Josie Romero | G8: Tobias Favero | H8: Novas CNs | P8: Thiago Sarkissian
A9: 5 | B9: Não-funcional | O9: Distribuição | P9: Davi Fugimoto
A10: 6 | B10: Funcional-Partes Interessadas | O10: Gestão de Conteudo | P10: Lourenço Trevenzolli
O11: Mobile | P11: Cesar Gomes
O12: Suprimentos | P12: Daniele Mancinelli
O13: Industrial | P13: Jania Carvalho
O14: Plan & Produção | P14: Guilherme Kajimoto
O15: Finanças | P15: Wesley Calegaretti
O16: RH e Sustentabilidade | P16: Adriano Beraldo
O17: Inovação e Marca | P17: Eliana Ferreira
O18: BI-SAP | P18: Priscila Chicaleski
O19: BI-Custom | P19: James Nakamura
O20: CRM Analitico | P20: Silvio Vechia
O24: N
O25: E
O29: 1
O30: 2
O31: 3
O33: Adicionado
O34: Cancelado
O35: Incluído
O36: Ampliado
O37: Simplificado
O38: N/A
A298: fim | B298: fim | C298: fim | D298: fim | E298: fim | F298: fim | G298: fim | H298: fim | I298: fim | J298: fim | K298: fim | L298: fim | M298: fim | N298: fim

Sheet Estimativa Funcionalidades(DA)
A1: Tecnologia | C1: Tecnologia | D1: Tipo | E1: Tecnologia | F1: Tipo | G1: Complexidade | H1: Concatenação | I1: Esforço | K1: Teste | L1: Xconstruç
A2: ABAP | C2: ABAP | D2: Conversão (carga) | E2: ABAP | F2: Conversão (carga) | G2: Baixa | H2: =E2&F2&G2 -> ABAPConversão (carga)Baixa | K2: baixa
A3: ABAP+BOL | C3: ABAP | D3: Conversão (extração) | E3: ABAP | F3: Conversão (carga) | G3: Média | H3: =E3&F3&G3 -> ABAPConversão (carga)Média | K3: média
A4: BO | C4: ABAP | D4: Enhacement | E4: ABAP | F4: Conversão (carga) | G4: Alta | H4: =E4&F4&G4 -> ABAPConversão (carga)Alta | K4: alta
A5: BW | C5: ABAP | D5: Formulário ou Tela | E5: ABAP | F5: Conversão (extração) | G5: Baixa | H5: =E5&F5&G5 -> ABAPConversão (extração)Baixa
A6: Java/WCS | C6: ABAP | D6: Interface Inbound | E6: ABAP | F6: Conversão (extração) | G6: Média | H6: =E6&F6&G6 -> ABAPConversão (extração)Média | K6: SPGL | L6: Xconstruç
A7: Mobile | C7: ABAP | D7: Interface Outbound | E7: ABAP | F7: Conversão (extração) | G7: Alta | H7: =E7&F7&G7 -> ABAPConversão (extração)Alta | K7: curto
A8: POWERCENTER | C8: ABAP | D8: Outros | E8: ABAP | F8: Enhacement | G8: Baixa | H8: =E8&F8&G8 -> ABAPEnhacementBaixa | K8: intermed.
A9: SAS | C9: ABAP | D9: Relatório | E9: ABAP | F9: Enhacement | G9: Média | H9: =E9&F9&G9 -> ABAPEnhacementMédia | K9: longo
A10: Sharepoint | C10: ABAP+BOL | D10: Enhacement | E10: ABAP | F10: Enhacement | G10: Alta | H10: =E10&F10&G10 -> ABAPEnhacementAlta
A11: SOA | C11: ABAP+BOL | D11: Formulário ou Tela | E11: ABAP | F11: Formulário ou Tela | G11: Baixa | H11: =E11&F11&G11 -> ABAPFormulário ou TelaBaixa | K11: Gestão | L11: Xconstruç
C12: ABAP+BOL | D12: Outros | E12: ABAP | F12: Formulário ou Tela | G12: Média | H12: =E12&F12&G12 -> ABAPFormulário ou TelaMédia | K12: normal
C13: ABAP+BOL | D13: Relatório | E13: ABAP | F13: Formulário ou Tela | G13: Alta | H13: =E13&F13&G13 -> ABAPFormulário ou TelaAlta | K13: complexa
C14: BO | D14: Information Spaces | E14: ABAP | F14: Interface Inbound | G14: Baixa | H14: =E14&F14&G14 -> ABAPInterface InboundBaixa
C15: BO | D15: Relatórios | E15: ABAP | F15: Interface Inbound | G15: Média | H15: =E15&F15&G15 -> ABAPInterface InboundMédia
C16: BO | D16: Universos | E16: ABAP | F16: Interface Inbound | G16: Alta | H16: =E16&F16&G16 -> ABAPInterface InboundAlta
C17: BW | D17: Análise de Impacto | E17: ABAP | F17: Interface Outbound | G17: Baixa | H17: =E17&F17&G17 -> ABAPInterface OutboundBaixa
C18: BW | D18: Extrator não standard fonte SAP | E18: ABAP | F18: Interface Outbound | G18: Média | H18: =E18&F18&G18 -> ABAPInterface OutboundMédia
C19: BW | D19: Extrator standard fonte SAP | E19: ABAP | F19: Interface Outbound | G19: Alta | H19: =E19&F19&G19 -> ABAPInterface OutboundAlta
C20: BW | D20: Extrator fonte não SAP | E20: ABAP | F20: Outros | G20: Baixa | H20: =E20&F20&G20 -> ABAPOutrosBaixa
C21: BW | D21: Modelagem (cubos , DSOs) | E21: ABAP | F21: Outros | G21: Média | H21: =E21&F21&G21 -> ABAPOutrosMédia
C22: Java/WCS | D22: Conversão (carga) | E22: ABAP | F22: Outros | G22: Alta | H22: =E22&F22&G22 -> ABAPOutrosAlta
C23: Java/WCS | D23: Conversão (extração) | E23: ABAP | F23: Relatório | G23: Baixa | H23: =E23&F23&G23 -> ABAPRelatórioBaixa
C24: Java/WCS | D24: Enhancement/Evolução em tela existente | E24: ABAP | F24: Relatório | G24: Média | H24: =E24&F24&G24 -> ABAPRelatórioMédia
C25: Java/WCS | D25: Formulário ou Tela | E25: ABAP | F25: Relatório | G25: Alta | H25: =E25&F25&G25 -> ABAPRelatórioAlta
... C34: Mobile | D34: Relatório | E34: ABAP+BOL | F34: Outros | G34: Alta | H34: =E34&F34&G34 -> ABAP+BOLOutrosAlta
E35: ABAP+BOL | F35: Relatório | G35: Baixa | H35: =E35&F35&G35 -> ABAP+BOLRelatórioBaixa
E36: ABAP+BOL | F36: Relatório | G36: Média | H36: =E36&F36&G36 -> ABAP+BOLRelatórioMédia
E37: ABAP+BOL | F37: Relatório | G37: Alta | H37: =E37&F37&G37 -> ABAP+BOLRelatórioAlta
E38: BO | F38: Information Spaces | G38: Baixa | H38: =E38&F38&G38 -> BOInformation SpacesBaixa
E39: BO | F39: Information Spaces | G39: Média | H39: =E39&F39&G39 -> BOInformation SpacesMédia
E40: BO | F40: Information Spaces | G40: Alta | H40: =E40&F40&G40 -> BOInformation SpacesAlta
E41: BO | F41: Relatórios | G41: Baixa | H41: =E41&F41&G41 -> BORelatóriosBaixa
E42: BO | F42: Relatórios | G42: Média | H42: =E42&F42&G42 -> BORelatóriosMédia
C43: POWERCENTER | D43: CDC | E43: BO | F43: Relatórios | G43: Alta | H43: =E43&F43&G43 -> BORelatóriosAlta
C44: POWERCENTER | D44: ETL | E44: BO | F44: Universos | G44: Baixa | H44: =E44&F44&G44 -> BOUniversosBaixa
C45: SAS | D45: ETL | E45: BO | F45: Universos | G45: Média | H45: =E45&F45&G45 -> BOUniversosMédia
C46: Sharepoint | D46: Conversão (carga) | E46: BO | F46: Universos | G46: Alta | H46: =E46&F46&G46 -> BOUniversosAlta
C47: Sharepoint | D47: Conversão (extração) | E47: BW | F47: Análise de Impacto | G47: Baixa | H47: =E47&F47&G47 -> BWAnálise de ImpactoBaixa
C48: Sharepoint | D48: Enhancement/Evolução em tela existente | E48: BW | F48: Análise de Impacto | G48: Média | H48: =E48&F48&G48 -> BWAnálise de ImpactoMédia
...

Sheet RefComplex
A1: Tipo | B1: Descrição | C1: Descrição | D1: Complexidade
A2: ABAP, ABAP+BOL | B2: Relatório | C2: Dados: Relatório com acesso até 3 tabelas ou com leitura de até 1 arquivo externo Lógico: Ordenação e agrupamento pequeno,não utiliza rotinas externas, com uma única versão que atende todas exigências( regiões) | D2: Baixa
C3: Dados: Relatório com acesso até 7 tabelas ou com leitura de até 3 arquivo externo Lógico: Pequena consistência de dados, drill drown, ordenação de calculos moderados,tratamento de campos, pequena variação de regras | D3: Média
C4: Dados: Relatório com acesso de 8 ou mais tabelas ou com leitura de 4 ou mais arquivos externos, dados de mais de um modulos Lógico: Utilização de varias telas,tratamento de campos,grande variação de regras, layout dos relatórios complexos (janelas, texto, fonte etc) e vários drill downs | D4: Alta
A5: ABAP, ABAP+BOL | B5: Interface Inbound (Criar WebService com regra de negócio,RFC) | C5: Dados: 1 arquivo externo ou até 3 tipos de registros ou objetos Lógico: Sem log de processamento de erro, sem tratamento de dados, sem reconciliação, até uma transação(BADI,BAPI,Batch input). | D5: Baixa
C6: Dados: Até 4 arquivos externos ou até 5 tipos de registros ou objetos Lógico: validação simples(Ex:data, cliente existe), retorno de log e erro simples, apenas mensagem ou descrição do erro e reconciliação simples | D6: Média
C7: Dados: Mais que 4 arquivos externos ou mais 5 tipos de registros ou objetos Lógico: mais de 4 transações,validação completa( Ex: credito do cliente), retorno de log e erro completo(motivo do erro trace) e reprocessamento | D7: Alta
A8: ABAP, ABAP+BOL | B8: Interface Outbound (Consumo de WebService ,RFC) | C8: Dados: 1 arquivo externo ou até 3 tipos de registros ou objetos Lógico: sem tratamento de dados ou leitura de dados de até 5 tabelas ou batch. | D8: Baixa
C9: Dados: Até 4 arquivos externos ou até 5 tipos de registros ou objetos Lógico: tratamento de dados moderado ou leitura de dados de até 9 tabelas ou batch. | D9: Média
C10: Dados: Mais que 4 arquivos externos ou mais 5 tipos de registros ou objetos Lógico: tratamento de dados complexos ou leitura de dados de 10 ou mais tabelas . | D10: Alta
A11: ABAP, ABAP+BOL | B11: Formulário ou Tela (Sapscript,SmartForm, Online) | C11: Dados: Leitura e manutenção de até 3 tabelas Lógico: validações simples( Ex: emails,telefone), utilização de ate 2 telas | D11: Baixa
C12: Dados: Leitura e manutenção de até 5 tabelas Lógico: regras de negócio/validações significativas( Ex: cliente existe), drill drown, 1 transação ou utilização de um componente de tela simples (table-control,paginação) | D12: Média
C13: Dados: Leitura e manutenção de mais do que 5 tabelas Lógico: Atualizações com tela inicial e subtelas(menu),validações complexas(Ex: credito do cliente) , drill drown, mais de 1 transação ou 4 telas, chamada de rotina externa, utilização de um componente complexo em mais de 1 tela (table-control,paginação) | D13: Alta
A14: ABAP, ABAP+BOL | B14: Enhacement (Transações,Batch input,Userexit,BADI,Include) | C14: Dados: Programas com seleção de até 2 tabelas Lógico:Poucas alterações na camada visual (alterações em telas do SAP) logica e física, apenas consultas sem atualizações de banco,validações simples( Ex: emails,telefone). | D14: Baixa
C15: Dados: Programas com seleção de até 5 tabelas com consistência/captura de dados, a Lógico:atualização em banco e alterações na camada visual (alterações em telas existentes), regras de negócio/validações significativas( Ex: cliente existe), até 2 funções externas | D15: Média
C16: Dados: Programas com seleção de mais do que 5 tabelas com consistência/captura de dados, Lógico: Grande número de alterações na camada visual (novas telas), validações complexas(Ex: credito do cliente) , mais do que 3 funções externas | D16: Alta
A17: BW | B17: Análise de Impacto | C17: Alteração em regras de negócio ou sistemas origem que impactem apenas 1 fluxo de informação dentro do BW. | D17: Baixa
A18: BW | B18: Análise de Impacto | C18: Alteração em regras de negócio ou sistemas origem que impactem mais de 1 fluxo de informação dentro do BW. | D18: Média
A19: BW | B19: Análise de Impacto | C19: Alteração complexas em regras de negócio ou sistemas origem que impactem fluxos complexos de informação dentro do BW. | D19: Alta
A20: SAS | B20: ETL | C20: Dados: Seleção de 1 tabela de origem. Lógico: Filtro simples ou sem filtros. | D20: Baixa
A21: SAS | B21: ETL | C21: Dados: Seleção de dados a partir de mais de uma tabela. Lógico: Regras de negócio, filtros e cálculos simples. | D21: Média
A22: SAS | B22: ETL | C22: Dados: Seleção de dados a partir de diversas tabelas, em bancos de dados diferentes (BW, Oracle). Lógico: Regras de negócio complexas, mudança de granularidade dos dados e cálculos e consolidações não-triviais. | D22: Alta
A23: POWERCENTER | B23: ETL | C23: Dados: Seleção de 1 tabela de origem. Lógico: Mapa com pouca ou nehuma transformação envolvida no workflow. | D23: Baixa
A24: POWERCENTER | B24: ETL | C24: Dados: Extração de dados a partir de mais de uma tabela. Lógico: Workflows com mais de um mapa e transformações simples (Extract, Filter) envolvidas. | D24: Média
A25: POWERCENTER | B25: ETL | C25: Dados: Extração de dados a partir de mais de uma tabela. Lógico: Workflows com vários mapa, transformações não triviais(Aggregator, Joiner, Router, LookUps) e/ou loops envolvidos. | D25: Alta
A26: POWERCENTER | B26: CDC | C26: Dados: Seleção de 1 tabela de origem. Lógico: Mapa com pouca ou nehuma transformação envolvida no workflow. | D26: Baixa
A27: POWERCENTER | B27: ETL CDC | C27: Dados: Extração de dados a partir de mais de uma tabela. Lógico: Workflows com mais de um mapa e transformações simples (Extract, Filter) envolvidas. | D27: Média
A28: POWERCENTER | B28: ETL CDC | C28: Dados: Extração de dados a partir de mais de uma tabela. Lógico: Workflows com vários mapa, transformações não triviais(Aggregator, Joiner, Router, LookUps) e/ou loops envolvidos. | D28: Alta
... A100: Sharepoint | B100: Relatório | C100: Dados: Relatório com acesso de 8 ou mais tabelas ou com leitura de 4 ou mais arquivos externos, dados de mais de um modulos Lógico: Utilização de varias telas,tratamento de campos,grande variação de regras, layout dos relatórios complexos (janelas, texto, fonte etc) e vários drill downs e chamada de 3 ou mais funções de bibliotecas fora do conjunto nativo do Sharepoint. | D100: Alta

Sheet Listas
A1: Briefing_Req | F1: Estimativa Funcionalidades
A2: Prioridade | B2: Alteração de Requerimento após P0? | C2: Núcleo | F2: Atendimento | G2: Forma Atendimento | I2: Ação | J2: Complexidade
A3: 1 | B3: Adicionado | C3: Cadastro | F3: Atende | G3: 1- Desenvolvimento | I3: Criação | J3: Alta
A4: 2 | B4: Cancelado | C4: CRM Marketing | F4: Atende Parcial | G4: 2- Configuração de Pacote | I4: Alteração | J4: Média
A5: 3 | B5: Incluído | C5: Comercial | F5: Não atende | G5: 3- Solução SaaS | I5: Exclusão | J5: Baixa
B6: Ampliado | C6: Captação | I6: Reaprov. Serviço
B7: Simplificado | C7: Atendimento Pós Venda
B8: N/A | C8: Distribuição
C9: Sharepoint
C10: Gestão de Conteudo
C11: Mobile
C12: Suprimentos
C13: Industrial
C14: Plan & Produção
C15: Finanças
C16: RH e Sustentabilidade
C17: Inovação e Marca
C18: BI-SAP
C19: BI-Custom
C20: CRM Analitico
