Workbook

Sheet Campaign Name Validation
A1: Placement Name (Please paste Placement Names below) | B1: Overall Placement Name Validity | D1: KPI Validity | E1: Priority Partner Validity | F1: Costing Model Validity | G1: Primary Targeting Segment Validity | H1: Detailed Targeting Segment Validity | I1: Format Validity | M1: Column1 | N1: KPI Field | O1: Format Field | P1: Priority Partner Field | Q1: Costing model Field | R1: Primary Targeting Segment Field | S1: Detailed Targeting Segment Field | T1: Column2 | U1: Column3 | V1: Column4 | W1: Column5 | X1: Column6
C2: good | F2: Region | G2: Portfolio | H2: business-channel | I2: media-channel | J2: objective | K2: addressable-code | L2: Campaign Start
A3: Campaign Name (Please paste Campaign Names below) | B3: Overall Validity | C3: Market Validity | D3: Sub-Product Validity | E3: Segment Validity | F3: Region Validity | G3: Portfolio Validity | H3: Business-Channel Validity | I3: Media Channel Validity | J3: Objective Validity | K3: Addressable Code Validity | L3: Campaign Start Date Validity | M3: Market | N3: Sub-Product | O3: Campaign Name | P3: Segment | Q3: Region | R3: Portfolio | S3: business-channel | T3: media-channel | U3: objective | V3: addressable-code | W3: Campaign Start | X3: free-form
B4: =IF(AND(D4="YES",I4="YES",E4="YES",F4="YES",G4="YES",H4="Yes"),"YES","NO") -> NO | C4: =IFERROR(VLOOKUP(M4,Lookups!$A$3:$B$87,2,FALSE),"NO") -> NO | D4: =IFERROR(VLOOKUP(N4,Lookups!$D$2:$E$211,2,FALSE),"NO") -> NO | E4: =IFERROR(VLOOKUP(P4,Lookups!$I$3:$J$8,2,FALSE),"NO") -> NO | F4: =IFERROR(VLOOKUP(Q4,Lookups!$L$3:$M$7,2,FALSE),"NO") -> NO | G4: =IFERROR(VLOOKUP(R4,Lookups!$O$3:$P$21,2,FALSE),"NO") -> NO | H4: =IFERROR(VLOOKUP(S4,Lookups!$S$3:$T$6,2,FALSE),"NO") -> NO | I4: =IFERROR(VLOOKUP(T4,Lookups!$V$3:$W$15,2,FALSE),"NO") -> NO | J4: =IFERROR(VLOOKUP(U4,Lookups!$Z$3:$AA$9,2,FALSE),"NO") -> NO | K4: =IFERROR(VLOOKUP(V4,Lookups!$AC$3:$AD$12,2,FALSE),"NO") -> NO | L4: =IFERROR(VLOOKUP(W4,Lookups!$AH$3:$AI$74,2,FALSE),"NO") -> NO | M4: =TRIM(MID(SUBSTITUTE(A4,"_",REPT(" ",LEN(A4))),(1-1)*LEN(A4)+1,LEN(A4))) | N4: =TRIM(MID(SUBSTITUTE(A4,"_",REPT(" ",LEN(A4))),(2-1)*LEN(A4)+1,LEN(A4))) | O4: =TRIM(MID(SUBSTITUTE(A4,"_",REPT(" ",LEN(A4))),(3-1)*LEN(A4)+1,LEN(A4))) | P4: =TRIM(MID(SUBSTITUTE(A4,"_",REPT(" ",LEN(A4))),(4-1)*LEN(A4)+1,LEN(A4))) | Q4: =TRIM(MID(SUBSTITUTE(A4,"_",REPT(" ",LEN(A4))),(5-1)*LEN(A4)+1,LEN(A4))) | R4: =TRIM(MID(SUBSTITUTE(A4,"_",REPT(" ",LEN(A4))),(6-1)*LEN(A4)+1,LEN(A4))) | S4: =TRIM(MID(SUBSTITUTE(A4,"_",REPT(" ",LEN(A4))),(7-1)*LEN(A4)+1,LEN(A4))) | T4: =TRIM(MID(SUBSTITUTE(A4,"_",REPT(" ",LEN(A4))),(8-1)*LEN(A4)+1,LEN(A4))) | U4: =TRIM(MID(SUBSTITUTE(A4,"_",REPT(" ",LEN(A4))),(9-1)*LEN(A4)+1,LEN(A4))) | V4: =TRIM(MID(SUBSTITUTE(A4,"_",REPT(" ",LEN(A4))),(10-1)*LEN(A4)+1,LEN(A4))) | W4: =TRIM(MID(SUBSTITUTE(A4,"_",REPT(" ",LEN(A4))),(11-1)*LEN(A4)+1,LEN(A4))) | X4: =TRIM(MID(SUBSTITUTE(A4,"_",REPT(" ",LEN(A4))),(12-1)*LEN(A4)+1,LEN(A4)))
A5: es_pdg_p1-p2-vnp_pn_mea_ct_brand_olv_awareness_bid-adr_0122_0 | B5: =IF(AND(D5="YES",I5="YES",E5="YES",F5="YES",G5="YES",H5="Yes"),"YES","NO") -> YES | C5: =IFERROR(VLOOKUP(M5,Lookups!$A$3:$B$87,2,FALSE),"NO") -> Yes | D5: =IFERROR(VLOOKUP(N5,Lookups!$D$2:$E$211,2,FALSE),"NO") -> YES | E5: =IFERROR(VLOOKUP(P5,Lookups!$I$3:$J$8,2,FALSE),"NO") -> YES | F5: =IFERROR(VLOOKUP(Q5,Lookups!$L$3:$M$7,2,FALSE),"NO") -> YES | G5: =IFERROR(VLOOKUP(R5,Lookups!$O$3:$P$21,2,FALSE),"NO") -> YES | H5: =IFERROR(VLOOKUP(S5,Lookups!$S$3:$T$6,2,FALSE),"NO") -> YES | I5: =IFERROR(VLOOKUP(T5,Lookups!$V$3:$W$15,2,FALSE),"NO") -> YES | J5: =IFERROR(VLOOKUP(U5,Lookups!$Z$3:$AA$9,2,FALSE),"NO") -> YES | K5: =IFERROR(VLOOKUP(V5,Lookups!$AC$3:$AD$12,2,FALSE),"NO") -> Yes | L5: =IFERROR(VLOOKUP(W5,Lookups!$AH$3:$AI$74,2,FALSE),"NO") -> Yes | M5: =TRIM(MID(SUBSTITUTE(A5,"_",REPT(" ",LEN(A5))),(1-1)*LEN(A5)+1,LEN(A5))) -> es | N5: =TRIM(MID(SUBSTITUTE(A5,"_",REPT(" ",LEN(A5))),(2-1)*LEN(A5)+1,LEN(A5))) -> pdg | O5: =TRIM(MID(SUBSTITUTE(A5,"_",REPT(" ",LEN(A5))),(3-1)*LEN(A5)+1,LEN(A5))) -> p1-p2-vnp | P5: =TRIM(MID(SUBSTITUTE(A5,"_",REPT(" ",LEN(A5))),(4-1)*LEN(A5)+1,LEN(A5))) -> pn | Q5: =TRIM(MID(SUBSTITUTE(A5,"_",REPT(" ",LEN(A5))),(5-1)*LEN(A5)+1,LEN(A5))) -> mea | R5: =TRIM(MID(SUBSTITUTE(A5,"_",REPT(" ",LEN(A5))),(6-1)*LEN(A5)+1,LEN(A5))) -> ct | S5: =TRIM(MID(SUBSTITUTE(A5,"_",REPT(" ",LEN(A5))),(7-1)*LEN(A5)+1,LEN(A5))) -> brand | T5: =TRIM(MID(SUBSTITUTE(A5,"_",REPT(" ",LEN(A5))),(8-1)*LEN(A5)+1,LEN(A5))) -> olv | U5: =TRIM(MID(SUBSTITUTE(A5,"_",REPT(" ",LEN(A5))),(9-1)*LEN(A5)+1,LEN(A5))) -> awareness | V5: =TRIM(MID(SUBSTITUTE(A5,"_",REPT(" ",LEN(A5))),(10-1)*LEN(A5)+1,LEN(A5))) -> bid-adr | W5: =TRIM(MID(SUBSTITUTE(A5,"_",REPT(" ",LEN(A5))),(11-1)*LEN(A5)+1,LEN(A5))) -> 0122 | X5: =TRIM(MID(SUBSTITUTE(A5,"_",REPT(" ",LEN(A5))),(12-1)*LEN(A5)+1,LEN(A5))) -> 0
A6: sa_exg_p1-gydb-3.0_mw_mea_gum_brand_olv_awareness_dir-dda_0123_olv | B6: =IF(AND(D6="YES",I6="YES",E6="YES",F6="YES",G6="YES",H6="Yes"),"YES","NO") -> YES | C6: =IFERROR(VLOOKUP(M6,Lookups!$A$3:$B$87,2,FALSE),"NO") -> Yes | D6: =IFERROR(VLOOKUP(N6,Lookups!$D$2:$E$211,2,FALSE),"NO") -> YES | E6: =IFERROR(VLOOKUP(P6,Lookups!$I$3:$J$8,2,FALSE),"NO") -> YES | F6: =IFERROR(VLOOKUP(Q6,Lookups!$L$3:$M$7,2,FALSE),"NO") -> YES | G6: =IFERROR(VLOOKUP(R6,Lookups!$O$3:$P$21,2,FALSE),"NO") -> YES | H6: =IFERROR(VLOOKUP(S6,Lookups!$S$3:$T$6,2,FALSE),"NO") -> YES | I6: =IFERROR(VLOOKUP(T6,Lookups!$V$3:$W$15,2,FALSE),"NO") -> YES | J6: =IFERROR(VLOOKUP(U6,Lookups!$Z$3:$AA$9,2,FALSE),"NO") -> YES | K6: =IFERROR(VLOOKUP(V6,Lookups!$AC$3:$AD$12,2,FALSE),"NO") -> Yes | L6: =IFERROR(VLOOKUP(W6,Lookups!$AH$3:$AI$74,2,FALSE),"NO") -> Yes | M6: =TRIM(MID(SUBSTITUTE(A6,"_",REPT(" ",LEN(A6))),(1-1)*LEN(A6)+1,LEN(A6))) -> sa | N6: =TRIM(MID(SUBSTITUTE(A6,"_",REPT(" ",LEN(A6))),(2-1)*LEN(A6)+1,LEN(A6))) -> exg | O6: =TRIM(MID(SUBSTITUTE(A6,"_",REPT(" ",LEN(A6))),(3-1)*LEN(A6)+1,LEN(A6))) -> p1-gydb-3.0 | P6: =TRIM(MID(SUBSTITUTE(A6,"_",REPT(" ",LEN(A6))),(4-1)*LEN(A6)+1,LEN(A6))) -> mw | Q6: =TRIM(MID(SUBSTITUTE(A6,"_",REPT(" ",LEN(A6))),(5-1)*LEN(A6)+1,LEN(A6))) -> mea | R6: =TRIM(MID(SUBSTITUTE(A6,"_",REPT(" ",LEN(A6))),(6-1)*LEN(A6)+1,LEN(A6))) -> gum | S6: =TRIM(MID(SUBSTITUTE(A6,"_",REPT(" ",LEN(A6))),(7-1)*LEN(A6)+1,LEN(A6))) -> brand | T6: =TRIM(MID(SUBSTITUTE(A6,"_",REPT(" ",LEN(A6))),(8-1)*LEN(A6)+1,LEN(A6))) -> olv | U6: =TRIM(MID(SUBSTITUTE(A6,"_",REPT(" ",LEN(A6))),(9-1)*LEN(A6)+1,LEN(A6))) -> awareness | V6: =TRIM(MID(SUBSTITUTE(A6,"_",REPT(" ",LEN(A6))),(10-1)*LEN(A6)+1,LEN(A6))) -> dir-dda | W6: =TRIM(MID(SUBSTITUTE(A6,"_",REPT(" ",LEN(A6))),(11-1)*LEN(A6)+1,LEN(A6))) -> 0123 | X6: =TRIM(MID(SUBSTITUTE(A6,"_",REPT(" ",LEN(A6))),(12-1)*LEN(A6)+1,LEN(A6))) -> olv
B7: =IF(AND(D7="YES",I7="YES",E7="YES",F7="YES",G7="YES",H7="Yes"),"YES","NO") -> NO | C7: =IFERROR(VLOOKUP(M7,Lookups!$A$3:$B$87,2,FALSE),"NO") -> NO | D7: =IFERROR(VLOOKUP(N7,Lookups!$D$2:$E$211,2,FALSE),"NO") -> NO | E7: =IFERROR(VLOOKUP(P7,Lookups!$I$3:$J$8,2,FALSE),"NO") -> NO | F7: =IFERROR(VLOOKUP(Q7,Lookups!$L$3:$M$7,2,FALSE),"NO") -> NO | G7: =IFERROR(VLOOKUP(R7,Lookups!$O$3:$P$21,2,FALSE),"NO") -> NO | H7: =IFERROR(VLOOKUP(S7,Lookups!$S$3:$T$6,2,FALSE),"NO") -> NO | I7: =IFERROR(VLOOKUP(T7,Lookups!$V$3:$W$15,2,FALSE),"NO") -> NO | J7: =IFERROR(VLOOKUP(U7,Lookups!$Z$3:$AA$9,2,FALSE),"NO") -> NO | K7: =IFERROR(VLOOKUP(V7,Lookups!$AC$3:$AD$12,2,FALSE),"NO") -> NO | L7: =IFERROR(VLOOKUP(W7,Lookups!$AH$3:$AI$74,2,FALSE),"NO") -> NO | M7: =TRIM(MID(SUBSTITUTE(A7,"_",REPT(" ",LEN(A7))),(1-1)*LEN(A7)+1,LEN(A7))) | N7: =TRIM(MID(SUBSTITUTE(A7,"_",REPT(" ",LEN(A7))),(2-1)*LEN(A7)+1,LEN(A7))) | O7: =TRIM(MID(SUBSTITUTE(A7,"_",REPT(" ",LEN(A7))),(3-1)*LEN(A7)+1,LEN(A7))) | P7: =TRIM(MID(SUBSTITUTE(A7,"_",REPT(" ",LEN(A7))),(4-1)*LEN(A7)+1,LEN(A7))) | Q7: =TRIM(MID(SUBSTITUTE(A7,"_",REPT(" ",LEN(A7))),(5-1)*LEN(A7)+1,LEN(A7))) | R7: =TRIM(MID(SUBSTITUTE(A7,"_",REPT(" ",LEN(A7))),(6-1)*LEN(A7)+1,LEN(A7))) | S7: =TRIM(MID(SUBSTITUTE(A7,"_",REPT(" ",LEN(A7))),(7-1)*LEN(A7)+1,LEN(A7))) | T7: =TRIM(MID(SUBSTITUTE(A7,"_",REPT(" ",LEN(A7))),(8-1)*LEN(A7)+1,LEN(A7))) | U7: =TRIM(MID(SUBSTITUTE(A7,"_",REPT(" ",LEN(A7))),(9-1)*LEN(A7)+1,LEN(A7))) | V7: =TRIM(MID(SUBSTITUTE(A7,"_",REPT(" ",LEN(A7))),(10-1)*LEN(A7)+1,LEN(A7))) | W7: =TRIM(MID(SUBSTITUTE(A7,"_",REPT(" ",LEN(A7))),(11-1)*LEN(A7)+1,LEN(A7))) | X7: =TRIM(MID(SUBSTITUTE(A7,"_",REPT(" ",LEN(A7))),(12-1)*LEN(A7)+1,LEN(A7)))
A8: fr_fre_p1-gydb-3.0-vnp_mw_eur_gum_brand_olv_awareness_bid-nadr_0123_na | B8: =IF(AND(D8="YES",I8="YES",E8="YES",F8="YES",G8="YES",H8="Yes"),"YES","NO") -> YES | C8: =IFERROR(VLOOKUP(M8,Lookups!$A$3:$B$87,2,FALSE),"NO") -> Yes | D8: =IFERROR(VLOOKUP(N8,Lookups!$D$2:$E$211,2,FALSE),"NO") -> YES | E8: =IFERROR(VLOOKUP(P8,Lookups!$I$3:$J$8,2,FALSE),"NO") -> YES | F8: =IFERROR(VLOOKUP(Q8,Lookups!$L$3:$M$7,2,FALSE),"NO") -> YES | G8: =IFERROR(VLOOKUP(R8,Lookups!$O$3:$P$21,2,FALSE),"NO") -> YES | H8: =IFERROR(VLOOKUP(S8,Lookups!$S$3:$T$6,2,FALSE),"NO") -> YES | I8: =IFERROR(VLOOKUP(T8,Lookups!$V$3:$W$15,2,FALSE),"NO") -> YES | J8: =IFERROR(VLOOKUP(U8,Lookups!$Z$3:$AA$9,2,FALSE),"NO") -> YES | K8: =IFERROR(VLOOKUP(V8,Lookups!$AC$3:$AD$12,2,FALSE),"NO") -> Yes | L8: =IFERROR(VLOOKUP(W8,Lookups!$AH$3:$AI$74,2,FALSE),"NO") -> Yes | M8: =TRIM(MID(SUBSTITUTE(A8,"_",REPT(" ",LEN(A8))),(1-1)*LEN(A8)+1,LEN(A8))) -> fr | N8: =TRIM(MID(SUBSTITUTE(A8,"_",REPT(" ",LEN(A8))),(2-1)*LEN(A8)+1,LEN(A8))) -> fre | O8: =TRIM(MID(SUBSTITUTE(A8,"_",REPT(" ",LEN(A8))),(3-1)*LEN(A8)+1,LEN(A8))) -> p1-gydb-3.0-vnp | P8: =TRIM(MID(SUBSTITUTE(A8,"_",REPT(" ",LEN(A8))),(4-1)*LEN(A8)+1,LEN(A8))) -> mw | Q8: =TRIM(MID(SUBSTITUTE(A8,"_",REPT(" ",LEN(A8))),(5-1)*LEN(A8)+1,LEN(A8))) -> eur | R8: =TRIM(MID(SUBSTITUTE(A8,"_",REPT(" ",LEN(A8))),(6-1)*LEN(A8)+1,LEN(A8))) -> gum | S8: =TRIM(MID(SUBSTITUTE(A8,"_",REPT(" ",LEN(A8))),(7-1)*LEN(A8)+1,LEN(A8))) -> brand | T8: =TRIM(MID(SUBSTITUTE(A8,"_",REPT(" ",LEN(A8))),(8-1)*LEN(A8)+1,LEN(A8))) -> olv | U8: =TRIM(MID(SUBSTITUTE(A8,"_",REPT(" ",LEN(A8))),(9-1)*LEN(A8)+1,LEN(A8))) -> awareness | V8: =TRIM(MID(SUBSTITUTE(A8,"_",REPT(" ",LEN(A8))),(10-1)*LEN(A8)+1,LEN(A8))) -> bid-nadr | W8: =TRIM(MID(SUBSTITUTE(A8,"_",REPT(" ",LEN(A8))),(11-1)*LEN(A8)+1,LEN(A8))) -> 0123 | X8: =TRIM(MID(SUBSTITUTE(A8,"_",REPT(" ",LEN(A8))),(12-1)*LEN(A8)+1,LEN(A8))) -> na
B9: =IF(AND(D9="YES",I9="YES",E9="YES",F9="YES",G9="YES",H9="Yes"),"YES","NO") -> NO | C9: =IFERROR(VLOOKUP(M9,Lookups!$A$3:$B$87,2,FALSE),"NO") -> NO | D9: =IFERROR(VLOOKUP(N9,Lookups!$D$2:$E$211,2,FALSE),"NO") -> NO | E9: =IFERROR(VLOOKUP(P9,Lookups!$I$3:$J$8,2,FALSE),"NO") -> NO | F9: =IFERROR(VLOOKUP(Q9,Lookups!$L$3:$M$7,2,FALSE),"NO") -> NO | G9: =IFERROR(VLOOKUP(R9,Lookups!$O$3:$P$21,2,FALSE),"NO") -> NO | H9: =IFERROR(VLOOKUP(S9,Lookups!$S$3:$T$6,2,FALSE),"NO") -> NO | I9: =IFERROR(VLOOKUP(T9,Lookups!$V$3:$W$15,2,FALSE),"NO") -> NO | J9: =IFERROR(VLOOKUP(U9,Lookups!$Z$3:$AA$9,2,FALSE),"NO") -> NO | K9: =IFERROR(VLOOKUP(V9,Lookups!$AC$3:$AD$12,2,FALSE),"NO") -> NO | L9: =IFERROR(VLOOKUP(W9,Lookups!$AH$3:$AI$74,2,FALSE),"NO") -> NO | M9: =TRIM(MID(SUBSTITUTE(A9,"_",REPT(" ",LEN(A9))),(1-1)*LEN(A9)+1,LEN(A9))) | N9: =TRIM(MID(SUBSTITUTE(A9,"_",REPT(" ",LEN(A9))),(2-1)*LEN(A9)+1,LEN(A9))) | O9: =TRIM(MID(SUBSTITUTE(A9,"_",REPT(" ",LEN(A9))),(3-1)*LEN(A9)+1,LEN(A9))) | P9: =TRIM(MID(SUBSTITUTE(A9,"_",REPT(" ",LEN(A9))),(4-1)*LEN(A9)+1,LEN(A9))) | Q9: =TRIM(MID(SUBSTITUTE(A9,"_",REPT(" ",LEN(A9))),(5-1)*LEN(A9)+1,LEN(A9))) | R9: =TRIM(MID(SUBSTITUTE(A9,"_",REPT(" ",LEN(A9))),(6-1)*LEN(A9)+1,LEN(A9))) | S9: =TRIM(MID(SUBSTITUTE(A9,"_",REPT(" ",LEN(A9))),(7-1)*LEN(A9)+1,LEN(A9))) | T9: =TRIM(MID(SUBSTITUTE(A9,"_",REPT(" ",LEN(A9))),(8-1)*LEN(A9)+1,LEN(A9))) | U9: =TRIM(MID(SUBSTITUTE(A9,"_",REPT(" ",LEN(A9))),(9-1)*LEN(A9)+1,LEN(A9))) | V9: =TRIM(MID(SUBSTITUTE(A9,"_",REPT(" ",LEN(A9))),(10-1)*LEN(A9)+1,LEN(A9))) | W9: =TRIM(MID(SUBSTITUTE(A9,"_",REPT(" ",LEN(A9))),(11-1)*LEN(A9)+1,LEN(A9))) | X9: =TRIM(MID(SUBSTITUTE(A9,"_",REPT(" ",LEN(A9))),(12-1)*LEN(A9)+1,LEN(A9)))
A10: gb_mal_bunnies_mw_mea_con_d2c_display_awareness_bid-nadr_0123_bliss | B10: =IF(AND(D10="YES",I10="YES",E10="YES",F10="YES",G10="YES",H10="Yes"),"YES","NO") -> YES | C10: =IFERROR(VLOOKUP(M10,Lookups!$A$3:$B$87,2,FALSE),"NO") -> Yes | D10: =IFERROR(VLOOKUP(N10,Lookups!$D$2:$E$211,2,FALSE),"NO") -> YES | E10: =IFERROR(VLOOKUP(P10,Lookups!$I$3:$J$8,2,FALSE),"NO") -> YES | F10: =IFERROR(VLOOKUP(Q10,Lookups!$L$3:$M$7,2,FALSE),"NO") -> YES | G10: =IFERROR(VLOOKUP(R10,Lookups!$O$3:$P$21,2,FALSE),"NO") -> YES | H10: =IFERROR(VLOOKUP(S10,Lookups!$S$3:$T$6,2,FALSE),"NO") -> YES | I10: =IFERROR(VLOOKUP(T10,Lookups!$V$3:$W$15,2,FALSE),"NO") -> YES | J10: =IFERROR(VLOOKUP(U10,Lookups!$Z$3:$AA$9,2,FALSE),"NO") -> YES | K10: =IFERROR(VLOOKUP(V10,Lookups!$AC$3:$AD$12,2,FALSE),"NO") -> Yes | L10: =IFERROR(VLOOKUP(W10,Lookups!$AH$3:$AI$74,2,FALSE),"NO") -> Yes | M10: =TRIM(MID(SUBSTITUTE(A10,"_",REPT(" ",LEN(A10))),(1-1)*LEN(A10)+1,LEN(A10))) -> gb | N10: =TRIM(MID(SUBSTITUTE(A10,"_",REPT(" ",LEN(A10))),(2-1)*LEN(A10)+1,LEN(A10))) -> mal | O10: =TRIM(MID(SUBSTITUTE(A10,"_",REPT(" ",LEN(A10))),(3-1)*LEN(A10)+1,LEN(A10))) -> bunnies | P10: =TRIM(MID(SUBSTITUTE(A10,"_",REPT(" ",LEN(A10))),(4-1)*LEN(A10)+1,LEN(A10))) -> mw | Q10: =TRIM(MID(SUBSTITUTE(A10,"_",REPT(" ",LEN(A10))),(5-1)*LEN(A10)+1,LEN(A10))) -> mea | R10: =TRIM(MID(SUBSTITUTE(A10,"_",REPT(" ",LEN(A10))),(6-1)*LEN(A10)+1,LEN(A10))) -> con | S10: =TRIM(MID(SUBSTITUTE(A10,"_",REPT(" ",LEN(A10))),(7-1)*LEN(A10)+1,LEN(A10))) -> d2c | T10: =TRIM(MID(SUBSTITUTE(A10,"_",REPT(" ",LEN(A10))),(8-1)*LEN(A10)+1,LEN(A10))) -> display | U10: =TRIM(MID(SUBSTITUTE(A10,"_",REPT(" ",LEN(A10))),(9-1)*LEN(A10)+1,LEN(A10))) -> awareness | V10: =TRIM(MID(SUBSTITUTE(A10,"_",REPT(" ",LEN(A10))),(10-1)*LEN(A10)+1,LEN(A10))) -> bid-nadr | W10: =TRIM(MID(SUBSTITUTE(A10,"_",REPT(" ",LEN(A10))),(11-1)*LEN(A10)+1,LEN(A10))) -> 0123 | X10: =TRIM(MID(SUBSTITUTE(A10,"_",REPT(" ",LEN(A10))),(12-1)*LEN(A10)+1,LEN(A10))) -> bliss
A11: fr_suw_p1-cny_food_eur_oth_brand_olv_awareness_bid-dda_0123_na | B11: =IF(AND(D11="YES",I11="YES",E11="YES",F11="YES",G11="YES",H11="Yes"),"YES","NO") -> YES | C11: =IFERROR(VLOOKUP(M11,Lookups!$A$3:$B$87,2,FALSE),"NO") -> Yes | D11: =IFERROR(VLOOKUP(N11,Lookups!$D$2:$E$211,2,FALSE),"NO") -> YES | E11: =IFERROR(VLOOKUP(P11,Lookups!$I$3:$J$8,2,FALSE),"NO") -> YES | F11: =IFERROR(VLOOKUP(Q11,Lookups!$L$3:$M$7,2,FALSE),"NO") -> YES | G11: =IFERROR(VLOOKUP(R11,Lookups!$O$3:$P$21,2,FALSE),"NO") -> YES | H11: =IFERROR(VLOOKUP(S11,Lookups!$S$3:$T$6,2,FALSE),"NO") -> YES | I11: =IFERROR(VLOOKUP(T11,Lookups!$V$3:$W$15,2,FALSE),"NO") -> YES | J11: =IFERROR(VLOOKUP(U11,Lookups!$Z$3:$AA$9,2,FALSE),"NO") -> YES | K11: =IFERROR(VLOOKUP(V11,Lookups!$AC$3:$AD$12,2,FALSE),"NO") -> Yes | L11: =IFERROR(VLOOKUP(W11,Lookups!$AH$3:$AI$74,2,FALSE),"NO") -> Yes | M11: =TRIM(MID(SUBSTITUTE(A11,"_",REPT(" ",LEN(A11))),(1-1)*LEN(A11)+1,LEN(A11))) -> fr | N11: =TRIM(MID(SUBSTITUTE(A11,"_",REPT(" ",LEN(A11))),(2-1)*LEN(A11)+1,LEN(A11))) -> suw | O11: =TRIM(MID(SUBSTITUTE(A11,"_",REPT(" ",LEN(A11))),(3-1)*LEN(A11)+1,LEN(A11))) -> p1-cny | P11: =TRIM(MID(SUBSTITUTE(A11,"_",REPT(" ",LEN(A11))),(4-1)*LEN(A11)+1,LEN(A11))) -> food | Q11: =TRIM(MID(SUBSTITUTE(A11,"_",REPT(" ",LEN(A11))),(5-1)*LEN(A11)+1,LEN(A11))) -> eur | R11: =TRIM(MID(SUBSTITUTE(A11,"_",REPT(" ",LEN(A11))),(6-1)*LEN(A11)+1,LEN(A11))) -> oth | S11: =TRIM(MID(SUBSTITUTE(A11,"_",REPT(" ",LEN(A11))),(7-1)*LEN(A11)+1,LEN(A11))) -> brand | T11: =TRIM(MID(SUBSTITUTE(A11,"_",REPT(" ",LEN(A11))),(8-1)*LEN(A11)+1,LEN(A11))) -> olv | U11: =TRIM(MID(SUBSTITUTE(A11,"_",REPT(" ",LEN(A11))),(9-1)*LEN(A11)+1,LEN(A11))) -> awareness | V11: =TRIM(MID(SUBSTITUTE(A11,"_",REPT(" ",LEN(A11))),(10-1)*LEN(A11)+1,LEN(A11))) -> bid-dda | W11: =TRIM(MID(SUBSTITUTE(A11,"_",REPT(" ",LEN(A11))),(11-1)*LEN(A11)+1,LEN(A11))) -> 0123 | X11: =TRIM(MID(SUBSTITUTE(A11,"_",REPT(" ",LEN(A11))),(12-1)*LEN(A11)+1,LEN(A11))) -> na
A12: fr_fre_p1-gydb-3.0-vnp_mw_eur_gum_brand_olv_awareness_bid-nadr_0123_na | B12: =IF(AND(D12="YES",I12="YES",E12="YES",F12="YES",G12="YES",H12="Yes"),"YES","NO") -> YES | C12: =IFERROR(VLOOKUP(M12,Lookups!$A$3:$B$87,2,FALSE),"NO") -> Yes | D12: =IFERROR(VLOOKUP(N12,Lookups!$D$2:$E$211,2,FALSE),"NO") -> YES | E12: =IFERROR(VLOOKUP(P12,Lookups!$I$3:$J$8,2,FALSE),"NO") -> YES | F12: =IFERROR(VLOOKUP(Q12,Lookups!$L$3:$M$7,2,FALSE),"NO") -> YES | G12: =IFERROR(VLOOKUP(R12,Lookups!$O$3:$P$21,2,FALSE),"NO") -> YES | H12: =IFERROR(VLOOKUP(S12,Lookups!$S$3:$T$6,2,FALSE),"NO") -> YES | I12: =IFERROR(VLOOKUP(T12,Lookups!$V$3:$W$15,2,FALSE),"NO") -> YES | J12: =IFERROR(VLOOKUP(U12,Lookups!$Z$3:$AA$9,2,FALSE),"NO") -> YES | K12: =IFERROR(VLOOKUP(V12,Lookups!$AC$3:$AD$12,2,FALSE),"NO") -> Yes | L12: =IFERROR(VLOOKUP(W12,Lookups!$AH$3:$AI$74,2,FALSE),"NO") -> Yes | M12: =TRIM(MID(SUBSTITUTE(A12,"_",REPT(" ",LEN(A12))),(1-1)*LEN(A12)+1,LEN(A12))) -> fr | N12: =TRIM(MID(SUBSTITUTE(A12,"_",REPT(" ",LEN(A12))),(2-1)*LEN(A12)+1,LEN(A12))) -> fre | O12: =TRIM(MID(SUBSTITUTE(A12,"_",REPT(" ",LEN(A12))),(3-1)*LEN(A12)+1,LEN(A12))) -> p1-gydb-3.0-vnp | P12: =TRIM(MID(SUBSTITUTE(A12,"_",REPT(" ",LEN(A12))),(4-1)*LEN(A12)+1,LEN(A12))) -> mw | Q12: =TRIM(MID(SUBSTITUTE(A12,"_",REPT(" ",LEN(A12))),(5-1)*LEN(A12)+1,LEN(A12))) -> eur | R12: =TRIM(MID(SUBSTITUTE(A12,"_",REPT(" ",LEN(A12))),(6-1)*LEN(A12)+1,LEN(A12))) -> gum | S12: =TRIM(MID(SUBSTITUTE(A12,"_",REPT(" ",LEN(A12))),(7-1)*LEN(A12)+1,LEN(A12))) -> brand | T12: =TRIM(MID(SUBSTITUTE(A12,"_",REPT(" ",LEN(A12))),(8-1)*LEN(A12)+1,LEN(A12))) -> olv | U12: =TRIM(MID(SUBSTITUTE(A12,"_",REPT(" ",LEN(A12))),(9-1)*LEN(A12)+1,LEN(A12))) -> awareness | V12: =TRIM(MID(SUBSTITUTE(A12,"_",REPT(" ",LEN(A12))),(10-1)*LEN(A12)+1,LEN(A12))) -> bid-nadr | W12: =TRIM(MID(SUBSTITUTE(A12,"_",REPT(" ",LEN(A12))),(11-1)*LEN(A12)+1,LEN(A12))) -> 0123 | X12: =TRIM(MID(SUBSTITUTE(A12,"_",REPT(" ",LEN(A12))),(12-1)*LEN(A12)+1,LEN(A12))) -> na
A13: de_twx_p1-vnp_mw_eur_cho_brand_olv_awareness_bid-nadr_0123_na | B13: =IF(AND(D13="YES",I13="YES",E13="YES",F13="YES",G13="YES",H13="Yes"),"YES","NO") -> YES | C13: =IFERROR(VLOOKUP(M13,Lookups!$A$3:$B$87,2,FALSE),"NO") -> Yes | D13: =IFERROR(VLOOKUP(N13,Lookups!$D$2:$E$211,2,FALSE),"NO") -> YES | E13: =IFERROR(VLOOKUP(P13,Lookups!$I$3:$J$8,2,FALSE),"NO") -> YES | F13: =IFERROR(VLOOKUP(Q13,Lookups!$L$3:$M$7,2,FALSE),"NO") -> YES | G13: =IFERROR(VLOOKUP(R13,Lookups!$O$3:$P$21,2,FALSE),"NO") -> YES | H13: =IFERROR(VLOOKUP(S13,Lookups!$S$3:$T$6,2,FALSE),"NO") -> YES | I13: =IFERROR(VLOOKUP(T13,Lookups!$V$3:$W$15,2,FALSE),"NO") -> YES | J13: =IFERROR(VLOOKUP(U13,Lookups!$Z$3:$AA$9,2,FALSE),"NO") -> YES | K13: =IFERROR(VLOOKUP(V13,Lookups!$AC$3:$AD$12,2,FALSE),"NO") -> Yes | L13: =IFERROR(VLOOKUP(W13,Lookups!$AH$3:$AI$74,2,FALSE),"NO") -> Yes | M13: =TRIM(MID(SUBSTITUTE(A13,"_",REPT(" ",LEN(A13))),(1-1)*LEN(A13)+1,LEN(A13))) -> de | N13: =TRIM(MID(SUBSTITUTE(A13,"_",REPT(" ",LEN(A13))),(2-1)*LEN(A13)+1,LEN(A13))) -> twx | O13: =TRIM(MID(SUBSTITUTE(A13,"_",REPT(" ",LEN(A13))),(3-1)*LEN(A13)+1,LEN(A13))) -> p1-vnp | P13: =TRIM(MID(SUBSTITUTE(A13,"_",REPT(" ",LEN(A13))),(4-1)*LEN(A13)+1,LEN(A13))) -> mw | Q13: =TRIM(MID(SUBSTITUTE(A13,"_",REPT(" ",LEN(A13))),(5-1)*LEN(A13)+1,LEN(A13))) -> eur | R13: =TRIM(MID(SUBSTITUTE(A13,"_",REPT(" ",LEN(A13))),(6-1)*LEN(A13)+1,LEN(A13))) -> cho | S13: =TRIM(MID(SUBSTITUTE(A13,"_",REPT(" ",LEN(A13))),(7-1)*LEN(A13)+1,LEN(A13))) -> brand | T13: =TRIM(MID(SUBSTITUTE(A13,"_",REPT(" ",LEN(A13))),(8-1)*LEN(A13)+1,LEN(A13))) -> olv | U13: =TRIM(MID(SUBSTITUTE(A13,"_",REPT(" ",LEN(A13))),(9-1)*LEN(A13)+1,LEN(A13))) -> awareness | V13: =TRIM(MID(SUBSTITUTE(A13,"_",REPT(" ",LEN(A13))),(10-1)*LEN(A13)+1,LEN(A13))) -> bid-nadr | W13: =TRIM(MID(SUBSTITUTE(A13,"_",REPT(" ",LEN(A13))),(11-1)*LEN(A13)+1,LEN(A13))) -> 0123 | X13: =TRIM(MID(SUBSTITUTE(A13,"_",REPT(" ",LEN(A13))),(12-1)*LEN(A13)+1,LEN(A13))) -> na
A14: de_pff_h1s1d2c_pn_eur_sph_d2c_social_conversions_bid-nadr_0123_22441 | B14: =IF(AND(D14="YES",I14="YES",E14="YES",F14="YES",G14="YES",H14="Yes"),"YES","NO") -> YES | C14: =IFERROR(VLOOKUP(M14,Lookups!$A$3:$B$87,2,FALSE),"NO") -> Yes | D14: =IFERROR(VLOOKUP(N14,Lookups!$D$2:$E$211,2,FALSE),"NO") -> YES | E14: =IFERROR(VLOOKUP(P14,Lookups!$I$3:$J$8,2,FALSE),"NO") -> YES | F14: =IFERROR(VLOOKUP(Q14,Lookups!$L$3:$M$7,2,FALSE),"NO") -> YES | G14: =IFERROR(VLOOKUP(R14,Lookups!$O$3:$P$21,2,FALSE),"NO") -> YES | H14: =IFERROR(VLOOKUP(S14,Lookups!$S$3:$T$6,2,FALSE),"NO") -> YES | I14: =IFERROR(VLOOKUP(T14,Lookups!$V$3:$W$15,2,FALSE),"NO") -> YES | J14: =IFERROR(VLOOKUP(U14,Lookups!$Z$3:$AA$9,2,FALSE),"NO") -> YES | K14: =IFERROR(VLOOKUP(V14,Lookups!$AC$3:$AD$12,2,FALSE),"NO") -> Yes | L14: =IFERROR(VLOOKUP(W14,Lookups!$AH$3:$AI$74,2,FALSE),"NO") -> Yes | M14: =TRIM(MID(SUBSTITUTE(A14,"_",REPT(" ",LEN(A14))),(1-1)*LEN(A14)+1,LEN(A14))) -> de | N14: =TRIM(MID(SUBSTITUTE(A14,"_",REPT(" ",LEN(A14))),(2-1)*LEN(A14)+1,LEN(A14))) -> pff | O14: =TRIM(MID(SUBSTITUTE(A14,"_",REPT(" ",LEN(A14))),(3-1)*LEN(A14)+1,LEN(A14))) -> h1s1d2c | P14: =TRIM(MID(SUBSTITUTE(A14,"_",REPT(" ",LEN(A14))),(4-1)*LEN(A14)+1,LEN(A14))) -> pn | Q14: =TRIM(MID(SUBSTITUTE(A14,"_",REPT(" ",LEN(A14))),(5-1)*LEN(A14)+1,LEN(A14))) -> eur | R14: =TRIM(MID(SUBSTITUTE(A14,"_",REPT(" ",LEN(A14))),(6-1)*LEN(A14)+1,LEN(A14))) -> sph | S14: =TRIM(MID(SUBSTITUTE(A14,"_",REPT(" ",LEN(A14))),(7-1)*LEN(A14)+1,LEN(A14))) -> d2c | T14: =TRIM(MID(SUBSTITUTE(A14,"_",REPT(" ",LEN(A14))),(8-1)*LEN(A14)+1,LEN(A14))) -> social | U14: =TRIM(MID(SUBSTITUTE(A14,"_",REPT(" ",LEN(A14))),(9-1)*LEN(A14)+1,LEN(A14))) -> conversions | V14: =TRIM(MID(SUBSTITUTE(A14,"_",REPT(" ",LEN(A14))),(10-1)*LEN(A14)+1,LEN(A14))) -> bid-nadr | W14: =TRIM(MID(SUBSTITUTE(A14,"_",REPT(" ",LEN(A14))),(11-1)*LEN(A14)+1,LEN(A14))) -> 0123 | X14: =TRIM(MID(SUBSTITUTE(A14,"_",REPT(" ",LEN(A14))),(12-1)*LEN(A14)+1,LEN(A14))) -> 22441
B15: =IF(AND(D15="YES",I15="YES",E15="YES",F15="YES",G15="YES",H15="Yes"),"YES","NO") -> NO | C15: =IFERROR(VLOOKUP(M15,Lookups!$A$3:$B$87,2,FALSE),"NO") -> NO | D15: =IFERROR(VLOOKUP(N15,Lookups!$D$2:$E$211,2,FALSE),"NO") -> NO | E15: =IFERROR(VLOOKUP(P15,Lookups!$I$3:$J$8,2,FALSE),"NO") -> NO | F15: =IFERROR(VLOOKUP(Q15,Lookups!$L$3:$M$7,2,FALSE),"NO") -> NO | G15: =IFERROR(VLOOKUP(R15,Lookups!$O$3:$P$21,2,FALSE),"NO") -> NO | H15: =IFERROR(VLOOKUP(S15,Lookups!$S$3:$T$6,2,FALSE),"NO") -> NO | I15: =IFERROR(VLOOKUP(T15,Lookups!$V$3:$W$15,2,FALSE),"NO") -> NO | J15: =IFERROR(VLOOKUP(U15,Lookups!$Z$3:$AA$9,2,FALSE),"NO") -> NO | K15: =IFERROR(VLOOKUP(V15,Lookups!$AC$3:$AD$12,2,FALSE),"NO") -> NO | L15: =IFERROR(VLOOKUP(W15,Lookups!$AH$3:$AI$74,2,FALSE),"NO") -> NO | M15: =TRIM(MID(SUBSTITUTE(A15,"_",REPT(" ",LEN(A15))),(1-1)*LEN(A15)+1,LEN(A15))) | N15: =TRIM(MID(SUBSTITUTE(A15,"_",REPT(" ",LEN(A15))),(2-1)*LEN(A15)+1,LEN(A15))) | O15: =TRIM(MID(SUBSTITUTE(A15,"_",REPT(" ",LEN(A15))),(3-1)*LEN(A15)+1,LEN(A15))) | P15: =TRIM(MID(SUBSTITUTE(A15,"_",REPT(" ",LEN(A15))),(4-1)*LEN(A15)+1,LEN(A15))) | Q15: =TRIM(MID(SUBSTITUTE(A15,"_",REPT(" ",LEN(A15))),(5-1)*LEN(A15)+1,LEN(A15))) | R15: =TRIM(MID(SUBSTITUTE(A15,"_",REPT(" ",LEN(A15))),(6-1)*LEN(A15)+1,LEN(A15))) | S15: =TRIM(MID(SUBSTITUTE(A15,"_",REPT(" ",LEN(A15))),(7-1)*LEN(A15)+1,LEN(A15))) | T15: =TRIM(MID(SUBSTITUTE(A15,"_",REPT(" ",LEN(A15))),(8-1)*LEN(A15)+1,LEN(A15))) | U15: =TRIM(MID(SUBSTITUTE(A15,"_",REPT(" ",LEN(A15))),(9-1)*LEN(A15)+1,LEN(A15))) | V15: =TRIM(MID(SUBSTITUTE(A15,"_",REPT(" ",LEN(A15))),(10-1)*LEN(A15)+1,LEN(A15))) | W15: =TRIM(MID(SUBSTITUTE(A15,"_",REPT(" ",LEN(A15))),(11-1)*LEN(A15)+1,LEN(A15))) | X15: =TRIM(MID(SUBSTITUTE(A15,"_",REPT(" ",LEN(A15))),(12-1)*LEN(A15)+1,LEN(A15)))
B16: =IF(AND(D16="YES",I16="YES",E16="YES",F16="YES",G16="YES",H16="Yes"),"YES","NO") -> NO | C16: =IFERROR(VLOOKUP(M16,Lookups!$A$3:$B$87,2,FALSE),"NO") -> NO | D16: =IFERROR(VLOOKUP(N16,Lookups!$D$2:$E$211,2,FALSE),"NO") -> NO | E16: =IFERROR(VLOOKUP(P16,Lookups!$I$3:$J$8,2,FALSE),"NO") -> NO | F16: =IFERROR(VLOOKUP(Q16,Lookups!$L$3:$M$7,2,FALSE),"NO") -> NO | G16: =IFERROR(VLOOKUP(R16,Lookups!$O$3:$P$21,2,FALSE),"NO") -> NO | H16: =IFERROR(VLOOKUP(S16,Lookups!$S$3:$T$6,2,FALSE),"NO") -> NO | I16: =IFERROR(VLOOKUP(T16,Lookups!$V$3:$W$15,2,FALSE),"NO") -> NO | J16: =IFERROR(VLOOKUP(U16,Lookups!$Z$3:$AA$9,2,FALSE),"NO") -> NO | K16: =IFERROR(VLOOKUP(V16,Lookups!$AC$3:$AD$12,2,FALSE),"NO") -> NO | L16: =IFERROR(VLOOKUP(W16,Lookups!$AH$3:$AI$74,2,FALSE),"NO") -> NO | M16: =TRIM(MID(SUBSTITUTE(A16,"_",REPT(" ",LEN(A16))),(1-1)*LEN(A16)+1,LEN(A16))) | N16: =TRIM(MID(SUBSTITUTE(A16,"_",REPT(" ",LEN(A16))),(2-1)*LEN(A16)+1,LEN(A16))) | O16: =TRIM(MID(SUBSTITUTE(A16,"_",REPT(" ",LEN(A16))),(3-1)*LEN(A16)+1,LEN(A16))) | P16: =TRIM(MID(SUBSTITUTE(A16,"_",REPT(" ",LEN(A16))),(4-1)*LEN(A16)+1,LEN(A16))) | Q16: =TRIM(MID(SUBSTITUTE(A16,"_",REPT(" ",LEN(A16))),(5-1)*LEN(A16)+1,LEN(A16))) | R16: =TRIM(MID(SUBSTITUTE(A16,"_",REPT(" ",LEN(A16))),(6-1)*LEN(A16)+1,LEN(A16))) | S16: =TRIM(MID(SUBSTITUTE(A16,"_",REPT(" ",LEN(A16))),(7-1)*LEN(A16)+1,LEN(A16))) | T16: =TRIM(MID(SUBSTITUTE(A16,"_",REPT(" ",LEN(A16))),(8-1)*LEN(A16)+1,LEN(A16))) | U16: =TRIM(MID(SUBSTITUTE(A16,"_",REPT(" ",LEN(A16))),(9-1)*LEN(A16)+1,LEN(A16))) | V16: =TRIM(MID(SUBSTITUTE(A16,"_",REPT(" ",LEN(A16))),(10-1)*LEN(A16)+1,LEN(A16))) | W16: =TRIM(MID(SUBSTITUTE(A16,"_",REPT(" ",LEN(A16))),(11-1)*LEN(A16)+1,LEN(A16))) | X16: =TRIM(MID(SUBSTITUTE(A16,"_",REPT(" ",LEN(A16))),(12-1)*LEN(A16)+1,LEN(A16)))
A17: MX_Kitekat_Pedigree launch_mw_apac_CT_Brand_audio_awareness_bid-adr_0522_xxxx | B17: =IF(AND(D17="YES",I17="YES",E17="YES",F17="YES",G17="YES",H17="Yes"),"YES","NO") -> NO | C17: =IFERROR(VLOOKUP(M17,Lookups!$A$3:$B$87,2,FALSE),"NO") -> Yes | D17: =IFERROR(VLOOKUP(N17,Lookups!$D$2:$E$211,2,FALSE),"NO") -> NO | E17: =IFERROR(VLOOKUP(P17,Lookups!$I$3:$J$8,2,FALSE),"NO") -> YES | F17: =IFERROR(VLOOKUP(Q17,Lookups!$L$3:$M$7,2,FALSE),"NO") -> YES | G17: =IFERROR(VLOOKUP(R17,Lookups!$O$3:$P$21,2,FALSE),"NO") -> YES | H17: =IFERROR(VLOOKUP(S17,Lookups!$S$3:$T$6,2,FALSE),"NO") -> YES | I17: =IFERROR(VLOOKUP(T17,Lookups!$V$3:$W$15,2,FALSE),"NO") -> YES | J17: =IFERROR(VLOOKUP(U17,Lookups!$Z$3:$AA$9,2,FALSE),"NO") -> YES | K17: =IFERROR(VLOOKUP(V17,Lookups!$AC$3:$AD$12,2,FALSE),"NO") -> Yes | L17: =IFERROR(VLOOKUP(W17,Lookups!$AH$3:$AI$74,2,FALSE),"NO") -> Yes | M17: =TRIM(MID(SUBSTITUTE(A17,"_",REPT(" ",LEN(A17))),(1-1)*LEN(A17)+1,LEN(A17))) -> MX | N17: =TRIM(MID(SUBSTITUTE(A17,"_",REPT(" ",LEN(A17))),(2-1)*LEN(A17)+1,LEN(A17))) -> Kitekat | O17: =TRIM(MID(SUBSTITUTE(A17,"_",REPT(" ",LEN(A17))),(3-1)*LEN(A17)+1,LEN(A17))) -> Pedigree launch | P17: =TRIM(MID(SUBSTITUTE(A17,"_",REPT(" ",LEN(A17))),(4-1)*LEN(A17)+1,LEN(A17))) -> mw | Q17: =TRIM(MID(SUBSTITUTE(A17,"_",REPT(" ",LEN(A17))),(5-1)*LEN(A17)+1,LEN(A17))) -> apac | R17: =TRIM(MID(SUBSTITUTE(A17,"_",REPT(" ",LEN(A17))),(6-1)*LEN(A17)+1,LEN(A17))) -> CT | S17: =TRIM(MID(SUBSTITUTE(A17,"_",REPT(" ",LEN(A17))),(7-1)*LEN(A17)+1,LEN(A17))) -> Brand | T17: =TRIM(MID(SUBSTITUTE(A17,"_",REPT(" ",LEN(A17))),(8-1)*LEN(A17)+1,LEN(A17))) -> audio | U17: =TRIM(MID(SUBSTITUTE(A17,"_",REPT(" ",LEN(A17))),(9-1)*LEN(A17)+1,LEN(A17))) -> awareness | V17: =TRIM(MID(SUBSTITUTE(A17,"_",REPT(" ",LEN(A17))),(10-1)*LEN(A17)+1,LEN(A17))) -> bid-adr | W17: =TRIM(MID(SUBSTITUTE(A17,"_",REPT(" ",LEN(A17))),(11-1)*LEN(A17)+1,LEN(A17))) -> 0522 | X17: =TRIM(MID(SUBSTITUTE(A17,"_",REPT(" ",LEN(A17))),(12-1)*LEN(A17)+1,LEN(A17))) -> xxxx
B18: =IF(AND(D18="YES",I18="YES",E18="YES",F18="YES",G18="YES",H18="Yes"),"YES","NO") -> NO | C18: =IFERROR(VLOOKUP(M18,Lookups!$A$3:$B$87,2,FALSE),"NO") -> NO | D18: =IFERROR(VLOOKUP(N18,Lookups!$D$2:$E$211,2,FALSE),"NO") -> NO | E18: =IFERROR(VLOOKUP(P18,Lookups!$I$3:$J$8,2,FALSE),"NO") -> NO | F18: =IFERROR(VLOOKUP(Q18,Lookups!$L$3:$M$7,2,FALSE),"NO") -> NO | G18: =IFERROR(VLOOKUP(R18,Lookups!$O$3:$P$21,2,FALSE),"NO") -> NO | H18: =IFERROR(VLOOKUP(S18,Lookups!$S$3:$T$6,2,FALSE),"NO") -> NO | I18: =IFERROR(VLOOKUP(T18,Lookups!$V$3:$W$15,2,FALSE),"NO") -> NO | J18: =IFERROR(VLOOKUP(U18,Lookups!$Z$3:$AA$9,2,FALSE),"NO") -> NO | K18: =IFERROR(VLOOKUP(V18,Lookups!$AC$3:$AD$12,2,FALSE),"NO") -> NO | L18: =IFERROR(VLOOKUP(W18,Lookups!$AH$3:$AI$74,2,FALSE),"NO") -> NO | M18: =TRIM(MID(SUBSTITUTE(A18,"_",REPT(" ",LEN(A18))),(1-1)*LEN(A18)+1,LEN(A18))) | N18: =TRIM(MID(SUBSTITUTE(A18,"_",REPT(" ",LEN(A18))),(2-1)*LEN(A18)+1,LEN(A18))) | O18: =TRIM(MID(SUBSTITUTE(A18,"_",REPT(" ",LEN(A18))),(3-1)*LEN(A18)+1,LEN(A18))) | P18: =TRIM(MID(SUBSTITUTE(A18,"_",REPT(" ",LEN(A18))),(4-1)*LEN(A18)+1,LEN(A18))) | Q18: =TRIM(MID(SUBSTITUTE(A18,"_",REPT(" ",LEN(A18))),(5-1)*LEN(A18)+1,LEN(A18))) | R18: =TRIM(MID(SUBSTITUTE(A18,"_",REPT(" ",LEN(A18))),(6-1)*LEN(A18)+1,LEN(A18))) | S18: =TRIM(MID(SUBSTITUTE(A18,"_",REPT(" ",LEN(A18))),(7-1)*LEN(A18)+1,LEN(A18))) | T18: =TRIM(MID(SUBSTITUTE(A18,"_",REPT(" ",LEN(A18))),(8-1)*LEN(A18)+1,LEN(A18))) | U18: =TRIM(MID(SUBSTITUTE(A18,"_",REPT(" ",LEN(A18))),(9-1)*LEN(A18)+1,LEN(A18))) | V18: =TRIM(MID(SUBSTITUTE(A18,"_",REPT(" ",LEN(A18))),(10-1)*LEN(A18)+1,LEN(A18))) | W18: =TRIM(MID(SUBSTITUTE(A18,"_",REPT(" ",LEN(A18))),(11-1)*LEN(A18)+1,LEN(A18))) | X18: =TRIM(MID(SUBSTITUTE(A18,"_",REPT(" ",LEN(A18))),(12-1)*LEN(A18)+1,LEN(A18)))
B19: =IF(AND(D19="YES",I19="YES",E19="YES",F19="YES",G19="YES",H19="Yes"),"YES","NO") -> NO | C19: =IFERROR(VLOOKUP(M19,Lookups!$A$3:$B$87,2,FALSE),"NO") -> NO | D19: =IFERROR(VLOOKUP(N19,Lookups!$D$2:$E$211,2,FALSE),"NO") -> NO | E19: =IFERROR(VLOOKUP(P19,Lookups!$I$3:$J$8,2,FALSE),"NO") -> NO | F19: =IFERROR(VLOOKUP(Q19,Lookups!$L$3:$M$7,2,FALSE),"NO") -> NO | G19: =IFERROR(VLOOKUP(R19,Lookups!$O$3:$P$21,2,FALSE),"NO") -> NO | H19: =IFERROR(VLOOKUP(S19,Lookups!$S$3:$T$6,2,FALSE),"NO") -> NO | I19: =IFERROR(VLOOKUP(T19,Lookups!$V$3:$W$15,2,FALSE),"NO") -> NO | J19: =IFERROR(VLOOKUP(U19,Lookups!$Z$3:$AA$9,2,FALSE),"NO") -> NO | K19: =IFERROR(VLOOKUP(V19,Lookups!$AC$3:$AD$12,2,FALSE),"NO") -> NO | L19: =IFERROR(VLOOKUP(W19,Lookups!$AH$3:$AI$74,2,FALSE),"NO") -> NO | M19: =TRIM(MID(SUBSTITUTE(A19,"_",REPT(" ",LEN(A19))),(1-1)*LEN(A19)+1,LEN(A19))) | N19: =TRIM(MID(SUBSTITUTE(A19,"_",REPT(" ",LEN(A19))),(2-1)*LEN(A19)+1,LEN(A19))) | O19: =TRIM(MID(SUBSTITUTE(A19,"_",REPT(" ",LEN(A19))),(3-1)*LEN(A19)+1,LEN(A19))) | P19: =TRIM(MID(SUBSTITUTE(A19,"_",REPT(" ",LEN(A19))),(4-1)*LEN(A19)+1,LEN(A19))) | Q19: =TRIM(MID(SUBSTITUTE(A19,"_",REPT(" ",LEN(A19))),(5-1)*LEN(A19)+1,LEN(A19))) | R19: =TRIM(MID(SUBSTITUTE(A19,"_",REPT(" ",LEN(A19))),(6-1)*LEN(A19)+1,LEN(A19))) | S19: =TRIM(MID(SUBSTITUTE(A19,"_",REPT(" ",LEN(A19))),(7-1)*LEN(A19)+1,LEN(A19))) | T19: =TRIM(MID(SUBSTITUTE(A19,"_",REPT(" ",LEN(A19))),(8-1)*LEN(A19)+1,LEN(A19))) | U19: =TRIM(MID(SUBSTITUTE(A19,"_",REPT(" ",LEN(A19))),(9-1)*LEN(A19)+1,LEN(A19))) | V19: =TRIM(MID(SUBSTITUTE(A19,"_",REPT(" ",LEN(A19))),(10-1)*LEN(A19)+1,LEN(A19))) | W19: =TRIM(MID(SUBSTITUTE(A19,"_",REPT(" ",LEN(A19))),(11-1)*LEN(A19)+1,LEN(A19))) | X19: =TRIM(MID(SUBSTITUTE(A19,"_",REPT(" ",LEN(A19))),(12-1)*LEN(A19)+1,LEN(A19)))
A20: BR_Kitekat_Pedigree launch_mw_apac_CT_Brand_audio_awareness_bid-adr_0522_xxxx | B20: =IF(AND(D20="YES",I20="YES",E20="YES",F20="YES",G20="YES",H20="Yes"),"YES","NO") -> NO | C20: =IFERROR(VLOOKUP(M20,Lookups!$A$3:$B$87,2,FALSE),"NO") -> Yes | D20: =IFERROR(VLOOKUP(N20,Lookups!$D$2:$E$211,2,FALSE),"NO") -> NO | E20: =IFERROR(VLOOKUP(P20,Lookups!$I$3:$J$8,2,FALSE),"NO") -> YES | F20: =IFERROR(VLOOKUP(Q20,Lookups!$L$3:$M$7,2,FALSE),"NO") -> YES | G20: =IFERROR(VLOOKUP(R20,Lookups!$O$3:$P$21,2,FALSE),"NO") -> YES | H20: =IFERROR(VLOOKUP(S20,Lookups!$S$3:$T$6,2,FALSE),"NO") -> YES | I20: =IFERROR(VLOOKUP(T20,Lookups!$V$3:$W$15,2,FALSE),"NO") -> YES | J20: =IFERROR(VLOOKUP(U20,Lookups!$Z$3:$AA$9,2,FALSE),"NO") -> YES | K20: =IFERROR(VLOOKUP(V20,Lookups!$AC$3:$AD$12,2,FALSE),"NO") -> Yes | L20: =IFERROR(VLOOKUP(W20,Lookups!$AH$3:$AI$74,2,FALSE),"NO") -> Yes | M20: =TRIM(MID(SUBSTITUTE(A20,"_",REPT(" ",LEN(A20))),(1-1)*LEN(A20)+1,LEN(A20))) -> BR | N20: =TRIM(MID(SUBSTITUTE(A20,"_",REPT(" ",LEN(A20))),(2-1)*LEN(A20)+1,LEN(A20))) -> Kitekat | O20: =TRIM(MID(SUBSTITUTE(A20,"_",REPT(" ",LEN(A20))),(3-1)*LEN(A20)+1,LEN(A20))) -> Pedigree launch | P20: =TRIM(MID(SUBSTITUTE(A20,"_",REPT(" ",LEN(A20))),(4-1)*LEN(A20)+1,LEN(A20))) -> mw | Q20: =TRIM(MID(SUBSTITUTE(A20,"_",REPT(" ",LEN(A20))),(5-1)*LEN(A20)+1,LEN(A20))) -> apac | R20: =TRIM(MID(SUBSTITUTE(A20,"_",REPT(" ",LEN(A20))),(6-1)*LEN(A20)+1,LEN(A20))) -> CT | S20: =TRIM(MID(SUBSTITUTE(A20,"_",REPT(" ",LEN(A20))),(7-1)*LEN(A20)+1,LEN(A20))) -> Brand | T20: =TRIM(MID(SUBSTITUTE(A20,"_",REPT(" ",LEN(A20))),(8-1)*LEN(A20)+1,LEN(A20))) -> audio | U20: =TRIM(MID(SUBSTITUTE(A20,"_",REPT(" ",LEN(A20))),(9-1)*LEN(A20)+1,LEN(A20))) -> awareness | V20: =TRIM(MID(SUBSTITUTE(A20,"_",REPT(" ",LEN(A20))),(10-1)*LEN(A20)+1,LEN(A20))) -> bid-adr | W20: =TRIM(MID(SUBSTITUTE(A20,"_",REPT(" ",LEN(A20))),(11-1)*LEN(A20)+1,LEN(A20))) -> 0522 | X20: =TRIM(MID(SUBSTITUTE(A20,"_",REPT(" ",LEN(A20))),(12-1)*LEN(A20)+1,LEN(A20))) -> xxxx
B21: =IF(AND(D21="YES",I21="YES",E21="YES",F21="YES",G21="YES",H21="Yes"),"YES","NO") -> NO | C21: =IFERROR(VLOOKUP(M21,Lookups!$A$3:$B$87,2,FALSE),"NO") -> NO | D21: =IFERROR(VLOOKUP(N21,Lookups!$D$2:$E$211,2,FALSE),"NO") -> NO | E21: =IFERROR(VLOOKUP(P21,Lookups!$I$3:$J$8,2,FALSE),"NO") -> NO | F21: =IFERROR(VLOOKUP(Q21,Lookups!$L$3:$M$7,2,FALSE),"NO") -> NO | G21: =IFERROR(VLOOKUP(R21,Lookups!$O$3:$P$21,2,FALSE),"NO") -> NO | H21: =IFERROR(VLOOKUP(S21,Lookups!$S$3:$T$6,2,FALSE),"NO") -> NO | I21: =IFERROR(VLOOKUP(T21,Lookups!$V$3:$W$15,2,FALSE),"NO") -> NO | J21: =IFERROR(VLOOKUP(U21,Lookups!$Z$3:$AA$9,2,FALSE),"NO") -> NO | K21: =IFERROR(VLOOKUP(V21,Lookups!$AC$3:$AD$12,2,FALSE),"NO") -> NO | L21: =IFERROR(VLOOKUP(W21,Lookups!$AH$3:$AI$74,2,FALSE),"NO") -> NO | M21: =TRIM(MID(SUBSTITUTE(A21,"_",REPT(" ",LEN(A21))),(1-1)*LEN(A21)+1,LEN(A21))) | N21: =TRIM(MID(SUBSTITUTE(A21,"_",REPT(" ",LEN(A21))),(2-1)*LEN(A21)+1,LEN(A21))) | O21: =TRIM(MID(SUBSTITUTE(A21,"_",REPT(" ",LEN(A21))),(3-1)*LEN(A21)+1,LEN(A21))) | P21: =TRIM(MID(SUBSTITUTE(A21,"_",REPT(" ",LEN(A21))),(4-1)*LEN(A21)+1,LEN(A21))) | Q21: =TRIM(MID(SUBSTITUTE(A21,"_",REPT(" ",LEN(A21))),(5-1)*LEN(A21)+1,LEN(A21))) | R21: =TRIM(MID(SUBSTITUTE(A21,"_",REPT(" ",LEN(A21))),(6-1)*LEN(A21)+1,LEN(A21))) | S21: =TRIM(MID(SUBSTITUTE(A21,"_",REPT(" ",LEN(A21))),(7-1)*LEN(A21)+1,LEN(A21))) | T21: =TRIM(MID(SUBSTITUTE(A21,"_",REPT(" ",LEN(A21))),(8-1)*LEN(A21)+1,LEN(A21))) | U21: =TRIM(MID(SUBSTITUTE(A21,"_",REPT(" ",LEN(A21))),(9-1)*LEN(A21)+1,LEN(A21))) | V21: =TRIM(MID(SUBSTITUTE(A21,"_",REPT(" ",LEN(A21))),(10-1)*LEN(A21)+1,LEN(A21))) | W21: =TRIM(MID(SUBSTITUTE(A21,"_",REPT(" ",LEN(A21))),(11-1)*LEN(A21)+1,LEN(A21))) | X21: =TRIM(MID(SUBSTITUTE(A21,"_",REPT(" ",LEN(A21))),(12-1)*LEN(A21)+1,LEN(A21)))
B22: =IF(AND(D22="YES",I22="YES",E22="YES",F22="YES",G22="YES",H22="Yes"),"YES","NO") -> NO | C22: =IFERROR(VLOOKUP(M22,Lookups!$A$3:$B$87,2,FALSE),"NO") -> NO | D22: =IFERROR(VLOOKUP(N22,Lookups!$D$2:$E$211,2,FALSE),"NO") -> NO | E22: =IFERROR(VLOOKUP(P22,Lookups!$I$3:$J$8,2,FALSE),"NO") -> NO | F22: =IFERROR(VLOOKUP(Q22,Lookups!$L$3:$M$7,2,FALSE),"NO") -> NO | G22: =IFERROR(VLOOKUP(R22,Lookups!$O$3:$P$21,2,FALSE),"NO") -> NO | H22: =IFERROR(VLOOKUP(S22,Lookups!$S$3:$T$6,2,FALSE),"NO") -> NO | I22: =IFERROR(VLOOKUP(T22,Lookups!$V$3:$W$15,2,FALSE),"NO") -> NO | J22: =IFERROR(VLOOKUP(U22,Lookups!$Z$3:$AA$9,2,FALSE),"NO") -> NO | K22: =IFERROR(VLOOKUP(V22,Lookups!$AC$3:$AD$12,2,FALSE),"NO") -> NO | L22: =IFERROR(VLOOKUP(W22,Lookups!$AH$3:$AI$74,2,FALSE),"NO") -> NO | M22: =TRIM(MID(SUBSTITUTE(A22,"_",REPT(" ",LEN(A22))),(1-1)*LEN(A22)+1,LEN(A22))) | N22: =TRIM(MID(SUBSTITUTE(A22,"_",REPT(" ",LEN(A22))),(2-1)*LEN(A22)+1,LEN(A22))) | O22: =TRIM(MID(SUBSTITUTE(A22,"_",REPT(" ",LEN(A22))),(3-1)*LEN(A22)+1,LEN(A22))) | P22: =TRIM(MID(SUBSTITUTE(A22,"_",REPT(" ",LEN(A22))),(4-1)*LEN(A22)+1,LEN(A22))) | Q22: =TRIM(MID(SUBSTITUTE(A22,"_",REPT(" ",LEN(A22))),(5-1)*LEN(A22)+1,LEN(A22))) | R22: =TRIM(MID(SUBSTITUTE(A22,"_",REPT(" ",LEN(A22))),(6-1)*LEN(A22)+1,LEN(A22))) | S22: =TRIM(MID(SUBSTITUTE(A22,"_",REPT(" ",LEN(A22))),(7-1)*LEN(A22)+1,LEN(A22))) | T22: =TRIM(MID(SUBSTITUTE(A22,"_",REPT(" ",LEN(A22))),(8-1)*LEN(A22)+1,LEN(A22))) | U22: =TRIM(MID(SUBSTITUTE(A22,"_",REPT(" ",LEN(A22))),(9-1)*LEN(A22)+1,LEN(A22))) | V22: =TRIM(MID(SUBSTITUTE(A22,"_",REPT(" ",LEN(A22))),(10-1)*LEN(A22)+1,LEN(A22))) | W22: =TRIM(MID(SUBSTITUTE(A22,"_",REPT(" ",LEN(A22))),(11-1)*LEN(A22)+1,LEN(A22))) | X22: =TRIM(MID(SUBSTITUTE(A22,"_",REPT(" ",LEN(A22))),(12-1)*LEN(A22)+1,LEN(A22)))
A23: BR_Kitkat_Pedigree launch_mw_latam_CT_Brand_audio_awareness_bid-adr_0522_xxxx | B23: =IF(AND(D23="YES",I23="YES",E23="YES",F23="YES",G23="YES",H23="Yes"),"YES","NO") -> NO | C23: =IFERROR(VLOOKUP(M23,Lookups!$A$3:$B$87,2,FALSE),"NO") -> Yes | D23: =IFERROR(VLOOKUP(N23,Lookups!$D$2:$E$211,2,FALSE),"NO") -> NO | E23: =IFERROR(VLOOKUP(P23,Lookups!$I$3:$J$8,2,FALSE),"NO") -> YES | F23: =IFERROR(VLOOKUP(Q23,Lookups!$L$3:$M$7,2,FALSE),"NO") -> YES | G23: =IFERROR(VLOOKUP(R23,Lookups!$O$3:$P$21,2,FALSE),"NO") -> YES | H23: =IFERROR(VLOOKUP(S23,Lookups!$S$3:$T$6,2,FALSE),"NO") -> YES | I23: =IFERROR(VLOOKUP(T23,Lookups!$V$3:$W$15,2,FALSE),"NO") -> YES | J23: =IFERROR(VLOOKUP(U23,Lookups!$Z$3:$AA$9,2,FALSE),"NO") -> YES | K23: =IFERROR(VLOOKUP(V23,Lookups!$AC$3:$AD$12,2,FALSE),"NO") -> Yes | L23: =IFERROR(VLOOKUP(W23,Lookups!$AH$3:$AI$74,2,FALSE),"NO") -> Yes | M23: =TRIM(MID(SUBSTITUTE(A23,"_",REPT(" ",LEN(A23))),(1-1)*LEN(A23)+1,LEN(A23))) -> BR | N23: =TRIM(MID(SUBSTITUTE(A23,"_",REPT(" ",LEN(A23))),(2-1)*LEN(A23)+1,LEN(A23))) -> Kitkat | O23: =TRIM(MID(SUBSTITUTE(A23,"_",REPT(" ",LEN(A23))),(3-1)*LEN(A23)+1,LEN(A23))) -> Pedigree launch | P23: =TRIM(MID(SUBSTITUTE(A23,"_",REPT(" ",LEN(A23))),(4-1)*LEN(A23)+1,LEN(A23))) -> mw | Q23: =TRIM(MID(SUBSTITUTE(A23,"_",REPT(" ",LEN(A23))),(5-1)*LEN(A23)+1,LEN(A23))) -> latam | R23: =TRIM(MID(SUBSTITUTE(A23,"_",REPT(" ",LEN(A23))),(6-1)*LEN(A23)+1,LEN(A23))) -> CT | S23: =TRIM(MID(SUBSTITUTE(A23,"_",REPT(" ",LEN(A23))),(7-1)*LEN(A23)+1,LEN(A23))) -> Brand | T23: =TRIM(MID(SUBSTITUTE(A23,"_",REPT(" ",LEN(A23))),(8-1)*LEN(A23)+1,LEN(A23))) -> audio | U23: =TRIM(MID(SUBSTITUTE(A23,"_",REPT(" ",LEN(A23))),(9-1)*LEN(A23)+1,LEN(A23))) -> awareness | V23: =TRIM(MID(SUBSTITUTE(A23,"_",REPT(" ",LEN(A23))),(10-1)*LEN(A23)+1,LEN(A23))) -> bid-adr | W23: =TRIM(MID(SUBSTITUTE(A23,"_",REPT(" ",LEN(A23))),(11-1)*LEN(A23)+1,LEN(A23))) -> 0522 | X23: =TRIM(MID(SUBSTITUTE(A23,"_",REPT(" ",LEN(A23))),(12-1)*LEN(A23)+1,LEN(A23))) -> xxxx
B24: =IF(AND(D24="YES",I24="YES",E24="YES",F24="YES",G24="YES",H24="Yes"),"YES","NO") -> NO | C24: =IFERROR(VLOOKUP(M24,Lookups!$A$3:$B$87,2,FALSE),"NO") -> NO | D24: =IFERROR(VLOOKUP(N24,Lookups!$D$2:$E$211,2,FALSE),"NO") -> NO | E24: =IFERROR(VLOOKUP(P24,Lookups!$I$3:$J$8,2,FALSE),"NO") -> NO | F24: =IFERROR(VLOOKUP(Q24,Lookups!$L$3:$M$7,2,FALSE),"NO") -> NO | G24: =IFERROR(VLOOKUP(R24,Lookups!$O$3:$P$21,2,FALSE),"NO") -> NO | H24: =IFERROR(VLOOKUP(S24,Lookups!$S$3:$T$6,2,FALSE),"NO") -> NO | I24: =IFERROR(VLOOKUP(T24,Lookups!$V$3:$W$15,2,FALSE),"NO") -> NO | J24: =IFERROR(VLOOKUP(U24,Lookups!$Z$3:$AA$9,2,FALSE),"NO") -> NO | K24: =IFERROR(VLOOKUP(V24,Lookups!$AC$3:$AD$12,2,FALSE),"NO") -> NO | L24: =IFERROR(VLOOKUP(W24,Lookups!$AH$3:$AI$74,2,FALSE),"NO") -> NO | M24: =TRIM(MID(SUBSTITUTE(A24,"_",REPT(" ",LEN(A24))),(1-1)*LEN(A24)+1,LEN(A24))) | N24: =TRIM(MID(SUBSTITUTE(A24,"_",REPT(" ",LEN(A24))),(2-1)*LEN(A24)+1,LEN(A24))) | O24: =TRIM(MID(SUBSTITUTE(A24,"_",REPT(" ",LEN(A24))),(3-1)*LEN(A24)+1,LEN(A24))) | P24: =TRIM(MID(SUBSTITUTE(A24,"_",REPT(" ",LEN(A24))),(4-1)*LEN(A24)+1,LEN(A24))) | Q24: =TRIM(MID(SUBSTITUTE(A24,"_",REPT(" ",LEN(A24))),(5-1)*LEN(A24)+1,LEN(A24))) | R24: =TRIM(MID(SUBSTITUTE(A24,"_",REPT(" ",LEN(A24))),(6-1)*LEN(A24)+1,LEN(A24))) | S24: =TRIM(MID(SUBSTITUTE(A24,"_",REPT(" ",LEN(A24))),(7-1)*LEN(A24)+1,LEN(A24))) | T24: =TRIM(MID(SUBSTITUTE(A24,"_",REPT(" ",LEN(A24))),(8-1)*LEN(A24)+1,LEN(A24))) | U24: =TRIM(MID(SUBSTITUTE(A24,"_",REPT(" ",LEN(A24))),(9-1)*LEN(A24)+1,LEN(A24))) | V24: =TRIM(MID(SUBSTITUTE(A24,"_",REPT(" ",LEN(A24))),(10-1)*LEN(A24)+1,LEN(A24))) | W24: =TRIM(MID(SUBSTITUTE(A24,"_",REPT(" ",LEN(A24))),(11-1)*LEN(A24)+1,LEN(A24))) | X24: =TRIM(MID(SUBSTITUTE(A24,"_",REPT(" ",LEN(A24))),(12-1)*LEN(A24)+1,LEN(A24)))
A25: BR_Alert_Pedigree launch_mw_latam_CT_Brand_audio_awareness_bid-adr_0522_xxxx | B25: =IF(AND(D25="YES",I25="YES",E25="YES",F25="YES",G25="YES",H25="Yes"),"YES","NO") -> NO | C25: =IFERROR(VLOOKUP(M25,Lookups!$A$3:$B$87,2,FALSE),"NO") -> Yes | D25: =IFERROR(VLOOKUP(N25,Lookups!$D$2:$E$211,2,FALSE),"NO") -> NO | E25: =IFERROR(VLOOKUP(P25,Lookups!$I$3:$J$8,2,FALSE),"NO") -> YES | F25: =IFERROR(VLOOKUP(Q25,Lookups!$L$3:$M$7,2,FALSE),"NO") -> YES | G25: =IFERROR(VLOOKUP(R25,Lookups!$O$3:$P$21,2,FALSE),"NO") -> YES | H25: =IFERROR(VLOOKUP(S25,Lookups!$S$3:$T$6,2,FALSE),"NO") -> YES | I25: =IFERROR(VLOOKUP(T25,Lookups!$V$3:$W$15,2,FALSE),"NO") -> YES | J25: =IFERROR(VLOOKUP(U25,Lookups!$Z$3:$AA$9,2,FALSE),"NO") -> YES | K25: =IFERROR(VLOOKUP(V25,Lookups!$AC$3:$AD$12,2,FALSE),"NO") -> Yes | L25: =IFERROR(VLOOKUP(W25,Lookups!$AH$3:$AI$74,2,FALSE),"NO") -> Yes | M25: =TRIM(MID(SUBSTITUTE(A25,"_",REPT(" ",LEN(A25))),(1-1)*LEN(A25)+1,LEN(A25))) -> BR | N25: =TRIM(MID(SUBSTITUTE(A25,"_",REPT(" ",LEN(A25))),(2-1)*LEN(A25)+1,LEN(A25))) -> Alert | O25: =TRIM(MID(SUBSTITUTE(A25,"_",REPT(" ",LEN(A25))),(3-1)*LEN(A25)+1,LEN(A25))) -> Pedigree launch | P25: =TRIM(MID(SUBSTITUTE(A25,"_",REPT(" ",LEN(A25))),(4-1)*LEN(A25)+1,LEN(A25))) -> mw | Q25: =TRIM(MID(SUBSTITUTE(A25,"_",REPT(" ",LEN(A25))),(5-1)*LEN(A25)+1,LEN(A25))) -> latam | R25: =TRIM(MID(SUBSTITUTE(A25,"_",REPT(" ",LEN(A25))),(6-1)*LEN(A25)+1,LEN(A25))) -> CT | S25: =TRIM(MID(SUBSTITUTE(A25,"_",REPT(" ",LEN(A25))),(7-1)*LEN(A25)+1,LEN(A25))) -> Brand | T25: =TRIM(MID(SUBSTITUTE(A25,"_",REPT(" ",LEN(A25))),(8-1)*LEN(A25)+1,LEN(A25))) -> audio | U25: =TRIM(MID(SUBSTITUTE(A25,"_",REPT(" ",LEN(A25))),(9-1)*LEN(A25)+1,LEN(A25))) -> awareness | V25: =TRIM(MID(SUBSTITUTE(A25,"_",REPT(" ",LEN(A25))),(10-1)*LEN(A25)+1,LEN(A25))) -> bid-adr | W25: =TRIM(MID(SUBSTITUTE(A25,"_",REPT(" ",LEN(A25))),(11-1)*LEN(A25)+1,LEN(A25))) -> 0522 | X25: =TRIM(MID(SUBSTITUTE(A25,"_",REPT(" ",LEN(A25))),(12-1)*LEN(A25)+1,LEN(A25))) -> xxxx
B26: =IF(AND(D26="YES",I26="YES",E26="YES",F26="YES",G26="YES",H26="Yes"),"YES","NO") -> NO | C26: =IFERROR(VLOOKUP(M26,Lookups!$A$3:$B$87,2,FALSE),"NO") -> NO | D26: =IFERROR(VLOOKUP(N26,Lookups!$D$2:$E$211,2,FALSE),"NO") -> NO | E26: =IFERROR(VLOOKUP(P26,Lookups!$I$3:$J$8,2,FALSE),"NO") -> NO | F26: =IFERROR(VLOOKUP(Q26,Lookups!$L$3:$M$7,2,FALSE),"NO") -> NO | G26: =IFERROR(VLOOKUP(R26,Lookups!$O$3:$P$21,2,FALSE),"NO") -> NO | H26: =IFERROR(VLOOKUP(S26,Lookups!$S$3:$T$6,2,FALSE),"NO") -> NO | I26: =IFERROR(VLOOKUP(T26,Lookups!$V$3:$W$15,2,FALSE),"NO") -> NO | J26: =IFERROR(VLOOKUP(U26,Lookups!$Z$3:$AA$9,2,FALSE),"NO") -> NO | K26: =IFERROR(VLOOKUP(V26,Lookups!$AC$3:$AD$12,2,FALSE),"NO") -> NO | L26: =IFERROR(VLOOKUP(W26,Lookups!$AH$3:$AI$74,2,FALSE),"NO") -> NO | M26: =TRIM(MID(SUBSTITUTE(A26,"_",REPT(" ",LEN(A26))),(1-1)*LEN(A26)+1,LEN(A26))) | N26: =TRIM(MID(SUBSTITUTE(A26,"_",REPT(" ",LEN(A26))),(2-1)*LEN(A26)+1,LEN(A26))) | O26: =TRIM(MID(SUBSTITUTE(A26,"_",REPT(" ",LEN(A26))),(3-1)*LEN(A26)+1,LEN(A26))) | P26: =TRIM(MID(SUBSTITUTE(A26,"_",REPT(" ",LEN(A26))),(4-1)*LEN(A26)+1,LEN(A26))) | Q26: =TRIM(MID(SUBSTITUTE(A26,"_",REPT(" ",LEN(A26))),(5-1)*LEN(A26)+1,LEN(A26))) | R26: =TRIM(MID(SUBSTITUTE(A26,"_",REPT(" ",LEN(A26))),(6-1)*LEN(A26)+1,LEN(A26))) | S26: =TRIM(MID(SUBSTITUTE(A26,"_",REPT(" ",LEN(A26))),(7-1)*LEN(A26)+1,LEN(A26))) | T26: =TRIM(MID(SUBSTITUTE(A26,"_",REPT(" ",LEN(A26))),(8-1)*LEN(A26)+1,LEN(A26))) | U26: =TRIM(MID(SUBSTITUTE(A26,"_",REPT(" ",LEN(A26))),(9-1)*LEN(A26)+1,LEN(A26))) | V26: =TRIM(MID(SUBSTITUTE(A26,"_",REPT(" ",LEN(A26))),(10-1)*LEN(A26)+1,LEN(A26))) | W26: =TRIM(MID(SUBSTITUTE(A26,"_",REPT(" ",LEN(A26))),(11-1)*LEN(A26)+1,LEN(A26))) | X26: =TRIM(MID(SUBSTITUTE(A26,"_",REPT(" ",LEN(A26))),(12-1)*LEN(A26)+1,LEN(A26)))
A27: BR_alr_Pedigree launch_mw_latam_CT_Brand_audio_awareness_bid-adr_0522_xxxx | B27: =IF(AND(D27="YES",I27="YES",E27="YES",F27="YES",G27="YES",H27="Yes"),"YES","NO") -> YES | C27: =IFERROR(VLOOKUP(M27,Lookups!$A$3:$B$87,2,FALSE),"NO") -> Yes | D27: =IFERROR(VLOOKUP(N27,Lookups!$D$2:$E$211,2,FALSE),"NO") -> YES | E27: =IFERROR(VLOOKUP(P27,Lookups!$I$3:$J$8,2,FALSE),"NO") -> YES | F27: =IFERROR(VLOOKUP(Q27,Lookups!$L$3:$M$7,2,FALSE),"NO") -> YES | G27: =IFERROR(VLOOKUP(R27,Lookups!$O$3:$P$21,2,FALSE),"NO") -> YES | H27: =IFERROR(VLOOKUP(S27,Lookups!$S$3:$T$6,2,FALSE),"NO") -> YES | I27: =IFERROR(VLOOKUP(T27,Lookups!$V$3:$W$15,2,FALSE),"NO") -> YES | J27: =IFERROR(VLOOKUP(U27,Lookups!$Z$3:$AA$9,2,FALSE),"NO") -> YES | K27: =IFERROR(VLOOKUP(V27,Lookups!$AC$3:$AD$12,2,FALSE),"NO") -> Yes | L27: =IFERROR(VLOOKUP(W27,Lookups!$AH$3:$AI$74,2,FALSE),"NO") -> Yes | M27: =TRIM(MID(SUBSTITUTE(A27,"_",REPT(" ",LEN(A27))),(1-1)*LEN(A27)+1,LEN(A27))) -> BR | N27: =TRIM(MID(SUBSTITUTE(A27,"_",REPT(" ",LEN(A27))),(2-1)*LEN(A27)+1,LEN(A27))) -> alr | O27: =TRIM(MID(SUBSTITUTE(A27,"_",REPT(" ",LEN(A27))),(3-1)*LEN(A27)+1,LEN(A27))) -> Pedigree launch | P27: =TRIM(MID(SUBSTITUTE(A27,"_",REPT(" ",LEN(A27))),(4-1)*LEN(A27)+1,LEN(A27))) -> mw | Q27: =TRIM(MID(SUBSTITUTE(A27,"_",REPT(" ",LEN(A27))),(5-1)*LEN(A27)+1,LEN(A27))) -> latam | R27: =TRIM(MID(SUBSTITUTE(A27,"_",REPT(" ",LEN(A27))),(6-1)*LEN(A27)+1,LEN(A27))) -> CT | S27: =TRIM(MID(SUBSTITUTE(A27,"_",REPT(" ",LEN(A27))),(7-1)*LEN(A27)+1,LEN(A27))) -> Brand | T27: =TRIM(MID(SUBSTITUTE(A27,"_",REPT(" ",LEN(A27))),(8-1)*LEN(A27)+1,LEN(A27))) -> audio | U27: =TRIM(MID(SUBSTITUTE(A27,"_",REPT(" ",LEN(A27))),(9-1)*LEN(A27)+1,LEN(A27))) -> awareness | V27: =TRIM(MID(SUBSTITUTE(A27,"_",REPT(" ",LEN(A27))),(10-1)*LEN(A27)+1,LEN(A27))) -> bid-adr | W27: =TRIM(MID(SUBSTITUTE(A27,"_",REPT(" ",LEN(A27))),(11-1)*LEN(A27)+1,LEN(A27))) -> 0522 | X27: =TRIM(MID(SUBSTITUTE(A27,"_",REPT(" ",LEN(A27))),(12-1)*LEN(A27)+1,LEN(A27))) -> xxxx
B28: =IF(AND(D28="YES",I28="YES",E28="YES",F28="YES",G28="YES",H28="Yes"),"YES","NO") -> NO | C28: =IFERROR(VLOOKUP(M28,Lookups!$A$3:$B$87,2,FALSE),"NO") -> NO | D28: =IFERROR(VLOOKUP(N28,Lookups!$D$2:$E$211,2,FALSE),"NO") -> NO | E28: =IFERROR(VLOOKUP(P28,Lookups!$I$3:$J$8,2,FALSE),"NO") -> NO | F28: =IFERROR(VLOOKUP(Q28,Lookups!$L$3:$M$7,2,FALSE),"NO") -> NO | G28: =IFERROR(VLOOKUP(R28,Lookups!$O$3:$P$21,2,FALSE),"NO") -> NO | H28: =IFERROR(VLOOKUP(S28,Lookups!$S$3:$T$6,2,FALSE),"NO") -> NO | I28: =IFERROR(VLOOKUP(T28,Lookups!$V$3:$W$15,2,FALSE),"NO") -> NO | J28: =IFERROR(VLOOKUP(U28,Lookups!$Z$3:$AA$9,2,FALSE),"NO") -> NO | K28: =IFERROR(VLOOKUP(V28,Lookups!$AC$3:$AD$12,2,FALSE),"NO") -> NO | L28: =IFERROR(VLOOKUP(W28,Lookups!$AH$3:$AI$74,2,FALSE),"NO") -> NO | M28: =TRIM(MID(SUBSTITUTE(A28,"_",REPT(" ",LEN(A28))),(1-1)*LEN(A28)+1,LEN(A28))) | N28: =TRIM(MID(SUBSTITUTE(A28,"_",REPT(" ",LEN(A28))),(2-1)*LEN(A28)+1,LEN(A28))) | O28: =TRIM(MID(SUBSTITUTE(A28,"_",REPT(" ",LEN(A28))),(3-1)*LEN(A28)+1,LEN(A28))) | P28: =TRIM(MID(SUBSTITUTE(A28,"_",REPT(" ",LEN(A28))),(4-1)*LEN(A28)+1,LEN(A28))) | Q28: =TRIM(MID(SUBSTITUTE(A28,"_",REPT(" ",LEN(A28))),(5-1)*LEN(A28)+1,LEN(A28))) | R28: =TRIM(MID(SUBSTITUTE(A28,"_",REPT(" ",LEN(A28))),(6-1)*LEN(A28)+1,LEN(A28))) | S28: =TRIM(MID(SUBSTITUTE(A28,"_",REPT(" ",LEN(A28))),(7-1)*LEN(A28)+1,LEN(A28))) | T28: =TRIM(MID(SUBSTITUTE(A28,"_",REPT(" ",LEN(A28))),(8-1)*LEN(A28)+1,LEN(A28))) | U28: =TRIM(MID(SUBSTITUTE(A28,"_",REPT(" ",LEN(A28))),(9-1)*LEN(A28)+1,LEN(A28))) | V28: =TRIM(MID(SUBSTITUTE(A28,"_",REPT(" ",LEN(A28))),(10-1)*LEN(A28)+1,LEN(A28))) | W28: =TRIM(MID(SUBSTITUTE(A28,"_",REPT(" ",LEN(A28))),(11-1)*LEN(A28)+1,LEN(A28))) | X28: =TRIM(MID(SUBSTITUTE(A28,"_",REPT(" ",LEN(A28))),(12-1)*LEN(A28)+1,LEN(A28)))
B29: =IF(AND(D29="YES",I29="YES",E29="YES",F29="YES",G29="YES",H29="Yes"),"YES","NO") -> NO | C29: =IFERROR(VLOOKUP(M29,Lookups!$A$3:$B$87,2,FALSE),"NO") -> NO | D29: =IFERROR(VLOOKUP(N29,Lookups!$D$2:$E$211,2,FALSE),"NO") -> NO | E29: =IFERROR(VLOOKUP(P29,Lookups!$I$3:$J$8,2,FALSE),"NO") -> NO | F29: =IFERROR(VLOOKUP(Q29,Lookups!$L$3:$M$7,2,FALSE),"NO") -> NO | G29: =IFERROR(VLOOKUP(R29,Lookups!$O$3:$P$21,2,FALSE),"NO") -> NO | H29: =IFERROR(VLOOKUP(S29,Lookups!$S$3:$T$6,2,FALSE),"NO") -> NO | I29: =IFERROR(VLOOKUP(T29,Lookups!$V$3:$W$15,2,FALSE),"NO") -> NO | J29: =IFERROR(VLOOKUP(U29,Lookups!$Z$3:$AA$9,2,FALSE),"NO") -> NO | K29: =IFERROR(VLOOKUP(V29,Lookups!$AC$3:$AD$12,2,FALSE),"NO") -> NO | L29: =IFERROR(VLOOKUP(W29,Lookups!$AH$3:$AI$74,2,FALSE),"NO") -> NO | M29: =TRIM(MID(SUBSTITUTE(A29,"_",REPT(" ",LEN(A29))),(1-1)*LEN(A29)+1,LEN(A29))) | N29: =TRIM(MID(SUBSTITUTE(A29,"_",REPT(" ",LEN(A29))),(2-1)*LEN(A29)+1,LEN(A29))) | O29: =TRIM(MID(SUBSTITUTE(A29,"_",REPT(" ",LEN(A29))),(3-1)*LEN(A29)+1,LEN(A29))) | P29: =TRIM(MID(SUBSTITUTE(A29,"_",REPT(" ",LEN(A29))),(4-1)*LEN(A29)+1,LEN(A29))) | Q29: =TRIM(MID(SUBSTITUTE(A29,"_",REPT(" ",LEN(A29))),(5-1)*LEN(A29)+1,LEN(A29))) | R29: =TRIM(MID(SUBSTITUTE(A29,"_",REPT(" ",LEN(A29))),(6-1)*LEN(A29)+1,LEN(A29))) | S29: =TRIM(MID(SUBSTITUTE(A29,"_",REPT(" ",LEN(A29))),(7-1)*LEN(A29)+1,LEN(A29))) | T29: =TRIM(MID(SUBSTITUTE(A29,"_",REPT(" ",LEN(A29))),(8-1)*LEN(A29)+1,LEN(A29))) | U29: =TRIM(MID(SUBSTITUTE(A29,"_",REPT(" ",LEN(A29))),(9-1)*LEN(A29)+1,LEN(A29))) | V29: =TRIM(MID(SUBSTITUTE(A29,"_",REPT(" ",LEN(A29))),(10-1)*LEN(A29)+1,LEN(A29))) | W29: =TRIM(MID(SUBSTITUTE(A29,"_",REPT(" ",LEN(A29))),(11-1)*LEN(A29)+1,LEN(A29))) | X29: =TRIM(MID(SUBSTITUTE(A29,"_",REPT(" ",LEN(A29))),(12-1)*LEN(A29)+1,LEN(A29)))
B30: =IF(AND(D30="YES",I30="YES",E30="YES",F30="YES",G30="YES",H30="Yes"),"YES","NO") -> NO | C30: =IFERROR(VLOOKUP(M30,Lookups!$A$3:$B$87,2,FALSE),"NO") -> NO | D30: =IFERROR(VLOOKUP(N30,Lookups!$D$2:$E$211,2,FALSE),"NO") -> NO | E30: =IFERROR(VLOOKUP(P30,Lookups!$I$3:$J$8,2,FALSE),"NO") -> NO | F30: =IFERROR(VLOOKUP(Q30,Lookups!$L$3:$M$7,2,FALSE),"NO") -> NO | G30: =IFERROR(VLOOKUP(R30,Lookups!$O$3:$P$21,2,FALSE),"NO") -> NO | H30: =IFERROR(VLOOKUP(S30,Lookups!$S$3:$T$6,2,FALSE),"NO") -> NO | I30: =IFERROR(VLOOKUP(T30,Lookups!$V$3:$W$15,2,FALSE),"NO") -> NO | J30: =IFERROR(VLOOKUP(U30,Lookups!$Z$3:$AA$9,2,FALSE),"NO") -> NO | K30: =IFERROR(VLOOKUP(V30,Lookups!$AC$3:$AD$12,2,FALSE),"NO") -> NO | L30: =IFERROR(VLOOKUP(W30,Lookups!$AH$3:$AI$74,2,FALSE),"NO") -> NO | M30: =TRIM(MID(SUBSTITUTE(A30,"_",REPT(" ",LEN(A30))),(1-1)*LEN(A30)+1,LEN(A30))) | N30: =TRIM(MID(SUBSTITUTE(A30,"_",REPT(" ",LEN(A30))),(2-1)*LEN(A30)+1,LEN(A30))) | O30: =TRIM(MID(SUBSTITUTE(A30,"_",REPT(" ",LEN(A30))),(3-1)*LEN(A30)+1,LEN(A30))) | P30: =TRIM(MID(SUBSTITUTE(A30,"_",REPT(" ",LEN(A30))),(4-1)*LEN(A30)+1,LEN(A30))) | Q30: =TRIM(MID(SUBSTITUTE(A30,"_",REPT(" ",LEN(A30))),(5-1)*LEN(A30)+1,LEN(A30))) | R30: =TRIM(MID(SUBSTITUTE(A30,"_",REPT(" ",LEN(A30))),(6-1)*LEN(A30)+1,LEN(A30))) | S30: =TRIM(MID(SUBSTITUTE(A30,"_",REPT(" ",LEN(A30))),(7-1)*LEN(A30)+1,LEN(A30))) | T30: =TRIM(MID(SUBSTITUTE(A30,"_",REPT(" ",LEN(A30))),(8-1)*LEN(A30)+1,LEN(A30))) | U30: =TRIM(MID(SUBSTITUTE(A30,"_",REPT(" ",LEN(A30))),(9-1)*LEN(A30)+1,LEN(A30))) | V30: =TRIM(MID(SUBSTITUTE(A30,"_",REPT(" ",LEN(A30))),(10-1)*LEN(A30)+1,LEN(A30))) | W30: =TRIM(MID(SUBSTITUTE(A30,"_",REPT(" ",LEN(A30))),(11-1)*LEN(A30)+1,LEN(A30))) | X30: =TRIM(MID(SUBSTITUTE(A30,"_",REPT(" ",LEN(A30))),(12-1)*LEN(A30)+1,LEN(A30)))
B31: =IF(AND(D31="YES",I31="YES",E31="YES",F31="YES",G31="YES",H31="Yes"),"YES","NO") -> NO | C31: =IFERROR(VLOOKUP(M31,Lookups!$A$3:$B$87,2,FALSE),"NO") -> NO | D31: =IFERROR(VLOOKUP(N31,Lookups!$D$2:$E$211,2,FALSE),"NO") -> NO | E31: =IFERROR(VLOOKUP(P31,Lookups!$I$3:$J$8,2,FALSE),"NO") -> NO | F31: =IFERROR(VLOOKUP(Q31,Lookups!$L$3:$M$7,2,FALSE),"NO") -> NO | G31: =IFERROR(VLOOKUP(R31,Lookups!$O$3:$P$21,2,FALSE),"NO") -> NO | H31: =IFERROR(VLOOKUP(S31,Lookups!$S$3:$T$6,2,FALSE),"NO") -> NO | I31: =IFERROR(VLOOKUP(T31,Lookups!$V$3:$W$15,2,FALSE),"NO") -> NO | J31: =IFERROR(VLOOKUP(U31,Lookups!$Z$3:$AA$9,2,FALSE),"NO") -> NO | K31: =IFERROR(VLOOKUP(V31,Lookups!$AC$3:$AD$12,2,FALSE),"NO") -> NO | L31: =IFERROR(VLOOKUP(W31,Lookups!$AH$3:$AI$74,2,FALSE),"NO") -> NO | M31: =TRIM(MID(SUBSTITUTE(A31,"_",REPT(" ",LEN(A31))),(1-1)*LEN(A31)+1,LEN(A31))) | N31: =TRIM(MID(SUBSTITUTE(A31,"_",REPT(" ",LEN(A31))),(2-1)*LEN(A31)+1,LEN(A31))) | O31: =TRIM(MID(SUBSTITUTE(A31,"_",REPT(" ",LEN(A31))),(3-1)*LEN(A31)+1,LEN(A31))) | P31: =TRIM(MID(SUBSTITUTE(A31,"_",REPT(" ",LEN(A31))),(4-1)*LEN(A31)+1,LEN(A31))) | Q31: =TRIM(MID(SUBSTITUTE(A31,"_",REPT(" ",LEN(A31))),(5-1)*LEN(A31)+1,LEN(A31))) | R31: =TRIM(MID(SUBSTITUTE(A31,"_",REPT(" ",LEN(A31))),(6-1)*LEN(A31)+1,LEN(A31))) | S31: =TRIM(MID(SUBSTITUTE(A31,"_",REPT(" ",LEN(A31))),(7-1)*LEN(A31)+1,LEN(A31))) | T31: =TRIM(MID(SUBSTITUTE(A31,"_",REPT(" ",LEN(A31))),(8-1)*LEN(A31)+1,LEN(A31))) | U31: =TRIM(MID(SUBSTITUTE(A31,"_",REPT(" ",LEN(A31))),(9-1)*LEN(A31)+1,LEN(A31))) | V31: =TRIM(MID(SUBSTITUTE(A31,"_",REPT(" ",LEN(A31))),(10-1)*LEN(A31)+1,LEN(A31))) | W31: =TRIM(MID(SUBSTITUTE(A31,"_",REPT(" ",LEN(A31))),(11-1)*LEN(A31)+1,LEN(A31))) | X31: =TRIM(MID(SUBSTITUTE(A31,"_",REPT(" ",LEN(A31))),(12-1)*LEN(A31)+1,LEN(A31)))
B32: =IF(AND(D32="YES",I32="YES",E32="YES",F32="YES",G32="YES",H32="Yes"),"YES","NO") -> NO | C32: =IFERROR(VLOOKUP(M32,Lookups!$A$3:$B$87,2,FALSE),"NO") -> NO | D32: =IFERROR(VLOOKUP(N32,Lookups!$D$2:$E$211,2,FALSE),"NO") -> NO | E32: =IFERROR(VLOOKUP(P32,Lookups!$I$3:$J$8,2,FALSE),"NO") -> NO | F32: =IFERROR(VLOOKUP(Q32,Lookups!$L$3:$M$7,2,FALSE),"NO") -> NO | G32: =IFERROR(VLOOKUP(R32,Lookups!$O$3:$P$21,2,FALSE),"NO") -> NO | H32: =IFERROR(VLOOKUP(S32,Lookups!$S$3:$T$6,2,FALSE),"NO") -> NO | I32: =IFERROR(VLOOKUP(T32,Lookups!$V$3:$W$15,2,FALSE),"NO") -> NO | J32: =IFERROR(VLOOKUP(U32,Lookups!$Z$3:$AA$9,2,FALSE),"NO") -> NO | K32: =IFERROR(VLOOKUP(V32,Lookups!$AC$3:$AD$12,2,FALSE),"NO") -> NO | L32: =IFERROR(VLOOKUP(W32,Lookups!$AH$3:$AI$74,2,FALSE),"NO") -> NO | M32: =TRIM(MID(SUBSTITUTE(A32,"_",REPT(" ",LEN(A32))),(1-1)*LEN(A32)+1,LEN(A32))) | N32: =TRIM(MID(SUBSTITUTE(A32,"_",REPT(" ",LEN(A32))),(2-1)*LEN(A32)+1,LEN(A32))) | O32: =TRIM(MID(SUBSTITUTE(A32,"_",REPT(" ",LEN(A32))),(3-1)*LEN(A32)+1,LEN(A32))) | P32: =TRIM(MID(SUBSTITUTE(A32,"_",REPT(" ",LEN(A32))),(4-1)*LEN(A32)+1,LEN(A32))) | Q32: =TRIM(MID(SUBSTITUTE(A32,"_",REPT(" ",LEN(A32))),(5-1)*LEN(A32)+1,LEN(A32))) | R32: =TRIM(MID(SUBSTITUTE(A32,"_",REPT(" ",LEN(A32))),(6-1)*LEN(A32)+1,LEN(A32))) | S32: =TRIM(MID(SUBSTITUTE(A32,"_",REPT(" ",LEN(A32))),(7-1)*LEN(A32)+1,LEN(A32))) | T32: =TRIM(MID(SUBSTITUTE(A32,"_",REPT(" ",LEN(A32))),(8-1)*LEN(A32)+1,LEN(A32))) | U32: =TRIM(MID(SUBSTITUTE(A32,"_",REPT(" ",LEN(A32))),(9-1)*LEN(A32)+1,LEN(A32))) | V32: =TRIM(MID(SUBSTITUTE(A32,"_",REPT(" ",LEN(A32))),(10-1)*LEN(A32)+1,LEN(A32))) | W32: =TRIM(MID(SUBSTITUTE(A32,"_",REPT(" ",LEN(A32))),(11-1)*LEN(A32)+1,LEN(A32))) | X32: =TRIM(MID(SUBSTITUTE(A32,"_",REPT(" ",LEN(A32))),(12-1)*LEN(A32)+1,LEN(A32)))
B33: =IF(AND(D33="YES",I33="YES",E33="YES",F33="YES",G33="YES",H33="Yes"),"YES","NO") -> NO | C33: =IFERROR(VLOOKUP(M33,Lookups!$A$3:$B$87,2,FALSE),"NO") -> NO | D33: =IFERROR(VLOOKUP(N33,Lookups!$D$2:$E$211,2,FALSE),"NO") -> NO | E33: =IFERROR(VLOOKUP(P33,Lookups!$I$3:$J$8,2,FALSE),"NO") -> NO | F33: =IFERROR(VLOOKUP(Q33,Lookups!$L$3:$M$7,2,FALSE),"NO") -> NO | G33: =IFERROR(VLOOKUP(R33,Lookups!$O$3:$P$21,2,FALSE),"NO") -> NO | H33: =IFERROR(VLOOKUP(S33,Lookups!$S$3:$T$6,2,FALSE),"NO") -> NO | I33: =IFERROR(VLOOKUP(T33,Lookups!$V$3:$W$15,2,FALSE),"NO") -> NO | J33: =IFERROR(VLOOKUP(U33,Lookups!$Z$3:$AA$9,2,FALSE),"NO") -> NO | K33: =IFERROR(VLOOKUP(V33,Lookups!$AC$3:$AD$12,2,FALSE),"NO") -> NO | L33: =IFERROR(VLOOKUP(W33,Lookups!$AH$3:$AI$74,2,FALSE),"NO") -> NO | M33: =TRIM(MID(SUBSTITUTE(A33,"_",REPT(" ",LEN(A33))),(1-1)*LEN(A33)+1,LEN(A33))) | N33: =TRIM(MID(SUBSTITUTE(A33,"_",REPT(" ",LEN(A33))),(2-1)*LEN(A33)+1,LEN(A33))) | O33: =TRIM(MID(SUBSTITUTE(A33,"_",REPT(" ",LEN(A33))),(3-1)*LEN(A33)+1,LEN(A33))) | P33: =TRIM(MID(SUBSTITUTE(A33,"_",REPT(" ",LEN(A33))),(4-1)*LEN(A33)+1,LEN(A33))) | Q33: =TRIM(MID(SUBSTITUTE(A33,"_",REPT(" ",LEN(A33))),(5-1)*LEN(A33)+1,LEN(A33))) | R33: =TRIM(MID(SUBSTITUTE(A33,"_",REPT(" ",LEN(A33))),(6-1)*LEN(A33)+1,LEN(A33))) | S33: =TRIM(MID(SUBSTITUTE(A33,"_",REPT(" ",LEN(A33))),(7-1)*LEN(A33)+1,LEN(A33))) | T33: =TRIM(MID(SUBSTITUTE(A33,"_",REPT(" ",LEN(A33))),(8-1)*LEN(A33)+1,LEN(A33))) | U33: =TRIM(MID(SUBSTITUTE(A33,"_",REPT(" ",LEN(A33))),(9-1)*LEN(A33)+1,LEN(A33))) | V33: =TRIM(MID(SUBSTITUTE(A33,"_",REPT(" ",LEN(A33))),(10-1)*LEN(A33)+1,LEN(A33))) | W33: =TRIM(MID(SUBSTITUTE(A33,"_",REPT(" ",LEN(A33))),(11-1)*LEN(A33)+1,LEN(A33))) | X33: =TRIM(MID(SUBSTITUTE(A33,"_",REPT(" ",LEN(A33))),(12-1)*LEN(A33)+1,LEN(A33)))
B34: =IF(AND(D34="YES",I34="YES",E34="YES",F34="YES",G34="YES",H34="Yes"),"YES","NO") -> NO | C34: =IFERROR(VLOOKUP(M34,Lookups!$A$3:$B$87,2,FALSE),"NO") -> NO | D34: =IFERROR(VLOOKUP(N34,Lookups!$D$2:$E$211,2,FALSE),"NO") -> NO | E34: =IFERROR(VLOOKUP(P34,Lookups!$I$3:$J$8,2,FALSE),"NO") -> NO | F34: =IFERROR(VLOOKUP(Q34,Lookups!$L$3:$M$7,2,FALSE),"NO") -> NO | G34: =IFERROR(VLOOKUP(R34,Lookups!$O$3:$P$21,2,FALSE),"NO") -> NO | H34: =IFERROR(VLOOKUP(S34,Lookups!$S$3:$T$6,2,FALSE),"NO") -> NO | I34: =IFERROR(VLOOKUP(T34,Lookups!$V$3:$W$15,2,FALSE),"NO") -> NO | J34: =IFERROR(VLOOKUP(U34,Lookups!$Z$3:$AA$9,2,FALSE),"NO") -> NO | K34: =IFERROR(VLOOKUP(V34,Lookups!$AC$3:$AD$12,2,FALSE),"NO") -> NO | L34: =IFERROR(VLOOKUP(W34,Lookups!$AH$3:$AI$74,2,FALSE),"NO") -> NO | M34: =TRIM(MID(SUBSTITUTE(A34,"_",REPT(" ",LEN(A34))),(1-1)*LEN(A34)+1,LEN(A34))) | N34: =TRIM(MID(SUBSTITUTE(A34,"_",REPT(" ",LEN(A34))),(2-1)*LEN(A34)+1,LEN(A34))) | O34: =TRIM(MID(SUBSTITUTE(A34,"_",REPT(" ",LEN(A34))),(3-1)*LEN(A34)+1,LEN(A34))) | P34: =TRIM(MID(SUBSTITUTE(A34,"_",REPT(" ",LEN(A34))),(4-1)*LEN(A34)+1,LEN(A34))) | Q34: =TRIM(MID(SUBSTITUTE(A34,"_",REPT(" ",LEN(A34))),(5-1)*LEN(A34)+1,LEN(A34))) | R34: =TRIM(MID(SUBSTITUTE(A34,"_",REPT(" ",LEN(A34))),(6-1)*LEN(A34)+1,LEN(A34))) | S34: =TRIM(MID(SUBSTITUTE(A34,"_",REPT(" ",LEN(A34))),(7-1)*LEN(A34)+1,LEN(A34))) | T34: =TRIM(MID(SUBSTITUTE(A34,"_",REPT(" ",LEN(A34))),(8-1)*LEN(A34)+1,LEN(A34))) | U34: =TRIM(MID(SUBSTITUTE(A34,"_",REPT(" ",LEN(A34))),(9-1)*LEN(A34)+1,LEN(A34))) | V34: =TRIM(MID(SUBSTITUTE(A34,"_",REPT(" ",LEN(A34))),(10-1)*LEN(A34)+1,LEN(A34))) | W34: =TRIM(MID(SUBSTITUTE(A34,"_",REPT(" ",LEN(A34))),(11-1)*LEN(A34)+1,LEN(A34))) | X34: =TRIM(MID(SUBSTITUTE(A34,"_",REPT(" ",LEN(A34))),(12-1)*LEN(A34)+1,LEN(A34)))
