Workbook

Sheet TRECHOS NACIONAL
B7: Principais Trechos | Google Search | 16/nov/2020 a 22/nov/2020
B9: Trechos mais vendidos | D9: Δ posição | E9: PNRs | F9: Vendas | G9: Ticket Médio
B10: ='Dina NACIONAL'!G5 -> GIG-JPA | C10: 1 | D10: =IFERROR((VLOOKUP(B10,'Dina NACIONAL'!A:E,5,FALSE)-(VLOOKUP(B10,B:C,2,FALSE))),"") -> 11 | E10: ='Dina NACIONAL'!H5 -> 116 | F10: ='Dina NACIONAL'!I5 -> 82331.6 | G10: ='Dina NACIONAL'!J5 -> 709.75517 | I10: =#REF! -> #REF!
B11: ='Dina NACIONAL'!G6 -> SSA-CGH | C11: 2 | D11: =IFERROR((VLOOKUP(B11,'Dina NACIONAL'!A:E,5,FALSE)-(VLOOKUP(B11,B:C,2,FALSE))),"") -> 11 | E11: ='Dina NACIONAL'!H6 -> 115 | F11: ='Dina NACIONAL'!I6 -> 76013.68 | G11: ='Dina NACIONAL'!J6 -> 660.98852 | I11: =#REF! -> #REF!
B12: ='Dina NACIONAL'!G7 -> CGH-SSA | C12: 3 | D12: =IFERROR((VLOOKUP(B12,'Dina NACIONAL'!A:E,5,FALSE)-(VLOOKUP(B12,B:C,2,FALSE))),"") -> 5 | E12: ='Dina NACIONAL'!H7 -> 109 | F12: ='Dina NACIONAL'!I7 -> 75531.57 | G12: ='Dina NACIONAL'!J7 -> 692.95018 | I12: =#REF! -> #REF!
B13: ='Dina NACIONAL'!G8 -> GRU-SSA | C13: 4 | D13: =IFERROR((VLOOKUP(B13,'Dina NACIONAL'!A:E,5,FALSE)-(VLOOKUP(B13,B:C,2,FALSE))),"") -> 2 | E13: ='Dina NACIONAL'!H8 -> 132 | F13: ='Dina NACIONAL'!I8 -> 72718.98 | G13: ='Dina NACIONAL'!J8 -> 550.90136 | I13: =#REF! -> #REF!
B14: ='Dina NACIONAL'!G9 -> JPA-GIG | C14: 5 | D14: =IFERROR((VLOOKUP(B14,'Dina NACIONAL'!A:E,5,FALSE)-(VLOOKUP(B14,B:C,2,FALSE))),"") -> 15 | E14: ='Dina NACIONAL'!H9 -> 105 | F14: ='Dina NACIONAL'!I9 -> 66425.98 | G14: ='Dina NACIONAL'!J9 -> 632.62838 | I14: =#REF! -> #REF!
B15: ='Dina NACIONAL'!G10 -> GIG-FOR | C15: 6 | D15: =IFERROR((VLOOKUP(B15,'Dina NACIONAL'!A:E,5,FALSE)-(VLOOKUP(B15,B:C,2,FALSE))),"") -> -5 | E15: ='Dina NACIONAL'!H10 -> 78 | F15: ='Dina NACIONAL'!I10 -> 63716.35 | G15: ='Dina NACIONAL'!J10 -> 816.87628 | I15: =#REF! -> #REF!
B16: ='Dina NACIONAL'!G11 -> CGH-SDU | C16: 7 | D16: =IFERROR((VLOOKUP(B16,'Dina NACIONAL'!A:E,5,FALSE)-(VLOOKUP(B16,B:C,2,FALSE))),"") -> -3 | E16: ='Dina NACIONAL'!H11 -> 189 | F16: ='Dina NACIONAL'!I11 -> 62308.49 | G16: ='Dina NACIONAL'!J11 -> 329.67455 | I16: =#REF! -> #REF!
B17: ='Dina NACIONAL'!G12 -> FOR-GRU | C17: 8 | D17: =IFERROR((VLOOKUP(B17,'Dina NACIONAL'!A:E,5,FALSE)-(VLOOKUP(B17,B:C,2,FALSE))),"") -> 3 | E17: ='Dina NACIONAL'!H12 -> 50 | F17: ='Dina NACIONAL'!I12 -> 61970.57 | G17: ='Dina NACIONAL'!J12 -> 1239.4114 | I17: =#REF! -> #REF!
B18: ='Dina NACIONAL'!G13 -> SSA-GRU | C18: 9 | D18: =IFERROR((VLOOKUP(B18,'Dina NACIONAL'!A:E,5,FALSE)-(VLOOKUP(B18,B:C,2,FALSE))),"") -> 1 | E18: ='Dina NACIONAL'!H13 -> 113 | F18: ='Dina NACIONAL'!I13 -> 59594.99 | G18: ='Dina NACIONAL'!J13 -> 527.38929 | I18: =#REF! -> #REF!
B19: ='Dina NACIONAL'!G14 -> CGH-FOR | C19: 10 | D19: =IFERROR((VLOOKUP(B19,'Dina NACIONAL'!A:E,5,FALSE)-(VLOOKUP(B19,B:C,2,FALSE))),"") -> 4 | E19: ='Dina NACIONAL'!H14 -> 73 | F19: ='Dina NACIONAL'!I14 -> 55921.67 | G19: ='Dina NACIONAL'!J14 -> 766.05027 | I19: =#REF! -> #REF!
B20: ='Dina NACIONAL'!G15 -> FOR-GIG | C20: 11 | D20: =IFERROR((VLOOKUP(B20,'Dina NACIONAL'!A:E,5,FALSE)-(VLOOKUP(B20,B:C,2,FALSE))),"") -> -9 | E20: ='Dina NACIONAL'!H15 -> 71 | F20: ='Dina NACIONAL'!I15 -> 52619.89 | G20: ='Dina NACIONAL'!J15 -> 741.12521 | I20: =#REF! -> #REF!
B21: ='Dina NACIONAL'!G16 -> SDU-CGH | C21: 12 | D21: =IFERROR((VLOOKUP(B21,'Dina NACIONAL'!A:E,5,FALSE)-(VLOOKUP(B21,B:C,2,FALSE))),"") -> -7 | E21: ='Dina NACIONAL'!H16 -> 177 | F21: ='Dina NACIONAL'!I16 -> 52332.11 | G21: ='Dina NACIONAL'!J16 -> 295.66164 | I21: =#REF! -> #REF!
... B39: ='Dina NACIONAL'!G34 -> JPA-BSB | C39: 30 | D39: =IFERROR((VLOOKUP(B39,'Dina NACIONAL'!A:E,5,FALSE)-(VLOOKUP(B39,B:C,2,FALSE))),"") -> 162 | E39: ='Dina NACIONAL'!H34 -> 43 | F39: ='Dina NACIONAL'!I34 -> 36094.18 | G39: ='Dina NACIONAL'!J34 -> 839.39953 | I39: =#REF! -> #REF!
B41: *O comparativo de variação é com base nos resultados da semana anterior

Sheet TRECHOS INTERNACIONAL
B7: ='TRECHOS NACIONAL'!B7 -> Principais Trechos | Google Search | 16/nov/2020 a 22/nov/2020
B9: Trechos mais vendidos | D9: Δ posição | E9: PNRs | F9: Vendas | G9: Ticket Médio
B10: ='Dina INTER'!G5 -> SCL-GRU | C10: 1 | D10: =IFERROR((VLOOKUP(B10,'Dina INTER'!A:E,5,FALSE)-(VLOOKUP(B10,B:C,2,FALSE))),"") -> 12 | E10: ='Dina INTER'!H5 -> 4 | F10: ='Dina INTER'!I5 -> 5453.5 | G10: ='Dina INTER'!J5 -> 1363.375 | I10: =#REF! -> #REF!
B11: ='Dina INTER'!G6 -> GRU-SCL | C11: 2 | D11: =IFERROR((VLOOKUP(B11,'Dina INTER'!A:E,5,FALSE)-(VLOOKUP(B11,B:C,2,FALSE))),"") -> 15 | E11: ='Dina INTER'!H6 -> 3 | F11: ='Dina INTER'!I6 -> 4866.22 | G11: ='Dina INTER'!J6 -> 1622.0733 | I11: =#REF! -> #REF!
B12: ='Dina INTER'!G7 -> BSB-MCZ | C12: 3 | D12: =IFERROR((VLOOKUP(B12,'Dina INTER'!A:E,5,FALSE)-(VLOOKUP(B12,B:C,2,FALSE))),"") -> 712 | E12: ='Dina INTER'!H7 -> 3 | F12: ='Dina INTER'!I7 -> 3764.92 | G12: ='Dina INTER'!J7 -> 1254.9733 | I12: =#REF! -> #REF!
B13: ='Dina INTER'!G8 -> MCO-CGH | C13: 4 | D13: =IFERROR((VLOOKUP(B13,'Dina INTER'!A:E,5,FALSE)-(VLOOKUP(B13,B:C,2,FALSE))),"") | E13: ='Dina INTER'!H8 -> 1 | F13: ='Dina INTER'!I8 -> 3530.58 | G13: ='Dina INTER'!J8 -> 3530.58 | I13: =#REF! -> #REF!
B14: ='Dina INTER'!G9 -> CGH-MCO | C14: 5 | D14: =IFERROR((VLOOKUP(B14,'Dina INTER'!A:E,5,FALSE)-(VLOOKUP(B14,B:C,2,FALSE))),"") | E14: ='Dina INTER'!H9 -> 1 | F14: ='Dina INTER'!I9 -> 3530.58 | G14: ='Dina INTER'!J9 -> 3530.58 | I14: =#REF! -> #REF!
B15: ='Dina INTER'!G10 -> SCL-CNF | C15: 6 | D15: =IFERROR((VLOOKUP(B15,'Dina INTER'!A:E,5,FALSE)-(VLOOKUP(B15,B:C,2,FALSE))),"") | E15: ='Dina INTER'!H10 -> 1 | F15: ='Dina INTER'!I10 -> 2558.16 | G15: ='Dina INTER'!J10 -> 2558.16 | I15: =#REF! -> #REF!
B16: ='Dina INTER'!G11 -> CNF-SCL | C16: 7 | D16: =IFERROR((VLOOKUP(B16,'Dina INTER'!A:E,5,FALSE)-(VLOOKUP(B16,B:C,2,FALSE))),"") | E16: ='Dina INTER'!H11 -> 1 | F16: ='Dina INTER'!I11 -> 2558.16 | G16: ='Dina INTER'!J11 -> 2558.16 | I16: =#REF! -> #REF!
B17: ='Dina INTER'!G12 -> MCZ-BSB | C17: 8 | D17: =IFERROR((VLOOKUP(B17,'Dina INTER'!A:E,5,FALSE)-(VLOOKUP(B17,B:C,2,FALSE))),"") -> 1226 | E17: ='Dina INTER'!H12 -> 3 | F17: ='Dina INTER'!I12 -> 2223.9 | G17: ='Dina INTER'!J12 -> 741.3 | I17: =#REF! -> #REF!
B18: ='Dina INTER'!G13 -> REC-SCL | C18: 9 | D18: =IFERROR((VLOOKUP(B18,'Dina INTER'!A:E,5,FALSE)-(VLOOKUP(B18,B:C,2,FALSE))),"") -> -5 | E18: ='Dina INTER'!H13 -> 1 | F18: ='Dina INTER'!I13 -> 1578.56 | G18: ='Dina INTER'!J13 -> 1578.56 | I18: =#REF! -> #REF!
B19: ='Dina INTER'!G14 -> SCL-REC | C19: 10 | D19: =IFERROR((VLOOKUP(B19,'Dina INTER'!A:E,5,FALSE)-(VLOOKUP(B19,B:C,2,FALSE))),"") -> -5 | E19: ='Dina INTER'!H14 -> 1 | F19: ='Dina INTER'!I14 -> 1471.9 | G19: ='Dina INTER'!J14 -> 1471.9 | I19: =#REF! -> #REF!
B20: ='Dina INTER'!G15 -> JPA-BVB | C20: 11 | D20: =IFERROR((VLOOKUP(B20,'Dina INTER'!A:E,5,FALSE)-(VLOOKUP(B20,B:C,2,FALSE))),"") | E20: ='Dina INTER'!H15 -> 1 | F20: ='Dina INTER'!I15 -> 1367.9 | G20: ='Dina INTER'!J15 -> 1367.9 | I20: =#REF! -> #REF!
B21: ='Dina INTER'!G16 -> PNZ-EZE | C21: 12 | D21: =IFERROR((VLOOKUP(B21,'Dina INTER'!A:E,5,FALSE)-(VLOOKUP(B21,B:C,2,FALSE))),"") | E21: ='Dina INTER'!H16 -> 2 | F21: ='Dina INTER'!I16 -> 1241.26 | G21: ='Dina INTER'!J16 -> 620.63 | I21: =#REF! -> #REF!
... B39: ='Dina INTER'!G34 -> POA-CWB | C39: 30 | D39: =IFERROR((VLOOKUP(B39,'Dina INTER'!A:E,5,FALSE)-(VLOOKUP(B39,B:C,2,FALSE))),"") -> 1114 | E39: ='Dina INTER'!H34 -> 1 | F39: ='Dina INTER'!I34 -> 64.14 | G39: ='Dina INTER'!J34 -> 64.14 | I39: =#REF! -> #REF!

Sheet Dina NACIONAL
A1: Tipo de Voo | B1: Destinos Nacionais GOL - Site Brasil | G1: Tipo de Voo | H1: Destinos Nacionais GOL - Site Brasil
A2: Período | B2: Anterior | G2: Período | H2: Atual
A4: Rótulos de Linha | B4: Soma de Quantidade | C4: Soma de Receita do produto | D4: Soma de TKM | E4: Posição | G4: Rótulos de Linha | H4: Soma de Quantidade | I4: Soma de Receita do produto | J4: Soma de TKM | K4: Posição
A5: GIG-FOR | B5: 134 | C5: 120181.54 | D5: 896.87716 | E5: 1 | G5: GIG-JPA | H5: 116 | I5: 82331.6 | J5: 709.75517 | K5: 1
A6: FOR-GIG | B6: 135 | C6: 99292.95 | D6: 735.50333 | E6: 2 | G6: SSA-CGH | H6: 115 | I6: 76013.68 | J6: 660.98852 | K6: 2
A7: BSB-FOR | B7: 97 | C7: 80289.96 | D7: 827.73155 | E7: 3 | G7: CGH-SSA | H7: 109 | I7: 75531.57 | J7: 692.95018 | K7: 3
A8: CGH-SDU | B8: 271 | C8: 76767.49 | D8: 283.27487 | E8: 4 | G8: GRU-SSA | H8: 132 | I8: 72718.98 | J8: 550.90136 | K8: 4
A9: SDU-CGH | B9: 271 | C9: 76674.13 | D9: 282.93037 | E9: 5 | G9: JPA-GIG | H9: 105 | I9: 66425.98 | J9: 632.62838 | K9: 5
A10: GRU-SSA | B10: 110 | C10: 70994.546 | D10: 645.40496 | E10: 6 | G10: GIG-FOR | H10: 78 | I10: 63716.35 | J10: 816.87628 | K10: 6
A11: FOR-BSB | B11: 92 | C11: 69008.43 | D11: 750.09163 | E11: 7 | G11: CGH-SDU | H11: 189 | I11: 62308.49 | J11: 329.67455 | K11: 7
A12: CGH-SSA | B12: 74 | C12: 66116.42 | D12: 893.46514 | E12: 8 | G12: FOR-GRU | H12: 50 | I12: 61970.57 | J12: 1239.4114 | K12: 8
A13: GRU-FOR | B13: 73 | C13: 66042.12 | D13: 904.68658 | E13: 9 | G13: SSA-GRU | H13: 113 | I13: 59594.99 | J13: 527.38929 | K13: 9
A14: SSA-GRU | B14: 105 | C14: 64748.92 | D14: 616.65638 | E14: 10 | G14: CGH-FOR | H14: 73 | I14: 55921.67 | J14: 766.05027 | K14: 10
A15: FOR-GRU | B15: 67 | C15: 62936.4 | D15: 939.34925 | E15: 11 | G15: FOR-GIG | H15: 71 | I15: 52619.89 | J15: 741.12521 | K15: 11
A16: GIG-JPA | B16: 75 | C16: 59518.82 | D16: 793.58427 | E16: 12 | G16: SDU-CGH | H16: 177 | I16: 52332.11 | J16: 295.66164 | K16: 12
... A1087: MCZ-DOU | B1087: 1 | C1087: 0 | D1087: 0 | E1087: 1083 | G1087: UDI-PNZ | H1087: 1 | I1087: 0 | J1087: 0 | K1087: 1083
A1088: PPB-BEL | B1088: 1 | C1088: 0 | D1088: 0 | E1088: 1084 | G1088: MDZ-CWB | H1088: 0 | I1088: 0 | J1088: #DIV/0! | K1088: 1084
A1089: VCP-VDC | B1089: 1 | C1089: 0 | D1089: 0 | E1089: 1085 | G1089: FOR-BRA | H1089: 1 | I1089: 0 | J1089: 0 | K1089: 1085
A1090: DOU-CNF | B1090: 1 | C1090: 0 | D1090: 0 | E1090: 1086 | G1090: BRA-BEL | H1090: 2 | I1090: 0 | J1090: 0 | K1090: 1086
A1091: VDC-BEL | B1091: 3 | C1091: 0 | D1091: 0 | E1091: 1087 | G1091: IOS-SSA | H1091: 13 | I1091: 0 | J1091: 0 | K1091: 1087
A1092: BVB-SSA | B1092: 1 | C1092: 0 | D1092: 0 | E1092: 1088 | G1092: PVH-FLN | H1092: 1 | I1092: 0 | J1092: 0 | K1092: 1088
A1093: VDC-GIG | B1093: 2 | C1093: 0 | D1093: 0 | E1093: 1089 | G1093: REC-BRA | H1093: 2 | I1093: 0 | J1093: 0 | K1093: 1089
A1094: CGR-IOS | B1094: 1 | C1094: 0 | D1094: 0 | E1094: 1090 | G1094: MAB-CFB | H1094: 1 | I1094: 0 | J1094: 0 | K1094: 1090
A1095: BEL-VDC | B1095: 2 | C1095: 0 | D1095: 0 | E1095: 1091 | G1095: MDE-POA | H1095: 1 | I1095: 0 | J1095: 0 | K1095: 1091
A1096: BRA-FOR | B1096: 1 | C1096: 0 | D1096: 0 | E1096: 1092 | G1096: VDC-GYN | H1096: 1 | I1096: 0 | J1096: 0 | K1096: 1092
A1097: DOU-MCZ | B1097: 1 | C1097: 0 | D1097: 0 | E1097: 1093 | G1097: CWB-MDZ | H1097: 0 | I1097: 0 | J1097: #DIV/0! | K1097: 1093
A1098: GYN-PNZ | B1098: 1 | C1098: 0 | D1098: 0 | E1098: 1094 | G1098: BPS-SLZ | H1098: 4 | I1098: 0 | J1098: 0 | K1098: 1094
A1099: MCZ-SSA | B1099: 3 | C1099: 0 | D1099: 0 | E1099: 1095 | G1099: BIO-NVT | H1099: 1 | I1099: 0 | J1099: 0 | K1099: 1095
A1100: BRA-MCZ | B1100: 3 | C1100: 0 | D1100: 0 | E1100: 1096 | G1100: BRA-XAP | H1100: 1 | I1100: 0 | J1100: 0 | K1100: 1096
A1101: UDI-IOS | B1101: 1 | C1101: 0 | D1101: 0 | E1101: 1097 | G1101: CFB-MAB | H1101: 1 | I1101: 0 | J1101: 0 | K1101: 1097
A1102: SLZ-BPS | B1102: 2 | C1102: 0 | D1102: 0 | E1102: 1098 | G1102: PNZ-BEL | H1102: 1 | I1102: 0 | J1102: 0 | K1102: 1098
A1103: GIG-VDC | B1103: 3 | C1103: 0 | D1103: 0 | E1103: 1099 | G1103: IGU-DOU | H1103: 1 | I1103: 0 | J1103: 0 | K1103: 1099
A1104: SJP-NAT | B1104: 1 | C1104: 0 | D1104: 0 | E1104: 1100 | G1104: RAO-MCZ | H1104: 1 | I1104: 0 | J1104: 0 | K1104: 1100
A1105: PNZ-SSA | B1105: 1 | C1105: 0 | D1105: 0 | E1105: 1101 | G1105: MOC-CWB | H1105: 1 | I1105: 0 | J1105: 0 | K1105: 1101
A1106: SLZ-VDC | B1106: 1 | C1106: 0 | D1106: 0 | E1106: 1102 | G1106: THE-BPS | H1106: 1 | I1106: 0 | J1106: 0 | K1106: 1102
A1107: ARU-FOR | B1107: 5 | C1107: 0 | D1107: 0 | E1107: 1103 | G1107: MDE-VIX | H1107: 1 | I1107: 0 | J1107: 0 | K1107: 1103
A1108: VDC-SLZ | B1108: 1 | C1108: 0 | D1108: 0 | E1108: 1104 | G1108: XAP-BRA | H1108: 1 | I1108: 0 | J1108: 0 | K1108: 1104
A1109: NAT-RAO | B1109: 1 | C1109: 0 | D1109: 0 | E1109: 1105 | G1109: CNF-PNZ | H1109: 1 | I1109: 0 | J1109: 0 | K1109: 1105
... A1137: FOR-MCZ | B1137: 1 | C1137: 0 | D1137: 0 | E1137: 1133 | G1137: SJP-REC | H1137: 3 | I1137: 0 | J1137: 0 | K1137: 1133
A1138: VCP-BRA | B1138: 1 | C1138: 0 | D1138: 0 | E1138: 1134 | G1138: CGH-MCO | H1138: 0 | I1138: 0 | J1138: #DIV/0! | K1138: 1134
...

Sheet Dina INTER
A1: Tipo de Voo | B1: Destinos Internacionais GOL - Site Brasil | G1: Tipo de Voo | H1: Destinos Internacionais GOL - Site Brasil
A2: Período | B2: Anterior | G2: Período | H2: Atual
A4: Rótulos de Linha | B4: Soma de Quantidade | C4: Soma de Receita do produto | D4: Soma de TKM | E4: Posição | G4: Rótulos de Linha | H4: Soma de Quantidade | I4: Soma de Receita do produto | J4: Soma de TKM | K4: Posição
A5: FOR-VCP | B5: 1 | C5: 4099.6 | D5: 4099.6 | E5: 1 | G5: SCL-GRU | H5: 4 | I5: 5453.5 | J5: 1363.375 | K5: 1
A6: MVD-CNF | B6: 2 | C6: 3357.08 | D6: 1678.54 | E6: 2 | G6: GRU-SCL | H6: 3 | I6: 4866.22 | J6: 1622.0733 | K6: 2
A7: GYN-MCZ | B7: 2 | C7: 1861.6 | D7: 930.8 | E7: 3 | G7: BSB-MCZ | H7: 3 | I7: 3764.92 | J7: 1254.9733 | K7: 3
A8: REC-SCL | B8: 2 | C8: 1431.69 | D8: 715.845 | E8: 4 | G8: MCO-CGH | H8: 1 | I8: 3530.58 | J8: 3530.58 | K8: 4
A9: SCL-REC | B9: 2 | C9: 1431.69 | D9: 715.845 | E9: 5 | G9: CGH-MCO | H9: 1 | I9: 3530.58 | J9: 3530.58 | K9: 5
A10: BSB-POA | B10: 1 | C10: 1131.9 | D10: 1131.9 | E10: 6 | G10: SCL-CNF | H10: 1 | I10: 2558.16 | J10: 2558.16 | K10: 6
A11: VVI-GRU | B11: 1 | C11: 995.63 | D11: 995.63 | E11: 7 | G11: CNF-SCL | H11: 1 | I11: 2558.16 | J11: 2558.16 | K11: 7
A12: CNF-EZE | B12: 1 | C12: 965.44 | D12: 965.44 | E12: 8 | G12: MCZ-BSB | H12: 3 | I12: 2223.9 | J12: 741.3 | K12: 8
A13: POA-BSB | B13: 1 | C13: 913.9 | D13: 913.9 | E13: 9 | G13: REC-SCL | H13: 1 | I13: 1578.56 | J13: 1578.56 | K13: 9
A14: FOR-GRU | B14: 1 | C14: 891.8 | D14: 891.8 | E14: 10 | G14: SCL-REC | H14: 1 | I14: 1471.9 | J14: 1471.9 | K14: 10
A15: GRU-FOR | B15: 1 | C15: 891.8 | D15: 891.8 | E15: 11 | G15: JPA-BVB | H15: 1 | I15: 1367.9 | J15: 1367.9 | K15: 11
A16: FOR-SSA | B16: 2 | C16: 753.8 | D16: 376.9 | E16: 12 | G16: PNZ-EZE | H16: 2 | I16: 1241.26 | J16: 620.63 | K16: 12
... A26: SDU-CNF | B26: 1 | C26: 416.14 | D26: 416.14 | E26: 22 | G26: GRU-IOS | H26: 1 | I26: 605.8 | J26: 605.8 | K26: 22
A27: LDB-OPS | B27: 0 | C27: 0 | D27: #DIV/0! | E27: 23 | G27: IOS-GRU | H27: 1 | I27: 605.8 | J27: 605.8 | K27: 23
A28: PVH-JPA | B28: 0 | C28: 0 | D28: #DIV/0! | E28: 24 | G28: POA-VIX | H28: 1 | I28: 263.9 | J28: 263.9 | K28: 24
A29: BEL-CZS | B29: 0 | C29: 0 | D29: #DIV/0! | E29: 25 | G29: POA-GIG | H29: 1 | I29: 215 | J29: 215 | K29: 25
A30: XAP-SSA | B30: 0 | C30: 0 | D30: #DIV/0! | E30: 26 | G30: MCZ-GIG | H30: 1 | I30: 199 | J30: 199 | K30: 26
A31: VCP-SDU | B31: 0 | C31: 0 | D31: #DIV/0! | E31: 27 | G31: GIG-MCZ | H31: 1 | I31: 199 | J31: 199 | K31: 27
A32: MAO-CGH | B32: 0 | C32: 0 | D32: #DIV/0! | E32: 28 | G32: BSB-VCP | H32: 1 | I32: 73.9 | J32: 73.9 | K32: 28
A33: IOS-PVH | B33: 0 | C33: 0 | D33: #DIV/0! | E33: 29 | G33: CWB-POA | H33: 1 | I33: 64.14 | J33: 64.14 | K33: 29
A34: CAC-FOR | B34: 0 | C34: 0 | D34: #DIV/0! | E34: 30 | G34: POA-CWB | H34: 1 | I34: 64.14 | J34: 64.14 | K34: 30
A35: POA-NVT | B35: 0 | C35: 0 | D35: #DIV/0! | E35: 31 | G35: VIX-STM | H35: 0 | I35: 0 | J35: #DIV/0! | K35: 31
A36: FEN-IGU | B36: 0 | C36: 0 | D36: #DIV/0! | E36: 32 | G36: NAT-RBR | H36: 0 | I36: 0 | J36: #DIV/0! | K36: 32
A37: NVT-VDC | B37: 0 | C37: 0 | D37: #DIV/0! | E37: 33 | G37: DOU-CWB | H37: 0 | I37: 0 | J37: #DIV/0! | K37: 33
A38: IGU-FEN | B38: 0 | C38: 0 | D38: #DIV/0! | E38: 34 | G38: CAC-MCZ | H38: 0 | I38: 0 | J38: #DIV/0! | K38: 34
A39: POA-SMT | B39: 0 | C39: 0 | D39: #DIV/0! | E39: 35 | G39: PFB-IGU | H39: 0 | I39: 0 | J39: #DIV/0! | K39: 35
A40: BSB-CZS | B40: 0 | C40: 0 | D40: #DIV/0! | E40: 36 | G40: FOR-CAC | H40: 0 | I40: 0 | J40: #DIV/0! | K40: 36
A41: BPS-PVH | B41: 0 | C41: 0 | D41: #DIV/0! | E41: 37 | G41: BRA-BEL | H41: 0 | I41: 0 | J41: #DIV/0! | K41: 37
A42: CAC-MCZ | B42: 0 | C42: 0 | D42: #DIV/0! | E42: 38 | G42: FOR-CGB | H42: 0 | I42: 0 | J42: #DIV/0! | K42: 38
A43: CWB-CFB | B43: 0 | C43: 0 | D43: #DIV/0! | E43: 39 | G43: CNF-PNZ | H43: 0 | I43: 0 | J43: #DIV/0! | K43: 39
A44: FOR-CAC | B44: 0 | C44: 0 | D44: #DIV/0! | E44: 40 | G44: GIG-XAP | H44: 0 | I44: 0 | J44: #DIV/0! | K44: 40
A45: MCZ-MAB | B45: 0 | C45: 0 | D45: #DIV/0! | E45: 41 | G45: IOS-CGR | H45: 0 | I45: 0 | J45: #DIV/0! | K45: 41
A46: FOR-CGB | B46: 0 | C46: 0 | D46: #DIV/0! | E46: 42 | G46: MAB-BPS | H46: 0 | I46: 0 | J46: #DIV/0! | K46: 42
... A676: CGH-MCZ | B676: 0 | C676: 0 | D676: #DIV/0! | E676: 672 | G676: CWB-PMW | H676: 0 | I676: 0 | J676: #DIV/0! | K676: 672
A677: CGH-BSB | B677: 1 | C677: 0 | D677: 0 | E677: 673 | G677: SDU-CNF | H677: 0 | I677: 0 | J677: #DIV/0! | K677: 673
A678: CGR-BPS | B678: 0 | C678: 0 | D678: #DIV/0! | E678: 674 | G678: GRU-PPB | H678: 0 | I678: 0 | J678: #DIV/0! | K678: 674
A679: CGH-BPS | B679: 0 | C679: 0 | D679: #DIV/0! | E679: 675 | G679: SDU-CWB | H679: 0 | I679: 0 | J679: #DIV/0! | K679: 675
...

Sheet Base
A1: Período | B1: Produto | C1: Tipo de Voo | D1: Quantidade | E1: Receita do produto
A2: Anterior | B2: EZE-FLN | C2: Destinos Internacionais GOL - Site Brasil | D2: 2 | E2: 0
A3: Anterior | B3: EZE-FLN | C3: Destinos Nacionais GOL - Site Brasil | D3: 0 | E3: 0
A4: Anterior | B4: FLN-EZE | C4: Destinos Internacionais GOL - Site Brasil | D4: 2 | E4: 0
A5: Anterior | B5: FLN-EZE | C5: Destinos Nacionais GOL - Site Brasil | D5: 0 | E5: 0
A6: Anterior | B6: FOR-SSA | C6: Destinos Internacionais GOL - Site Brasil | D6: 2 | E6: 753.8
A7: Anterior | B7: FOR-SSA | C7: Destinos Nacionais GOL - Site Brasil | D7: 34 | E7: 22580.35
A8: Anterior | B8: GYN-MCZ | C8: Destinos Internacionais GOL - Site Brasil | D8: 2 | E8: 1861.6
A9: Anterior | B9: GYN-MCZ | C9: Destinos Nacionais GOL - Site Brasil | D9: 9 | E9: 12771.85
A10: Anterior | B10: MVD-CNF | C10: Destinos Internacionais GOL - Site Brasil | D10: 2 | E10: 3357.08
A11: Anterior | B11: MVD-CNF | C11: Destinos Nacionais GOL - Site Brasil | D11: 0 | E11: 0
A12: Anterior | B12: REC-SCL | C12: Destinos Internacionais GOL - Site Brasil | D12: 2 | E12: 1431.69
A13: Anterior | B13: REC-SCL | C13: Destinos Nacionais GOL - Site Brasil | D13: 0 | E13: 0
... A5021: Atual | B5021: XAP-VIX | C5021: Destinos Nacionais GOL - Site Brasil | D5021: 1 | E5021: 0
