Workbook

Sheet AI06
B2: MODELO DE MATURIDADE
B4: AI06 Gerenciar Mudanças
C6: ESTA AFIRMAÇÃO É VERDADEIRA? indique com um X no quadro abaixo | I6: VALOR MÉDIO DO NÍVEL DE MATURIDADE
C7: 0% Não existente | D7: 15% Está iniciando um trabalho | E7: 25% Significativamente inferior | F7: 50% Parcialmente | G7: 75% Levemente interior ao anterior | H7: 100% Totalmente aderente
B8: 0 Inexistente quando | I8: =I11 -> 1
A9: 1 | B9: Não há um processo de gerenciamento de mudanças formalmente estabelecido, as mudanças podem ser feitas praticamente sem nenhum controle. | H9: x
A10: =A9+ 1 -> 2 | B10: Não há consciência de que as mudanças podem interromper as operações de TI de negócio, tampouco há consciência dos benefícios de um bom gerenciamento de mudanças. | H10: x
C11: =(COUNTIF(C9:C10,"*")*0%) -> 0 | D11: =(COUNTIF(D9:D10,"*")*15%) -> 0 | E11: =(COUNTIF(E9:E10,"*")*25%) -> 0 | F11: =(COUNTIF(F9:F10,"*")*50%) -> 0 | G11: =(COUNTIF(G9:G10,"*")*75%) -> 0 | H11: =(COUNTIF(H9:H10,"*")*100%) -> 2 | I11: =SUM(C11:H11)/2 -> 1 | J11: 2 | K11: =J11/$J$48 -> 0.076923077 | L11: =I11*K11 -> 0.076923077
B12: 1 Inicial/ Ad Hoc quando | I12: =I17 -> 0.75
A13: =A10 + 1 -> 3 | B13: É reconhecido que as mudanças devem ser gerenciadas e controladas. | G13: x
A14: =A13+1 -> 4 | B14: As práticas variam, e existe a probabilidade de execução de mudanças não autorizadas. | G14: x
A15: =A14+1 -> 5 | B15: A documentação de mudança é insuficiente ou inexistente e a de configuração é incompleta e não confiável. | G15: x
A16: =A15+1 -> 6 | B16: Provavelmente os erros ocorrem junto com interrupções no ambiente de produção devido a um gerenciamento de mudanças ineficiente. | G16: x
C17: =(COUNTIF(C13:C16,"*")*0%) -> 0 | D17: =(COUNTIF(D13:D16,"*")*15%) -> 0 | E17: =(COUNTIF(E13:E16,"*")*25%) -> 0 | F17: =(COUNTIF(F13:F16,"*")*50%) -> 0 | G17: =(COUNTIF(G13:G16,"*")*75%) -> 3 | H17: =(COUNTIF(H13:H16,"*")*100%) -> 0 | I17: =SUM(C17:H17)/4 -> 0.75 | J17: 4 | K17: =J17/$J$48 -> 0.15384615 | L17: =I17*K17 -> 0.11538462
B18: 2 Repetível porém Intuitivo quando | I18: =I21 -> 0.325
A19: =A16 + 1 -> 7 | B19: Há um processo informal de gerenciamento de mudanças seguido na maioria das mudanças ocorridas, porém esse processo é desestruturado, rudimentar e propenso a erros. | F19: x
A20: =A19 + 1 -> 8 | B20: A precisão da documentação de configuração é inconsistente, e antes da mudança apenas são realizados um planejamento e uma avaliação limitados dos impactos. | D20: x
C21: =(COUNTIF(C19:C20,"*")*0%) -> 0 | D21: =(COUNTIF(D19:D20,"*")*15%) -> 0.15 | E21: =(COUNTIF(E19:E20,"*")*25%) -> 0 | F21: =(COUNTIF(F19:F20,"*")*50%) -> 0.5 | G21: =(COUNTIF(G19:G20,"*")*75%) -> 0 | H21: =(COUNTIF(H19:H20,"*")*100%) -> 0 | I21: =SUM(C21:H21)/2 -> 0.325 | J21: 2 | K21: =J21/$J$48 -> 0.076923077 | L21: =I21*K21 -> 0.025
B22: 3 Processo Definido quando | I22: =I27 -> 0.625
A23: =A20 + 1 -> 9 | B23: Há um processo formal de gerenciamento de mudanças, que inclui categorização, priorização, procedimentos de emergência, autorização de mudança e controle de versão, porém a conformidade com o processo ainda é emergente. | G23: x
A24: =A23+1 -> 10 | B24: São aplicadas soluções alternativas, e com frequência os processos são ignorados. | F24: x
A25: =A24+1 -> 11 | B25: Podem ocorrer erros, e mudanças não autorizadas acontecem ocasionalmente. | F25: x
A26: =A25+1 -> 12 | B26: A análise de impacto das mudanças de TI sobre as operações de negócios começa a ser formalizada para apoiar a implementação planejada de novas tecnologias e aplicações. | G26: x
C27: =(COUNTIF(C23:C26,"*")*0%) -> 0 | D27: =(COUNTIF(D23:D26,"*")*15%) -> 0 | E27: =(COUNTIF(E23:E26,"*")*25%) -> 0 | F27: =(COUNTIF(F23:F26,"*")*50%) -> 1 | G27: =(COUNTIF(G23:G26,"*")*75%) -> 1.5 | H27: =(COUNTIF(H23:H26,"*")*100%) -> 0 | I27: =SUM(C27:H27)/4 -> 0.625 | J27: 4 | K27: =J27/$J$48 -> 0.15384615 | L27: =I27*K27 -> 0.096153846
B28: 4 Gerenciado e Mensurável quando | I28: =I38 -> 0
A29: =A26 + 1 -> 13 | B29: O processo de gerenciamento de mudanças é bem desenvolvido, acompanha consistentemente todas as mudanças e os responsáveis pelo gerenciamento podem afirmar que as exceções são mínimas. | C29: x
A30: =A29 + 1 -> 14 | B30: Os processos são eficazes e eficientes, porém se apóiam em vários procedimentos e controles manuais para assegurar que a qualidade seja obtida. | C30: x
A31: =A30 + 1 -> 15 | B31: Todas as mudanças estão sujeitas ao planejamento e à avaliação de impacto para minimizar a probabilidade de problemas após a produção. | C31: x
A32: =A31 + 1 -> 16 | B32: Há um processo de aprovação de mudanças estabelecido. | C32: x
A33: =A32 + 1 -> 17 | B33: A documentação de gerenciamento de mudanças está atualizada e correta, e as mudanças são controladas formalmente. | C33: x
A34: =A33 + 1 -> 18 | B34: A documentação de configuração é precisa. | C34: x
A35: =A34 + 1 -> 19 | B35: O planejamento e a implementação do gerenciamento de mudanças estão ficando mais integrados com as mudanças nos processos de negócio, para assegurar que o treinamento, as mudanças organizacionais e as questões de continuidade de negócio sejam tratados. | C35: x
A36: =A35 + 1 -> 20 | B36: Há maior coordenação entre o gerenciamento de mudanças de TI e a redefinição de processos de negócio. | C36: x
A37: =A36 + 1 -> 21 | B37: Há um processo consistente para monitorar a qualidade e o desempenho do processo de gerenciamento de mudanças. | C37: x
C38: =(COUNTIF(C29:C37,"*")*0%) -> 0 | D38: =(COUNTIF(D29:D37,"*")*15%) -> 0 | E38: =(COUNTIF(E29:E37,"*")*25%) -> 0 | F38: =(COUNTIF(F29:F37,"*")*50%) -> 0 | G38: =(COUNTIF(G29:G37,"*")*75%) -> 0 | H38: =(COUNTIF(H29:H37,"*")*100%) -> 0 | I38: =SUM(C38:H38)/9 -> 0 | J38: 9 | K38: =J38/$J$48 -> 0.34615385 | L38: =I38*K38 -> 0
B39: 5 Otimizado quando | I39: =I45 -> 0
A40: =A37+1 -> 22 | B40: O processo de gerenciamento de mudanças é revisado e atualizado regularmente para permanecer em alinhamento com as boas práticas. | C40: x
A41: =A40+1 -> 23 | B41: O processo de revisão reflete o resultado do monitoramento. | C41: x
A42: =A41+1 -> 24 | B42: As informações de configuração são automatizadas por software e propiciam o controle de versão. | C42: x
A43: =A42+1 -> 25 | B43: O rastreamento de mudanças é sofisticado e inclui ferramentas que detectam software sem licença e não autorizado. | C43: x
...

Sheet AI06 Grafico
A2: Maturidade
A3: Nível | B3: Aderência ao nível | C3: Falta para atingir o nível
A4: Nível 0 | B4: ='AI06'!$I$8 -> 1 | C4: =1-B4 -> 0
A5: Nível 1 | B5: ='AI06'!$I$12 -> 0.75 | C5: =1-B5 -> 0.25
A6: Nível 2 | B6: ='AI06'!$I$18 -> 0.325 | C6: =1-B6 -> 0.675
A7: Nível 3 | B7: ='AI06'!$I$22 -> 0.625 | C7: =1-B7 -> 0.375
A8: Nível 4 | B8: ='AI06'!$I$28 -> 0 | C8: =1-B8 -> 1
A9: Nível 5 | B9: ='AI06'!$I$39 -> 0 | C9: =1-B9 -> 1
